Workbook
Name damp: calibration!$J$1

Sheet summary
A3: ACS 2023, Table B08201: Household Size by Vehicles Available (Universe, Households) | J3: 2023 Model Data | R3: Model Share minus Observed Share
B6: County | C6: Number of Vehicles | J6: County | K6: Number of Vehicles
C7: 0 | D7: 1 | E7: 2 | F7: 3 | G7: 4+ | H7: Total | K7: 0 | L7: 1 | M7: 2 | N7: 3 | O7: 4+ | P7: Total
B8: San Francisco | C8: =ACS_1YR_B08201!F$9 -> 115112 | D8: =ACS_1YR_B08201!H$9 -> 163438 | E8: =ACS_1YR_B08201!J$9 -> 70754 | F8: =ACS_1YR_B08201!L$9 -> 14842 | G8: =ACS_1YR_B08201!N$9 -> 7881 | H8: =SUM(C8:G8) -> 372027 | J8: San Francisco | K8: =modeldata!C4 -> 1 | L8: =modeldata!D4 -> 1 | M8: =modeldata!E4 -> 1 | N8: =modeldata!F4 -> 1 | O8: =modeldata!G4 -> 1 | P8: =SUM(K8:O8) -> 5
B9: San Mateo | C9: =ACS_1YR_B08201!F$10 -> 13792 | D9: =ACS_1YR_B08201!H$10 -> 87455 | E9: =ACS_1YR_B08201!J$10 -> 100042 | F9: =ACS_1YR_B08201!L$10 -> 41492 | G9: =+ACS_1YR_B08201!N$10 -> 22343 | H9: =SUM(C9:G9) -> 265124 | J9: San Mateo | K9: =modeldata!C5 -> 1 | L9: =modeldata!D5 -> 1 | M9: =modeldata!E5 -> 1 | N9: =modeldata!F5 -> 1 | O9: =modeldata!G5 -> 1 | P9: =SUM(K9:O9) -> 5
B10: Santa Clara | C10: =ACS_1YR_B08201!F$11 -> 39177 | D10: =ACS_1YR_B08201!H$11 -> 217368 | E10: =ACS_1YR_B08201!J$11 -> 250244 | F10: =ACS_1YR_B08201!L$11 -> 99869 | G10: =+ACS_1YR_B08201!N$11 -> 58891 | H10: =SUM(C10:G10) -> 665549 | J10: Santa Clara | K10: =modeldata!C6 -> 1 | L10: =modeldata!D6 -> 1 | M10: =modeldata!E6 -> 1 | N10: =modeldata!F6 -> 1 | O10: =modeldata!G6 -> 1 | P10: =SUM(K10:O10) -> 5
B11: Alameda | C11: =ACS_1YR_B08201!F$5 -> 66589 | D11: =ACS_1YR_B08201!H$5 -> 209193 | E11: =ACS_1YR_B08201!J$5 -> 208803 | F11: =ACS_1YR_B08201!L$5 -> 78038 | G11: =+ACS_1YR_B08201!N$5 -> 45911 | H11: =SUM(C11:G11) -> 608534 | J11: Alameda | K11: =modeldata!C7 -> 1 | L11: =modeldata!D7 -> 1 | M11: =modeldata!E7 -> 1 | N11: =modeldata!F7 -> 1 | O11: =modeldata!G7 -> 1 | P11: =SUM(K11:O11) -> 5
B12: Contra Costa | C12: =ACS_1YR_B08201!F$6 -> 20544 | D12: =ACS_1YR_B08201!H$6 -> 122178 | E12: =ACS_1YR_B08201!J$6 -> 156754 | F12: =ACS_1YR_B08201!L$6 -> 72177 | G12: =+ACS_1YR_B08201!N$6 -> 44519 | H12: =SUM(C12:G12) -> 416172 | J12: Contra Costa | K12: =modeldata!C8 -> 1 | L12: =modeldata!D8 -> 1 | M12: =modeldata!E8 -> 1 | N12: =modeldata!F8 -> 1 | O12: =modeldata!G8 -> 1 | P12: =SUM(K12:O12) -> 5
B13: Solano | C13: =ACS_1YR_B08201!F$12 -> 8484 | D13: =ACS_1YR_B08201!H$12 -> 41211 | E13: =ACS_1YR_B08201!J$12 -> 57659 | F13: =ACS_1YR_B08201!L$12 -> 29578 | G13: =+ACS_1YR_B08201!N$12 -> 20834 | H13: =SUM(C13:G13) -> 157766 | J13: Solano | K13: =modeldata!C9 -> 1 | L13: =modeldata!D9 -> 1 | M13: =modeldata!E9 -> 1 | N13: =modeldata!F9 -> 1 | O13: =modeldata!G9 -> 1 | P13: =SUM(K13:O13) -> 5
B14: Napa | C14: =ACS_1YR_B08201!F$8 -> 2839 | D14: =ACS_1YR_B08201!H$8 -> 13612 | E14: =ACS_1YR_B08201!J$8 -> 20390 | F14: =ACS_1YR_B08201!L$8 -> 8406 | G14: =+ACS_1YR_B08201!N$8 -> 5920 | H14: =SUM(C14:G14) -> 51167 | J14: Napa | K14: =modeldata!C10 -> 1 | L14: =modeldata!D10 -> 1 | M14: =modeldata!E10 -> 1 | N14: =modeldata!F10 -> 1 | O14: =modeldata!G10 -> 1 | P14: =SUM(K14:O14) -> 5
B15: Sonoma | C15: =ACS_1YR_B08201!F$13 -> 8223 | D15: =ACS_1YR_B08201!H$13 -> 58846 | E15: =ACS_1YR_B08201!J$13 -> 72836 | F15: =ACS_1YR_B08201!L$13 -> 33514 | G15: =+ACS_1YR_B08201!N$13 -> 19346 | H15: =SUM(C15:G15) -> 192765 | J15: Sonoma | K15: =modeldata!C11 -> 1 | L15: =modeldata!D11 -> 1 | M15: =modeldata!E11 -> 1 | N15: =modeldata!F11 -> 1 | O15: =modeldata!G11 -> 1 | P15: =SUM(K15:O15) -> 5
B16: Marin | C16: =ACS_1YR_B08201!F$7 -> 4136 | D16: =ACS_1YR_B08201!H$7 -> 32863 | E16: =ACS_1YR_B08201!J$7 -> 43411 | F16: =ACS_1YR_B08201!L$7 -> 16097 | G16: =+ACS_1YR_B08201!N$7 -> 5101 | H16: =SUM(C16:G16) -> 101608 | J16: Marin | K16: =modeldata!C12 -> 1 | L16: =modeldata!D12 -> 1 | M16: =modeldata!E12 -> 1 | N16: =modeldata!F12 -> 1 | O16: =modeldata!G12 -> 1 | P16: =SUM(K16:O16) -> 5
B17: Total | C17: =SUM(C8:C16) -> 278896 | D17: =SUM(D8:D16) -> 946164 | E17: =SUM(E8:E16) -> 980893 | F17: =SUM(F8:F16) -> 394013 | G17: =SUM(G8:G16) -> 230746 | H17: =SUM(H8:H16) -> 2830712 | J17: Total | K17: =SUM(K8:K16) -> 9 | L17: =SUM(L8:L16) -> 9 | M17: =SUM(M8:M16) -> 9 | N17: =SUM(N8:N16) -> 9 | O17: =SUM(O8:O16) -> 9 | P17: =SUM(P8:P16) -> 45
B20: County | C20: Number of Vehicles | J20: County | K20: Number of Vehicles | R20: County | S20: Number of Vehicles
C21: 0 | D21: 1 | E21: 2 | F21: 3 | G21: 4+ | H21: Total | K21: 0 | L21: 1 | M21: 2 | N21: 3 | O21: 4+ | P21: Total | S21: 0 | T21: 1 | U21: 2 | V21: 3 | W21: 4+ | X21: Total
B22: San Francisco | C22: =C8/$H8 -> 0.3094184 | D22: =D8/$H8 -> 0.43931758 | E22: =E8/$H8 -> 0.19018512 | F22: =F8/$H8 -> 0.039894954 | G22: =G8/$H8 -> 0.021183946 | H22: =H8/$H8 -> 1 | J22: San Francisco | K22: =K8/$P8 -> 0.2 | L22: =L8/$P8 -> 0.2 | M22: =M8/$P8 -> 0.2 | N22: =N8/$P8 -> 0.2 | O22: =O8/$P8 -> 0.2 | P22: =P8/$P8 -> 1 | R22: San Francisco | S22: =K22-C22 -> -0.1094184 | T22: =L22-D22 -> -0.23931758 | U22: =M22-E22 -> 0.009814879 | V22: =N22-F22 -> 0.16010505 | W22: =O22-G22 -> 0.17881605 | X22: =P22-H22 -> 0
B23: San Mateo | C23: =C9/$H9 -> 0.052020941 | D23: =D9/$H9 -> 0.32986452 | E23: =E9/$H9 -> 0.37734041 | F23: =F9/$H9 -> 0.15650035 | G23: =G9/$H9 -> 0.084273774 | H23: =H9/$H9 -> 1 | J23: San Mateo | K23: =K9/$P9 -> 0.2 | L23: =L9/$P9 -> 0.2 | M23: =M9/$P9 -> 0.2 | N23: =N9/$P9 -> 0.2 | O23: =O9/$P9 -> 0.2 | P23: =P9/$P9 -> 1 | R23: San Mateo | S23: =K23-C23 -> 0.14797906 | T23: =L23-D23 -> -0.12986452 | U23: =M23-E23 -> -0.17734041 | V23: =N23-F23 -> 0.043499645 | W23: =O23-G23 -> 0.11572623 | X23: =P23-H23 -> 0
B24: Santa Clara | C24: =C10/$H10 -> 0.058864186 | D24: =D10/$H10 -> 0.32659954 | E24: =E10/$H10 -> 0.37599636 | F24: =F10/$H10 -> 0.15005507 | G24: =G10/$H10 -> 0.088484845 | H24: =H10/$H10 -> 1 | J24: Santa Clara | K24: =K10/$P10 -> 0.2 | L24: =L10/$P10 -> 0.2 | M24: =M10/$P10 -> 0.2 | N24: =N10/$P10 -> 0.2 | O24: =O10/$P10 -> 0.2 | P24: =P10/$P10 -> 1 | R24: Santa Clara | S24: =K24-C24 -> 0.14113581 | T24: =L24-D24 -> -0.12659954 | U24: =M24-E24 -> -0.17599636 | V24: =N24-F24 -> 0.049944933 | W24: =O24-G24 -> 0.11151516 | X24: =P24-H24 -> 0
B25: Alameda | C25: =C11/$H11 -> 0.10942527 | D25: =D11/$H11 -> 0.34376551 | E25: =E11/$H11 -> 0.34312462 | F25: =F11/$H11 -> 0.12823934 | G25: =G11/$H11 -> 0.07544525 | H25: =H11/$H11 -> 1 | J25: Alameda | K25: =K11/$P11 -> 0.2 | L25: =L11/$P11 -> 0.2 | M25: =M11/$P11 -> 0.2 | N25: =N11/$P11 -> 0.2 | O25: =O11/$P11 -> 0.2 | P25: =P11/$P11 -> 1 | R25: Alameda | S25: =K25-C25 -> 0.090574725 | T25: =L25-D25 -> -0.14376551 | U25: =M25-E25 -> -0.14312462 | V25: =N25-F25 -> 0.071760658 | W25: =O25-G25 -> 0.12455475 | X25: =P25-H25 -> 0
B26: Contra Costa | C26: =C12/$H12 -> 0.049364205 | D26: =D12/$H12 -> 0.29357573 | E26: =E12/$H12 -> 0.37665677 | F26: =F12/$H12 -> 0.1734307 | G26: =G12/$H12 -> 0.1069726 | H26: =H12/$H12 -> 1 | J26: Contra Costa | K26: =K12/$P12 -> 0.2 | L26: =L12/$P12 -> 0.2 | M26: =M12/$P12 -> 0.2 | N26: =N12/$P12 -> 0.2 | O26: =O12/$P12 -> 0.2 | P26: =P12/$P12 -> 1 | R26: Contra Costa | S26: =K26-C26 -> 0.15063579 | T26: =L26-D26 -> -0.093575733 | U26: =M26-E26 -> -0.17665677 | V26: =N26-F26 -> 0.026569303 | W26: =O26-G26 -> 0.093027402 | X26: =P26-H26 -> 0
B27: Solano | C27: =C13/$H13 -> 0.053775845 | D27: =D13/$H13 -> 0.26121598 | E27: =E13/$H13 -> 0.36547165 | F27: =F13/$H13 -> 0.18748019 | G27: =G13/$H13 -> 0.13205634 | H27: =H13/$H13 -> 1 | J27: Solano | K27: =K13/$P13 -> 0.2 | L27: =L13/$P13 -> 0.2 | M27: =M13/$P13 -> 0.2 | N27: =N13/$P13 -> 0.2 | O27: =O13/$P13 -> 0.2 | P27: =P13/$P13 -> 1 | R27: Solano | S27: =K27-C27 -> 0.14622415 | T27: =L27-D27 -> -0.061215978 | U27: =M27-E27 -> -0.16547165 | V27: =N27-F27 -> 0.012519808 | W27: =O27-G27 -> 0.067943663 | X27: =P27-H27 -> 0
B28: Napa | C28: =C14/$H14 -> 0.055484981 | D28: =D14/$H14 -> 0.26603084 | E28: =E14/$H14 -> 0.39849903 | F28: =F14/$H14 -> 0.16428557 | G28: =G14/$H14 -> 0.11569957 | H28: =H14/$H14 -> 1 | J28: Napa | K28: =K14/$P14 -> 0.2 | L28: =L14/$P14 -> 0.2 | M28: =M14/$P14 -> 0.2 | N28: =N14/$P14 -> 0.2 | O28: =O14/$P14 -> 0.2 | P28: =P14/$P14 -> 1 | R28: Napa | S28: =K28-C28 -> 0.14451502 | T28: =L28-D28 -> -0.06603084 | U28: =M28-E28 -> -0.19849903 | V28: =N28-F28 -> 0.035714425 | W28: =O28-G28 -> 0.084300428 | X28: =P28-H28 -> 0
B29: Sonoma | C29: =C15/$H15 -> 0.042658159 | D29: =D15/$H15 -> 0.30527326 | E29: =E15/$H15 -> 0.37784868 | F29: =F15/$H15 -> 0.17385936 | G29: =G15/$H15 -> 0.10036054 | H29: =H15/$H15 -> 1 | J29: Sonoma | K29: =K15/$P15 -> 0.2 | L29: =L15/$P15 -> 0.2 | M29: =M15/$P15 -> 0.2 | N29: =N15/$P15 -> 0.2 | O29: =O15/$P15 -> 0.2 | P29: =P15/$P15 -> 1 | R29: Sonoma | S29: =K29-C29 -> 0.15734184 | T29: =L29-D29 -> -0.10527326 | U29: =M29-E29 -> -0.17784868 | V29: =N29-F29 -> 0.026140638 | W29: =O29-G29 -> 0.099639457 | X29: =P29-H29 -> 0
B30: Marin | C30: =C16/$H16 -> 0.040705456 | D30: =D16/$H16 -> 0.32342926 | E30: =E16/$H16 -> 0.42723998 | F30: =F16/$H16 -> 0.15842257 | G30: =G16/$H16 -> 0.05020274 | H30: =H16/$H16 -> 1 | J30: Marin | K30: =K16/$P16 -> 0.2 | L30: =L16/$P16 -> 0.2 | M30: =M16/$P16 -> 0.2 | N30: =N16/$P16 -> 0.2 | O30: =O16/$P16 -> 0.2 | P30: =P16/$P16 -> 1 | R30: Marin | S30: =K30-C30 -> 0.15929454 | T30: =L30-D30 -> -0.12342926 | U30: =M30-E30 -> -0.22723998 | V30: =N30-F30 -> 0.041577435 | W30: =O30-G30 -> 0.14979726 | X30: =P30-H30 -> 0
B31: Total | C31: =C17/$H17 -> 0.098525035 | D31: =D17/$H17 -> 0.33424948 | E31: =E17/$H17 -> 0.34651812 | F31: =F17/$H17 -> 0.13919219 | G31: =G17/$H17 -> 0.081515181 | H31: =H17/$H17 -> 1 | J31: Total | K31: =K17/$P17 -> 0.2 | L31: =L17/$P17 -> 0.2 | M31: =M17/$P17 -> 0.2 | N31: =N17/$P17 -> 0.2 | O31: =O17/$P17 -> 0.2 | P31: =P17/$P17 -> 1 | R31: Total | S31: =K31-C31 -> 0.10147496 | T31: =L31-D31 -> -0.13424948 | U31: =M31-E31 -> -0.14651812 | V31: =N31-F31 -> 0.060807811 | W31: =O31-G31 -> 0.11848482 | X31: =P31-H31 -> 0

Sheet calibration
I1: Dampening | J1: 0
B4: Old Constants | C4: 0_car | D4: 1_car | E4: 2_cars | F4: 3_cars | G4: 4+_cars | I4: Total | J4: 0_car | K4: 1_car | L4: 2_cars | M4: 3_cars | N4: 4+_cars
B5: Constant | C5: 0 | D5: ='[1]Auto ownership'!H53 -> 1.1172992 | E5: ='[1]Auto ownership'!J53 -> -1.2565052 | F5: ='[1]Auto ownership'!M53 -> -3.3877107 | G5: ='[1]Auto ownership'!Q53 -> -5.3502031 | I5: Observed Share | J5: =summary!#REF! -> #REF! | K5: =summary!#REF! -> #REF! | L5: =summary!#REF! -> #REF! | M5: =summary!#REF! -> #REF! | N5: =summary!#REF! -> #REF!
B6: San Francisco county | C6: 0 | D6: ='[1]Auto ownership'!H54 -> 0.57931801 | E6: ='[1]Auto ownership'!J54 -> 0.56301198 | F6: ='[1]Auto ownership'!M54 -> 0.40509384 | G6: ='[1]Auto ownership'!Q54 -> -0.20245079 | I6: Modeled Share | J6: =SUM(modeldata!C$4:C$12)/SUM(modeldata!$C$4:$G$12) -> 0.2 | K6: =SUM(modeldata!D$4:D$12)/SUM(modeldata!$C$4:$G$12) -> 0.2 | L6: =SUM(modeldata!E$4:E$12)/SUM(modeldata!$C$4:$G$12) -> 0.2 | M6: =SUM(modeldata!F$4:F$12)/SUM(modeldata!$C$4:$G$12) -> 0.2 | N6: =SUM(modeldata!G$4:G$12)/SUM(modeldata!$C$4:$G$12) -> 0.2
B7: San Mateo county | C7: 0 | D7: 0 | E7: 0 | F7: 0 | G7: 0 | I7: Difference | J7: =J6-J5 -> #REF! | K7: =K6-K5 -> #REF! | L7: =L6-L5 -> #REF! | M7: =M6-M5 -> #REF! | N7: =N6-N5 -> #REF!
B8: Santa Clara county | C8: 0 | D8: ='[1]Auto ownership'!H59 -> 0.18444711 | E8: ='[1]Auto ownership'!I59 -> 0.18444711 | F8: ='[1]Auto ownership'!J59 -> 0.20643155 | G8: ='[1]Auto ownership'!K59 -> 0.20643155 | I8: % Difference | J8: =J7/J5 -> #REF! | K8: =K7/K5 -> #REF! | L8: =L7/L5 -> #REF! | M8: =M7/M5 -> #REF! | N8: =N7/N5 -> #REF!
B9: Alameda county | C9: 0 | D9: 0 | E9: 0 | F9: 0 | G9: 0 | I9: Constant
B10: Contra Costa county | C10: 0 | D10: 0 | E10: 0 | F10: 0 | G10: 0 | I10: Existing Constant | J10: =C5 -> 0 | K10: =D5 -> 1.1172992 | L10: =E5 -> -1.2565052 | M10: =F5 -> -3.3877107 | N10: =G5 -> -5.3502031
B11: Solano county | C11: 0 | D11: ='[1]Auto ownership'!H55 -> -0.57903682 | E11: ='[1]Auto ownership'!J55 -> -0.39433065 | F11: ='[1]Auto ownership'!M55 -> -0.20319232 | G11: ='[1]Auto ownership'!Q55 -> -0.045351682 | I11: Change | J11: 0 | K11: =damp*LN(K5/K6)-damp*LN($J5/$J6) -> #REF! | L11: =damp*LN(L5/L6)-damp*LN($J5/$J6) -> #REF! | M11: =damp*LN(M5/M6)-damp*LN($J5/$J6) -> #REF! | N11: =damp*LN(N5/N6)-damp*LN($J5/$J6) -> #REF!
B12: Napa county | C12: 0 | D12: ='[1]Auto ownership'!H56 -> -0.57903682 | E12: ='[1]Auto ownership'!J56 -> -0.39433065 | F12: ='[1]Auto ownership'!M56 -> -0.20319232 | G12: ='[1]Auto ownership'!Q56 -> -0.045351682 | I12: New Constant | J12: =J10+J11 -> 0 | K12: =K10+K11 -> #REF! | L12: =L10+L11 -> #REF! | M12: =M10+M11 -> #REF! | N12: =N10+N11 -> #REF!
B13: Sonoma county | C13: 0 | D13: ='[1]Auto ownership'!H57 -> -0.57903682 | E13: ='[1]Auto ownership'!J57 -> -0.39433065 | F13: ='[1]Auto ownership'!M57 -> -0.20319232 | G13: ='[1]Auto ownership'!Q57 -> -0.045351682
B14: Marin county | C14: 0 | D14: ='[1]Auto ownership'!H58 -> -0.43045596 | E14: ='[1]Auto ownership'!J58 -> -0.18915885 | F14: ='[1]Auto ownership'!M58 -> -0.17100234 | G14: ='[1]Auto ownership'!Q58 -> -0.14149246
B17: New Constants | C17: 0_car | D17: 1_car | E17: 2_cars | F17: 3_cars | G17: 4+_cars | I17: San Francisco | J17: 0_car | K17: 1_car | L17: 2_cars | M17: 3_cars | N17: 4+_cars
B18: Constant | C18: 0 | D18: =K12 -> #REF! | E18: =L12 -> #REF! | F18: =M12 -> #REF! | G18: =N12 -> #REF! | I18: Observed Share | J18: =summary!#REF! -> #REF! | K18: =summary!#REF! -> #REF! | L18: =summary!#REF! -> #REF! | M18: =summary!#REF! -> #REF! | N18: =summary!#REF! -> #REF!
B19: San Francisco county | C19: 0 | D19: =K25 -> #REF! | E19: =L25 -> #REF! | F19: =M25 -> #REF! | G19: =N25 -> #REF! | I19: Modeled Share | J19: =modeldata!C$4/SUM(modeldata!$C4:$G4) -> 0.2 | K19: =modeldata!D$4/SUM(modeldata!$C4:$G4) -> 0.2 | L19: =modeldata!E$4/SUM(modeldata!$C4:$G4) -> 0.2 | M19: =modeldata!F$4/SUM(modeldata!$C4:$G4) -> 0.2 | N19: =modeldata!G$4/SUM(modeldata!$C4:$G4) -> 0.2
B20: San Mateo county | C20: 0 | D20: 0 | E20: 0 | F20: 0 | G20: 0 | I20: Difference | J20: =J19-J18 -> #REF! | K20: =K19-K18 -> #REF! | L20: =L19-L18 -> #REF! | M20: =M19-M18 -> #REF! | N20: =N19-N18 -> #REF!
B21: Santa Clara county | C21: =J61 -> 0 | D21: =K61 -> #REF! | E21: =L61 -> #REF! | F21: =M61 -> #REF! | G21: =N61 -> #REF! | I21: % Difference | J21: =J20/J18 -> #REF! | K21: =K20/K18 -> #REF! | L21: =L20/L18 -> #REF! | M21: =M20/M18 -> #REF! | N21: =N20/N18 -> #REF!
B22: Alameda county | C22: 0 | D22: 0 | E22: 0 | F22: 0 | G22: 0
B23: Contra Costa county | C23: 0 | D23: 0 | E23: 0 | F23: 0 | G23: 0 | I23: Existing Constant | J23: =C6 -> 0 | K23: =D6 -> 0.57931801 | L23: =E6 -> 0.56301198 | M23: =F6 -> 0.40509384 | N23: =G6 -> -0.20245079
B24: Solano county | C24: =J37 -> 0 | D24: =K37 -> #REF! | E24: =L37 -> #REF! | F24: =M37 -> #REF! | G24: =N37 -> #REF! | I24: Change | J24: 0 | K24: =damp*LN(K18/K19)-damp*LN($J18/$J19)-K11 -> #REF! | L24: =damp*LN(L18/L19)-damp*LN($J18/$J19)-L11 -> #REF! | M24: =damp*LN(M18/M19)-damp*LN($J18/$J19)-M11 -> #REF! | N24: =damp*LN(N18/N19)-damp*LN($J18/$J19) -> #REF!
B25: Napa county | C25: =J37 -> 0 | D25: =K37 -> #REF! | E25: =L37 -> #REF! | F25: =M37 -> #REF! | G25: =N37 -> #REF! | I25: New Constant | J25: =J23+J24 -> 0 | K25: =K23+K24 -> #REF! | L25: =L23+L24 -> #REF! | M25: =M23+M24 -> #REF! | N25: =N23+N24 -> #REF!
B26: Sonoma county | C26: =J37 -> 0 | D26: =K37 -> #REF! | E26: =L37 -> #REF! | F26: =M37 -> #REF! | G26: =N37 -> #REF!
B27: Marin county | C27: 0 | D27: =K49 -> #REF! | E27: =L49 -> #REF! | F27: =M49 -> #REF! | G27: =N49 -> #REF!
I29: Sonoma + Napa + Solano | J29: 0_car | K29: 1_car | L29: 2_cars | M29: 3_cars | N29: 4+_cars
I30: Observed Share | J30: =SUM(summary!#REF!)/SUM(summary!#REF!) -> #REF! | K30: =SUM(summary!#REF!)/SUM(summary!#REF!) -> #REF! | L30: =SUM(summary!#REF!)/SUM(summary!#REF!) -> #REF! | M30: =SUM(summary!#REF!)/SUM(summary!#REF!) -> #REF! | N30: =SUM(summary!#REF!)/SUM(summary!#REF!) -> #REF!
I31: Modeled Share | J31: =SUM(modeldata!C$9:C$11)/SUM(modeldata!$C$9:$G$11) -> 0.2 | K31: =SUM(modeldata!D$9:D$11)/SUM(modeldata!$C$9:$G$11) -> 0.2 | L31: =SUM(modeldata!E$9:E$11)/SUM(modeldata!$C$9:$G$11) -> 0.2 | M31: =SUM(modeldata!F$9:F$11)/SUM(modeldata!$C$9:$G$11) -> 0.2 | N31: =SUM(modeldata!G$9:G$11)/SUM(modeldata!$C$9:$G$11) -> 0.2
I32: Difference | J32: =J31-J30 -> #REF! | K32: =K31-K30 -> #REF! | L32: =L31-L30 -> #REF! | M32: =M31-M30 -> #REF! | N32: =N31-N30 -> #REF!
I33: % Difference | J33: =J32/J30 -> #REF! | K33: =K32/K30 -> #REF! | L33: =L32/L30 -> #REF! | M33: =M32/M30 -> #REF! | N33: =N32/N30 -> #REF!
I35: Existing Constant | J35: =C12 -> 0 | K35: =D12 -> -0.57903682 | L35: =E12 -> -0.39433065 | M35: =F12 -> -0.20319232 | N35: =G12 -> -0.045351682
I36: Change | J36: 0 | K36: =damp*LN(K30/K31)-damp*LN($J30/$J31)-K11 -> #REF! | L36: =damp*LN(L30/L31)-damp*LN($J30/$J31)-L11 -> #REF! | M36: =damp*LN(M30/M31)-damp*LN($J30/$J31)-M11 -> #REF! | N36: =damp*LN(N30/N31)-damp*LN($J30/$J31) -> #REF!
I37: New Constant | J37: =J35+J36 -> 0 | K37: =K35+K36 -> #REF! | L37: =L35+L36 -> #REF! | M37: =M35+M36 -> #REF! | N37: =N35+N36 -> #REF!
I41: Marin | J41: 0_car | K41: 1_car | L41: 2_cars | M41: 3_cars | N41: 4+_cars
I42: Observed Share | J42: =summary!#REF! -> #REF! | K42: =summary!#REF! -> #REF! | L42: =summary!#REF! -> #REF! | M42: =summary!#REF! -> #REF! | N42: =summary!#REF! -> #REF!
I43: Modeled Share | J43: =modeldata!C$12/SUM(modeldata!$C$12:$G$12) -> 0.2 | K43: =modeldata!D$12/SUM(modeldata!$C$12:$G$12) -> 0.2 | L43: =modeldata!E$12/SUM(modeldata!$C$12:$G$12) -> 0.2 | M43: =modeldata!F$12/SUM(modeldata!$C$12:$G$12) -> 0.2 | N43: =modeldata!G$12/SUM(modeldata!$C$12:$G$12) -> 0.2
I44: Difference | J44: =J43-J42 -> #REF! | K44: =K43-K42 -> #REF! | L44: =L43-L42 -> #REF! | M44: =M43-M42 -> #REF! | N44: =N43-N42 -> #REF!
I45: % Difference | J45: =J44/J42 -> #REF! | K45: =K44/K42 -> #REF! | L45: =L44/L42 -> #REF! | M45: =M44/M42 -> #REF! | N45: =N44/N42 -> #REF!
I47: Existing Constant | J47: =C14 -> 0 | K47: =D14 -> -0.43045596 | L47: =E14 -> -0.18915885 | M47: =F14 -> -0.17100234 | N47: =G14 -> -0.14149246
I48: Change | J48: 0 | K48: =damp*LN(K42/K43)-damp*LN($J42/$J43)-K11 -> #REF! | L48: =damp*LN(L42/L43)-damp*LN($J42/$J43)-L11 -> #REF! | M48: =damp*LN(M42/M43)-damp*LN($J42/$J43)-M11 -> #REF! | N48: =damp*LN(N42/N43)-damp*LN($J42/$J43)-N11 -> #REF!
I49: New Constant | J49: =J47+J48 -> 0 | K49: =K47+K48 -> #REF! | L49: =L47+L48 -> #REF! | M49: =M47+M48 -> #REF! | N49: =N47+N48 -> #REF!
I53: Santa Clara | J53: 0_car | K53: 1_car | L53: 2_cars | M53: 3_cars | N53: 4+_cars
...

Sheet modeldata
A1: Source:
A3: COUNTY | B3: county_name | C3: 0 | D3: 1 | E3: 2 | F3: 3 | G3: 4
A4: 1 | B4: San Francisco | C4: 1 | D4: 1 | E4: 1 | F4: 1 | G4: 1
A5: 2 | B5: San Mateo | C5: 1 | D5: 1 | E5: 1 | F5: 1 | G5: 1
A6: 3 | B6: Santa Clara | C6: 1 | D6: 1 | E6: 1 | F6: 1 | G6: 1
A7: 4 | B7: Alameda | C7: 1 | D7: 1 | E7: 1 | F7: 1 | G7: 1
A8: 5 | B8: Contra Costa | C8: 1 | D8: 1 | E8: 1 | F8: 1 | G8: 1
A9: 6 | B9: Solano | C9: 1 | D9: 1 | E9: 1 | F9: 1 | G9: 1
A10: 7 | B10: Napa | C10: 1 | D10: 1 | E10: 1 | F10: 1 | G10: 1
A11: 8 | B11: Sonoma | C11: 1 | D11: 1 | E11: 1 | F11: 1 | G11: 1
A12: 9 | B12: Marin | C12: 1 | D12: 1 | E12: 1 | F12: 1 | G12: 1

Sheet ACS_1YR_B08201
A1: Source: ACSDT1Y2023.B08201.zip\ACSDT1Y2023.B08201-DATA.csv
A2: Download at https://api.census.gov/data/2023/acs/acs1?get=group(B08201)&ucgid=0500000US06001,0500000US06013,0500000US06041,0500000US06055,0500000US06075,0500000US06081,0500000US06085,0500000US06095,0500000US06097
A3: GEO_ID | B3: STATE_COUNTY | C3: NAME | D3: B08201_001E | E3: B08201_001M | F3: B08201_002E | G3: B08201_002M | H3: B08201_003E | I3: B08201_003M | J3: B08201_004E | K3: B08201_004M | L3: B08201_005E | M3: B08201_005M | N3: B08201_006E | O3: B08201_006M | P3: B08201_007E | Q3: B08201_007M | R3: B08201_008E | S3: B08201_008M | T3: B08201_009E | U3: B08201_009M | V3: B08201_010E | W3: B08201_010M | X3: B08201_011E | Y3: B08201_011M | Z3: B08201_012E | AA3: B08201_012M | AB3: B08201_013E | AC3: B08201_013M | AD3: B08201_014E | AE3: B08201_014M | AF3: B08201_015E | AG3: B08201_015M | AH3: B08201_016E | AI3: B08201_016M | AJ3: B08201_017E | AK3: B08201_017M | AL3: B08201_018E | AM3: B08201_018M | AN3: B08201_019E | AO3: B08201_019M | AP3: B08201_020E | AQ3: B08201_020M | AR3: B08201_021E | AS3: B08201_021M | AT3: B08201_022E | AU3: B08201_022M | AV3: B08201_023E | AW3: B08201_023M | AX3: B08201_024E | AY3: B08201_024M | AZ3: B08201_025E | BA3: B08201_025M | BB3: B08201_026E | BC3: B08201_026M | BD3: B08201_027E | BE3: B08201_027M | BF3: B08201_028E | BG3: B08201_028M | BH3: B08201_029E | BI3: B08201_029M | BJ3: B08201_030E | BK3: B08201_030M
A4: Geography | B4: State County | C4: Geographic Area Name | D4: Estimate!!Total: | E4: Margin of Error!!Total: | F4: Estimate!!Total:!!No vehicle available | G4: Margin of Error!!Total:!!No vehicle available | H4: Estimate!!Total:!!1 vehicle available | I4: Margin of Error!!Total:!!1 vehicle available | J4: Estimate!!Total:!!2 vehicles available | K4: Margin of Error!!Total:!!2 vehicles available | L4: Estimate!!Total:!!3 vehicles available | M4: Margin of Error!!Total:!!3 vehicles available | N4: Estimate!!Total:!!4 or more vehicles available | O4: Margin of Error!!Total:!!4 or more vehicles available | P4: Estimate!!Total:!!1-person household: | Q4: Margin of Error!!Total:!!1-person household: | R4: Estimate!!Total:!!1-person household:!!No vehicle available | S4: Margin of Error!!Total:!!1-person household:!!No vehicle available | T4: Estimate!!Total:!!1-person household:!!1 vehicle available | U4: Margin of Error!!Total:!!1-person household:!!1 vehicle available | V4: Estimate!!Total:!!1-person household:!!2 vehicles available | W4: Margin of Error!!Total:!!1-person household:!!2 vehicles available | X4: Estimate!!Total:!!1-person household:!!3 vehicles available | Y4: Margin of Error!!Total:!!1-person household:!!3 vehicles available | Z4: Estimate!!Total:!!1-person household:!!4 or more vehicles available | AA4: Margin of Error!!Total:!!1-person household:!!4 or more vehicles available | AB4: Estimate!!Total:!!2-person household: | AC4: Margin of Error!!Total:!!2-person household: | AD4: Estimate!!Total:!!2-person household:!!No vehicle available | AE4: Margin of Error!!Total:!!2-person household:!!No vehicle available | AF4: Estimate!!Total:!!2-person household:!!1 vehicle available | AG4: Margin of Error!!Total:!!2-person household:!!1 vehicle available | AH4: Estimate!!Total:!!2-person household:!!2 vehicles available | AI4: Margin of Error!!Total:!!2-person household:!!2 vehicles available | AJ4: Estimate!!Total:!!2-person household:!!3 vehicles available | AK4: Margin of Error!!Total:!!2-person household:!!3 vehicles available | AL4: Estimate!!Total:!!2-person household:!!4 or more vehicles available | AM4: Margin of Error!!Total:!!2-person household:!!4 or more vehicles available | AN4: Estimate!!Total:!!3-person household: | AO4: Margin of Error!!Total:!!3-person household: | AP4: Estimate!!Total:!!3-person household:!!No vehicle available | AQ4: Margin of Error!!Total:!!3-person household:!!No vehicle available | AR4: Estimate!!Total:!!3-person household:!!1 vehicle available | AS4: Margin of Error!!Total:!!3-person household:!!1 vehicle available | AT4: Estimate!!Total:!!3-person household:!!2 vehicles available | AU4: Margin of Error!!Total:!!3-person household:!!2 vehicles available | AV4: Estimate!!Total:!!3-person household:!!3 vehicles available | AW4: Margin of Error!!Total:!!3-person household:!!3 vehicles available | AX4: Estimate!!Total:!!3-person household:!!4 or more vehicles available | AY4: Margin of Error!!Total:!!3-person household:!!4 or more vehicles available | AZ4: Estimate!!Total:!!4-or-more-person household: | BA4: Margin of Error!!Total:!!4-or-more-person household: | BB4: Estimate!!Total:!!4-or-more-person household:!!No vehicle available | BC4: Margin of Error!!Total:!!4-or-more-person household:!!No vehicle available | BD4: Estimate!!Total:!!4-or-more-person household:!!1 vehicle available | BE4: Margin of Error!!Total:!!4-or-more-person household:!!1 vehicle available | BF4: Estimate!!Total:!!4-or-more-person household:!!2 vehicles available | BG4: Margin of Error!!Total:!!4-or-more-person household:!!2 vehicles available | BH4: Estimate!!Total:!!4-or-more-person household:!!3 vehicles available | BI4: Margin of Error!!Total:!!4-or-more-person household:!!3 vehicles available | BJ4: Estimate!!Total:!!4-or-more-person household:!!4 or more vehicles available | BK4: Margin of Error!!Total:!!4-or-more-person household:!!4 or more vehicles available
A5: 0500000US06001 | B5: 6001 | C5: Alameda County, California | D5: 608534 | E5: 4026 | F5: 66589 | G5: 4670 | H5: 209193 | I5: 5777 | J5: 208803 | K5: 6977 | L5: 78038 | M5: 5421 | N5: 45911 | O5: 4519 | P5: 162846 | Q5: 6473 | R5: 39939 | S5: 4045 | T5: 101436 | U5: 5445 | V5: 16379 | W5: 2019 | X5: 3828 | Y5: 1304 | Z5: 1264 | AA5: 751 | AB5: 191889 | AC5: 7234 | AD5: 16556 | AE5: 2109 | AF5: 62424 | AG5: 4577 | AH5: 87734 | AI5: 5373 | AJ5: 18917 | AK5: 2293 | AL5: 6258 | AM5: 1586 | AN5: 104708 | AO5: 5256 | AP5: 4274 | AQ5: 1045 | AR5: 25277 | AS5: 2430 | AT5: 42666 | AU5: 3383 | AV5: 23140 | AW5: 2675 | AX5: 9351 | AY5: 2111 | AZ5: 149091 | BA5: 5035 | BB5: 5820 | BC5: 1415 | BD5: 20056 | BE5: 2483 | BF5: 62024 | BG5: 4301 | BH5: 32153 | BI5: 3626 | BJ5: 29038 | BK5: 2675
A6: 0500000US06013 | B6: 6013 | C6: Contra Costa County, California | D6: 416172 | E6: 2488 | F6: 20544 | G6: 2680 | H6: 122178 | I6: 4880 | J6: 156754 | K6: 5877 | L6: 72177 | M6: 4760 | N6: 44519 | O6: 3727 | P6: 91727 | Q6: 4968 | R6: 8874 | S6: 1964 | T6: 63449 | U6: 3757 | V6: 14796 | W6: 2051 | X6: 3280 | Y6: 1283 | Z6: 1328 | AA6: 793 | AB6: 136730 | AC6: 5274 | AD6: 5950 | AE6: 1492 | AF6: 32791 | AG6: 3339 | AH6: 68916 | AI6: 4227 | AJ6: 22205 | AK6: 2355 | AL6: 6868 | AM6: 1610 | AN6: 74349 | AO6: 4879 | AP6: 3046 | AQ6: 1190 | AR6: 12892 | AS6: 2114 | AT6: 30028 | AU6: 3046 | AV6: 18908 | AW6: 2492 | AX6: 9475 | AY6: 1977 | AZ6: 113366 | BA6: 5699 | BB6: 2674 | BC6: 923 | BD6: 13046 | BE6: 2259 | BF6: 43014 | BG6: 3837 | BH6: 27784 | BI6: 2867 | BJ6: 26848 | BK6: 3017
A7: 0500000US06041 | B7: 6041 | C7: Marin County, California | D7: 101608 | E7: 2158 | F7: 4136 | G7: 930 | H7: 32863 | I7: 2880 | J7: 43411 | K7: 3102 | L7: 16097 | M7: 1935 | N7: 5101 | O7: 1104 | P7: 28440 | Q7: 2335 | R7: 3423 | S7: 842 | T7: 20232 | U7: 2130 | V7: 4312 | W7: 1192 | X7: 349 | Y7: 300 | Z7: 124 | AA7: 165 | AB7: 36739 | AC7: 2800 | AD7: 292 | AE7: 254 | AF7: 6559 | AG7: 1512 | AH7: 22656 | AI7: 2441 | AJ7: 5866 | AK7: 1181 | AL7: 1366 | AM7: 575 | AN7: 16389 | AO7: 2234 | AP7: 291 | AQ7: 306 | AR7: 3118 | AS7: 1009 | AT7: 6057 | AU7: 1544 | AV7: 5702 | AW7: 1402 | AX7: 1221 | AY7: 614 | AZ7: 20040 | BA7: 2106 | BB7: 130 | BC7: 131 | BD7: 2954 | BE7: 1065 | BF7: 10386 | BG7: 1810 | BH7: 4180 | BI7: 1086 | BJ7: 2390 | BK7: 820
A8: 0500000US06055 | B8: 6055 | C8: Napa County, California | D8: 51167 | E8: 1100 | F8: 2839 | G8: 814 | H8: 13612 | I8: 1734 | J8: 20390 | K8: 1733 | L8: 8406 | M8: 1259 | N8: 5920 | O8: 1086 | P8: 12300 | Q8: 1449 | R8: 1799 | S8: 642 | T8: 8373 | U8: 1283 | V8: 1594 | W8: 588 | X8: 477 | Y8: 393 | Z8: 57 | AA8: 94 | AB8: 18809 | AC8: 1665 | AD8: 390 | AE8: 307 | AF8: 3794 | AG8: 1116 | AH8: 10701 | AI8: 1338 | AJ8: 2848 | AK8: 672 | AL8: 1076 | AM8: 546 | AN8: 7956 | AO8: 1350 | AP8: 85 | AQ8: 140 | AR8: 649 | AS8: 410 | AT8: 3692 | AU8: 1019 | AV8: 2371 | AW8: 740 | AX8: 1159 | AY8: 509 | AZ8: 12102 | BA8: 1512 | BB8: 565 | BC8: 424 | BD8: 796 | BE8: 559 | BF8: 4403 | BG8: 1130 | BH8: 2710 | BI8: 908 | BJ8: 3628 | BK8: 965
A9: 0500000US06075 | B9: 6075 | C9: San Francisco County, California | D9: 372027 | E9: 4832 | F9: 115112 | G9: 4922 | H9: 163438 | I9: 5738 | J9: 70754 | K9: 3487 | L9: 14842 | M9: 2098 | N9: 7881 | O9: 1468 | P9: 146930 | Q9: 5553 | R9: 72928 | S9: 4120 | T9: 67647 | U9: 4592 | V9: 5430 | W9: 1289 | X9: 366 | Y9: 249 | Z9: 559 | AA9: 396 | AB9: 121777 | AC9: 4617 | AD9: 29841 | AE9: 2756 | AF9: 59948 | AG9: 3315 | AH9: 29206 | AI9: 2348 | AJ9: 2368 | AK9: 993 | AL9: 414 | AM9: 272 | AN9: 46767 | AO9: 2884 | AP9: 6276 | AQ9: 1346 | AR9: 19534 | AS9: 2170 | AT9: 16264 | AU9: 2116 | AV9: 4157 | AW9: 955 | AX9: 536 | AY9: 445 | AZ9: 56553 | BA9: 3507 | BB9: 6067 | BC9: 1549 | BD9: 16309 | BE9: 2231 | BF9: 19854 | BG9: 2226 | BH9: 7951 | BI9: 1656 | BJ9: 6372 | BK9: 1381
A10: 0500000US06081 | B10: 6081 | C10: San Mateo County, California | D10: 265124 | E10: 3090 | F10: 13792 | G10: 1879 | H10: 87455 | I10: 4557 | J10: 100042 | K10: 3638 | L10: 41492 | M10: 3177 | N10: 22343 | O10: 2549 | P10: 69876 | Q10: 4258 | R10: 7878 | S10: 1279 | T10: 50099 | U10: 3742 | V10: 8790 | W10: 1672 | X10: 2007 | Y10: 675 | Z10: 1102 | AA10: 754 | AB10: 86182 | AC10: 4058 | AD10: 3310 | AE10: 922 | AF10: 22068 | AG10: 2570 | AH10: 45020 | AI10: 2968 | AJ10: 11877 | AK10: 1764 | AL10: 3907 | AM10: 1062 | AN10: 43193 | AO10: 3552 | AP10: 839 | AQ10: 456 | AR10: 8537 | AS10: 1647 | AT10: 19962 | AU10: 2599 | AV10: 9884 | AW10: 1613 | AX10: 3971 | AY10: 1103 | AZ10: 65873 | BA10: 3761 | BB10: 1765 | BC10: 701 | BD10: 6751 | BE10: 1501 | BF10: 26270 | BG10: 2366 | BH10: 17724 | BI10: 2315 | BJ10: 13363 | BK10: 1909
A11: 0500000US06085 | B11: 6085 | C11: Santa Clara County, California | D11: 665549 | E11: 3723 | F11: 39177 | G11: 3870 | H11: 217368 | I11: 6604 | J11: 250244 | K11: 6612 | L11: 99869 | M11: 5258 | N11: 58891 | O11: 4145 | P11: 151634 | Q11: 7014 | R11: 21649 | S11: 2931 | T11: 109929 | U11: 6242 | V11: 14982 | W11: 1810 | X11: 3701 | Y11: 1165 | Z11: 1373 | AA11: 603 | AB11: 217571 | AC11: 6859 | AD11: 8082 | AE11: 1706 | AF11: 66642 | AG11: 4500 | AH11: 111458 | AI11: 4710 | AJ11: 24389 | AK11: 2366 | AL11: 7000 | AM11: 1473 | AN11: 120053 | AO11: 5654 | AP11: 4264 | AQ11: 1209 | AR11: 20620 | AS11: 2453 | AT11: 52610 | AU11: 3357 | AV11: 30875 | AW11: 2871 | AX11: 11684 | AY11: 1758 | AZ11: 176291 | BA11: 5480 | BB11: 5182 | BC11: 1320 | BD11: 20177 | BE11: 2451 | BF11: 71194 | BG11: 3954 | BH11: 40904 | BI11: 3596 | BJ11: 38834 | BK11: 2903
A12: 0500000US06095 | B12: 6095 | C12: Solano County, California | D12: 157766 | E12: 1986 | F12: 8484 | G12: 2103 | H12: 41211 | I12: 3010 | J12: 57659 | K12: 3446 | L12: 29578 | M12: 2349 | N12: 20834 | O12: 2220 | P12: 38918 | Q12: 3465 | R12: 4614 | S12: 1429 | T12: 24350 | U12: 2648 | V12: 7038 | W12: 1598 | X12: 2159 | Y12: 817 | Z12: 757 | AA12: 474 | AB12: 50271 | AC12: 2974 | AD12: 1815 | AE12: 1198 | AF12: 10109 | AG12: 1676 | AH12: 27080 | AI12: 2466 | AJ12: 7560 | AK12: 1441 | AL12: 3707 | AM12: 1084 | AN12: 27249 | AO12: 2831 | AP12: 1346 | AQ12: 821 | AR12: 3548 | AS12: 1084 | AT12: 10153 | AU12: 1677 | AV12: 8014 | AW12: 1439 | AX12: 4188 | AY12: 976 | AZ12: 41328 | BA12: 2827 | BB12: 709 | BC12: 522 | BD12: 3204 | BE12: 1150 | BF12: 13388 | BG12: 2084 | BH12: 11845 | BI12: 1579 | BJ12: 12182 | BK12: 1612
A13: 0500000US06097 | B13: 6097 | C13: Sonoma County, California | D13: 192765 | E13: 2138 | F13: 8223 | G13: 1587 | H13: 58846 | I13: 3714 | J13: 72836 | K13: 3683 | L13: 33514 | M13: 2951 | N13: 19346 | O13: 2569 | P13: 53236 | Q13: 3641 | R13: 4547 | S13: 912 | T13: 38367 | U13: 3068 | V13: 8211 | W13: 1419 | X13: 1373 | Y13: 438 | Z13: 738 | AA13: 491 | AB13: 70246 | AC13: 4033 | AD13: 2147 | AE13: 858 | AF13: 12594 | AG13: 1924 | AH13: 38946 | AI13: 3164 | AJ13: 12535 | AK13: 1791 | AL13: 4024 | AM13: 1083 | AN13: 27110 | AO13: 2639 | AP13: 602 | AQ13: 617 | AR13: 4137 | AS13: 1456 | AT13: 10744 | AU13: 1814 | AV13: 8627 | AW13: 1306 | AX13: 3000 | AY13: 890 | AZ13: 42173 | BA13: 3288 | BB13: 927 | BC13: 719 | BD13: 3748 | BE13: 1088 | BF13: 14935 | BG13: 2047 | BH13: 10979 | BI13: 1747 | BJ13: 11584 | BK13: 2141
F15: 0 | H15: 1 | J15: 2 | L15: 3 | N15: 3
