Workbook
Name damp: 'TM1 v03 Targets'!$L$50
Name damp: calibration!#REF!
Name damp_cdap: calibration!$C$27
Name damp_cdap_v2: calibration!#REF!
Name klaus: 'TM1 v03 Targets'!#REF!

Sheet calibration
B2: Bay Area Travel Study 2023 | H2: Model | M2: Model minus Observed
C3: M | D3: N | E3: H
B4: Person type | C4: Mandatory | D4: Non-Mandatory | E4: Home | F4: Total | H4: Mandatory | I4: Non-Mandatory | J4: Home | K4: Total | M4: Mandatory | N4: Non-Mandatory | O4: Home | P4: Total
A5: 1 | B5: Full-time worker | C5: =SUMIFS('BATS 2023'!$E$3:$E$34,'BATS 2023'!$B$3:$B$34,calibration!$A5,'BATS 2023'!$C$3:$C$34,calibration!C$3) -> 1588701.5 | D5: =SUMIFS('BATS 2023'!$E$3:$E$34,'BATS 2023'!$B$3:$B$34,calibration!$A5,'BATS 2023'!$C$3:$C$34,calibration!D$3) -> 1105032.5 | E5: =SUMIFS('BATS 2023'!$E$3:$E$34,'BATS 2023'!$B$3:$B$34,calibration!$A5,'BATS 2023'!$C$3:$C$34,calibration!E$3) -> 487610.63 | F5: =SUM(C5:E5) -> 3181344.6 | H5: =modeldata!C3 -> 1 | I5: =modeldata!D3 -> 1 | J5: =modeldata!B3 -> 1 | K5: =SUM(H5:J5) -> 3 | M5: =IFERROR(H5-C5,0) -> -1588700.5 | N5: =IFERROR(I5-D5,0) -> -1105031.5 | O5: =IFERROR(J5-E5,0) -> -487609.63 | P5: =IFERROR(K5-F5,0) -> -3181341.6
A6: 2 | B6: Part-time worker | C6: =SUMIFS('BATS 2023'!$E$3:$E$34,'BATS 2023'!$B$3:$B$34,calibration!$A6,'BATS 2023'!$C$3:$C$34,calibration!C$3) -> 319170.3 | D6: =SUMIFS('BATS 2023'!$E$3:$E$34,'BATS 2023'!$B$3:$B$34,calibration!$A6,'BATS 2023'!$C$3:$C$34,calibration!D$3) -> 257636.16 | E6: =SUMIFS('BATS 2023'!$E$3:$E$34,'BATS 2023'!$B$3:$B$34,calibration!$A6,'BATS 2023'!$C$3:$C$34,calibration!E$3) -> 95209.139 | F6: =SUM(C6:E6) -> 672015.6 | H6: =modeldata!C4 -> 1 | I6: =modeldata!D4 -> 1 | J6: =modeldata!B4 -> 1 | K6: =SUM(H6:J6) -> 3 | M6: =IFERROR(H6-C6,0) -> -319169.3 | N6: =IFERROR(I6-D6,0) -> -257635.16 | O6: =IFERROR(J6-E6,0) -> -95208.139 | P6: =IFERROR(K6-F6,0) -> -672012.6
A7: 3 | B7: University student | C7: =SUMIFS('BATS 2023'!$E$3:$E$34,'BATS 2023'!$B$3:$B$34,calibration!$A7,'BATS 2023'!$C$3:$C$34,calibration!C$3) -> 108654.68 | D7: =SUMIFS('BATS 2023'!$E$3:$E$34,'BATS 2023'!$B$3:$B$34,calibration!$A7,'BATS 2023'!$C$3:$C$34,calibration!D$3) -> 226287.48 | E7: =SUMIFS('BATS 2023'!$E$3:$E$34,'BATS 2023'!$B$3:$B$34,calibration!$A7,'BATS 2023'!$C$3:$C$34,calibration!E$3) -> 77720.499 | F7: =SUM(C7:E7) -> 412662.66 | H7: =modeldata!C5 -> 1 | I7: =modeldata!D5 -> 1 | J7: =modeldata!B5 -> 1 | K7: =SUM(H7:J7) -> 3 | M7: =IFERROR(H7-C7,0) -> -108653.68 | N7: =IFERROR(I7-D7,0) -> -226286.48 | O7: =IFERROR(J7-E7,0) -> -77719.499 | P7: =IFERROR(K7-F7,0) -> -412659.66
A8: 4 | B8: Non-worker | C8: =SUMIFS('BATS 2023'!$E$3:$E$34,'BATS 2023'!$B$3:$B$34,calibration!$A8,'BATS 2023'!$C$3:$C$34,calibration!C$3) -> 0 | D8: =SUMIFS('BATS 2023'!$E$3:$E$34,'BATS 2023'!$B$3:$B$34,calibration!$A8,'BATS 2023'!$C$3:$C$34,calibration!D$3) -> 572446.56 | E8: =SUMIFS('BATS 2023'!$E$3:$E$34,'BATS 2023'!$B$3:$B$34,calibration!$A8,'BATS 2023'!$C$3:$C$34,calibration!E$3) -> 197443.74 | F8: =SUM(C8:E8) -> 769890.31 | H8: =modeldata!C6 -> 1 | I8: =modeldata!D6 -> 1 | J8: =modeldata!B6 -> 1 | K8: =SUM(H8:J8) -> 3 | M8: =IFERROR(H8-C8,0) -> 1 | N8: =IFERROR(I8-D8,0) -> -572445.56 | O8: =IFERROR(J8-E8,0) -> -197442.74 | P8: =IFERROR(K8-F8,0) -> -769887.31
A9: 5 | B9: Retired | C9: =SUMIFS('BATS 2023'!$E$3:$E$34,'BATS 2023'!$B$3:$B$34,calibration!$A9,'BATS 2023'!$C$3:$C$34,calibration!C$3) -> 0 | D9: =SUMIFS('BATS 2023'!$E$3:$E$34,'BATS 2023'!$B$3:$B$34,calibration!$A9,'BATS 2023'!$C$3:$C$34,calibration!D$3) -> 661707.41 | E9: =SUMIFS('BATS 2023'!$E$3:$E$34,'BATS 2023'!$B$3:$B$34,calibration!$A9,'BATS 2023'!$C$3:$C$34,calibration!E$3) -> 292213.43 | F9: =SUM(C9:E9) -> 953920.84 | H9: =modeldata!C7 -> 1 | I9: =modeldata!D7 -> 1 | J9: =modeldata!B7 -> 1 | K9: =SUM(H9:J9) -> 3 | M9: =IFERROR(H9-C9,0) -> 1 | N9: =IFERROR(I9-D9,0) -> -661706.41 | O9: =IFERROR(J9-E9,0) -> -292212.43 | P9: =IFERROR(K9-F9,0) -> -953917.84
A10: 6 | B10: Student of driving age | C10: =SUMIFS('BATS 2023'!$E$3:$E$34,'BATS 2023'!$B$3:$B$34,calibration!$A10,'BATS 2023'!$C$3:$C$34,calibration!C$3) -> 123094.59 | D10: =SUMIFS('BATS 2023'!$E$3:$E$34,'BATS 2023'!$B$3:$B$34,calibration!$A10,'BATS 2023'!$C$3:$C$34,calibration!D$3) -> 17712.812 | E10: =SUMIFS('BATS 2023'!$E$3:$E$34,'BATS 2023'!$B$3:$B$34,calibration!$A10,'BATS 2023'!$C$3:$C$34,calibration!E$3) -> 17630.207 | F10: =SUM(C10:E10) -> 158437.61 | H10: =modeldata!C8 -> 1 | I10: =modeldata!D8 -> 1 | J10: =modeldata!B8 -> 1 | K10: =SUM(H10:J10) -> 3 | M10: =IFERROR(H10-C10,0) -> -123093.59 | N10: =IFERROR(I10-D10,0) -> -17711.812 | O10: =IFERROR(J10-E10,0) -> -17629.207 | P10: =IFERROR(K10-F10,0) -> -158434.61
A11: 7 | B11: Student of non-driving age | C11: =SUMIFS('BATS 2023'!$E$3:$E$34,'BATS 2023'!$B$3:$B$34,calibration!$A11,'BATS 2023'!$C$3:$C$34,calibration!C$3) -> 665066.56 | D11: =SUMIFS('BATS 2023'!$E$3:$E$34,'BATS 2023'!$B$3:$B$34,calibration!$A11,'BATS 2023'!$C$3:$C$34,calibration!D$3) -> 64858.529 | E11: =SUMIFS('BATS 2023'!$E$3:$E$34,'BATS 2023'!$B$3:$B$34,calibration!$A11,'BATS 2023'!$C$3:$C$34,calibration!E$3) -> 85466.73 | F11: =SUM(C11:E11) -> 815391.82 | H11: =modeldata!C9 -> 1 | I11: =modeldata!D9 -> 1 | J11: =modeldata!B9 -> 1 | K11: =SUM(H11:J11) -> 3 | M11: =IFERROR(H11-C11,0) -> -665065.56 | N11: =IFERROR(I11-D11,0) -> -64857.529 | O11: =IFERROR(J11-E11,0) -> -85465.73 | P11: =IFERROR(K11-F11,0) -> -815388.82
A12: 8 | B12: Child too young for school | C12: =SUMIFS('BATS 2023'!$E$3:$E$34,'BATS 2023'!$B$3:$B$34,calibration!$A12,'BATS 2023'!$C$3:$C$34,calibration!C$3) -> 138048.92 | D12: =SUMIFS('BATS 2023'!$E$3:$E$34,'BATS 2023'!$B$3:$B$34,calibration!$A12,'BATS 2023'!$C$3:$C$34,calibration!D$3) -> 145623.69 | E12: =SUMIFS('BATS 2023'!$E$3:$E$34,'BATS 2023'!$B$3:$B$34,calibration!$A12,'BATS 2023'!$C$3:$C$34,calibration!E$3) -> 121625.5 | F12: =SUM(C12:E12) -> 405298.11 | H12: =modeldata!C10 -> 1 | I12: =modeldata!D10 -> 1 | J12: =modeldata!B10 -> 1 | K12: =SUM(H12:J12) -> 3 | M12: =IFERROR(H12-C12,0) -> -138047.92 | N12: =IFERROR(I12-D12,0) -> -145622.69 | O12: =IFERROR(J12-E12,0) -> -121624.5 | P12: =IFERROR(K12-F12,0) -> -405295.11
B13: Total | C13: =SUM(C5:C12) -> 2942736.6 | D13: =SUM(D5:D12) -> 3051305.1 | E13: =SUM(E5:E12) -> 1374919.9 | F13: =SUM(C13:E13) -> 7368961.5 | H13: =SUM(H5:H12) -> 8 | I13: =SUM(I5:I12) -> 8 | J13: =SUM(J5:J12) -> 8 | K13: =SUM(K5:K12) -> 24 | M13: =IFERROR(H13-C13,0) -> -2942728.6 | N13: =IFERROR(I13-D13,0) -> -3051297.1 | O13: =IFERROR(J13-E13,0) -> -1374911.9 | P13: =IFERROR(K13-F13,0) -> -7368937.5
B16: Person type | C16: Mandatory | D16: Non-Mandatory | E16: Home | F16: Total | H16: Mandatory | I16: Non-Mandatory | J16: Home | K16: Total | M16: Mandatory | N16: Non-Mandatory | O16: Home | P16: Total
B17: Full-time worker | C17: =C5/$F5 -> 0.49938051 | D17: =D5/$F5 -> 0.34734762 | E17: =E5/$F5 -> 0.15327187 | F17: =F5/$F5 -> 1 | H17: =IFERROR(H5/$K5,0) -> 0.33333333 | I17: =IFERROR(I5/$K5,0) -> 0.33333333 | J17: =IFERROR(J5/$K5,0) -> 0.33333333 | K17: =IFERROR(K5/$K5,0) -> 1 | M17: =IFERROR(H17-C17,0) -> -0.16604718 | N17: =IFERROR(I17-D17,0) -> -0.014014286 | O17: =IFERROR(J17-E17,0) -> 0.18006147 | P17: =IFERROR(K17-F17,0) -> 0
B18: Part-time worker | C18: =C6/$F6 -> 0.47494478 | D18: =D6/$F6 -> 0.38337824 | E18: =E6/$F6 -> 0.14167698 | F18: =F6/$F6 -> 1 | H18: =IFERROR(H6/$K6,0) -> 0.33333333 | I18: =IFERROR(I6/$K6,0) -> 0.33333333 | J18: =IFERROR(J6/$K6,0) -> 0.33333333 | K18: =IFERROR(K6/$K6,0) -> 1 | M18: =IFERROR(H18-C18,0) -> -0.14161145 | N18: =IFERROR(I18-D18,0) -> -0.050044905 | O18: =IFERROR(J18-E18,0) -> 0.19165636 | P18: =IFERROR(K18-F18,0) -> 0
B19: University student | C19: =C7/$F7 -> 0.26330147 | D19: =D7/$F7 -> 0.54835947 | E19: =E7/$F7 -> 0.18833907 | F19: =F7/$F7 -> 1 | H19: =IFERROR(H7/$K7,0) -> 0.33333333 | I19: =IFERROR(I7/$K7,0) -> 0.33333333 | J19: =IFERROR(J7/$K7,0) -> 0.33333333 | K19: =IFERROR(K7/$K7,0) -> 1 | M19: =IFERROR(H19-C19,0) -> 0.070031867 | N19: =IFERROR(I19-D19,0) -> -0.21502614 | O19: =IFERROR(J19-E19,0) -> 0.14499427 | P19: =IFERROR(K19-F19,0) -> 0
B20: Non-worker | C20: =C8/$F8 -> 0 | D20: =D8/$F8 -> 0.74354302 | E20: =E8/$F8 -> 0.25645698 | F20: =F8/$F8 -> 1 | H20: =IFERROR(H8/$K8,0) -> 0.33333333 | I20: =IFERROR(I8/$K8,0) -> 0.33333333 | J20: =IFERROR(J8/$K8,0) -> 0.33333333 | K20: =IFERROR(K8/$K8,0) -> 1 | M20: =IFERROR(H20-C20,0) -> 0.33333333 | N20: =IFERROR(I20-D20,0) -> -0.41020968 | O20: =IFERROR(J20-E20,0) -> 0.076876351 | P20: =IFERROR(K20-F20,0) -> 0
B21: Retired | C21: =C9/$F9 -> 0 | D21: =D9/$F9 -> 0.6936712 | E21: =E9/$F9 -> 0.3063288 | F21: =F9/$F9 -> 1 | H21: =IFERROR(H9/$K9,0) -> 0.33333333 | I21: =IFERROR(I9/$K9,0) -> 0.33333333 | J21: =IFERROR(J9/$K9,0) -> 0.33333333 | K21: =IFERROR(K9/$K9,0) -> 1 | M21: =IFERROR(H21-C21,0) -> 0.33333333 | N21: =IFERROR(I21-D21,0) -> -0.36033787 | O21: =IFERROR(J21-E21,0) -> 0.027004532 | P21: =IFERROR(K21-F21,0) -> 0
B22: Student of driving age | C22: =C10/$F10 -> 0.77692784 | D22: =D10/$F10 -> 0.11179676 | E22: =E10/$F10 -> 0.11127539 | F22: =F10/$F10 -> 1 | H22: =IFERROR(H10/$K10,0) -> 0.33333333 | I22: =IFERROR(I10/$K10,0) -> 0.33333333 | J22: =IFERROR(J10/$K10,0) -> 0.33333333 | K22: =IFERROR(K10/$K10,0) -> 1 | M22: =IFERROR(H22-C22,0) -> -0.44359451 | N22: =IFERROR(I22-D22,0) -> 0.22153657 | O22: =IFERROR(J22-E22,0) -> 0.22205794 | P22: =IFERROR(K22-F22,0) -> 0
B23: Student of non-driving age | C23: =C11/$F11 -> 0.81564046 | D23: =D11/$F11 -> 0.079542776 | E23: =E11/$F11 -> 0.10481676 | F23: =F11/$F11 -> 1 | H23: =IFERROR(H11/$K11,0) -> 0.33333333 | I23: =IFERROR(I11/$K11,0) -> 0.33333333 | J23: =IFERROR(J11/$K11,0) -> 0.33333333 | K23: =IFERROR(K11/$K11,0) -> 1 | M23: =IFERROR(H23-C23,0) -> -0.48230713 | N23: =IFERROR(I23-D23,0) -> 0.25379056 | O23: =IFERROR(J23-E23,0) -> 0.22851657 | P23: =IFERROR(K23-F23,0) -> 0
B24: Child too young for school | C24: =C12/$F12 -> 0.34061082 | D24: =D12/$F12 -> 0.3593002 | E24: =E12/$F12 -> 0.30008898 | F24: =F12/$F12 -> 1 | H24: =IFERROR(H12/$K12,0) -> 0.33333333 | I24: =IFERROR(I12/$K12,0) -> 0.33333333 | J24: =IFERROR(J12/$K12,0) -> 0.33333333 | K24: =IFERROR(K12/$K12,0) -> 1 | M24: =IFERROR(H24-C24,0) -> -0.0072774881 | N24: =IFERROR(I24-D24,0) -> -0.025966868 | O24: =IFERROR(J24-E24,0) -> 0.033244356 | P24: =IFERROR(K24-F24,0) -> 0
B25: Total | C25: =C13/$F13 -> 0.3993421 | D25: =D13/$F13 -> 0.41407532 | E25: =E13/$F13 -> 0.18658258 | F25: =F13/$F13 -> 1 | H25: =IFERROR(H13/$K13,0) -> 0.33333333 | I25: =IFERROR(I13/$K13,0) -> 0.33333333 | J25: =IFERROR(J13/$K13,0) -> 0.33333333 | K25: =IFERROR(K13/$K13,0) -> 1 | M25: =IFERROR(H25-C25,0) -> -0.066008765 | N25: =IFERROR(I25-D25,0) -> -0.080741987 | O25: =IFERROR(J25-E25,0) -> 0.14675075 | P25: =IFERROR(K25-F25,0) -> 0
B27: dampening | C27: 0
B29: Old Constant | H29: Change in Constant | M29: New Constant
B30: Person type | C30: Mandatory | D30: Non-Mandatory | E30: Home | H30: Mandatory | I30: Non-Mandatory | J30: Home | M30: Mandatory | N30: Non-Mandatory | O30: Home
B31: Full-time worker | C31: =[1]OnePerson!G31 -> 1.3787346 | D31: =[1]OnePerson!H31 -> 0.62266239 | H31: =damp_cdap*LN(C17/H17)-damp_cdap*LN(E17/J17) -> 0 | I31: =damp_cdap*LN(D17/I17)-damp_cdap*LN(F17/K17) -> 0 | M31: =C31+H31 -> 1.3787346 | N31: =D31+I31 -> 0.62266239
B32: Part-time worker | C32: =[1]OnePerson!G32 -> -0.71882374 | D32: =[1]OnePerson!H32 -> 0.63603247 | H32: =damp_cdap*LN(C18/H18)-damp_cdap*LN(E18/J18) -> 0 | I32: =damp_cdap*LN(D18/I18)-damp_cdap*LN(F18/K18) -> 0 | M32: =C32+H32 -> -0.71882374 | N32: =D32+I32 -> 0.63603247
B33: University student | C33: =[1]OnePerson!G33 -> 2.3535952 | D33: =[1]OnePerson!H33 -> 0.60970985 | H33: =damp_cdap*LN(C19/H19)-damp_cdap*LN(E19/J19) -> 0 | I33: =damp_cdap*LN(D19/I19)-damp_cdap*LN(F19/K19) -> 0 | M33: =C33+H33 -> 2.3535952 | N33: =D33+I33 -> 0.60970985
B34: Non-worker | C34: =[1]OnePerson!G34 -> -999 | D34: =[1]OnePerson!H34 -> 0.59464539 | I34: =damp_cdap*LN(D20/I20)-damp_cdap*LN(F20/K20) -> 0 | M34: =C34+H34 -> -999 | N34: =D34+I34 -> 0.59464539
B35: Retired | C35: =[1]OnePerson!G35 -> -999 | D35: =[1]OnePerson!H35 -> 0.40820207 | I35: =damp_cdap*LN(D21/I21)-damp_cdap*LN(F21/K21) -> 0 | M35: =C35+H35 -> -999 | N35: =D35+I35 -> 0.40820207
B36: Student of driving age | C36: =[1]OnePerson!G36 -> 2.3309187 | D36: =[1]OnePerson!H36 -> -0.59911911 | H36: =damp_cdap*LN(C22/H22)-damp_cdap*LN(E22/J22) -> 0 | I36: =damp_cdap*LN(D22/I22)-damp_cdap*LN(F22/K22) -> 0 | M36: =C36+H36 -> 2.3309187 | N36: =D36+I36 -> -0.59911911
B37: Student of non-driving age | C37: =[1]OnePerson!G37 -> 3.2958635 | D37: =[1]OnePerson!H37 -> 0.57142434 | H37: =damp_cdap*LN(C23/H23)-damp_cdap*LN(E23/J23) -> 0 | I37: =damp_cdap*LN(D23/I23)-damp_cdap*LN(F23/K23) -> 0 | M37: =C37+H37 -> 3.2958635 | N37: =D37+I37 -> 0.57142434
B38: Child too young for school | C38: =[1]OnePerson!G38 -> 1.0525312 | D38: =[1]OnePerson!H38 -> -0.83756778 | H38: =damp_cdap*LN(C24/H24)-damp_cdap*LN(E24/J24) -> 0 | I38: =damp_cdap*LN(D24/I24)-damp_cdap*LN(F24/K24) -> 0 | M38: =C38+H38 -> 1.0525312 | N38: =D38+I38 -> -0.83756778
B41: Bay Area Travel Study 2023 - WFH | K41: Modeled
C42: M | D42: M | E42: N | F42: N | G42: H | H42: H
C43: 0 | D43: 1 | E43: 0 | F43: 1 | G43: 0 | H43: 1
B44: Person type | C44: Mandatory | D44: Mandatory | E44: Non-Mandatory | F44: Non-Mandatory | G44: Home | H44: Home | I44: Total | K44: Mandatory | L44: Mandatory | M44: Non-Mandatory | N44: Non-Mandatory | O44: Home | P44: Home | Q44: Total | S44: Mandatory | T44: Mandatory | U44: Non-Mandatory | V44: Non-Mandatory | W44: Home | X44: Home
C45: Did not WFH | D45: WFH | E45: Did not WFH | F45: WFH | G45: Did not WFH | H45: WFH | K45: Did not WFH | L45: WFH | M45: Did not WFH | N45: WFH | O45: Did not WFH | P45: WFH | S45: Did not WFH | T45: WFH | U45: Did not WFH | V45: WFH | W45: Did not WFH | X45: WFH
A46: 1 | B46: Full-time worker | C46: =SUMIFS('BATS 2023'!$E$3:$E$34,'BATS 2023'!$B$3:$B$34,$A46,'BATS 2023'!$C$3:$C$34,C$42,'BATS 2023'!$D$3:$D$34,C$43) -> 1587716.9 | D46: =SUMIFS('BATS 2023'!$E$3:$E$34,'BATS 2023'!$B$3:$B$34,$A46,'BATS 2023'!$C$3:$C$34,D$42,'BATS 2023'!$D$3:$D$34,D$43) -> 984.62713 | E46: =SUMIFS('BATS 2023'!$E$3:$E$34,'BATS 2023'!$B$3:$B$34,$A46,'BATS 2023'!$C$3:$C$34,E$42,'BATS 2023'!$D$3:$D$34,E$43) -> 304252.93 | F46: =SUMIFS('BATS 2023'!$E$3:$E$34,'BATS 2023'!$B$3:$B$34,$A46,'BATS 2023'!$C$3:$C$34,F$42,'BATS 2023'!$D$3:$D$34,F$43) -> 800779.54 | G46: =SUMIFS('BATS 2023'!$E$3:$E$34,'BATS 2023'!$B$3:$B$34,$A46,'BATS 2023'!$C$3:$C$34,G$42,'BATS 2023'!$D$3:$D$34,G$43) -> 136311.22 | H46: =SUMIFS('BATS 2023'!$E$3:$E$34,'BATS 2023'!$B$3:$B$34,$A46,'BATS 2023'!$C$3:$C$34,H$42,'BATS 2023'!$D$3:$D$34,H$43) -> 351299.41 | I46: =SUM(C46:H46) -> 3181344.6 | K46: =modeldata!D15 -> 1 | L46: =modeldata!E15 -> 1 | M46: =modeldata!F15 -> 1 | N46: =modeldata!G15 -> 1 | O46: =modeldata!B15 -> 1 | P46: =modeldata!C15 -> 1 | Q46: =SUM(K46:P46) -> 6 | S46: =IFERROR(K46-C46,0) -> -1587715.9 | T46: =IFERROR(L46-D46,0) -> -983.62713 | U46: =IFERROR(M46-E46,0) -> -304251.93 | V46: =IFERROR(N46-F46,0) -> -800778.54 | W46: =IFERROR(O46-G46,0) -> -136310.22 | X46: =IFERROR(P46-H46,0) -> -351298.41
A47: 2 | B47: Part-time worker | C47: =SUMIFS('BATS 2023'!$E$3:$E$34,'BATS 2023'!$B$3:$B$34,$A47,'BATS 2023'!$C$3:$C$34,C$42,'BATS 2023'!$D$3:$D$34,C$43) -> 319170.3 | D47: =SUMIFS('BATS 2023'!$E$3:$E$34,'BATS 2023'!$B$3:$B$34,$A47,'BATS 2023'!$C$3:$C$34,D$42,'BATS 2023'!$D$3:$D$34,D$43) -> 0 | E47: =SUMIFS('BATS 2023'!$E$3:$E$34,'BATS 2023'!$B$3:$B$34,$A47,'BATS 2023'!$C$3:$C$34,E$42,'BATS 2023'!$D$3:$D$34,E$43) -> 168031.37 | F47: =SUMIFS('BATS 2023'!$E$3:$E$34,'BATS 2023'!$B$3:$B$34,$A47,'BATS 2023'!$C$3:$C$34,F$42,'BATS 2023'!$D$3:$D$34,F$43) -> 89604.784 | G47: =SUMIFS('BATS 2023'!$E$3:$E$34,'BATS 2023'!$B$3:$B$34,$A47,'BATS 2023'!$C$3:$C$34,G$42,'BATS 2023'!$D$3:$D$34,G$43) -> 66930.204 | H47: =SUMIFS('BATS 2023'!$E$3:$E$34,'BATS 2023'!$B$3:$B$34,$A47,'BATS 2023'!$C$3:$C$34,H$42,'BATS 2023'!$D$3:$D$34,H$43) -> 28278.935 | I47: =SUM(C47:H47) -> 672015.6 | K47: =modeldata!D16 -> 1 | L47: =modeldata!E16 -> 1 | M47: =modeldata!F16 -> 1 | N47: =modeldata!G16 -> 1 | O47: =modeldata!B16 -> 1 | P47: =modeldata!C16 -> 1 | Q47: =SUM(K47:P47) -> 6 | S47: =IFERROR(K47-C47,0) -> -319169.3 | T47: =IFERROR(L47-D47,0) -> 1 | U47: =IFERROR(M47-E47,0) -> -168030.37 | V47: =IFERROR(N47-F47,0) -> -89603.784 | W47: =IFERROR(O47-G47,0) -> -66929.204 | X47: =IFERROR(P47-H47,0) -> -28277.935
...

Sheet modeldata
A1: Source:
A2: PersonType | B2: H | C2: M | D2: N
A3: 1 | B3: 1 | C3: 1 | D3: 1
A4: 2 | B4: 1 | C4: 1 | D4: 1
A5: 3 | B5: 1 | C5: 1 | D5: 1
A6: 4 | B6: 1 | C6: 1 | D6: 1
A7: 5 | B7: 1 | C7: 1 | D7: 1
A8: 6 | B8: 1 | C8: 1 | D8: 1
A9: 7 | B9: 1 | C9: 1 | D9: 1
A10: 8 | B10: 1 | C10: 1 | D10: 1
A13: Source:
A14: PersonType | B14: H_WFH_0 | C14: H_WFH_1 | D14: M_WFH_0 | E14: M_WFH_1 | F14: N_WFH_0 | G14: N_WFH_1
A15: 1 | B15: 1 | C15: 1 | D15: 1 | E15: 1 | F15: 1 | G15: 1
A16: 2 | B16: 1 | C16: 1 | D16: 1 | E16: 1 | F16: 1 | G16: 1
A17: 3 | B17: 1 | C17: 1 | D17: 1 | E17: 1 | F17: 1 | G17: 1
A18: 4 | B18: 1 | C18: 1 | D18: 1 | E18: 1 | F18: 1 | G18: 1
A19: 5 | B19: 1 | C19: 1 | D19: 1 | E19: 1 | F19: 1 | G19: 1
A20: 6 | B20: 1 | C20: 1 | D20: 1 | E20: 1 | F20: 1 | G20: 1
A21: 7 | B21: 1 | C21: 1 | D21: 1 | E21: 1 | F21: 1 | G21: 1
A22: 8 | B22: 1 | C22: 1 | D22: 1 | E22: 1 | F22: 1 | G22: 1

Sheet BATS 2023
B1: Source: M:/Development/Travel Model One/Calibration/Version 1.7/2023_BATS_Summaries/pipeline_mt_20261027/ctramp_2023/BATS_Summaries/dap_summaries.csv
B2: person_type | C2: activity_pattern | D2: wfh_choice | E2: num_pers
B3: 1 | C3: H | D3: 0 | E3: 136311.22
B4: 1 | C4: H | D4: 1 | E4: 351299.41 | P4: Sum of num_pers | Q4: Column Labels
B5: 1 | C5: M | D5: 0 | E5: 1587716.9 | I5: Sum of num_pers | J5: Column Labels | Q5: H | S5: H Total | T5: M | V5: M Total | W5: N | Y5: N Total | Z5: (blank) | AA5: (blank) Total | AB5: Grand Total
B6: 1 | C6: M | D6: 1 | E6: 984.62713 | I6: Row Labels | J6: H | K6: M | L6: N | M6: Grand Total | P6: Row Labels | Q6: 0 | R6: 1 | T6: 0 | U6: 1 | W6: 0 | X6: 1 | Z6: (blank)
B7: 1 | C7: N | D7: 0 | E7: 304252.93 | H7: Full-time worker | I7: 1 | J7: 487610.63 | K7: 1588701.5 | L7: 1105032.5 | M7: 3181344.6 | P7: 1 | Q7: 136311.22 | R7: 351299.41 | S7: 487610.63 | T7: 1587716.9 | U7: 984.62713 | V7: 1588701.5 | W7: 304252.93 | X7: 800779.54 | Y7: 1105032.5 | AB7: 3181344.6
B8: 1 | C8: N | D8: 1 | E8: 800779.54 | H8: Part-time worker | I8: 2 | J8: 95209.139 | K8: 319170.3 | L8: 257636.16 | M8: 672015.6 | P8: 2 | Q8: 66930.204 | R8: 28278.935 | S8: 95209.139 | T8: 319170.3 | V8: 319170.3 | W8: 168031.37 | X8: 89604.784 | Y8: 257636.16 | AB8: 672015.6
B9: 2 | C9: H | D9: 0 | E9: 66930.204 | H9: University student | I9: 3 | J9: 77720.499 | K9: 108654.68 | L9: 226287.48 | M9: 412662.66 | P9: 3 | Q9: 71929.739 | R9: 5790.7602 | S9: 77720.499 | T9: 102255.24 | U9: 6399.4452 | V9: 108654.68 | W9: 185077.08 | X9: 41210.398 | Y9: 226287.48 | AB9: 412662.66
B10: 2 | C10: H | D10: 1 | E10: 28278.935 | H10: Non-worker | I10: 4 | J10: 197443.74 | L10: 572446.56 | M10: 769890.31 | P10: 4 | Q10: 197443.74 | S10: 197443.74 | W10: 572446.56 | Y10: 572446.56 | AB10: 769890.31
B11: 2 | C11: M | D11: 0 | E11: 319170.3 | H11: Retired | I11: 5 | J11: 292213.43 | L11: 661707.41 | M11: 953920.84 | P11: 5 | Q11: 292213.43 | S11: 292213.43 | W11: 661707.41 | Y11: 661707.41 | AB11: 953920.84
B12: 2 | C12: N | D12: 0 | E12: 168031.37 | H12: Student of driving age | I12: 6 | J12: 17630.207 | K12: 123094.59 | L12: 17712.812 | M12: 158437.61 | P12: 6 | Q12: 17630.207 | S12: 17630.207 | T12: 123094.59 | V12: 123094.59 | W12: 17712.812 | Y12: 17712.812 | AB12: 158437.61
B13: 2 | C13: N | D13: 1 | E13: 89604.784 | H13: Student of non-driving age | I13: 7 | J13: 85466.73 | K13: 665066.56 | L13: 64858.529 | M13: 815391.82 | P13: 7 | Q13: 85466.73 | S13: 85466.73 | T13: 665066.56 | V13: 665066.56 | W13: 64858.529 | Y13: 64858.529 | AB13: 815391.82
B14: 3 | C14: H | D14: 0 | E14: 71929.739 | H14: Child too young for school | I14: 8 | J14: 121625.5 | K14: 138048.92 | L14: 145623.69 | M14: 405298.11 | P14: 8 | Q14: 121625.5 | S14: 121625.5 | T14: 138048.92 | V14: 138048.92 | W14: 145623.69 | Y14: 145623.69 | AB14: 405298.11
B15: 3 | C15: H | D15: 1 | E15: 5790.7602 | I15: Grand Total | J15: 1374919.9 | K15: 2942736.6 | L15: 3051305.1 | M15: 7368961.5 | P15: (blank)
B16: 3 | C16: M | D16: 0 | E16: 102255.24 | P16: Grand Total | Q16: 989550.77 | R16: 385369.1 | S16: 1374919.9 | T16: 2935352.5 | U16: 7384.0723 | V16: 2942736.6 | W16: 2119710.4 | X16: 931594.72 | Y16: 3051305.1 | AB16: 7368961.5
B17: 3 | C17: M | D17: 1 | E17: 6399.4452
B18: 3 | C18: N | D18: 0 | E18: 185077.08
B19: 3 | C19: N | D19: 1 | E19: 41210.398
B20: 4 | C20: H | D20: 0 | E20: 197443.74
B21: 4 | C21: N | D21: 0 | E21: 572446.56
B22: 5 | C22: H | D22: 0 | E22: 292213.43
B23: 5 | C23: N | D23: 0 | E23: 661707.41 | I23: Type | J23: CDAP | K23: CHTS Values | P23: BATS 2023 Values
B24: 6 | C24: H | D24: 0 | E24: 17630.207 | I24: 6 | J24: H | K24: 17630.207 | M24: 6 | N24: H | O24: 0 | P24: 79476.998 | Q24: =P24/SUM($P$24:$P$27) -> 0.43872002
B25: 6 | C25: M | D25: 0 | E25: 123094.59 | I25: 6 | J25: M | K25: 123094.59 | M25: 6 | N25: M | O25: 0 | P25: 47573.543 | Q25: =P25/SUM($P$24:$P$27) -> 0.26261014
B26: 6 | C26: N | D26: 0 | E26: 17712.812 | I26: 6 | J26: N | K26: 17712.812 | M26: 6 | N26: N | O26: 0 | P26: 47942.382 | Q26: =P26/SUM($P$24:$P$27) -> 0.26464616
B27: 7 | C27: H | D27: 0 | E27: 85466.73 | I27: 7 | J27: H | K27: 85466.73 | M27: 6 | N27: N | O27: 1 | P27: 6163.6112 | Q27: =P27/SUM($P$24:$P$27) -> 0.034023676
B28: 7 | C28: M | D28: 0 | E28: 665066.56 | I28: 7 | J28: M | K28: 665066.56 | M28: 7 | N28: H | O28: 0 | P28: 219255.13 | Q28: =P28/SUM($P$28:$P$30) -> 0.28930448
B29: 7 | C29: N | D29: 0 | E29: 64858.529 | I29: 7 | J29: N | K29: 64858.529 | M29: 7 | N29: M | O29: 0 | P29: 209062.28 | Q29: =P29/SUM($P$28:$P$30) -> 0.27585515
B30: 8 | C30: H | D30: 0 | E30: 121625.5 | I30: 8 | J30: H | K30: 121625.5 | M30: 7 | N30: N | O30: 0 | P30: 329552.39 | Q30: =P30/SUM($P$28:$P$30) -> 0.43484038
B31: 8 | C31: M | D31: 0 | E31: 138048.92 | I31: 8 | J31: M | K31: 138048.92 | M31: 8 | N31: H | O31: 0 | P31: 142223.23 | Q31: =P31/SUM($P$31:$P$33) -> 0.37290803
B32: 8 | C32: N | D32: 0 | E32: 145623.69 | I32: 8 | J32: N | K32: 145623.69 | M32: 8 | N32: M | O32: 0 | P32: 90316.834 | Q32: =P32/SUM($P$31:$P$33) -> 0.23680992
M33: 8 | N33: N | O33: 0 | P33: 148849.51 | Q33: =P33/SUM($P$31:$P$33) -> 0.39028206
B37: **Since BATS2023 was under-reporting children under 18 due to proxy targets, CDAP targets for children under 18 are based on the previous CHTS targets
B39: North Bay
B40: Source: M:/Development/Travel Model One/Calibration/Version 1.7/2023_BATS_Summaries/pipeline_mt_20261027/ctramp_2023/BATS_Summaries/BATS2023_person_type_summary_north_bay
B41: person_type | C41: activity_pattern | D41: wfh_choice | E41: num_pers
B42: 1 | C42: H | D42: 0 | E42: 15840.428
B43: 1 | C43: H | D43: 1 | E43: 42291.266
B44: 1 | C44: M | D44: 0 | E44: 239109.16
...

Sheet BATS 2023 - WFH
A1: Source: M:\Development\Travel Model One\Calibration\Version 1.7\2023_BATS_Summaries\pipeline_mt_20261027\2023 BATS WFH Rates.xlsx
A2: Home County Name | B2: Unweighted WFH Workers | C2: Weighted WFH Workers | D2: Unweighted Workers | E2: Weighted Workers | F2: WFH Share
A3: Alameda | B3: 1360 | C3: 3432 | D3: 304422 | E3: 800915.15 | F3: 0.38009269
A4: Contra Costa | B4: 578 | C4: 1457 | D4: 173987.35 | E4: 611033.38 | F4: 0.2847428
A5: Marin | B5: 67 | C5: 172 | D5: 53866.3 | E5: 119215.37 | F5: 0.45184021
A6: Napa | B6: 91 | C6: 301 | D6: 20733.381 | E6: 88110.624 | F6: 0.2353108
A7: San Francisco | B7: 1968 | C7: 4906 | D7: 195932.9 | E7: 516743.65 | F7: 0.37916848
A8: San Mateo | B8: 285 | C8: 776 | D8: 128274.17 | E8: 379469.69 | F8: 0.33803536
A9: Santa Clara | B9: 883 | C9: 2493 | D9: 339742.84 | E9: 1108207.6 | F9: 0.30656968
A10: Solano | B10: 232 | C10: 742 | D10: 55426.964 | E10: 223746.2 | F10: 0.24772248
A11: Sonoma | B11: 164 | C11: 506 | D11: 58125.593 | E11: 242664.31 | F11: 0.23953087
A12: Grand Total | B12: 5628 | C12: 14785 | D12: 1330511.5 | E12: 4090106 | F12: 0.32530001
A14: **Workers are defined as person who employment category is Full-Time or Part-Time
A15: **WFH Workers are defined as workers who make a WFH Choice (WFH Choice = 1)
A16: ***WFH Choice is defined via the survey processing as: wfh = 1, telecommute > 0, and no work tours that day
A17: WFH Rate is calculated as: WFH Workers/Workers

Sheet TM1 v03 Targets
A1: Source: M:\Development\Travel Model One\Calibration\Version 03\04 Coordinated Daily Activity Pattern\4cdap_calib_mtccluster_2.xlsx
A2: HOUSEHOLD SURVEY
A3: Person type | B3: Mandatory | C3: Non-Mandatory | D3: Home | E3: Total
A4: Full-time worker | B4: 2245780.8 | C4: 359741.64 | D4: 327500.47 | E4: 2933023 | F4: =E4/$E$12 -> 0.44165999
A5: Part-time worker | B5: 198527.94 | C5: 116610.3 | D5: 56022.586 | E5: 371160.82 | F5: =E5/$E$12 -> 0.05589008
A6: University student | B6: 204361.06 | C6: 82763.101 | D6: 59894.928 | E6: 347019.09 | F6: =E6/$E$12 -> 0.052254773
A7: Non-worker | B7: 0 | C7: =80256.338677+370934.90183 -> 451191.24 | D7: 189396.05 | E7: 640587.29 | F7: =E7/$E$12 -> 0.096460813
A8: Retired | B8: 0 | C8: =36006.162668+245427.79974 -> 281433.96 | D8: 142119.24 | E8: 423553.2 | F8: =E8/$E$12 -> 0.063779421
A9: Student of driving age | B9: 132569.67 | C9: 23624.495 | D9: 32689.305 | E9: 188883.47 | F9: =E9/$E$12 -> 0.02844242
A10: Student of non-driving age | B10: 782213.25 | C10: 183362.53 | D10: 175575.13 | E10: 1141150.9 | F10: =E10/$E$12 -> 0.1718366
A11: Child too young for school | B11: 201049.05 | C11: 227303 | D11: 167177.24 | E11: 595529.28 | F11: =E11/$E$12 -> 0.089675896
A12: Total | B12: 3880764.3 | C12: 1609767.8 | D12: 1150374.9 | E12: 6640907 | F12: =E12/$E$12 -> 1
A14: HOUSEHOLD SURVEY SHARES
A15: Person type | B15: Mandatory | C15: Non-Mandatory | D15: Home | E15: Total
A16: Full-time worker | B16: =B4/$E4 -> 0.76568812 | C16: =C4/$E4 -> 0.12265217 | D16: =D4/$E4 -> 0.1116597 | E16: =E4/$E4 -> 1
A17: Part-time worker | B17: =B5/$E5 -> 0.53488387 | C17: =C5/$E5 -> 0.31417728 | D17: =D5/$E5 -> 0.15093885 | E17: =E5/$E5 -> 1
A18: University student | B18: =B6/$E6 -> 0.58890438 | C18: =C6/$E6 -> 0.23849726 | D18: =D6/$E6 -> 0.17259837 | E18: =E6/$E6 -> 1
A19: Non-worker | B19: =B7/$E7 -> 0 | C19: =C7/$E7 -> 0.70433998 | D19: =D7/$E7 -> 0.29566002 | E19: =E7/$E7 -> 1
A20: Retired | B20: =B8/$E8 -> 0 | C20: =C8/$E8 -> 0.66445953 | D20: =D8/$E8 -> 0.33554047 | E20: =E8/$E8 -> 1
A21: Student of driving age | B21: =B9/$E9 -> 0.70185956 | C21: =C9/$E9 -> 0.12507445 | D21: =D9/$E9 -> 0.173066 | E21: =E9/$E9 -> 1
A22: Student of non-driving age | B22: =B10/$E10 -> 0.68545996 | C22: =C10/$E10 -> 0.1606821 | D22: =D10/$E10 -> 0.15385794 | E22: =E10/$E10 -> 1
A23: Child too young for school | B23: =B11/$E11 -> 0.33759724 | C23: =C11/$E11 -> 0.38168232 | D23: =D11/$E11 -> 0.28072044 | E23: =E11/$E11 -> 1
A24: Total | B24: =B12/$E12 -> 0.58437263 | C24: =C12/$E12 -> 0.24240179 | D24: =D12/$E12 -> 0.17322558 | E24: =E12/$E12 -> 1
A27: SFCTA Adjusted Targets
A28: Person type | B28: Mandatory | C28: Non-Mandatory | D28: Home | E28: Total | F28: Share of Persons
A29: Full-time worker | B29: 0.79 | C29: 0.12 | D29: 0.09 | E29: =SUM(B29:D29) -> 1 | F29: 0.476
A30: Part-time worker
A31: University student | B31: 0.7 | C31: 0.22 | D31: 0.08 | E31: =SUM(B31:D31) -> 1 | F31: 0.052
A32: Non-worker | B32: 0 | C32: 0.8 | D32: 0.2 | E32: =SUM(B32:D32) -> 1 | F32: 0.226
A33: Retired
A34: Student of driving age | B34: 0.65 | C34: 0.2 | D34: 0.15 | E34: =SUM(B34:D34) -> 1 | F34: 0.246
A35: Student of non-driving age
A36: Child too young for school
A37: Total | B37: =SUMPRODUCT(B29:B36,$F29:$F36) -> 0.57234 | C37: =SUMPRODUCT(C29:C36,$F29:$F36) -> 0.29856 | D37: =SUMPRODUCT(D29:D36,$F29:$F36) -> 0.1291 | E37: =SUM(B37:D37) -> 1 | F37: =SUM(F29:F36) -> 1
B39: =A27&" split into 8 person types" -> SFCTA Adjusted Targets split into 8 person types
A40: Person type | B40: Mandatory | C40: Non-Mandatory | D40: Home | E40: Total | F40: Share of Persons
A41: Full-time worker | B41: =B4*B$29/(SUM(B$4:B$5)/SUM($E$4:$E$5))*$F$29/($F$4+$F$5) -> 2294419.1 | C41: =C4*C$29/(SUM(C$4:C$5)/SUM($E$4:$E$5))*$F$29/($F$4+$F$5) -> 286469.49 | D41: =D4*D$29/(SUM(D$4:D$5)/SUM($E$4:$E$5))*$F$29/($F$4+$F$5) -> 242939.04 | E41: =SUM(B41:D41) -> 2823827.6 | F41: =E41/$E$49 -> 0.42521716
A42: Part-time worker | B42: =B5*B$29/(SUM(B$4:B$5)/SUM($E$4:$E$5))*$F$29/($F$4+$F$5) -> 202827.58 | C42: =C5*C$29/(SUM(C$4:C$5)/SUM($E$4:$E$5))*$F$29/($F$4+$F$5) -> 92859.121 | D42: =D5*D$29/(SUM(D$4:D$5)/SUM($E$4:$E$5))*$F$29/($F$4+$F$5) -> 41557.416 | E42: =SUM(B42:D42) -> 337244.12 | F42: =E42/$E$49 -> 0.05078284
A43: University student | B43: =B6*B31/B18*$F$31/$F$6 -> 241729.02 | C43: =C6*C31/C18*$F$31/$F$6 -> 75971.976 | D43: =D6*D31/D18*$F$31/$F$6 -> 27626.173 | E43: =SUM(B43:D43) -> 345327.17 | F43: =E43/$E$49 -> 0.052
A44: Non-worker | B44: 0 | C44: =C7*C$32/(SUM(C$7:C$8)/SUM($E$7:$E$8))*$F32/($F$7+$F$8) -> 739442.88 | D44: =D7*D$32/(SUM(D$7:D$8)/SUM($E$7:$E$8))*$F32/($F$7+$F$8) -> 171487.78 | E44: =SUM(B44:D44) -> 910930.66 | F44: =E44/$E$49 -> 0.13716962
...
