Workbook
Name damp: #REF!
Name damp_atwork: calibration!$BX$1
Name damp_disc: calibration!$BL$1
Name damp_discr: calibration!$BL$1
Name damp_eatout: calibration!$AN$1
Name damp_escort: calibration!$D$1
Name damp_maint: calibration!$AB$1
Name damp_shopping: calibration!$P$1
Name damp_social: calibration!$AZ$1
Name damp_work: calibration!$D$1
Name damp4: #REF!
Name damp5: #REF!
Name damp6: #REF!
Name damp7: #REF!
Name damp8: #REF!
Name damp9: #REF!

Sheet calibration
C1: Dampening (Escort) | D1: 0 | O1: Dampening (Shop) | P1: 0 | AA1: Dampening (Maintenance) | AB1: 0 | AM1: Dampening (Eating Out) | AN1: 0 | AY1: Dampening (Social) | AZ1: 0 | BK1: Dampening (Discretionary) | BL1: 0 | BW1: Dampening (At Work) | BX1: 0
D3: ThisIter | E3: NextIter | P3: ThisIter | Q3: NextIter | AB3: ThisIter | AC3: NextIter | AN3: ThisIter | AO3: NextIter | AZ3: ThisIter | BA3: NextIter | BL3: ThisIter | BM3: NextIter | BX3: ThisIter | BY3: NextIter
C4: Dist0to1Miles | D4: =[1]EscortKids!$G12 -> -0.14986893 | E4: =MIN(K17,0) -> -0.14986893 | O4: Dist0to1Miles | P4: =[1]Shopping!$G12 -> 0 | Q4: =MIN(W17,0) -> 0 | AA4: Dist0to1Miles | AB4: =[1]OthMaint!$G12 -> 0 | AC4: =MIN(AI17,0) -> 0 | AM4: Dist0to1Miles | AN4: =[1]EatOut!$G12 -> -0.56088406 | AO4: =MIN(AU17,0) -> -0.56088406 | AY4: Dist0to1Miles | AZ4: =[1]Social!$G12 -> -0.7841358 | BA4: =MIN(BG17,0) -> -0.7841358 | BK4: Dist0to1Miles | BL4: =[1]OthDiscr!$G12 -> -0.16770689 | BM4: =MIN(BS17,0) -> -0.16770689 | BW4: Dist0to1Miles | BX4: =[1]WorkBased!$G12 -> -0.79256759 | BY4: =MIN(CE17,0) -> -0.79256759
C5: Dist1to2Miles | D5: =[1]EscortKids!$G13 -> -0.14986893 | E5: =MIN(K18-K17,0) -> -0.14986893 | O5: Dist1to2Miles | P5: =[1]Shopping!$G13 -> 0 | Q5: =MIN(W18-W17,0) -> 0 | AA5: Dist1to2Miles | AB5: =[1]OthMaint!$G13 -> 0 | AC5: =MIN(AI18-AI17,0) -> 0 | AM5: Dist1to2Miles | AN5: =[1]EatOut!$G13 -> -0.56088406 | AO5: =MIN(AU18-AU17,0) -> -0.56088406 | AY5: Dist1to2Miles | AZ5: =[1]Social!$G13 -> -0.7841358 | BA5: =MIN(BG18-BG17,0) -> -0.7841358 | BK5: Dist1to2Miles | BL5: =[1]OthDiscr!$G13 -> -0.16770689 | BM5: =MIN(BS18-BS17,0) -> -0.16770689 | BW5: Dist1to2Miles | BX5: =[1]WorkBased!$G13 -> -0.79256759 | BY5: =MIN(CE18-CE17,0) -> -0.79256759
C6: Dist2to5Miles | D6: =[1]EscortKids!$G14 -> -0.86713093 | E6: =MIN((K21-K18)/3,0) -> -0.86713093 | O6: Dist2to5Miles | P6: =[1]Shopping!$G14 -> -0.56554371 | Q6: =MIN((W21-W18)/3,0) -> -0.56554371 | AA6: Dist2to5Miles | AB6: =[1]OthMaint!$G14 -> -0.60549817 | AC6: =MIN((AI21-AI18)/3,0) -> -0.60549817 | AM6: Dist2to5Miles | AN6: =[1]EatOut!$G14 -> -0.3191705 | AO6: =MIN((AU21-AU18)/3,0) -> -0.3191705 | AY6: Dist2to5Miles | AZ6: =[1]Social!$G14 -> -0.34846404 | BA6: =MIN((BG21-BG18)/3,0) -> -0.34846404 | BK6: Dist2to5Miles | BL6: =[1]OthDiscr!$G14 -> -0.4954932 | BM6: =MIN((BS21-BS18)/3,0) -> -0.4954932 | BW6: Dist2to5Miles | BX6: =[1]WorkBased!$G14 -> -0.51970902 | BY6: =MIN((CE21-CE18)/3,0) -> -0.51970902
C7: Dist5to15Miles | D7: =[1]EscortKids!$G15 -> -0.21370826 | E7: =MIN((K31-K21)/10,0) -> -0.21370826 | O7: Dist5to15Miles | P7: =[1]Shopping!$G15 -> -0.18324871 | Q7: =MIN((W31-W21)/10,0) -> -0.18324871 | AA7: Dist5to15Miles | AB7: =[1]OthMaint!$G15 -> -0.10927639 | AC7: =MIN((AI31-AI21)/10,0) -> -0.10927639 | AM7: Dist5to15Miles | AN7: =[1]EatOut!$G15 -> -0.12376668 | AO7: =MIN((AU31-AU21)/10,0) -> -0.12376668 | AY7: Dist5to15Miles | AZ7: =[1]Social!$G15 -> -0.13060068 | BA7: =MIN((BG31-BG21)/10,0) -> -0.13060068 | BK7: Dist5to15Miles | BL7: =[1]OthDiscr!$G15 -> -0.11929589 | BM7: =MIN((BS31-BS21)/10,0) -> -0.11929589 | BW7: Dist5to15Miles | BX7: =[1]WorkBased!$G15 -> -0.20447345 | BY7: =MIN((CE31-CE21)/10,0) -> -0.20447345
C8: Dist15PlsMiles | D8: =[1]EscortKids!$G16 -> -0.21370826 | E8: =MIN((K46-K31)/15,0) -> -0.21370826 | O8: Dist15PlsMiles | P8: =[1]Shopping!$G16 -> -0.18324871 | Q8: =MIN((W46-W31)/15,0) -> -0.18324871 | AA8: Dist15PlsMiles | AB8: =[1]OthMaint!$G16 -> -0.10927639 | AC8: =MIN((AI46-AI31)/15,0) -> -0.10927639 | AM8: Dist15PlsMiles | AN8: =[1]EatOut!$G16 -> -0.12376668 | AO8: =MIN((AU46-AU31)/15,0) -> -0.12376668 | AY8: Dist15PlsMiles | AZ8: =[1]Social!$G16 -> -0.13060068 | BA8: =MIN((BG46-BG31)/15,0) -> -0.13060068 | BK8: Dist15PlsMiles | BL8: =[1]OthDiscr!$G16 -> -0.11929589 | BM8: =MIN((BS46-BS31)/15,0) -> -0.11929589 | BW8: Dist15PlsMiles | BX8: =[1]WorkBased!$G16 -> -0.20447345 | BY8: =MIN((CE46-CE31)/15,0) -> -0.20447345
C11: Escort | O11: Shopping | AA11: Maintenance | AM11: Eating Out | AY11: Social | BK11: Discretionary | BW11: Work Based
C12: Individual and Joint Tour Length Frequency Distribution, by Primary Tour Purpose | O12: Individual and Joint Tour Length Frequency Distribution, by Primary Tour Purpose | AA12: Individual and Joint Tour Length Frequency Distribution, by Primary Tour Purpose | AM12: Individual and Joint Tour Length Frequency Distribution, by Primary Tour Purpose | AY12: Individual and Joint Tour Length Frequency Distribution, by Primary Tour Purpose | BK12: Individual and Joint Tour Length Frequency Distribution, by Primary Tour Purpose | BW12: Individual and Joint Tour Length Frequency Distribution, by Primary Tour Purpose
D14: Existing | F14: Percent of Trips | I14: Coefficient Change | K14: Ideal | L14: Proposed | P14: Existing | R14: Percent of Trips | U14: Coefficient Change | W14: Ideal | X14: Proposed | AB14: Existing | AD14: Percent of Trips | AG14: Coefficient Change | AI14: Ideal | AJ14: Proposed | AN14: Existing | AP14: Percent of Trips | AS14: Coefficient Change | AU14: Ideal | AV14: Proposed | AZ14: Existing | BB14: Percent of Trips | BE14: Coefficient Change | BG14: Ideal | BH14: Proposed | BL14: Existing | BN14: Percent of Trips | BQ14: Coefficient Change | BS14: Ideal | BT14: Proposed | BX14: Existing | BZ14: Percent of Trips | CC14: Coefficient Change | CE14: Ideal | CF14: Proposed
A15: avg | B15: min | C15: Distance | D15: Coefficient | E15: Total Value | F15: Observed | G15: Modeled | H15: % Difference | I15: Raw | J15: Normalized | K15: Total Value | L15: Coefficient | M15: Total Value | O15: Distance | P15: Coefficient | Q15: Total Value | R15: Observed | S15: Modeled | T15: % Difference | U15: Raw | V15: Normalized | W15: Total Value | X15: Coefficient | Y15: Total Value | AA15: Distance | AB15: Coefficient | AC15: Total Value | AD15: Observed | AE15: Modeled | AF15: % Difference | AG15: Raw | AH15: Normalized | AI15: Total Value | AJ15: Coefficient | AK15: Total Value | AM15: Distance | AN15: Coefficient | AO15: Total Value | AP15: Observed | AQ15: Modeled | AR15: % Difference | AS15: Raw | AT15: Normalized | AU15: Total Value | AV15: Coefficient | AW15: Total Value | AY15: Distance | AZ15: Coefficient | BA15: Total Value | BB15: Observed | BC15: Modeled | BD15: % Difference | BE15: Raw | BF15: Normalized | BG15: Total Value | BH15: Coefficient | BI15: Total Value | BK15: Distance | BL15: Coefficient | BM15: Total Value | BN15: Observed | BO15: Modeled | BP15: % Difference | BQ15: Raw | BR15: Normalized | BS15: Total Value | BT15: Coefficient | BU15: Total Value | BW15: Distance | BX15: Coefficient | BY15: Total Value | BZ15: Observed | CA15: Modeled | CB15: % Difference | CC15: Raw | CD15: Normalized | CE15: Total Value | CF15: Coefficient | CG15: Total Value
A16: 0.5 | B16: 0 | C16: 0-1 | D16: =D4 -> -0.14986893 | E16: 0 | F16: =MAX('BATS 2023 TLFD'!M4,0.0001) -> 0.168539 | G16: =modeldata!B4/modeldata!B$156 -> 0.0066666667 | H16: =IF(F16>0,(G16-F16)/F16,"") -> -0.96044437 | I16: =damp_escort*LN(F16/G16) -> 0 | J16: =I16-I$16 -> 0 | K16: =SUM(E16,J16) -> 0 | L16: =E4 -> -0.14986893 | M16: 0 | O16: 0-1 | P16: =P4 -> 0 | Q16: 0 | R16: =MAX('BATS 2023 TLFD'!N4,0.0001) -> 0.13055948 | S16: =modeldata!C4/modeldata!C$156 -> 0.0066666667 | T16: =IF(R16>0,(S16-R16)/R16,"") -> -0.9489377 | U16: =damp_shopping*LN(R16/S16) -> 0 | V16: =U16-U$16 -> 0 | W16: =SUM(Q16,V16) -> 0 | X16: =Q4 -> 0 | Y16: 0 | AA16: 0-1 | AB16: =AB4 -> 0 | AC16: 0 | AD16: =MAX('BATS 2023 TLFD'!O4,0.0001) -> 0.10740873 | AE16: =modeldata!D4/modeldata!D$156 -> 0.0066666667 | AF16: =IF(AD16>0,(AE16-AD16)/AD16,"") -> -0.9379318 | AG16: =damp_maint*LN(AD16/AE16) -> 0 | AH16: =AG16-AG$16 -> 0 | AI16: =SUM(AC16,AH16) -> 0 | AJ16: =AC4 -> 0 | AK16: 0 | AM16: 0-1 | AN16: =AN4 -> -0.56088406 | AO16: 0 | AP16: =MAX('BATS 2023 TLFD'!P4,0.0001) -> 0.28524207 | AQ16: =modeldata!E4/modeldata!E$156 -> 0.0066666667 | AR16: =IF(AP16>0,(AQ16-AP16)/AP16,"") -> -0.97662804 | AS16: =damp_eatout*LN(AP16/AQ16) -> 0 | AT16: =AS16-AS$16 -> 0 | AU16: =SUM(AO16,AT16) -> 0 | AV16: =AO4 -> -0.56088406 | AW16: 0 | AY16: 0-1 | AZ16: =AZ4 -> -0.7841358 | BA16: 0 | BB16: =MAX('BATS 2023 TLFD'!Q4,0.0001) -> 0.33176409 | BC16: =modeldata!F4/modeldata!F$156 -> 0.0066666667 | BD16: =IF(BB16>0,(BC16-BB16)/BB16,"") -> -0.9799054 | BE16: =damp_social*LN(BB16/BC16) -> 0 | BF16: =BE16-BE$16 -> 0 | BG16: =SUM(BA16,BF16) -> 0 | BH16: =BA4 -> -0.7841358 | BI16: 0 | BK16: 0-1 | BL16: =BL4 -> -0.16770689 | BM16: 0 | BN16: =MAX('BATS 2023 TLFD'!R4,0.0001) -> 0.1863662 | BO16: =modeldata!G4/modeldata!G$156 -> 0.0066666667 | BP16: =IF(BN16>0,(BO16-BN16)/BN16,"") -> -0.96422813 | BQ16: =damp_discr*LN(BN16/BO16) -> 0 | BR16: =BQ16-BQ$16 -> 0 | BS16: =SUM(BM16,BR16) -> 0 | BT16: =BM4 -> -0.16770689 | BU16: 0 | BW16: 0-1 | BX16: =BX4 -> -0.79256759 | BY16: 0 | BZ16: =MAX('BATS 2023 TLFD'!S4,0.0001) -> 0.37435809 | CA16: =modeldata!H4/modeldata!H$156 -> 0.0066666667 | CB16: =IF(BZ16>0,(CA16-BZ16)/BZ16,"") -> -0.98219174 | CC16: =damp_atwork*LN(BZ16/CA16) -> 0 | CD16: =CC16-CC$16 -> 0 | CE16: =SUM(BY16,CD16) -> 0 | CF16: =BY4 -> -0.79256759 | CG16: 0
A17: =A16+1 -> 1.5 | B17: =B16+1 -> 1 | C17: 1-2 | D17: =D5 -> -0.14986893 | E17: =D16+E16 -> -0.14986893 | F17: =MAX('BATS 2023 TLFD'!M5,0.0001) -> 0.176815 | G17: =modeldata!B5/modeldata!B$156 -> 0.0066666667 | H17: =IF(F17>0,(G17-F17)/F17,"") -> -0.96229581 | I17: =damp_escort*LN(F17/G17) -> 0 | J17: =I17-I$16 -> 0 | K17: =SUM(E17,J17) -> -0.14986893 | L17: =E5 -> -0.14986893 | M17: =M16+L16 -> -0.14986893 | O17: 1-2 | P17: =P5 -> 0 | Q17: =P16+Q16 -> 0 | R17: =MAX('BATS 2023 TLFD'!N5,0.0001) -> 0.24022261 | S17: =modeldata!C5/modeldata!C$156 -> 0.0066666667 | T17: =IF(R17>0,(S17-R17)/R17,"") -> -0.97224796 | U17: =damp_shopping*LN(R17/S17) -> 0 | V17: =U17-U$16 -> 0 | W17: =SUM(Q17,V17) -> 0 | X17: =Q5 -> 0 | Y17: =Y16+X16 -> 0 | AA17: 1-2 | AB17: =AB5 -> 0 | AC17: =AB16+AC16 -> 0 | AD17: =MAX('BATS 2023 TLFD'!O5,0.0001) -> 0.32310662 | AE17: =modeldata!D5/modeldata!D$156 -> 0.0066666667 | AF17: =IF(AD17>0,(AE17-AD17)/AD17,"") -> -0.97936698 | AG17: =damp_maint*LN(AD17/AE17) -> 0 | AH17: =AG17-AG$16 -> 0 | AI17: =SUM(AC17,AH17) -> 0 | AJ17: =AC5 -> 0 | AK17: =AK16+AJ16 -> 0 | AM17: 1-2 | AN17: =AN5 -> -0.56088406 | AO17: =AN16+AO16 -> -0.56088406 | AP17: =MAX('BATS 2023 TLFD'!P5,0.0001) -> 0.17701301 | AQ17: =modeldata!E5/modeldata!E$156 -> 0.0066666667 | AR17: =IF(AP17>0,(AQ17-AP17)/AP17,"") -> -0.96233798 | AS17: =damp_eatout*LN(AP17/AQ17) -> 0 | AT17: =AS17-AS$16 -> 0 | AU17: =SUM(AO17,AT17) -> -0.56088406 | AV17: =AO5 -> -0.56088406 | AW17: =AW16+AV16 -> -0.56088406 | AY17: 1-2 | AZ17: =AZ5 -> -0.7841358 | BA17: =AZ16+BA16 -> -0.7841358 | BB17: =MAX('BATS 2023 TLFD'!Q5,0.0001) -> 0.22994102 | BC17: =modeldata!F5/modeldata!F$156 -> 0.0066666667 | BD17: =IF(BB17>0,(BC17-BB17)/BB17,"") -> -0.97100706 | BE17: =damp_social*LN(BB17/BC17) -> 0 | BF17: =BE17-BE$16 -> 0 | BG17: =SUM(BA17,BF17) -> -0.7841358 | BH17: =BA5 -> -0.7841358 | BI17: =BI16+BH16 -> -0.7841358 | BK17: 1-2 | BL17: =BL5 -> -0.16770689 | BM17: =BL16+BM16 -> -0.16770689 | BN17: =MAX('BATS 2023 TLFD'!R5,0.0001) -> 0.21973213 | BO17: =modeldata!G5/modeldata!G$156 -> 0.0066666667 | BP17: =IF(BN17>0,(BO17-BN17)/BN17,"") -> -0.96966003 | BQ17: =damp_discr*LN(BN17/BO17) -> 0 | BR17: =BQ17-BQ$16 -> 0 | BS17: =SUM(BM17,BR17) -> -0.16770689 | BT17: =BM5 -> -0.16770689 | BU17: =BU16+BT16 -> -0.16770689 | BW17: 1-2 | BX17: =BX5 -> -0.79256759 | BY17: =BX16+BY16 -> -0.79256759 | BZ17: =MAX('BATS 2023 TLFD'!S5,0.0001) -> 0.28806888 | CA17: =modeldata!H5/modeldata!H$156 -> 0.0066666667 | CB17: =IF(BZ17>0,(CA17-BZ17)/BZ17,"") -> -0.97685739 | CC17: =damp_atwork*LN(BZ17/CA17) -> 0 | CD17: =CC17-CC$16 -> 0 | CE17: =SUM(BY17,CD17) -> -0.79256759 | CF17: =BY5 -> -0.79256759 | CG17: =CG16+CF16 -> -0.79256759
A18: =A17+1 -> 2.5 | B18: =B17+1 -> 2 | C18: 2-3 | D18: =D6 -> -0.86713093 | E18: =D17+E17 -> -0.29973786 | F18: =MAX('BATS 2023 TLFD'!M6,0.0001) -> 0.1999185 | G18: =modeldata!B6/modeldata!B$156 -> 0.0066666667 | H18: =IF(F18>0,(G18-F18)/F18,"") -> -0.96665308 | I18: =damp_escort*LN(F18/G18) -> 0 | J18: =I18-I$16 -> 0 | K18: =SUM(E18,J18) -> -0.29973786 | L18: =E6 -> -0.86713093 | M18: =M17+L17 -> -0.29973786 | O18: 2-3 | P18: =P6 -> -0.56554371 | Q18: =P17+Q17 -> 0 | R18: =MAX('BATS 2023 TLFD'!N6,0.0001) -> 0.17440991 | S18: =modeldata!C6/modeldata!C$156 -> 0.0066666667 | T18: =IF(R18>0,(S18-R18)/R18,"") -> -0.96177587 | U18: =damp_shopping*LN(R18/S18) -> 0 | V18: =U18-U$16 -> 0 | W18: =SUM(Q18,V18) -> 0 | X18: =Q6 -> -0.56554371 | Y18: =Y17+X17 -> 0 | AA18: 2-3 | AB18: =AB6 -> -0.60549817 | AC18: =AB17+AC17 -> 0 | AD18: =MAX('BATS 2023 TLFD'!O6,0.0001) -> 0.093288232 | AE18: =modeldata!D6/modeldata!D$156 -> 0.0066666667 | AF18: =IF(AD18>0,(AE18-AD18)/AD18,"") -> -0.9285369 | AG18: =damp_maint*LN(AD18/AE18) -> 0 | AH18: =AG18-AG$16 -> 0 | AI18: =SUM(AC18,AH18) -> 0 | AJ18: =AC6 -> -0.60549817 | AK18: =AK17+AJ17 -> 0 | AM18: 2-3 | AN18: =AN6 -> -0.3191705 | AO18: =AN17+AO17 -> -1.1217681 | AP18: =MAX('BATS 2023 TLFD'!P6,0.0001) -> 0.17272879 | AQ18: =modeldata!E6/modeldata!E$156 -> 0.0066666667 | AR18: =IF(AP18>0,(AQ18-AP18)/AP18,"") -> -0.96140385 | AS18: =damp_eatout*LN(AP18/AQ18) -> 0 | AT18: =AS18-AS$16 -> 0 | AU18: =SUM(AO18,AT18) -> -1.1217681 | AV18: =AO6 -> -0.3191705 | AW18: =AW17+AV17 -> -1.1217681 | AY18: 2-3 | AZ18: =AZ6 -> -0.34846404 | BA18: =AZ17+BA17 -> -1.5682716 | BB18: =MAX('BATS 2023 TLFD'!Q6,0.0001) -> 0.10066614 | BC18: =modeldata!F6/modeldata!F$156 -> 0.0066666667 | BD18: =IF(BB18>0,(BC18-BB18)/BB18,"") -> -0.93377448 | BE18: =damp_social*LN(BB18/BC18) -> 0 | BF18: =BE18-BE$16 -> 0 | BG18: =SUM(BA18,BF18) -> -1.5682716 | BH18: =BA6 -> -0.34846404 | BI18: =BI17+BH17 -> -1.5682716 | BK18: 2-3 | BL18: =BL6 -> -0.4954932 | BM18: =BL17+BM17 -> -0.33541378 | BN18: =MAX('BATS 2023 TLFD'!R6,0.0001) -> 0.19196499 | BO18: =modeldata!G6/modeldata!G$156 -> 0.0066666667 | BP18: =IF(BN18>0,(BO18-BN18)/BN18,"") -> -0.96527145 | BQ18: =damp_discr*LN(BN18/BO18) -> 0 | BR18: =BQ18-BQ$16 -> 0 | BS18: =SUM(BM18,BR18) -> -0.33541378 | BT18: =BM6 -> -0.4954932 | BU18: =BU17+BT17 -> -0.33541378 | BW18: 2-3 | BX18: =BX6 -> -0.51970902 | BY18: =BX17+BY17 -> -1.5851352 | BZ18: =MAX('BATS 2023 TLFD'!S6,0.0001) -> 0.10686467 | CA18: =modeldata!H6/modeldata!H$156 -> 0.0066666667 | CB18: =IF(BZ18>0,(CA18-BZ18)/BZ18,"") -> -0.9376158 | CC18: =damp_atwork*LN(BZ18/CA18) -> 0 | CD18: =CC18-CC$16 -> 0 | CE18: =SUM(BY18,CD18) -> -1.5851352 | CF18: =BY6 -> -0.51970902 | CG18: =CG17+CF17 -> -1.5851352
A19: =A18+1 -> 3.5 | B19: =B18+1 -> 3 | C19: 3-4 | D19: =D18 -> -0.86713093 | E19: =D18+E18 -> -1.1668688 | F19: =MAX('BATS 2023 TLFD'!M7,0.0001) -> 0.1416232 | G19: =modeldata!B7/modeldata!B$156 -> 0.0066666667 | H19: =IF(F19>0,(G19-F19)/F19,"") -> -0.95292673 | I19: =damp_escort*LN(F19/G19) -> 0 | J19: =I19-I$16 -> 0 | K19: =SUM(E19,J19) -> -1.1668688 | L19: =L18 -> -0.86713093 | M19: =M18+L18 -> -1.1668688 | O19: 3-4 | P19: =P18 -> -0.56554371 | Q19: =P18+Q18 -> -0.56554371 | R19: =MAX('BATS 2023 TLFD'!N7,0.0001) -> 0.099816439 | S19: =modeldata!C7/modeldata!C$156 -> 0.0066666667 | T19: =IF(R19>0,(S19-R19)/R19,"") -> -0.93321073 | U19: =damp_shopping*LN(R19/S19) -> 0 | V19: =U19-U$16 -> 0 | W19: =SUM(Q19,V19) -> -0.56554371 | X19: =X18 -> -0.56554371 | Y19: =Y18+X18 -> -0.56554371 | AA19: 3-4 | AB19: =AB18 -> -0.60549817 | AC19: =AB18+AC18 -> -0.60549817 | AD19: =MAX('BATS 2023 TLFD'!O7,0.0001) -> 0.081459849 | AE19: =modeldata!D7/modeldata!D$156 -> 0.0066666667 | AF19: =IF(AD19>0,(AE19-AD19)/AD19,"") -> -0.91816009 | AG19: =damp_maint*LN(AD19/AE19) -> 0 | AH19: =AG19-AG$16 -> 0 | AI19: =SUM(AC19,AH19) -> -0.60549817 | AJ19: =AJ18 -> -0.60549817 | AK19: =AK18+AJ18 -> -0.60549817 | AM19: 3-4 | AN19: =AN18 -> -0.3191705 | AO19: =AN18+AO18 -> -1.4409386 | AP19: =MAX('BATS 2023 TLFD'!P7,0.0001) -> 0.091931183 | AQ19: =modeldata!E7/modeldata!E$156 -> 0.0066666667 | AR19: =IF(AP19>0,(AQ19-AP19)/AP19,"") -> -0.92748199 | AS19: =damp_eatout*LN(AP19/AQ19) -> 0 | AT19: =AS19-AS$16 -> 0 | AU19: =SUM(AO19,AT19) -> -1.4409386 | AV19: =AV18 -> -0.3191705 | AW19: =AW18+AV18 -> -1.4409386 | AY19: 3-4 | AZ19: =AZ18 -> -0.34846404 | BA19: =AZ18+BA18 -> -1.9167356 | BB19: =MAX('BATS 2023 TLFD'!Q7,0.0001) -> 0.074203382 | BC19: =modeldata!F7/modeldata!F$156 -> 0.0066666667 | BD19: =IF(BB19>0,(BC19-BB19)/BB19,"") -> -0.91015684 | BE19: =damp_social*LN(BB19/BC19) -> 0 | BF19: =BE19-BE$16 -> 0 | BG19: =SUM(BA19,BF19) -> -1.9167356 | BH19: =BH18 -> -0.34846404 | BI19: =BI18+BH18 -> -1.9167356 | BK19: 3-4 | BL19: =BL18 -> -0.4954932 | BM19: =BL18+BM18 -> -0.83090698 | BN19: =MAX('BATS 2023 TLFD'!R7,0.0001) -> 0.065994227 | BO19: =modeldata!G7/modeldata!G$156 -> 0.0066666667 | BP19: =IF(BN19>0,(BO19-BN19)/BN19,"") -> -0.89898106 | BQ19: =damp_discr*LN(BN19/BO19) -> 0 | BR19: =BQ19-BQ$16 -> 0 | BS19: =SUM(BM19,BR19) -> -0.83090698 | BT19: =BT18 -> -0.4954932 | BU19: =BU18+BT18 -> -0.83090698 | BW19: 3-4 | BX19: =BX18 -> -0.51970902 | BY19: =BX18+BY18 -> -2.1048442 | BZ19: =MAX('BATS 2023 TLFD'!S7,0.0001) -> 0.074296385 | CA19: =modeldata!H7/modeldata!H$156 -> 0.0066666667 | CB19: =IF(BZ19>0,(CA19-BZ19)/BZ19,"") -> -0.9102693 | CC19: =damp_atwork*LN(BZ19/CA19) -> 0 | CD19: =CC19-CC$16 -> 0 | CE19: =SUM(BY19,CD19) -> -2.1048442 | CF19: =CF18 -> -0.51970902 | CG19: =CG18+CF18 -> -2.1048442
A20: =A19+1 -> 4.5 | B20: =B19+1 -> 4 | C20: 4-5 | D20: =D19 -> -0.86713093 | E20: =D19+E19 -> -2.0339997 | F20: =MAX('BATS 2023 TLFD'!M8,0.0001) -> 0.077295582 | G20: =modeldata!B8/modeldata!B$156 -> 0.0066666667 | H20: =IF(F20>0,(G20-F20)/F20,"") -> -0.913751 | I20: =damp_escort*LN(F20/G20) -> 0 | J20: =I20-I$16 -> 0 | K20: =SUM(E20,J20) -> -2.0339997 | L20: =L19 -> -0.86713093 | M20: =M19+L19 -> -2.0339997 | O20: 4-5 | P20: =P19 -> -0.56554371 | Q20: =P19+Q19 -> -1.1310874 | R20: =MAX('BATS 2023 TLFD'!N8,0.0001) -> 0.082381529 | S20: =modeldata!C8/modeldata!C$156 -> 0.0066666667 | T20: =IF(R20>0,(S20-R20)/R20,"") -> -0.91907571 | U20: =damp_shopping*LN(R20/S20) -> 0 | V20: =U20-U$16 -> 0 | W20: =SUM(Q20,V20) -> -1.1310874 | X20: =X19 -> -0.56554371 | Y20: =Y19+X19 -> -1.1310874 | AA20: 4-5 | AB20: =AB19 -> -0.60549817 | AC20: =AB19+AC19 -> -1.2109963 | AD20: =MAX('BATS 2023 TLFD'!O8,0.0001) -> 0.075562359 | AE20: =modeldata!D8/modeldata!D$156 -> 0.0066666667 | AF20: =IF(AD20>0,(AE20-AD20)/AD20,"") -> -0.91177265 | AG20: =damp_maint*LN(AD20/AE20) -> 0 | AH20: =AG20-AG$16 -> 0 | AI20: =SUM(AC20,AH20) -> -1.2109963 | AJ20: =AJ19 -> -0.60549817 | AK20: =AK19+AJ19 -> -1.2109963 | AM20: 4-5 | AN20: =AN19 -> -0.3191705 | AO20: =AN19+AO19 -> -1.7601091 | AP20: =MAX('BATS 2023 TLFD'!P8,0.0001) -> 0.044246478 | AQ20: =modeldata!E8/modeldata!E$156 -> 0.0066666667 | AR20: =IF(AP20>0,(AQ20-AP20)/AP20,"") -> -0.84932887 | AS20: =damp_eatout*LN(AP20/AQ20) -> 0 | AT20: =AS20-AS$16 -> 0 | AU20: =SUM(AO20,AT20) -> -1.7601091 | AV20: =AV19 -> -0.3191705 | AW20: =AW19+AV19 -> -1.7601091 | AY20: 4-5 | AZ20: =AZ19 -> -0.34846404 | BA20: =AZ19+BA19 -> -2.2651997 | BB20: =MAX('BATS 2023 TLFD'!Q8,0.0001) -> 0.051433561 | BC20: =modeldata!F8/modeldata!F$156 -> 0.0066666667 | BD20: =IF(BB20>0,(BC20-BB20)/BB20,"") -> -0.87038295 | BE20: =damp_social*LN(BB20/BC20) -> 0 | BF20: =BE20-BE$16 -> 0 | BG20: =SUM(BA20,BF20) -> -2.2651997 | BH20: =BH19 -> -0.34846404 | BI20: =BI19+BH19 -> -2.2651997 | BK20: 4-5 | BL20: =BL19 -> -0.4954932 | BM20: =BL19+BM19 -> -1.3264002 | BN20: =MAX('BATS 2023 TLFD'!R8,0.0001) -> 0.02111736 | BO20: =modeldata!G8/modeldata!G$156 -> 0.0066666667 | BP20: =IF(BN20>0,(BO20-BN20)/BN20,"") -> -0.68430397 | BQ20: =damp_discr*LN(BN20/BO20) -> 0 | BR20: =BQ20-BQ$16 -> 0 | BS20: =SUM(BM20,BR20) -> -1.3264002 | BT20: =BT19 -> -0.4954932 | BU20: =BU19+BT19 -> -1.3264002 | BW20: 4-5 | BX20: =BX19 -> -0.51970902 | BY20: =BX19+BY19 -> -2.6245532 | BZ20: =MAX('BATS 2023 TLFD'!S8,0.0001) -> 0.042011628 | CA20: =modeldata!H8/modeldata!H$156 -> 0.0066666667 | CB20: =IF(BZ20>0,(CA20-BZ20)/BZ20,"") -> -0.84131378 | CC20: =damp_atwork*LN(BZ20/CA20) -> 0 | CD20: =CC20-CC$16 -> 0 | CE20: =SUM(BY20,CD20) -> -2.6245532 | CF20: =CF19 -> -0.51970902 | CG20: =CG19+CF19 -> -2.6245532
A21: =A20+1 -> 5.5 | B21: =B20+1 -> 5 | C21: 5-6 | D21: =D7 -> -0.21370826 | E21: =D20+E20 -> -2.9011306 | F21: =MAX('BATS 2023 TLFD'!M9,0.0001) -> 0.068568068 | G21: =modeldata!B9/modeldata!B$156 -> 0.0066666667 | H21: =IF(F21>0,(G21-F21)/F21,"") -> -0.90277301 | I21: =damp_escort*LN(F21/G21) -> 0 | J21: =I21-I$16 -> 0 | K21: =SUM(E21,J21) -> -2.9011306 | L21: =E7 -> -0.21370826 | M21: =M20+L20 -> -2.9011306 | O21: 5-6 | P21: =P7 -> -0.18324871 | Q21: =P20+Q20 -> -1.6966311 | R21: =MAX('BATS 2023 TLFD'!N9,0.0001) -> 0.046390393 | S21: =modeldata!C9/modeldata!C$156 -> 0.0066666667 | T21: =IF(R21>0,(S21-R21)/R21,"") -> -0.85629208 | U21: =damp_shopping*LN(R21/S21) -> 0 | V21: =U21-U$16 -> 0 | W21: =SUM(Q21,V21) -> -1.6966311 | X21: =Q7 -> -0.18324871 | Y21: =Y20+X20 -> -1.6966311 | AA21: 5-6 | AB21: =AB7 -> -0.10927639 | AC21: =AB20+AC20 -> -1.8164945 | AD21: =MAX('BATS 2023 TLFD'!O9,0.0001) -> 0.084378212 | AE21: =modeldata!D9/modeldata!D$156 -> 0.0066666667 | AF21: =IF(AD21>0,(AE21-AD21)/AD21,"") -> -0.92099066 | AG21: =damp_maint*LN(AD21/AE21) -> 0 | AH21: =AG21-AG$16 -> 0 | AI21: =SUM(AC21,AH21) -> -1.8164945 | AJ21: =AC7 -> -0.10927639 | AK21: =AK20+AJ20 -> -1.8164945 | AM21: 5-6 | AN21: =AN7 -> -0.12376668 | AO21: =AN20+AO20 -> -2.0792796 | AP21: =MAX('BATS 2023 TLFD'!P9,0.0001) -> 0.039196726 | AQ21: =modeldata!E9/modeldata!E$156 -> 0.0066666667 | AR21: =IF(AP21>0,(AQ21-AP21)/AP21,"") -> -0.82991777 | AS21: =damp_eatout*LN(AP21/AQ21) -> 0 | AT21: =AS21-AS$16 -> 0 | AU21: =SUM(AO21,AT21) -> -2.0792796 | AV21: =AO7 -> -0.12376668 | AW21: =AW20+AV20 -> -2.0792796 | AY21: 5-6 | AZ21: =AZ7 -> -0.13060068 | BA21: =AZ20+BA20 -> -2.6136637 | BB21: =MAX('BATS 2023 TLFD'!Q9,0.0001) -> 0.048760884 | BC21: =modeldata!F9/modeldata!F$156 -> 0.0066666667 | BD21: =IF(BB21>0,(BC21-BB21)/BB21,"") -> -0.86327839 | BE21: =damp_social*LN(BB21/BC21) -> 0 | BF21: =BE21-BE$16 -> 0 | BG21: =SUM(BA21,BF21) -> -2.6136637 | BH21: =BA7 -> -0.13060068 | BI21: =BI20+BH20 -> -2.6136637 | BK21: 5-6 | BL21: =BL7 -> -0.11929589 | BM21: =BL20+BM20 -> -1.8218934 | BN21: =MAX('BATS 2023 TLFD'!R9,0.0001) -> 0.073564813 | BO21: =modeldata!G9/modeldata!G$156 -> 0.0066666667 | BP21: =IF(BN21>0,(BO21-BN21)/BN21,"") -> -0.90937696 | BQ21: =damp_discr*LN(BN21/BO21) -> 0 | BR21: =BQ21-BQ$16 -> 0 | BS21: =SUM(BM21,BR21) -> -1.8218934 | BT21: =BM7 -> -0.11929589 | BU21: =BU20+BT20 -> -1.8218934 | BW21: 5-6 | BX21: =BX7 -> -0.20447345 | BY21: =BX20+BY20 -> -3.1442623 | BZ21: =MAX('BATS 2023 TLFD'!S9,0.0001) -> 0.041424275 | CA21: =modeldata!H9/modeldata!H$156 -> 0.0066666667 | CB21: =IF(BZ21>0,(CA21-BZ21)/BZ21,"") -> -0.83906377 | CC21: =damp_atwork*LN(BZ21/CA21) -> 0 | CD21: =CC21-CC$16 -> 0 | CE21: =SUM(BY21,CD21) -> -3.1442623 | CF21: =BY7 -> -0.20447345 | CG21: =CG20+CF20 -> -3.1442623
A22: =A21+1 -> 6.5 | B22: =B21+1 -> 6 | C22: 6-7 | D22: =D21 -> -0.21370826 | E22: =D21+E21 -> -3.1148389 | F22: =MAX('BATS 2023 TLFD'!M10,0.0001) -> 0.035629593 | G22: =modeldata!B10/modeldata!B$156 -> 0.0066666667 | H22: =IF(F22>0,(G22-F22)/F22,"") -> -0.81288962 | I22: =damp_escort*LN(F22/G22) -> 0 | J22: =I22-I$16 -> 0 | K22: =SUM(E22,J22) -> -3.1148389 | L22: =L21 -> -0.21370826 | M22: =M21+L21 -> -3.1148389 | O22: 6-7 | P22: =P21 -> -0.18324871 | Q22: =P21+Q21 -> -1.8798798 | R22: =MAX('BATS 2023 TLFD'!N10,0.0001) -> 0.060757632 | S22: =modeldata!C10/modeldata!C$156 -> 0.0066666667 | T22: =IF(R22>0,(S22-R22)/R22,"") -> -0.89027442 | U22: =damp_shopping*LN(R22/S22) -> 0 | V22: =U22-U$16 -> 0 | W22: =SUM(Q22,V22) -> -1.8798798 | X22: =X21 -> -0.18324871 | Y22: =Y21+X21 -> -1.8798798 | AA22: 6-7 | AB22: =AB21 -> -0.10927639 | AC22: =AB21+AC21 -> -1.9257709 | AD22: =MAX('BATS 2023 TLFD'!O10,0.0001) -> 0.047119553 | AE22: =modeldata!D10/modeldata!D$156 -> 0.0066666667 | AF22: =IF(AD22>0,(AE22-AD22)/AD22,"") -> -0.85851592 | AG22: =damp_maint*LN(AD22/AE22) -> 0 | AH22: =AG22-AG$16 -> 0 | AI22: =SUM(AC22,AH22) -> -1.9257709 | AJ22: =AJ21 -> -0.10927639 | AK22: =AK21+AJ21 -> -1.9257709 | AM22: 6-7 | AN22: =AN21 -> -0.12376668 | AO22: =AN21+AO21 -> -2.2030463 | AP22: =MAX('BATS 2023 TLFD'!P10,0.0001) -> 0.041506162 | AQ22: =modeldata!E10/modeldata!E$156 -> 0.0066666667 | AR22: =IF(AP22>0,(AQ22-AP22)/AP22,"") -> -0.83938128 | AS22: =damp_eatout*LN(AP22/AQ22) -> 0 | AT22: =AS22-AS$16 -> 0 | AU22: =SUM(AO22,AT22) -> -2.2030463 | AV22: =AV21 -> -0.12376668 | AW22: =AW21+AV21 -> -2.2030463 | AY22: 6-7 | AZ22: =AZ21 -> -0.13060068 | BA22: =AZ21+BA21 -> -2.7442644 | BB22: =MAX('BATS 2023 TLFD'!Q10,0.0001) -> 0.024047995 | BC22: =modeldata!F10/modeldata!F$156 -> 0.0066666667 | BD22: =IF(BB22>0,(BC22-BB22)/BB22,"") -> -0.72277662 | BE22: =damp_social*LN(BB22/BC22) -> 0 | BF22: =BE22-BE$16 -> 0 | BG22: =SUM(BA22,BF22) -> -2.7442644 | BH22: =BH21 -> -0.13060068 | BI22: =BI21+BH21 -> -2.7442644 | BK22: 6-7 | BL22: =BL21 -> -0.11929589 | BM22: =BL21+BM21 -> -1.9411893 | BN22: =MAX('BATS 2023 TLFD'!R10,0.0001) -> 0.034766895 | BO22: =modeldata!G10/modeldata!G$156 -> 0.0066666667 | BP22: =IF(BN22>0,(BO22-BN22)/BN22,"") -> -0.80824671 | BQ22: =damp_discr*LN(BN22/BO22) -> 0 | BR22: =BQ22-BQ$16 -> 0 | BS22: =SUM(BM22,BR22) -> -1.9411893 | BT22: =BT21 -> -0.11929589 | BU22: =BU21+BT21 -> -1.9411893 | BW22: 6-7 | BX22: =BX21 -> -0.20447345 | BY22: =BX21+BY21 -> -3.3487357 | BZ22: =MAX('BATS 2023 TLFD'!S10,0.0001) -> 0.009210962 | CA22: =modeldata!H10/modeldata!H$156 -> 0.0066666667 | CB22: =IF(BZ22>0,(CA22-BZ22)/BZ22,"") -> -0.27622471 | CC22: =damp_atwork*LN(BZ22/CA22) -> 0 | CD22: =CC22-CC$16 -> 0 | CE22: =SUM(BY22,CD22) -> -3.3487357 | CF22: =CF21 -> -0.20447345 | CG22: =CG21+CF21 -> -3.3487357
A23: =A22+1 -> 7.5 | B23: =B22+1 -> 7 | C23: 7-8 | D23: =D22 -> -0.21370826 | E23: =D22+E22 -> -3.3285472 | F23: =MAX('BATS 2023 TLFD'!M11,0.0001) -> 0.066129374 | G23: =modeldata!B11/modeldata!B$156 -> 0.0066666667 | H23: =IF(F23>0,(G23-F23)/F23,"") -> -0.89918751 | I23: =damp_escort*LN(F23/G23) -> 0 | J23: =I23-I$16 -> 0 | K23: =SUM(E23,J23) -> -3.3285472 | L23: =L22 -> -0.21370826 | M23: =M22+L22 -> -3.3285472 | O23: 7-8 | P23: =P22 -> -0.18324871 | Q23: =P22+Q22 -> -2.0631285 | R23: =MAX('BATS 2023 TLFD'!N11,0.0001) -> 0.028219888 | S23: =modeldata!C11/modeldata!C$156 -> 0.0066666667 | T23: =IF(R23>0,(S23-R23)/R23,"") -> -0.76375999 | U23: =damp_shopping*LN(R23/S23) -> 0 | V23: =U23-U$16 -> 0 | W23: =SUM(Q23,V23) -> -2.0631285 | X23: =X22 -> -0.18324871 | Y23: =Y22+X22 -> -2.0631285 | AA23: 7-8 | AB23: =AB22 -> -0.10927639 | AC23: =AB22+AC22 -> -2.0350473 | AD23: =MAX('BATS 2023 TLFD'!O11,0.0001) -> 0.050795706 | AE23: =modeldata!D11/modeldata!D$156 -> 0.0066666667 | AF23: =IF(AD23>0,(AE23-AD23)/AD23,"") -> -0.86875531 | AG23: =damp_maint*LN(AD23/AE23) -> 0 | AH23: =AG23-AG$16 -> 0 | AI23: =SUM(AC23,AH23) -> -2.0350473 | AJ23: =AJ22 -> -0.10927639 | AK23: =AK22+AJ22 -> -2.0350473 | AM23: 7-8 | AN23: =AN22 -> -0.12376668 | AO23: =AN22+AO22 -> -2.326813 | AP23: =MAX('BATS 2023 TLFD'!P11,0.0001) -> 0.018547993 | AQ23: =modeldata!E11/modeldata!E$156 -> 0.0066666667 | AR23: =IF(AP23>0,(AQ23-AP23)/AP23,"") -> -0.64057208 | AS23: =damp_eatout*LN(AP23/AQ23) -> 0 | AT23: =AS23-AS$16 -> 0 | AU23: =SUM(AO23,AT23) -> -2.326813 | AV23: =AV22 -> -0.12376668 | AW23: =AW22+AV22 -> -2.326813 | AY23: 7-8 | AZ23: =AZ22 -> -0.13060068 | BA23: =AZ22+BA22 -> -2.8748651 | BB23: =MAX('BATS 2023 TLFD'!Q11,0.0001) -> 0.022366431 | BC23: =modeldata!F11/modeldata!F$156 -> 0.0066666667 | BD23: =IF(BB23>0,(BC23-BB23)/BB23,"") -> -0.70193427 | BE23: =damp_social*LN(BB23/BC23) -> 0 | BF23: =BE23-BE$16 -> 0 | BG23: =SUM(BA23,BF23) -> -2.8748651 | BH23: =BH22 -> -0.13060068 | BI23: =BI22+BH22 -> -2.8748651 | BK23: 7-8 | BL23: =BL22 -> -0.11929589 | BM23: =BL22+BM22 -> -2.0604852 | BN23: =MAX('BATS 2023 TLFD'!R11,0.0001) -> 0.016818863 | BO23: =modeldata!G11/modeldata!G$156 -> 0.0066666667 | BP23: =IF(BN23>0,(BO23-BN23)/BN23,"") -> -0.60361967 | BQ23: =damp_discr*LN(BN23/BO23) -> 0 | BR23: =BQ23-BQ$16 -> 0 | BS23: =SUM(BM23,BR23) -> -2.0604852 | BT23: =BT22 -> -0.11929589 | BU23: =BU22+BT22 -> -2.0604852 | BW23: 7-8 | BX23: =BX22 -> -0.20447345 | BY23: =BX22+BY22 -> -3.5532092 | BZ23: =MAX('BATS 2023 TLFD'!S11,0.0001) -> 0.015051254 | CA23: =modeldata!H11/modeldata!H$156 -> 0.0066666667 | CB23: =IF(BZ23>0,(CA23-BZ23)/BZ23,"") -> -0.55706901 | CC23: =damp_atwork*LN(BZ23/CA23) -> 0 | CD23: =CC23-CC$16 -> 0 | CE23: =SUM(BY23,CD23) -> -3.5532092 | CF23: =CF22 -> -0.20447345 | CG23: =CG22+CF22 -> -3.5532092
A24: =A23+1 -> 8.5 | B24: =B23+1 -> 8 | C24: 8-9 | D24: =D23 -> -0.21370826 | E24: =D23+E23 -> -3.5422554 | F24: =MAX('BATS 2023 TLFD'!M12,0.0001) -> 0.02656993 | G24: =modeldata!B12/modeldata!B$156 -> 0.0066666667 | H24: =IF(F24>0,(G24-F24)/F24,"") -> -0.74908979 | I24: =damp_escort*LN(F24/G24) -> 0 | J24: =I24-I$16 -> 0 | K24: =SUM(E24,J24) -> -3.5422554 | L24: =L23 -> -0.21370826 | M24: =M23+L23 -> -3.5422554 | O24: 8-9 | P24: =P23 -> -0.18324871 | Q24: =P23+Q23 -> -2.2463773 | R24: =MAX('BATS 2023 TLFD'!N12,0.0001) -> 0.025743323 | S24: =modeldata!C12/modeldata!C$156 -> 0.0066666667 | T24: =IF(R24>0,(S24-R24)/R24,"") -> -0.74103317 | U24: =damp_shopping*LN(R24/S24) -> 0 | V24: =U24-U$16 -> 0 | W24: =SUM(Q24,V24) -> -2.2463773 | X24: =X23 -> -0.18324871 | Y24: =Y23+X23 -> -2.2463773 | AA24: 8-9 | AB24: =AB23 -> -0.10927639 | AC24: =AB23+AC23 -> -2.1443237 | AD24: =MAX('BATS 2023 TLFD'!O12,0.0001) -> 0.015553856 | AE24: =modeldata!D12/modeldata!D$156 -> 0.0066666667 | AF24: =IF(AD24>0,(AE24-AD24)/AD24,"") -> -0.57138175 | AG24: =damp_maint*LN(AD24/AE24) -> 0 | AH24: =AG24-AG$16 -> 0 | AI24: =SUM(AC24,AH24) -> -2.1443237 | AJ24: =AJ23 -> -0.10927639 | AK24: =AK23+AJ23 -> -2.1443237 | AM24: 8-9 | AN24: =AN23 -> -0.12376668 | AO24: =AN23+AO23 -> -2.4505797 | AP24: =MAX('BATS 2023 TLFD'!P12,0.0001) -> 0.026036915 | AQ24: =modeldata!E12/modeldata!E$156 -> 0.0066666667 | AR24: =IF(AP24>0,(AQ24-AP24)/AP24,"") -> -0.74395329 | AS24: =damp_eatout*LN(AP24/AQ24) -> 0 | AT24: =AS24-AS$16 -> 0 | AU24: =SUM(AO24,AT24) -> -2.4505797 | AV24: =AV23 -> -0.12376668 | AW24: =AW23+AV23 -> -2.4505797 | AY24: 8-9 | AZ24: =AZ23 -> -0.13060068 | BA24: =AZ23+BA23 -> -3.0054658 | BB24: =MAX('BATS 2023 TLFD'!Q12,0.0001) -> 0.030550924 | BC24: =modeldata!F12/modeldata!F$156 -> 0.0066666667 | BD24: =IF(BB24>0,(BC24-BB24)/BB24,"") -> -0.78178511 | BE24: =damp_social*LN(BB24/BC24) -> 0 | BF24: =BE24-BE$16 -> 0 | BG24: =SUM(BA24,BF24) -> -3.0054658 | BH24: =BH23 -> -0.13060068 | BI24: =BI23+BH23 -> -3.0054658 | BK24: 8-9 | BL24: =BL23 -> -0.11929589 | BM24: =BL23+BM23 -> -2.179781 | BN24: =MAX('BATS 2023 TLFD'!R12,0.0001) -> 0.020821532 | BO24: =modeldata!G12/modeldata!G$156 -> 0.0066666667 | BP24: =IF(BN24>0,(BO24-BN24)/BN24,"") -> -0.67981863 | BQ24: =damp_discr*LN(BN24/BO24) -> 0 | BR24: =BQ24-BQ$16 -> 0 | BS24: =SUM(BM24,BR24) -> -2.179781 | BT24: =BT23 -> -0.11929589 | BU24: =BU23+BT23 -> -2.179781 | BW24: 8-9 | BX24: =BX23 -> -0.20447345 | BY24: =BX23+BY23 -> -3.7576826 | BZ24: =MAX('BATS 2023 TLFD'!S12,0.0001) -> 0.0032547593 | CA24: =modeldata!H12/modeldata!H$156 -> 0.0066666667 | CB24: =IF(BZ24>0,(CA24-BZ24)/BZ24,"") -> 1.0482826 | CC24: =damp_atwork*LN(BZ24/CA24) -> 0 | CD24: =CC24-CC$16 -> 0 | CE24: =SUM(BY24,CD24) -> -3.7576826 | CF24: =CF23 -> -0.20447345 | CG24: =CG23+CF23 -> -3.7576826
A25: =A24+1 -> 9.5 | B25: =B24+1 -> 9 | C25: 9-10 | D25: =D24 -> -0.21370826 | E25: =D24+E24 -> -3.7559637 | F25: =MAX('BATS 2023 TLFD'!M13,0.0001) -> 0.0016437916 | G25: =modeldata!B13/modeldata!B$156 -> 0.0066666667 | H25: =IF(F25>0,(G25-F25)/F25,"") -> 3.0556642 | I25: =damp_escort*LN(F25/G25) -> 0 | J25: =I25-I$16 -> 0 | K25: =SUM(E25,J25) -> -3.7559637 | L25: =L24 -> -0.21370826 | M25: =M24+L24 -> -3.7559637 | O25: 9-10 | P25: =P24 -> -0.18324871 | Q25: =P24+Q24 -> -2.429626 | R25: =MAX('BATS 2023 TLFD'!N13,0.0001) -> 0.01206331 | S25: =modeldata!C13/modeldata!C$156 -> 0.0066666667 | T25: =IF(R25>0,(S25-R25)/R25,"") -> -0.4473601 | U25: =damp_shopping*LN(R25/S25) -> 0 | V25: =U25-U$16 -> 0 | W25: =SUM(Q25,V25) -> -2.429626 | X25: =X24 -> -0.18324871 | Y25: =Y24+X24 -> -2.429626 | AA25: 9-10 | AB25: =AB24 -> -0.10927639 | AC25: =AB24+AC24 -> -2.2536001 | AD25: =MAX('BATS 2023 TLFD'!O13,0.0001) -> 0.025114412 | AE25: =modeldata!D13/modeldata!D$156 -> 0.0066666667 | AF25: =IF(AD25>0,(AE25-AD25)/AD25,"") -> -0.73454816 | AG25: =damp_maint*LN(AD25/AE25) -> 0 | AH25: =AG25-AG$16 -> 0 | AI25: =SUM(AC25,AH25) -> -2.2536001 | AJ25: =AJ24 -> -0.10927639 | AK25: =AK24+AJ24 -> -2.2536001 | AM25: 9-10 | AN25: =AN24 -> -0.12376668 | AO25: =AN24+AO24 -> -2.5743464 | AP25: =MAX('BATS 2023 TLFD'!P13,0.0001) -> 0.015023083 | AQ25: =modeldata!E13/modeldata!E$156 -> 0.0066666667 | AR25: =IF(AP25>0,(AQ25-AP25)/AP25,"") -> -0.55623844 | AS25: =damp_eatout*LN(AP25/AQ25) -> 0 | AT25: =AS25-AS$16 -> 0 | AU25: =SUM(AO25,AT25) -> -2.5743464 | AV25: =AV24 -> -0.12376668 | AW25: =AW24+AV24 -> -2.5743464 | AY25: 9-10 | AZ25: =AZ24 -> -0.13060068 | BA25: =AZ24+BA24 -> -3.1360664 | BB25: =MAX('BATS 2023 TLFD'!Q13,0.0001) -> 0.0068844825 | BC25: =modeldata!F13/modeldata!F$156 -> 0.0066666667 | BD25: =IF(BB25>0,(BC25-BB25)/BB25,"") -> -0.031638659 | BE25: =damp_social*LN(BB25/BC25) -> 0 | BF25: =BE25-BE$16 -> 0 | BG25: =SUM(BA25,BF25) -> -3.1360664 | BH25: =BH24 -> -0.13060068 | BI25: =BI24+BH24 -> -3.1360664 | BK25: 9-10 | BL25: =BL24 -> -0.11929589 | BM25: =BL24+BM24 -> -2.2990769 | BN25: =MAX('BATS 2023 TLFD'!R13,0.0001) -> 0.015168305 | BO25: =modeldata!G13/modeldata!G$156 -> 0.0066666667 | BP25: =IF(BN25>0,(BO25-BN25)/BN25,"") -> -0.56048704 | BQ25: =damp_discr*LN(BN25/BO25) -> 0 | BR25: =BQ25-BQ$16 -> 0 | BS25: =SUM(BM25,BR25) -> -2.2990769 | BT25: =BT24 -> -0.11929589 | BU25: =BU24+BT24 -> -2.2990769 | BW25: 9-10 | BX25: =BX24 -> -0.20447345 | BY25: =BX24+BY24 -> -3.9621561 | BZ25: =MAX('BATS 2023 TLFD'!S13,0.0001) -> 0.012906974 | CA25: =modeldata!H13/modeldata!H$156 -> 0.0066666667 | CB25: =IF(BZ25>0,(CA25-BZ25)/BZ25,"") -> -0.48348337 | CC25: =damp_atwork*LN(BZ25/CA25) -> 0 | CD25: =CC25-CC$16 -> 0 | CE25: =SUM(BY25,CD25) -> -3.9621561 | CF25: =CF24 -> -0.20447345 | CG25: =CG24+CF24 -> -3.9621561
A26: =A25+1 -> 10.5 | B26: =B25+1 -> 10 | C26: 10-11 | D26: =D25 -> -0.21370826 | E26: =D25+E25 -> -3.9696719 | F26: =MAX('BATS 2023 TLFD'!M14,0.0001) -> 0.0074337647 | G26: =modeldata!B14/modeldata!B$156 -> 0.0066666667 | H26: =IF(F26>0,(G26-F26)/F26,"") -> -0.10319105 | I26: =damp_escort*LN(F26/G26) -> 0 | J26: =I26-I$16 -> 0 | K26: =SUM(E26,J26) -> -3.9696719 | L26: =L25 -> -0.21370826 | M26: =M25+L25 -> -3.9696719 | O26: 10-11 | P26: =P25 -> -0.18324871 | Q26: =P25+Q25 -> -2.6128747 | R26: =MAX('BATS 2023 TLFD'!N14,0.0001) -> 0.014428635 | S26: =modeldata!C14/modeldata!C$156 -> 0.0066666667 | T26: =IF(R26>0,(S26-R26)/R26,"") -> -0.53795582 | U26: =damp_shopping*LN(R26/S26) -> 0 | V26: =U26-U$16 -> 0 | W26: =SUM(Q26,V26) -> -2.6128747 | X26: =X25 -> -0.18324871 | Y26: =Y25+X25 -> -2.6128747 | AA26: 10-11 | AB26: =AB25 -> -0.10927639 | AC26: =AB25+AC25 -> -2.3628765 | AD26: =MAX('BATS 2023 TLFD'!O14,0.0001) -> 0.0061075732 | AE26: =modeldata!D14/modeldata!D$156 -> 0.0066666667 | AF26: =IF(AD26>0,(AE26-AD26)/AD26,"") -> 0.091541019 | AG26: =damp_maint*LN(AD26/AE26) -> 0 | AH26: =AG26-AG$16 -> 0 | AI26: =SUM(AC26,AH26) -> -2.3628765 | AJ26: =AJ25 -> -0.10927639 | AK26: =AK25+AJ25 -> -2.3628765 | AM26: 10-11 | AN26: =AN25 -> -0.12376668 | AO26: =AN25+AO25 -> -2.698113 | AP26: =MAX('BATS 2023 TLFD'!P14,0.0001) -> 0.0045616169 | AQ26: =modeldata!E14/modeldata!E$156 -> 0.0066666667 | AR26: =IF(AP26>0,(AQ26-AP26)/AP26,"") -> 0.46147008 | AS26: =damp_eatout*LN(AP26/AQ26) -> 0 | AT26: =AS26-AS$16 -> 0 | AU26: =SUM(AO26,AT26) -> -2.698113 | AV26: =AV25 -> -0.12376668 | AW26: =AW25+AV25 -> -2.698113 | AY26: 10-11 | AZ26: =AZ25 -> -0.13060068 | BA26: =AZ25+BA25 -> -3.2666671 | BB26: =MAX('BATS 2023 TLFD'!Q14,0.0001) -> 0.0073966957 | BC26: =modeldata!F14/modeldata!F$156 -> 0.0066666667 | BD26: =IF(BB26>0,(BC26-BB26)/BB26,"") -> -0.098696639 | BE26: =damp_social*LN(BB26/BC26) -> 0 | BF26: =BE26-BE$16 -> 0 | BG26: =SUM(BA26,BF26) -> -3.2666671 | BH26: =BH25 -> -0.13060068 | BI26: =BI25+BH25 -> -3.2666671 | BK26: 10-11 | BL26: =BL25 -> -0.11929589 | BM26: =BL25+BM25 -> -2.4183728 | BN26: =MAX('BATS 2023 TLFD'!R14,0.0001) -> 0.002270559 | BO26: =modeldata!G14/modeldata!G$156 -> 0.0066666667 | BP26: =IF(BN26>0,(BO26-BN26)/BN26,"") -> 1.9361346 | BQ26: =damp_discr*LN(BN26/BO26) -> 0 | BR26: =BQ26-BQ$16 -> 0 | BS26: =SUM(BM26,BR26) -> -2.4183728 | BT26: =BT25 -> -0.11929589 | BU26: =BU25+BT25 -> -2.4183728 | BW26: 10-11 | BX26: =BX25 -> -0.20447345 | BY26: =BX25+BY25 -> -4.1666295 | BZ26: =MAX('BATS 2023 TLFD'!S14,0.0001) -> 0.0016934567 | CA26: =modeldata!H14/modeldata!H$156 -> 0.0066666667 | CB26: =IF(BZ26>0,(CA26-BZ26)/BZ26,"") -> 2.9367211 | CC26: =damp_atwork*LN(BZ26/CA26) -> 0 | CD26: =CC26-CC$16 -> 0 | CE26: =SUM(BY26,CD26) -> -4.1666295 | CF26: =CF25 -> -0.20447345 | CG26: =CG25+CF25 -> -4.1666295
A27: =A26+1 -> 11.5 | B27: =B26+1 -> 11 | C27: 11-12 | D27: =D26 -> -0.21370826 | E27: =D26+E26 -> -4.1833802 | F27: =MAX('BATS 2023 TLFD'!M15,0.0001) -> 0.0019117328 | G27: =modeldata!B15/modeldata!B$156 -> 0.0066666667 | H27: =IF(F27>0,(G27-F27)/F27,"") -> 2.4872378 | I27: =damp_escort*LN(F27/G27) -> 0 | J27: =I27-I$16 -> 0 | K27: =SUM(E27,J27) -> -4.1833802 | L27: =L26 -> -0.21370826 | M27: =M26+L26 -> -4.1833802 | O27: 11-12 | P27: =P26 -> -0.18324871 | Q27: =P26+Q26 -> -2.7961234 | R27: =MAX('BATS 2023 TLFD'!N15,0.0001) -> 0.0050530418 | S27: =modeldata!C15/modeldata!C$156 -> 0.0066666667 | T27: =IF(R27>0,(S27-R27)/R27,"") -> 0.31933732 | U27: =damp_shopping*LN(R27/S27) -> 0 | V27: =U27-U$16 -> 0 | W27: =SUM(Q27,V27) -> -2.7961234 | X27: =X26 -> -0.18324871 | Y27: =Y26+X26 -> -2.7961234 | AA27: 11-12 | AB27: =AB26 -> -0.10927639 | AC27: =AB26+AC26 -> -2.4721528 | AD27: =MAX('BATS 2023 TLFD'!O15,0.0001) -> 0.0063601402 | AE27: =modeldata!D15/modeldata!D$156 -> 0.0066666667 | AF27: =IF(AD27>0,(AE27-AD27)/AD27,"") -> 0.048194926 | AG27: =damp_maint*LN(AD27/AE27) -> 0 | AH27: =AG27-AG$16 -> 0 | AI27: =SUM(AC27,AH27) -> -2.4721528 | AJ27: =AJ26 -> -0.10927639 | AK27: =AK26+AJ26 -> -2.4721528 | AM27: 11-12 | AN27: =AN26 -> -0.12376668 | AO27: =AN26+AO26 -> -2.8218797 | AP27: =MAX('BATS 2023 TLFD'!P15,0.0001) -> 0.0086006683 | AQ27: =modeldata!E15/modeldata!E$156 -> 0.0066666667 | AR27: =IF(AP27>0,(AQ27-AP27)/AP27,"") -> -0.22486644 | AS27: =damp_eatout*LN(AP27/AQ27) -> 0 | AT27: =AS27-AS$16 -> 0 | AU27: =SUM(AO27,AT27) -> -2.8218797 | AV27: =AV26 -> -0.12376668 | AW27: =AW26+AV26 -> -2.8218797 | AY27: 11-12 | AZ27: =AZ26 -> -0.13060068 | BA27: =AZ26+BA26 -> -3.3972678 | BB27: =MAX('BATS 2023 TLFD'!Q15,0.0001) -> 0.0031725354 | BC27: =modeldata!F15/modeldata!F$156 -> 0.0066666667 | BD27: =IF(BB27>0,(BC27-BB27)/BB27,"") -> 1.1013687 | BE27: =damp_social*LN(BB27/BC27) -> 0 | BF27: =BE27-BE$16 -> 0 | BG27: =SUM(BA27,BF27) -> -3.3972678 | BH27: =BH26 -> -0.13060068 | BI27: =BI26+BH26 -> -3.3972678 | BK27: 11-12 | BL27: =BL26 -> -0.11929589 | BM27: =BL26+BM26 -> -2.5376687 | BN27: =MAX('BATS 2023 TLFD'!R15,0.0001) -> 0.016735412 | BO27: =modeldata!G15/modeldata!G$156 -> 0.0066666667 | BP27: =IF(BN27>0,(BO27-BN27)/BN27,"") -> -0.60164312 | BQ27: =damp_discr*LN(BN27/BO27) -> 0 | BR27: =BQ27-BQ$16 -> 0 | BS27: =SUM(BM27,BR27) -> -2.5376687 | BT27: =BT26 -> -0.11929589 | BU27: =BU26+BT26 -> -2.5376687 | BW27: 11-12 | BX27: =BX26 -> -0.20447345 | BY27: =BX26+BY26 -> -4.371103 | BZ27: =MAX('BATS 2023 TLFD'!S15,0.0001) -> 0.00090061074 | CA27: =modeldata!H15/modeldata!H$156 -> 0.0066666667 | CB27: =IF(BZ27>0,(CA27-BZ27)/BZ27,"") -> 6.4023841 | CC27: =damp_atwork*LN(BZ27/CA27) -> 0 | CD27: =CC27-CC$16 -> 0 | CE27: =SUM(BY27,CD27) -> -4.371103 | CF27: =CF26 -> -0.20447345 | CG27: =CG26+CF26 -> -4.371103
A28: =A27+1 -> 12.5 | B28: =B27+1 -> 12 | C28: 12-13 | D28: =D27 -> -0.21370826 | E28: =D27+E27 -> -4.3970885 | F28: =MAX('BATS 2023 TLFD'!M16,0.0001) -> 0.0032445069 | G28: =modeldata!B16/modeldata!B$156 -> 0.0066666667 | H28: =IF(F28>0,(G28-F28)/F28,"") -> 1.054755 | I28: =damp_escort*LN(F28/G28) -> 0 | J28: =I28-I$16 -> 0 | K28: =SUM(E28,J28) -> -4.3970885 | L28: =L27 -> -0.21370826 | M28: =M27+L27 -> -4.3970885 | O28: 12-13 | P28: =P27 -> -0.18324871 | Q28: =P27+Q27 -> -2.9793721 | R28: =MAX('BATS 2023 TLFD'!N16,0.0001) -> 0.0069922164 | S28: =modeldata!C16/modeldata!C$156 -> 0.0066666667 | T28: =IF(R28>0,(S28-R28)/R28,"") -> -0.046558869 | U28: =damp_shopping*LN(R28/S28) -> 0 | V28: =U28-U$16 -> 0 | W28: =SUM(Q28,V28) -> -2.9793721 | X28: =X27 -> -0.18324871 | Y28: =Y27+X27 -> -2.9793721 | AA28: 12-13 | AB28: =AB27 -> -0.10927639 | AC28: =AB27+AC27 -> -2.5814292 | AD28: =MAX('BATS 2023 TLFD'!O16,0.0001) -> 0.00082141185 | AE28: =modeldata!D16/modeldata!D$156 -> 0.0066666667 | AF28: =IF(AD28>0,(AE28-AD28)/AD28,"") -> 7.1161072 | AG28: =damp_maint*LN(AD28/AE28) -> 0 | AH28: =AG28-AG$16 -> 0 | AI28: =SUM(AC28,AH28) -> -2.5814292 | AJ28: =AJ27 -> -0.10927639 | AK28: =AK27+AJ27 -> -2.5814292 | AM28: 12-13 | AN28: =AN27 -> -0.12376668 | AO28: =AN27+AO27 -> -2.9456464 | AP28: =MAX('BATS 2023 TLFD'!P16,0.0001) -> 0.010658938 | AQ28: =modeldata!E16/modeldata!E$156 -> 0.0066666667 | AR28: =IF(AP28>0,(AQ28-AP28)/AP28,"") -> -0.37454685 | AS28: =damp_eatout*LN(AP28/AQ28) -> 0 | AT28: =AS28-AS$16 -> 0 | AU28: =SUM(AO28,AT28) -> -2.9456464 | AV28: =AV27 -> -0.12376668 | AW28: =AW27+AV27 -> -2.9456464 | AY28: 12-13 | AZ28: =AZ27 -> -0.13060068 | BA28: =AZ27+BA27 -> -3.5278685 | BB28: =MAX('BATS 2023 TLFD'!Q16,0.0001) -> 0.0032622228 | BC28: =modeldata!F16/modeldata!F$156 -> 0.0066666667 | BD28: =IF(BB28>0,(BC28-BB28)/BB28,"") -> 1.0435964 | BE28: =damp_social*LN(BB28/BC28) -> 0 | BF28: =BE28-BE$16 -> 0 | BG28: =SUM(BA28,BF28) -> -3.5278685 | BH28: =BH27 -> -0.13060068 | BI28: =BI27+BH27 -> -3.5278685 | BK28: 12-13 | BL28: =BL27 -> -0.11929589 | BM28: =BL27+BM27 -> -2.6569646 | BN28: =MAX('BATS 2023 TLFD'!R16,0.0001) -> 0.0024918598 | BO28: =modeldata!G16/modeldata!G$156 -> 0.0066666667 | BP28: =IF(BN28>0,(BO28-BN28)/BN28,"") -> 1.6753779 | BQ28: =damp_discr*LN(BN28/BO28) -> 0 | BR28: =BQ28-BQ$16 -> 0 | BS28: =SUM(BM28,BR28) -> -2.6569646 | BT28: =BT27 -> -0.11929589 | BU28: =BU27+BT27 -> -2.6569646 | BW28: 12-13 | BX28: =BX27 -> -0.20447345 | BY28: =BX27+BY27 -> -4.5755764 | BZ28: =MAX('BATS 2023 TLFD'!S16,0.0001) -> 0.0001 | CA28: =modeldata!H16/modeldata!H$156 -> 0.0066666667 | CB28: =IF(BZ28>0,(CA28-BZ28)/BZ28,"") -> 65.666667 | CC28: =damp_atwork*LN(BZ28/CA28) -> 0 | CD28: =CC28-CC$16 -> 0 | CE28: =SUM(BY28,CD28) -> -4.5755764 | CF28: =CF27 -> -0.20447345 | CG28: =CG27+CF27 -> -4.5755764
A29: =A28+1 -> 13.5 | B29: =B28+1 -> 13 | C29: 13-14 | D29: =D28 -> -0.21370826 | E29: =D28+E28 -> -4.6107967 | F29: =MAX('BATS 2023 TLFD'!M17,0.0001) -> 0.0010640024 | G29: =modeldata!B17/modeldata!B$156 -> 0.0066666667 | H29: =IF(F29>0,(G29-F29)/F29,"") -> 5.2656502 | I29: =damp_escort*LN(F29/G29) -> 0 | J29: =I29-I$16 -> 0 | K29: =SUM(E29,J29) -> -4.6107967 | L29: =L28 -> -0.21370826 | M29: =M28+L28 -> -4.6107967 | O29: 13-14 | P29: =P28 -> -0.18324871 | Q29: =P28+Q28 -> -3.1626208 | R29: =MAX('BATS 2023 TLFD'!N17,0.0001) -> 0.0094696747 | S29: =modeldata!C17/modeldata!C$156 -> 0.0066666667 | T29: =IF(R29>0,(S29-R29)/R29,"") -> -0.29599834 | U29: =damp_shopping*LN(R29/S29) -> 0 | V29: =U29-U$16 -> 0 | W29: =SUM(Q29,V29) -> -3.1626208 | X29: =X28 -> -0.18324871 | Y29: =Y28+X28 -> -3.1626208 | AA29: 13-14 | AB29: =AB28 -> -0.10927639 | AC29: =AB28+AC28 -> -2.6907056 | AD29: =MAX('BATS 2023 TLFD'!O17,0.0001) -> 0.0036581585 | AE29: =modeldata!D17/modeldata!D$156 -> 0.0066666667 | AF29: =IF(AD29>0,(AE29-AD29)/AD29,"") -> 0.82241055 | AG29: =damp_maint*LN(AD29/AE29) -> 0 | AH29: =AG29-AG$16 -> 0 | AI29: =SUM(AC29,AH29) -> -2.6907056 | AJ29: =AJ28 -> -0.10927639 | AK29: =AK28+AJ28 -> -2.6907056 | AM29: 13-14 | AN29: =AN28 -> -0.12376668 | AO29: =AN28+AO28 -> -3.0694131 | AP29: =MAX('BATS 2023 TLFD'!P17,0.0001) -> 0.0073179997 | AQ29: =modeldata!E17/modeldata!E$156 -> 0.0066666667 | AR29: =IF(AP29>0,(AQ29-AP29)/AP29,"") -> -0.089004241 | AS29: =damp_eatout*LN(AP29/AQ29) -> 0 | AT29: =AS29-AS$16 -> 0 | AU29: =SUM(AO29,AT29) -> -3.0694131 | AV29: =AV28 -> -0.12376668 | AW29: =AW28+AV28 -> -3.0694131 | AY29: 13-14 | AZ29: =AZ28 -> -0.13060068 | BA29: =AZ28+BA28 -> -3.6584692 | BB29: =MAX('BATS 2023 TLFD'!Q17,0.0001) -> 0.0059832265 | BC29: =modeldata!F17/modeldata!F$156 -> 0.0066666667 | BD29: =IF(BB29>0,(BC29-BB29)/BB29,"") -> 0.11422603 | BE29: =damp_social*LN(BB29/BC29) -> 0 | BF29: =BE29-BE$16 -> 0 | BG29: =SUM(BA29,BF29) -> -3.6584692 | BH29: =BH28 -> -0.13060068 | BI29: =BI28+BH28 -> -3.6584692 | BK29: 13-14 | BL29: =BL28 -> -0.11929589 | BM29: =BL28+BM28 -> -2.7762605 | BN29: =MAX('BATS 2023 TLFD'!R17,0.0001) -> 0.046550588 | BO29: =modeldata!G17/modeldata!G$156 -> 0.0066666667 | BP29: =IF(BN29>0,(BO29-BN29)/BN29,"") -> -0.85678663 | BQ29: =damp_discr*LN(BN29/BO29) -> 0 | BR29: =BQ29-BQ$16 -> 0 | BS29: =SUM(BM29,BR29) -> -2.7762605 | BT29: =BT28 -> -0.11929589 | BU29: =BU28+BT28 -> -2.7762605 | BW29: 13-14 | BX29: =BX28 -> -0.20447345 | BY29: =BX28+BY28 -> -4.7800499 | BZ29: =MAX('BATS 2023 TLFD'!S17,0.0001) -> 0.0015423642 | CA29: =modeldata!H17/modeldata!H$156 -> 0.0066666667 | CB29: =IF(BZ29>0,(CA29-BZ29)/BZ29,"") -> 3.3223687 | CC29: =damp_atwork*LN(BZ29/CA29) -> 0 | CD29: =CC29-CC$16 -> 0 | CE29: =SUM(BY29,CD29) -> -4.7800499 | CF29: =CF28 -> -0.20447345 | CG29: =CG28+CF28 -> -4.7800499
A30: =A29+1 -> 14.5 | B30: =B29+1 -> 14 | C30: 14-15 | D30: =D29 -> -0.21370826 | E30: =D29+E29 -> -4.824505 | F30: =MAX('BATS 2023 TLFD'!M18,0.0001) -> 0.0089072054 | G30: =modeldata!B18/modeldata!B$156 -> 0.0066666667 | H30: =IF(F30>0,(G30-F30)/F30,"") -> -0.25154228 | I30: =damp_escort*LN(F30/G30) -> 0 | J30: =I30-I$16 -> 0 | K30: =SUM(E30,J30) -> -4.824505 | L30: =L29 -> -0.21370826 | M30: =M29+L29 -> -4.824505 | O30: 14-15 | P30: =P29 -> -0.18324871 | Q30: =P29+Q29 -> -3.3458695 | R30: =MAX('BATS 2023 TLFD'!N18,0.0001) -> 0.0038707186 | S30: =modeldata!C18/modeldata!C$156 -> 0.0066666667 | T30: =IF(R30>0,(S30-R30)/R30,"") -> 0.72233306 | U30: =damp_shopping*LN(R30/S30) -> 0 | V30: =U30-U$16 -> 0 | W30: =SUM(Q30,V30) -> -3.3458695 | X30: =X29 -> -0.18324871 | Y30: =Y29+X29 -> -3.3458695 | AA30: 14-15 | AB30: =AB29 -> -0.10927639 | AC30: =AB29+AC29 -> -2.799982 | AD30: =MAX('BATS 2023 TLFD'!O18,0.0001) -> 0.0059787708 | AE30: =modeldata!D18/modeldata!D$156 -> 0.0066666667 | AF30: =IF(AD30>0,(AE30-AD30)/AD30,"") -> 0.11505641 | AG30: =damp_maint*LN(AD30/AE30) -> 0 | AH30: =AG30-AG$16 -> 0 | AI30: =SUM(AC30,AH30) -> -2.799982 | AJ30: =AJ29 -> -0.10927639 | AK30: =AK29+AJ29 -> -2.799982 | AM30: 14-15 | AN30: =AN29 -> -0.12376668 | AO30: =AN29+AO29 -> -3.1931797 | AP30: =MAX('BATS 2023 TLFD'!P18,0.0001) -> 0.0019002367 | AQ30: =modeldata!E18/modeldata!E$156 -> 0.0066666667 | AR30: =IF(AP30>0,(AQ30-AP30)/AP30,"") -> 2.5083348 | AS30: =damp_eatout*LN(AP30/AQ30) -> 0 | AT30: =AS30-AS$16 -> 0 | AU30: =SUM(AO30,AT30) -> -3.1931797 | AV30: =AV29 -> -0.12376668 | AW30: =AW29+AV29 -> -3.1931797 | AY30: 14-15 | AZ30: =AZ29 -> -0.13060068 | BA30: =AZ29+BA29 -> -3.7890698 | BB30: =MAX('BATS 2023 TLFD'!Q18,0.0001) -> 0.0055699249 | BC30: =modeldata!F18/modeldata!F$156 -> 0.0066666667 | BD30: =IF(BB30>0,(BC30-BB30)/BB30,"") -> 0.19690422 | BE30: =damp_social*LN(BB30/BC30) -> 0 | BF30: =BE30-BE$16 -> 0 | BG30: =SUM(BA30,BF30) -> -3.7890698 | BH30: =BH29 -> -0.13060068 | BI30: =BI29+BH29 -> -3.7890698 | BK30: 14-15 | BL30: =BL29 -> -0.11929589 | BM30: =BL29+BM29 -> -2.8955564 | BN30: =MAX('BATS 2023 TLFD'!R18,0.0001) -> 0.00082946092 | BO30: =modeldata!G18/modeldata!G$156 -> 0.0066666667 | BP30: =IF(BN30>0,(BO30-BN30)/BN30,"") -> 7.0373487 | BQ30: =damp_discr*LN(BN30/BO30) -> 0 | BR30: =BQ30-BQ$16 -> 0 | BS30: =SUM(BM30,BR30) -> -2.8955564 | BT30: =BT29 -> -0.11929589 | BU30: =BU29+BT29 -> -2.8955564 | BW30: 14-15 | BX30: =BX29 -> -0.20447345 | BY30: =BX29+BY29 -> -4.9845233 | BZ30: =MAX('BATS 2023 TLFD'!S18,0.0001) -> 0.0037785111 | CA30: =modeldata!H18/modeldata!H$156 -> 0.0066666667 | CB30: =IF(BZ30>0,(CA30-BZ30)/BZ30,"") -> 0.76436338 | CC30: =damp_atwork*LN(BZ30/CA30) -> 0 | CD30: =CC30-CC$16 -> 0 | CE30: =SUM(BY30,CD30) -> -4.9845233 | CF30: =CF29 -> -0.20447345 | CG30: =CG29+CF29 -> -4.9845233
A31: =A30+1 -> 15.5 | B31: =B30+1 -> 15 | C31: 15-16 | D31: =D8 -> -0.21370826 | E31: =D30+E30 -> -5.0382133 | F31: =MAX('BATS 2023 TLFD'!M19,0.0001) -> 0.0023132052 | G31: =modeldata!B19/modeldata!B$156 -> 0.0066666667 | H31: =IF(F31>0,(G31-F31)/F31,"") -> 1.882004 | I31: =damp_escort*LN(F31/G31) -> 0 | J31: =I31-I$16 -> 0 | K31: =SUM(E31,J31) -> -5.0382133 | L31: =E8 -> -0.21370826 | M31: =M30+L30 -> -5.0382133 | O31: 15-16 | P31: =P8 -> -0.18324871 | Q31: =P30+Q30 -> -3.5291182 | R31: =MAX('BATS 2023 TLFD'!N19,0.0001) -> 0.0056096647 | S31: =modeldata!C19/modeldata!C$156 -> 0.0066666667 | T31: =IF(R31>0,(S31-R31)/R31,"") -> 0.18842516 | U31: =damp_shopping*LN(R31/S31) -> 0 | V31: =U31-U$16 -> 0 | W31: =SUM(Q31,V31) -> -3.5291182 | X31: =Q8 -> -0.18324871 | Y31: =Y30+X30 -> -3.5291182 | AA31: 15-16 | AB31: =AB8 -> -0.10927639 | AC31: =AB30+AC30 -> -2.9092584 | AD31: =MAX('BATS 2023 TLFD'!O19,0.0001) -> 0.011536381 | AE31: =modeldata!D19/modeldata!D$156 -> 0.0066666667 | AF31: =IF(AD31>0,(AE31-AD31)/AD31,"") -> -0.42211804 | AG31: =damp_maint*LN(AD31/AE31) -> 0 | AH31: =AG31-AG$16 -> 0 | AI31: =SUM(AC31,AH31) -> -2.9092584 | AJ31: =AC8 -> -0.10927639 | AK31: =AK30+AJ30 -> -2.9092584 | AM31: 15-16 | AN31: =AN8 -> -0.12376668 | AO31: =AN30+AO30 -> -3.3169464 | AP31: =MAX('BATS 2023 TLFD'!P19,0.0001) -> 0.010199094 | AQ31: =modeldata!E19/modeldata!E$156 -> 0.0066666667 | AR31: =IF(AP31>0,(AQ31-AP31)/AP31,"") -> -0.34634716 | AS31: =damp_eatout*LN(AP31/AQ31) -> 0 | AT31: =AS31-AS$16 -> 0 | AU31: =SUM(AO31,AT31) -> -3.3169464 | AV31: =AO8 -> -0.12376668 | AW31: =AW30+AV30 -> -3.3169464 | AY31: 15-16 | AZ31: =AZ8 -> -0.13060068 | BA31: =AZ30+BA30 -> -3.9196705 | BB31: =MAX('BATS 2023 TLFD'!Q19,0.0001) -> 0.012935192 | BC31: =modeldata!F19/modeldata!F$156 -> 0.0066666667 | BD31: =IF(BB31>0,(BC31-BB31)/BB31,"") -> -0.48461016 | BE31: =damp_social*LN(BB31/BC31) -> 0 | BF31: =BE31-BE$16 -> 0 | BG31: =SUM(BA31,BF31) -> -3.9196705 | BH31: =BA8 -> -0.13060068 | BI31: =BI30+BH30 -> -3.9196705 | BK31: 15-16 | BL31: =BL8 -> -0.11929589 | BM31: =BL30+BM30 -> -3.0148523 | BN31: =MAX('BATS 2023 TLFD'!R19,0.0001) -> 0.0088368963 | BO31: =modeldata!G19/modeldata!G$156 -> 0.0066666667 | BP31: =IF(BN31>0,(BO31-BN31)/BN31,"") -> -0.24558732 | BQ31: =damp_discr*LN(BN31/BO31) -> 0 | BR31: =BQ31-BQ$16 -> 0 | BS31: =SUM(BM31,BR31) -> -3.0148523 | BT31: =BM8 -> -0.11929589 | BU31: =BU30+BT30 -> -3.0148523 | BW31: 15-16 | BX31: =BX8 -> -0.20447345 | BY31: =BX30+BY30 -> -5.1889968 | BZ31: =MAX('BATS 2023 TLFD'!S19,0.0001) -> 0.00050514649 | CA31: =modeldata!H19/modeldata!H$156 -> 0.0066666667 | CB31: =IF(BZ31>0,(CA31-BZ31)/BZ31,"") -> 12.197492 | CC31: =damp_atwork*LN(BZ31/CA31) -> 0 | CD31: =CC31-CC$16 -> 0 | CE31: =SUM(BY31,CD31) -> -5.1889968 | CF31: =BY8 -> -0.20447345 | CG31: =CG30+CF30 -> -5.1889968
A32: =A31+1 -> 16.5 | B32: =B31+1 -> 16 | C32: 16-17 | D32: =D31 -> -0.21370826 | E32: =D31+E31 -> -5.2519215 | F32: =MAX('BATS 2023 TLFD'!M20,0.0001) -> 0.0012335126 | G32: =modeldata!B20/modeldata!B$156 -> 0.0066666667 | H32: =IF(F32>0,(G32-F32)/F32,"") -> 4.4046199 | I32: =damp_escort*LN(F32/G32) -> 0 | J32: =I32-I$16 -> 0 | K32: =SUM(E32,J32) -> -5.2519215 | L32: =L31 -> -0.21370826 | M32: =M31+L31 -> -5.2519215 | O32: 16-17 | P32: =P31 -> -0.18324871 | Q32: =P31+Q31 -> -3.712367 | R32: =MAX('BATS 2023 TLFD'!N20,0.0001) -> 0.00069807003 | S32: =modeldata!C20/modeldata!C$156 -> 0.0066666667 | T32: =IF(R32>0,(S32-R32)/R32,"") -> 8.5501402 | U32: =damp_shopping*LN(R32/S32) -> 0 | V32: =U32-U$16 -> 0 | W32: =SUM(Q32,V32) -> -3.712367 | X32: =X31 -> -0.18324871 | Y32: =Y31+X31 -> -3.712367 | AA32: 16-17 | AB32: =AB31 -> -0.10927639 | AC32: =AB31+AC31 -> -3.0185348 | AD32: =MAX('BATS 2023 TLFD'!O20,0.0001) -> 0.0027382708 | AE32: =modeldata!D20/modeldata!D$156 -> 0.0066666667 | AF32: =IF(AD32>0,(AE32-AD32)/AD32,"") -> 1.4346265 | AG32: =damp_maint*LN(AD32/AE32) -> 0 | AH32: =AG32-AG$16 -> 0 | AI32: =SUM(AC32,AH32) -> -3.0185348 | AJ32: =AJ31 -> -0.10927639 | AK32: =AK31+AJ31 -> -3.0185348 | AM32: 16-17 | AN32: =AN31 -> -0.12376668 | AO32: =AN31+AO31 -> -3.4407131 | AP32: =MAX('BATS 2023 TLFD'!P20,0.0001) -> 0.0030902044 | AQ32: =modeldata!E20/modeldata!E$156 -> 0.0066666667 | AR32: =IF(AP32>0,(AQ32-AP32)/AP32,"") -> 1.1573546 | AS32: =damp_eatout*LN(AP32/AQ32) -> 0 | AT32: =AS32-AS$16 -> 0 | AU32: =SUM(AO32,AT32) -> -3.4407131 | AV32: =AV31 -> -0.12376668 | AW32: =AW31+AV31 -> -3.4407131 | AY32: 16-17 | AZ32: =AZ31 -> -0.13060068 | BA32: =AZ31+BA31 -> -4.0502712 | BB32: =MAX('BATS 2023 TLFD'!Q20,0.0001) -> 0.0017314952 | BC32: =modeldata!F20/modeldata!F$156 -> 0.0066666667 | BD32: =IF(BB32>0,(BC32-BB32)/BB32,"") -> 2.8502369 | BE32: =damp_social*LN(BB32/BC32) -> 0 | BF32: =BE32-BE$16 -> 0 | BG32: =SUM(BA32,BF32) -> -4.0502712 | BH32: =BH31 -> -0.13060068 | BI32: =BI31+BH31 -> -4.0502712 | BK32: 16-17 | BL32: =BL31 -> -0.11929589 | BM32: =BL31+BM31 -> -3.1341482 | BN32: =MAX('BATS 2023 TLFD'!R20,0.0001) -> 0.0055037177 | BO32: =modeldata!G20/modeldata!G$156 -> 0.0066666667 | BP32: =IF(BN32>0,(BO32-BN32)/BN32,"") -> 0.21130243 | BQ32: =damp_discr*LN(BN32/BO32) -> 0 | BR32: =BQ32-BQ$16 -> 0 | BS32: =SUM(BM32,BR32) -> -3.1341482 | BT32: =BT31 -> -0.11929589 | BU32: =BU31+BT31 -> -3.1341482 | BW32: 16-17 | BX32: =BX31 -> -0.20447345 | BY32: =BX31+BY31 -> -5.3934702 | BZ32: =MAX('BATS 2023 TLFD'!S20,0.0001) -> 0.00010861617 | CA32: =modeldata!H20/modeldata!H$156 -> 0.0066666667 | CB32: =IF(BZ32>0,(CA32-BZ32)/BZ32,"") -> 60.378218 | CC32: =damp_atwork*LN(BZ32/CA32) -> 0 | CD32: =CC32-CC$16 -> 0 | CE32: =SUM(BY32,CD32) -> -5.3934702 | CF32: =CF31 -> -0.20447345 | CG32: =CG31+CF31 -> -5.3934702
A33: =A32+1 -> 17.5 | B33: =B32+1 -> 17 | C33: 17-18 | D33: =D32 -> -0.21370826 | E33: =D32+E32 -> -5.4656298 | F33: =MAX('BATS 2023 TLFD'!M21,0.0001) -> 0.0001 | G33: =modeldata!B21/modeldata!B$156 -> 0.0066666667 | H33: =IF(F33>0,(G33-F33)/F33,"") -> 65.666667 | I33: =damp_escort*LN(F33/G33) -> 0 | J33: =I33-I$16 -> 0 | K33: =SUM(E33,J33) -> -5.4656298 | L33: =L32 -> -0.21370826 | M33: =M32+L32 -> -5.4656298 | O33: 17-18 | P33: =P32 -> -0.18324871 | Q33: =P32+Q32 -> -3.8956157 | R33: =MAX('BATS 2023 TLFD'!N21,0.0001) -> 0.0051983718 | S33: =modeldata!C21/modeldata!C$156 -> 0.0066666667 | T33: =IF(R33>0,(S33-R33)/R33,"") -> 0.28245283 | U33: =damp_shopping*LN(R33/S33) -> 0 | V33: =U33-U$16 -> 0 | W33: =SUM(Q33,V33) -> -3.8956157 | X33: =X32 -> -0.18324871 | Y33: =Y32+X32 -> -3.8956157 | AA33: 17-18 | AB33: =AB32 -> -0.10927639 | AC33: =AB32+AC32 -> -3.1278112 | AD33: =MAX('BATS 2023 TLFD'!O21,0.0001) -> 0.0019387262 | AE33: =modeldata!D21/modeldata!D$156 -> 0.0066666667 | AF33: =IF(AD33>0,(AE33-AD33)/AD33,"") -> 2.4386839 | AG33: =damp_maint*LN(AD33/AE33) -> 0 | AH33: =AG33-AG$16 -> 0 | AI33: =SUM(AC33,AH33) -> -3.1278112 | AJ33: =AJ32 -> -0.10927639 | AK33: =AK32+AJ32 -> -3.1278112 | AM33: 17-18 | AN33: =AN32 -> -0.12376668 | AO33: =AN32+AO32 -> -3.5644798 | AP33: =MAX('BATS 2023 TLFD'!P21,0.0001) -> 0.0010850703 | AQ33: =modeldata!E21/modeldata!E$156 -> 0.0066666667 | AR33: =IF(AP33>0,(AQ33-AP33)/AP33,"") -> 5.1439953 | AS33: =damp_eatout*LN(AP33/AQ33) -> 0 | AT33: =AS33-AS$16 -> 0 | AU33: =SUM(AO33,AT33) -> -3.5644798 | AV33: =AV32 -> -0.12376668 | AW33: =AW32+AV32 -> -3.5644798 | AY33: 17-18 | AZ33: =AZ32 -> -0.13060068 | BA33: =AZ32+BA32 -> -4.1808719 | BB33: =MAX('BATS 2023 TLFD'!Q21,0.0001) -> 0.0094155432 | BC33: =modeldata!F21/modeldata!F$156 -> 0.0066666667 | BD33: =IF(BB33>0,(BC33-BB33)/BB33,"") -> -0.29195093 | BE33: =damp_social*LN(BB33/BC33) -> 0 | BF33: =BE33-BE$16 -> 0 | BG33: =SUM(BA33,BF33) -> -4.1808719 | BH33: =BH32 -> -0.13060068 | BI33: =BI32+BH32 -> -4.1808719 | BK33: 17-18 | BL33: =BL32 -> -0.11929589 | BM33: =BL32+BM32 -> -3.253444 | BN33: =MAX('BATS 2023 TLFD'!R21,0.0001) -> 0.0039736806 | BO33: =modeldata!G21/modeldata!G$156 -> 0.0066666667 | BP33: =IF(BN33>0,(BO33-BN33)/BN33,"") -> 0.67770574 | BQ33: =damp_discr*LN(BN33/BO33) -> 0 | BR33: =BQ33-BQ$16 -> 0 | BS33: =SUM(BM33,BR33) -> -3.253444 | BT33: =BT32 -> -0.11929589 | BU33: =BU32+BT32 -> -3.253444 | BW33: 17-18 | BX33: =BX32 -> -0.20447345 | BY33: =BX32+BY32 -> -5.5979437 | BZ33: =MAX('BATS 2023 TLFD'!S21,0.0001) -> 0.00022146408 | CA33: =modeldata!H21/modeldata!H$156 -> 0.0066666667 | CB33: =IF(BZ33>0,(CA33-BZ33)/BZ33,"") -> 29.1027 | CC33: =damp_atwork*LN(BZ33/CA33) -> 0 | CD33: =CC33-CC$16 -> 0 | CE33: =SUM(BY33,CD33) -> -5.5979437 | CF33: =CF32 -> -0.20447345 | CG33: =CG32+CF32 -> -5.5979437
