Workbook
Name atwork_damp: calibration_simplemodes!$AW$78
Name atwork_new: calibration_simplemodes!$BC$79
Name eatout_c_ivt: constants!$Y$1
Name escort_c_ivt: constants!$Q$1
Name indivdisc_damp: calibration_simplemodes!$AW$63
Name indivdisc_new: calibration_simplemodes!$BC$64
Name indivmaint_damp: calibration_simplemodes!$AW$48
Name indivmaint_new: calibration_simplemodes!$BC$49
Name joint_damp: calibration_simplemodes!$AW$93
Name joint_existing: constants!$C$30
Name joint_new: calibration_simplemodes!$BC$94
Name model_trn_tours: modeldata!$S:$Y
Name othdisc_existing: constants!$AI$3
Name othdiscr_c_ivt: constants!$AK$1
Name othmaint_c_ivt: constants!$AC$1
Name school_c_ivt: constants!$M$1
Name school_damp: calibration_simplemodes!$AW$33
Name school_existing: constants!$K$3
Name school_new: calibration_simplemodes!$BC$34
Name shopping_c_ivt: constants!$U$1
Name shopping_existing: constants!$S$3
Name simple_purposes: model_lookup!$A$23:$B$30
Name social_c_ivt: constants!$AG$1
Name sub_atwork_damp: calibration_trnsubmodes!$AK$68
Name sub_indivdisc_damp: calibration_trnsubmodes!$AK$55
Name sub_indivmaint_damp: calibration_trnsubmodes!$AK$42
Name sub_school_damp: calibration_trnsubmodes!$AK$29
Name sub_university_damp: calibration_trnsubmodes!$AK$16
Name sub_work_damp: calibration_trnsubmodes!$AK$3
Name taxi_scale: calibration_simplemodes!$F$122
Name taxi_share: calibration_simplemodes!$D$122
Name taxi_trips_per_tour: targets!#REF!
Name tnc_shared_share: calibration_simplemodes!$D$124
Name tnc_single_share: calibration_simplemodes!$D$123
Name tour_modes: model_lookup!$D$1:$F$22
Name tour_purposes: model_lookup!$A$1:$B$18
Name trn_modes: model_lookup!$A$33:$B$40
Name university_c_ivt: constants!$I$1
Name university_damp: calibration_simplemodes!$AW$18
Name university_existing: constants!$G$3
Name university_new: calibration_simplemodes!$BC$19
Name work_c_ivt: constants!$E$1
Name work_damp: calibration_simplemodes!$AW$3
Name work_existing: constants!$C$3
Name work_new: calibration_simplemodes!$BC$4
Name workbased_c_ivt: constants!$AO$1
Name workbased_existing: constants!$AM$3

Sheet DistrictTransitTourFlows
D1: Onboard Survey Counts | AP1: Row Percent | CB1: Column Percent
E2: Destination District | AQ2: Destination District | CC2: Destination District
A3: OBS trip Flows in Tour format ( home end is origin) | E3: Greater Downtown San Francisco | F3: San Francisco Richmond District | G3: San Francisco Mission District | H3: San Francisco Sunset District | I3: Daly City and San Bruno | J3: San Mateo and Burlingame | K3: Redwood City and Menlo Park | L3: Palo Alto and Los Altos | M3: Sunnyvale and Mountain View | N3: Cupertino and Saratoga | O3: Central San Jose | P3: Milpitas and East San Jose | Q3: South San Jose | R3: Gilroy and Morgan Hill | S3: Livermore and Pleasanton | T3: Fremont and Union City | U3: Hayward and San Leandro | V3: Oakland and Alameda | W3: Berkeley and Albany | X3: Richmond and El Cerrito | Y3: Concord and Martinez | Z3: Walnut Creek | AA3: Danville and San Ramon | AB3: Antioch and Pittsburg | AC3: Vallejo and Benicia | AD3: Fairfield and Vacaville | AE3: Napa | AF3: St Helena | AG3: Petaluma and Rohnert Park | AH3: Santa Rosa and Sebastopol | AI3: Healdsburg and Cloverdale | AJ3: Novato | AK3: San Rafael | AL3: Mill Valley and Sausalito | AM3: Total | AQ3: Greater Downtown San Francisco | AR3: San Francisco Richmond District | AS3: San Francisco Mission District | AT3: San Francisco Sunset District | AU3: Daly City and San Bruno | AV3: San Mateo and Burlingame | AW3: Redwood City and Menlo Park | AX3: Palo Alto and Los Altos | AY3: Sunnyvale and Mountain View | AZ3: Cupertino and Saratoga | BA3: Central San Jose | BB3: Milpitas and East San Jose | BC3: South San Jose | BD3: Gilroy and Morgan Hill | BE3: Livermore and Pleasanton | BF3: Fremont and Union City | BG3: Hayward and San Leandro | BH3: Oakland and Alameda | BI3: Berkeley and Albany | BJ3: Richmond and El Cerrito | BK3: Concord and Martinez | BL3: Walnut Creek | BM3: Danville and San Ramon | BN3: Antioch and Pittsburg | BO3: Vallejo and Benicia | BP3: Fairfield and Vacaville | BQ3: Napa | BR3: St Helena | BS3: Petaluma and Rohnert Park | BT3: Santa Rosa and Sebastopol | BU3: Healdsburg and Cloverdale | BV3: Novato | BW3: San Rafael | BX3: Mill Valley and Sausalito | BY3: Total | CC3: Greater Downtown San Francisco | CD3: San Francisco Richmond District | CE3: San Francisco Mission District | CF3: San Francisco Sunset District | CG3: Daly City and San Bruno | CH3: San Mateo and Burlingame | CI3: Redwood City and Menlo Park | CJ3: Palo Alto and Los Altos | CK3: Sunnyvale and Mountain View | CL3: Cupertino and Saratoga | CM3: Central San Jose | CN3: Milpitas and East San Jose | CO3: South San Jose | CP3: Gilroy and Morgan Hill | CQ3: Livermore and Pleasanton | CR3: Fremont and Union City | CS3: Hayward and San Leandro | CT3: Oakland and Alameda | CU3: Berkeley and Albany | CV3: Richmond and El Cerrito | CW3: Concord and Martinez | CX3: Walnut Creek | CY3: Danville and San Ramon | CZ3: Antioch and Pittsburg | DA3: Vallejo and Benicia | DB3: Fairfield and Vacaville | DC3: Napa | DD3: St Helena | DE3: Petaluma and Rohnert Park | DF3: Santa Rosa and Sebastopol | DG3: Healdsburg and Cloverdale | DH3: Novato | DI3: San Rafael | DJ3: Mill Valley and Sausalito | DK3: Total
C4: Origin District | D4: Greater Downtown San Francisco | E4: =IFERROR(VLOOKUP(CONCATENATE($A$15,"-",$A$12, "-", $D4, "-", E$3, "-", $A$9),OBS_District_Flows!$A:$K, 6,FALSE),0) -> 0 | F4: =IFERROR(VLOOKUP(CONCATENATE($A$15,"-",$A$12, "-", $D4, "-", F$3, "-", $A$9),OBS_District_Flows!$A:$K, 6,FALSE),0) -> 0 | G4: =IFERROR(VLOOKUP(CONCATENATE($A$15,"-",$A$12, "-", $D4, "-", G$3, "-", $A$9),OBS_District_Flows!$A:$K, 6,FALSE),0) -> 0 | H4: =IFERROR(VLOOKUP(CONCATENATE($A$15,"-",$A$12, "-", $D4, "-", H$3, "-", $A$9),OBS_District_Flows!$A:$K, 6,FALSE),0) -> 0 | I4: =IFERROR(VLOOKUP(CONCATENATE($A$15,"-",$A$12, "-", $D4, "-", I$3, "-", $A$9),OBS_District_Flows!$A:$K, 6,FALSE),0) -> 0 | J4: =IFERROR(VLOOKUP(CONCATENATE($A$15,"-",$A$12, "-", $D4, "-", J$3, "-", $A$9),OBS_District_Flows!$A:$K, 6,FALSE),0) -> 0 | K4: =IFERROR(VLOOKUP(CONCATENATE($A$15,"-",$A$12, "-", $D4, "-", K$3, "-", $A$9),OBS_District_Flows!$A:$K, 6,FALSE),0) -> 0 | L4: =IFERROR(VLOOKUP(CONCATENATE($A$15,"-",$A$12, "-", $D4, "-", L$3, "-", $A$9),OBS_District_Flows!$A:$K, 6,FALSE),0) -> 0 | ... AL4: =IFERROR(VLOOKUP(CONCATENATE($A$15,"-",$A$12, "-", $D4, "-", AL$3, "-", $A$9),OBS_District_Flows!$A:$K, 6,FALSE),0) -> 0 | AM4: =SUM(E4:AL4) -> 0 | AO4: Origin District | AP4: Greater Downtown San Francisco | AQ4: =IF($AM4>0,E4/$AM4, "") | AR4: =IF($AM4>0,F4/$AM4, "") | AS4: =IF($AM4>0,G4/$AM4, "") | AT4: =IF($AM4>0,H4/$AM4, "") | AU4: =IF($AM4>0,I4/$AM4, "") | AV4: =IF($AM4>0,J4/$AM4, "") | AW4: =IF($AM4>0,K4/$AM4, "") | AX4: =IF($AM4>0,L4/$AM4, "") | ... BY4: =IF($AM4>0,AM4/$AM4, "") | CA4: Origin District | CB4: Greater Downtown San Francisco | CC4: =IF(E$38>0, E4/E$38, "") | CD4: =IF(F$38>0, F4/F$38, "") | CE4: =IF(G$38>0, G4/G$38, "") | CF4: =IF(H$38>0, H4/H$38, "") | CG4: =IF(I$38>0, I4/I$38, "") | CH4: =IF(J$38>0, J4/J$38, "") | CI4: =IF(K$38>0, K4/K$38, "") | CJ4: =IF(L$38>0, L4/L$38, "") | ... DK4: =IF(AM$38>0, AM4/AM$38, "")
A5: Select Purpose | D5: San Francisco Richmond District | E5: =IFERROR(VLOOKUP(CONCATENATE($A$15,"-",$A$12, "-", $D5, "-", E$3, "-", $A$9),OBS_District_Flows!$A:$K, 6,FALSE),0) -> 0 | F5: =IFERROR(VLOOKUP(CONCATENATE($A$15,"-",$A$12, "-", $D5, "-", F$3, "-", $A$9),OBS_District_Flows!$A:$K, 6,FALSE),0) -> 0 | G5: =IFERROR(VLOOKUP(CONCATENATE($A$15,"-",$A$12, "-", $D5, "-", G$3, "-", $A$9),OBS_District_Flows!$A:$K, 6,FALSE),0) -> 0 | H5: =IFERROR(VLOOKUP(CONCATENATE($A$15,"-",$A$12, "-", $D5, "-", H$3, "-", $A$9),OBS_District_Flows!$A:$K, 6,FALSE),0) -> 0 | I5: =IFERROR(VLOOKUP(CONCATENATE($A$15,"-",$A$12, "-", $D5, "-", I$3, "-", $A$9),OBS_District_Flows!$A:$K, 6,FALSE),0) -> 0 | J5: =IFERROR(VLOOKUP(CONCATENATE($A$15,"-",$A$12, "-", $D5, "-", J$3, "-", $A$9),OBS_District_Flows!$A:$K, 6,FALSE),0) -> 0 | K5: =IFERROR(VLOOKUP(CONCATENATE($A$15,"-",$A$12, "-", $D5, "-", K$3, "-", $A$9),OBS_District_Flows!$A:$K, 6,FALSE),0) -> 0 | L5: =IFERROR(VLOOKUP(CONCATENATE($A$15,"-",$A$12, "-", $D5, "-", L$3, "-", $A$9),OBS_District_Flows!$A:$K, 6,FALSE),0) -> 0 | ... AL5: =IFERROR(VLOOKUP(CONCATENATE($A$15,"-",$A$12, "-", $D5, "-", AL$3, "-", $A$9),OBS_District_Flows!$A:$K, 6,FALSE),0) -> 0 | AM5: =SUM(E5:AL5) -> 0 | AP5: San Francisco Richmond District | AQ5: =IF($AM5>0,E5/$AM5, "") | AR5: =IF($AM5>0,F5/$AM5, "") | AS5: =IF($AM5>0,G5/$AM5, "") | AT5: =IF($AM5>0,H5/$AM5, "") | AU5: =IF($AM5>0,I5/$AM5, "") | AV5: =IF($AM5>0,J5/$AM5, "") | AW5: =IF($AM5>0,K5/$AM5, "") | AX5: =IF($AM5>0,L5/$AM5, "") | ... BY5: =IF($AM5>0,AM5/$AM5, "") | CB5: San Francisco Richmond District | CC5: =IF(E$38>0, E5/E$38, "") | CD5: =IF(F$38>0, F5/F$38, "") | CE5: =IF(G$38>0, G5/G$38, "") | CF5: =IF(H$38>0, H5/H$38, "") | CG5: =IF(I$38>0, I5/I$38, "") | CH5: =IF(J$38>0, J5/J$38, "") | CI5: =IF(K$38>0, K5/K$38, "") | CJ5: =IF(L$38>0, L5/L$38, "") | ... DK5: =IF(AM$38>0, AM5/AM$38, "")
A6: Total | D6: San Francisco Mission District | E6: =IFERROR(VLOOKUP(CONCATENATE($A$15,"-",$A$12, "-", $D6, "-", E$3, "-", $A$9),OBS_District_Flows!$A:$K, 6,FALSE),0) -> 0 | F6: =IFERROR(VLOOKUP(CONCATENATE($A$15,"-",$A$12, "-", $D6, "-", F$3, "-", $A$9),OBS_District_Flows!$A:$K, 6,FALSE),0) -> 0 | G6: =IFERROR(VLOOKUP(CONCATENATE($A$15,"-",$A$12, "-", $D6, "-", G$3, "-", $A$9),OBS_District_Flows!$A:$K, 6,FALSE),0) -> 0 | H6: =IFERROR(VLOOKUP(CONCATENATE($A$15,"-",$A$12, "-", $D6, "-", H$3, "-", $A$9),OBS_District_Flows!$A:$K, 6,FALSE),0) -> 0 | I6: =IFERROR(VLOOKUP(CONCATENATE($A$15,"-",$A$12, "-", $D6, "-", I$3, "-", $A$9),OBS_District_Flows!$A:$K, 6,FALSE),0) -> 0 | J6: =IFERROR(VLOOKUP(CONCATENATE($A$15,"-",$A$12, "-", $D6, "-", J$3, "-", $A$9),OBS_District_Flows!$A:$K, 6,FALSE),0) -> 0 | K6: =IFERROR(VLOOKUP(CONCATENATE($A$15,"-",$A$12, "-", $D6, "-", K$3, "-", $A$9),OBS_District_Flows!$A:$K, 6,FALSE),0) -> 0 | L6: =IFERROR(VLOOKUP(CONCATENATE($A$15,"-",$A$12, "-", $D6, "-", L$3, "-", $A$9),OBS_District_Flows!$A:$K, 6,FALSE),0) -> 0 | ... AL6: =IFERROR(VLOOKUP(CONCATENATE($A$15,"-",$A$12, "-", $D6, "-", AL$3, "-", $A$9),OBS_District_Flows!$A:$K, 6,FALSE),0) -> 0 | AM6: =SUM(E6:AL6) -> 0 | AP6: San Francisco Mission District | AQ6: =IF($AM6>0,E6/$AM6, "") | AR6: =IF($AM6>0,F6/$AM6, "") | AS6: =IF($AM6>0,G6/$AM6, "") | AT6: =IF($AM6>0,H6/$AM6, "") | AU6: =IF($AM6>0,I6/$AM6, "") | AV6: =IF($AM6>0,J6/$AM6, "") | AW6: =IF($AM6>0,K6/$AM6, "") | AX6: =IF($AM6>0,L6/$AM6, "") | ... BY6: =IF($AM6>0,AM6/$AM6, "") | CB6: San Francisco Mission District | CC6: =IF(E$38>0, E6/E$38, "") | CD6: =IF(F$38>0, F6/F$38, "") | CE6: =IF(G$38>0, G6/G$38, "") | CF6: =IF(H$38>0, H6/H$38, "") | CG6: =IF(I$38>0, I6/I$38, "") | CH6: =IF(J$38>0, J6/J$38, "") | CI6: =IF(K$38>0, K6/K$38, "") | CJ6: =IF(L$38>0, L6/L$38, "") | ... DK6: =IF(AM$38>0, AM6/AM$38, "")
D7: San Francisco Sunset District | E7: =IFERROR(VLOOKUP(CONCATENATE($A$15,"-",$A$12, "-", $D7, "-", E$3, "-", $A$9),OBS_District_Flows!$A:$K, 6,FALSE),0) -> 0 | F7: =IFERROR(VLOOKUP(CONCATENATE($A$15,"-",$A$12, "-", $D7, "-", F$3, "-", $A$9),OBS_District_Flows!$A:$K, 6,FALSE),0) -> 0 | G7: =IFERROR(VLOOKUP(CONCATENATE($A$15,"-",$A$12, "-", $D7, "-", G$3, "-", $A$9),OBS_District_Flows!$A:$K, 6,FALSE),0) -> 0 | H7: =IFERROR(VLOOKUP(CONCATENATE($A$15,"-",$A$12, "-", $D7, "-", H$3, "-", $A$9),OBS_District_Flows!$A:$K, 6,FALSE),0) -> 0 | I7: =IFERROR(VLOOKUP(CONCATENATE($A$15,"-",$A$12, "-", $D7, "-", I$3, "-", $A$9),OBS_District_Flows!$A:$K, 6,FALSE),0) -> 0 | J7: =IFERROR(VLOOKUP(CONCATENATE($A$15,"-",$A$12, "-", $D7, "-", J$3, "-", $A$9),OBS_District_Flows!$A:$K, 6,FALSE),0) -> 0 | K7: =IFERROR(VLOOKUP(CONCATENATE($A$15,"-",$A$12, "-", $D7, "-", K$3, "-", $A$9),OBS_District_Flows!$A:$K, 6,FALSE),0) -> 0 | L7: =IFERROR(VLOOKUP(CONCATENATE($A$15,"-",$A$12, "-", $D7, "-", L$3, "-", $A$9),OBS_District_Flows!$A:$K, 6,FALSE),0) -> 0 | ... AL7: =IFERROR(VLOOKUP(CONCATENATE($A$15,"-",$A$12, "-", $D7, "-", AL$3, "-", $A$9),OBS_District_Flows!$A:$K, 6,FALSE),0) -> 0 | AM7: =SUM(E7:AL7) -> 0 | AP7: San Francisco Sunset District | AQ7: =IF($AM7>0,E7/$AM7, "") | AR7: =IF($AM7>0,F7/$AM7, "") | AS7: =IF($AM7>0,G7/$AM7, "") | AT7: =IF($AM7>0,H7/$AM7, "") | AU7: =IF($AM7>0,I7/$AM7, "") | AV7: =IF($AM7>0,J7/$AM7, "") | AW7: =IF($AM7>0,K7/$AM7, "") | AX7: =IF($AM7>0,L7/$AM7, "") | ... BY7: =IF($AM7>0,AM7/$AM7, "") | CB7: San Francisco Sunset District | CC7: =IF(E$38>0, E7/E$38, "") | CD7: =IF(F$38>0, F7/F$38, "") | CE7: =IF(G$38>0, G7/G$38, "") | CF7: =IF(H$38>0, H7/H$38, "") | CG7: =IF(I$38>0, I7/I$38, "") | CH7: =IF(J$38>0, J7/J$38, "") | CI7: =IF(K$38>0, K7/K$38, "") | CJ7: =IF(L$38>0, L7/L$38, "") | ... DK7: =IF(AM$38>0, AM7/AM$38, "")
A8: Purpose ID | D8: Daly City and San Bruno | E8: =IFERROR(VLOOKUP(CONCATENATE($A$15,"-",$A$12, "-", $D8, "-", E$3, "-", $A$9),OBS_District_Flows!$A:$K, 6,FALSE),0) -> 0 | F8: =IFERROR(VLOOKUP(CONCATENATE($A$15,"-",$A$12, "-", $D8, "-", F$3, "-", $A$9),OBS_District_Flows!$A:$K, 6,FALSE),0) -> 0 | G8: =IFERROR(VLOOKUP(CONCATENATE($A$15,"-",$A$12, "-", $D8, "-", G$3, "-", $A$9),OBS_District_Flows!$A:$K, 6,FALSE),0) -> 0 | H8: =IFERROR(VLOOKUP(CONCATENATE($A$15,"-",$A$12, "-", $D8, "-", H$3, "-", $A$9),OBS_District_Flows!$A:$K, 6,FALSE),0) -> 0 | I8: =IFERROR(VLOOKUP(CONCATENATE($A$15,"-",$A$12, "-", $D8, "-", I$3, "-", $A$9),OBS_District_Flows!$A:$K, 6,FALSE),0) -> 0 | J8: =IFERROR(VLOOKUP(CONCATENATE($A$15,"-",$A$12, "-", $D8, "-", J$3, "-", $A$9),OBS_District_Flows!$A:$K, 6,FALSE),0) -> 0 | K8: =IFERROR(VLOOKUP(CONCATENATE($A$15,"-",$A$12, "-", $D8, "-", K$3, "-", $A$9),OBS_District_Flows!$A:$K, 6,FALSE),0) -> 0 | L8: =IFERROR(VLOOKUP(CONCATENATE($A$15,"-",$A$12, "-", $D8, "-", L$3, "-", $A$9),OBS_District_Flows!$A:$K, 6,FALSE),0) -> 0 | ... AL8: =IFERROR(VLOOKUP(CONCATENATE($A$15,"-",$A$12, "-", $D8, "-", AL$3, "-", $A$9),OBS_District_Flows!$A:$K, 6,FALSE),0) -> 0 | AM8: =SUM(E8:AL8) -> 0 | AP8: Daly City and San Bruno | AQ8: =IF($AM8>0,E8/$AM8, "") | AR8: =IF($AM8>0,F8/$AM8, "") | AS8: =IF($AM8>0,G8/$AM8, "") | AT8: =IF($AM8>0,H8/$AM8, "") | AU8: =IF($AM8>0,I8/$AM8, "") | AV8: =IF($AM8>0,J8/$AM8, "") | AW8: =IF($AM8>0,K8/$AM8, "") | AX8: =IF($AM8>0,L8/$AM8, "") | ... BY8: =IF($AM8>0,AM8/$AM8, "") | CB8: Daly City and San Bruno | CC8: =IF(E$38>0, E8/E$38, "") | CD8: =IF(F$38>0, F8/F$38, "") | CE8: =IF(G$38>0, G8/G$38, "") | CF8: =IF(H$38>0, H8/H$38, "") | CG8: =IF(I$38>0, I8/I$38, "") | CH8: =IF(J$38>0, J8/J$38, "") | CI8: =IF(K$38>0, K8/K$38, "") | CJ8: =IF(L$38>0, L8/L$38, "") | ... DK8: =IF(AM$38>0, AM8/AM$38, "")
A9: =VLOOKUP(A6, OBS_District_Flows!W2:X11,2,FALSE) -> Total | D9: San Mateo and Burlingame | E9: =IFERROR(VLOOKUP(CONCATENATE($A$15,"-",$A$12, "-", $D9, "-", E$3, "-", $A$9),OBS_District_Flows!$A:$K, 6,FALSE),0) -> 0 | F9: =IFERROR(VLOOKUP(CONCATENATE($A$15,"-",$A$12, "-", $D9, "-", F$3, "-", $A$9),OBS_District_Flows!$A:$K, 6,FALSE),0) -> 0 | G9: =IFERROR(VLOOKUP(CONCATENATE($A$15,"-",$A$12, "-", $D9, "-", G$3, "-", $A$9),OBS_District_Flows!$A:$K, 6,FALSE),0) -> 0 | H9: =IFERROR(VLOOKUP(CONCATENATE($A$15,"-",$A$12, "-", $D9, "-", H$3, "-", $A$9),OBS_District_Flows!$A:$K, 6,FALSE),0) -> 0 | I9: =IFERROR(VLOOKUP(CONCATENATE($A$15,"-",$A$12, "-", $D9, "-", I$3, "-", $A$9),OBS_District_Flows!$A:$K, 6,FALSE),0) -> 0 | J9: =IFERROR(VLOOKUP(CONCATENATE($A$15,"-",$A$12, "-", $D9, "-", J$3, "-", $A$9),OBS_District_Flows!$A:$K, 6,FALSE),0) -> 0 | K9: =IFERROR(VLOOKUP(CONCATENATE($A$15,"-",$A$12, "-", $D9, "-", K$3, "-", $A$9),OBS_District_Flows!$A:$K, 6,FALSE),0) -> 0 | L9: =IFERROR(VLOOKUP(CONCATENATE($A$15,"-",$A$12, "-", $D9, "-", L$3, "-", $A$9),OBS_District_Flows!$A:$K, 6,FALSE),0) -> 0 | ... AL9: =IFERROR(VLOOKUP(CONCATENATE($A$15,"-",$A$12, "-", $D9, "-", AL$3, "-", $A$9),OBS_District_Flows!$A:$K, 6,FALSE),0) -> 0 | AM9: =SUM(E9:AL9) -> 0 | AP9: San Mateo and Burlingame | AQ9: =IF($AM9>0,E9/$AM9, "") | AR9: =IF($AM9>0,F9/$AM9, "") | AS9: =IF($AM9>0,G9/$AM9, "") | AT9: =IF($AM9>0,H9/$AM9, "") | AU9: =IF($AM9>0,I9/$AM9, "") | AV9: =IF($AM9>0,J9/$AM9, "") | AW9: =IF($AM9>0,K9/$AM9, "") | AX9: =IF($AM9>0,L9/$AM9, "") | ... BY9: =IF($AM9>0,AM9/$AM9, "") | CB9: San Mateo and Burlingame | CC9: =IF(E$38>0, E9/E$38, "") | CD9: =IF(F$38>0, F9/F$38, "") | CE9: =IF(G$38>0, G9/G$38, "") | CF9: =IF(H$38>0, H9/H$38, "") | CG9: =IF(I$38>0, I9/I$38, "") | CH9: =IF(J$38>0, J9/J$38, "") | CI9: =IF(K$38>0, K9/K$38, "") | CJ9: =IF(L$38>0, L9/L$38, "") | ... DK9: =IF(AM$38>0, AM9/AM$38, "")
D10: Redwood City and Menlo Park | E10: =IFERROR(VLOOKUP(CONCATENATE($A$15,"-",$A$12, "-", $D10, "-", E$3, "-", $A$9),OBS_District_Flows!$A:$K, 6,FALSE),0) -> 0 | F10: =IFERROR(VLOOKUP(CONCATENATE($A$15,"-",$A$12, "-", $D10, "-", F$3, "-", $A$9),OBS_District_Flows!$A:$K, 6,FALSE),0) -> 0 | G10: =IFERROR(VLOOKUP(CONCATENATE($A$15,"-",$A$12, "-", $D10, "-", G$3, "-", $A$9),OBS_District_Flows!$A:$K, 6,FALSE),0) -> 0 | H10: =IFERROR(VLOOKUP(CONCATENATE($A$15,"-",$A$12, "-", $D10, "-", H$3, "-", $A$9),OBS_District_Flows!$A:$K, 6,FALSE),0) -> 0 | I10: =IFERROR(VLOOKUP(CONCATENATE($A$15,"-",$A$12, "-", $D10, "-", I$3, "-", $A$9),OBS_District_Flows!$A:$K, 6,FALSE),0) -> 0 | J10: =IFERROR(VLOOKUP(CONCATENATE($A$15,"-",$A$12, "-", $D10, "-", J$3, "-", $A$9),OBS_District_Flows!$A:$K, 6,FALSE),0) -> 0 | K10: =IFERROR(VLOOKUP(CONCATENATE($A$15,"-",$A$12, "-", $D10, "-", K$3, "-", $A$9),OBS_District_Flows!$A:$K, 6,FALSE),0) -> 0 | L10: =IFERROR(VLOOKUP(CONCATENATE($A$15,"-",$A$12, "-", $D10, "-", L$3, "-", $A$9),OBS_District_Flows!$A:$K, 6,FALSE),0) -> 0 | ... AL10: =IFERROR(VLOOKUP(CONCATENATE($A$15,"-",$A$12, "-", $D10, "-", AL$3, "-", $A$9),OBS_District_Flows!$A:$K, 6,FALSE),0) -> 0 | AM10: =SUM(E10:AL10) -> 0 | AP10: Redwood City and Menlo Park | AQ10: =IF($AM10>0,E10/$AM10, "") | AR10: =IF($AM10>0,F10/$AM10, "") | AS10: =IF($AM10>0,G10/$AM10, "") | AT10: =IF($AM10>0,H10/$AM10, "") | AU10: =IF($AM10>0,I10/$AM10, "") | AV10: =IF($AM10>0,J10/$AM10, "") | AW10: =IF($AM10>0,K10/$AM10, "") | AX10: =IF($AM10>0,L10/$AM10, "") | ... BY10: =IF($AM10>0,AM10/$AM10, "") | CB10: Redwood City and Menlo Park | CC10: =IF(E$38>0, E10/E$38, "") | CD10: =IF(F$38>0, F10/F$38, "") | CE10: =IF(G$38>0, G10/G$38, "") | CF10: =IF(H$38>0, H10/H$38, "") | CG10: =IF(I$38>0, I10/I$38, "") | CH10: =IF(J$38>0, J10/J$38, "") | CI10: =IF(K$38>0, K10/K$38, "") | CJ10: =IF(L$38>0, L10/L$38, "") | ... DK10: =IF(AM$38>0, AM10/AM$38, "")
A11: Select Primary Mode | D11: Palo Alto and Los Altos | E11: =IFERROR(VLOOKUP(CONCATENATE($A$15,"-",$A$12, "-", $D11, "-", E$3, "-", $A$9),OBS_District_Flows!$A:$K, 6,FALSE),0) -> 0 | F11: =IFERROR(VLOOKUP(CONCATENATE($A$15,"-",$A$12, "-", $D11, "-", F$3, "-", $A$9),OBS_District_Flows!$A:$K, 6,FALSE),0) -> 0 | G11: =IFERROR(VLOOKUP(CONCATENATE($A$15,"-",$A$12, "-", $D11, "-", G$3, "-", $A$9),OBS_District_Flows!$A:$K, 6,FALSE),0) -> 0 | H11: =IFERROR(VLOOKUP(CONCATENATE($A$15,"-",$A$12, "-", $D11, "-", H$3, "-", $A$9),OBS_District_Flows!$A:$K, 6,FALSE),0) -> 0 | I11: =IFERROR(VLOOKUP(CONCATENATE($A$15,"-",$A$12, "-", $D11, "-", I$3, "-", $A$9),OBS_District_Flows!$A:$K, 6,FALSE),0) -> 0 | J11: =IFERROR(VLOOKUP(CONCATENATE($A$15,"-",$A$12, "-", $D11, "-", J$3, "-", $A$9),OBS_District_Flows!$A:$K, 6,FALSE),0) -> 0 | K11: =IFERROR(VLOOKUP(CONCATENATE($A$15,"-",$A$12, "-", $D11, "-", K$3, "-", $A$9),OBS_District_Flows!$A:$K, 6,FALSE),0) -> 0 | L11: =IFERROR(VLOOKUP(CONCATENATE($A$15,"-",$A$12, "-", $D11, "-", L$3, "-", $A$9),OBS_District_Flows!$A:$K, 6,FALSE),0) -> 0 | ... AL11: =IFERROR(VLOOKUP(CONCATENATE($A$15,"-",$A$12, "-", $D11, "-", AL$3, "-", $A$9),OBS_District_Flows!$A:$K, 6,FALSE),0) -> 0 | AM11: =SUM(E11:AL11) -> 0 | AP11: Palo Alto and Los Altos | AQ11: =IF($AM11>0,E11/$AM11, "") | AR11: =IF($AM11>0,F11/$AM11, "") | AS11: =IF($AM11>0,G11/$AM11, "") | AT11: =IF($AM11>0,H11/$AM11, "") | AU11: =IF($AM11>0,I11/$AM11, "") | AV11: =IF($AM11>0,J11/$AM11, "") | AW11: =IF($AM11>0,K11/$AM11, "") | AX11: =IF($AM11>0,L11/$AM11, "") | ... BY11: =IF($AM11>0,AM11/$AM11, "") | CB11: Palo Alto and Los Altos | CC11: =IF(E$38>0, E11/E$38, "") | CD11: =IF(F$38>0, F11/F$38, "") | CE11: =IF(G$38>0, G11/G$38, "") | CF11: =IF(H$38>0, H11/H$38, "") | CG11: =IF(I$38>0, I11/I$38, "") | CH11: =IF(J$38>0, J11/J$38, "") | CI11: =IF(K$38>0, K11/K$38, "") | CJ11: =IF(L$38>0, L11/L$38, "") | ... DK11: =IF(AM$38>0, AM11/AM$38, "")
A12: Total | D12: Sunnyvale and Mountain View | E12: =IFERROR(VLOOKUP(CONCATENATE($A$15,"-",$A$12, "-", $D12, "-", E$3, "-", $A$9),OBS_District_Flows!$A:$K, 6,FALSE),0) -> 0 | F12: =IFERROR(VLOOKUP(CONCATENATE($A$15,"-",$A$12, "-", $D12, "-", F$3, "-", $A$9),OBS_District_Flows!$A:$K, 6,FALSE),0) -> 0 | G12: =IFERROR(VLOOKUP(CONCATENATE($A$15,"-",$A$12, "-", $D12, "-", G$3, "-", $A$9),OBS_District_Flows!$A:$K, 6,FALSE),0) -> 0 | H12: =IFERROR(VLOOKUP(CONCATENATE($A$15,"-",$A$12, "-", $D12, "-", H$3, "-", $A$9),OBS_District_Flows!$A:$K, 6,FALSE),0) -> 0 | I12: =IFERROR(VLOOKUP(CONCATENATE($A$15,"-",$A$12, "-", $D12, "-", I$3, "-", $A$9),OBS_District_Flows!$A:$K, 6,FALSE),0) -> 0 | J12: =IFERROR(VLOOKUP(CONCATENATE($A$15,"-",$A$12, "-", $D12, "-", J$3, "-", $A$9),OBS_District_Flows!$A:$K, 6,FALSE),0) -> 0 | K12: =IFERROR(VLOOKUP(CONCATENATE($A$15,"-",$A$12, "-", $D12, "-", K$3, "-", $A$9),OBS_District_Flows!$A:$K, 6,FALSE),0) -> 0 | L12: =IFERROR(VLOOKUP(CONCATENATE($A$15,"-",$A$12, "-", $D12, "-", L$3, "-", $A$9),OBS_District_Flows!$A:$K, 6,FALSE),0) -> 0 | ... AL12: =IFERROR(VLOOKUP(CONCATENATE($A$15,"-",$A$12, "-", $D12, "-", AL$3, "-", $A$9),OBS_District_Flows!$A:$K, 6,FALSE),0) -> 0 | AM12: =SUM(E12:AL12) -> 0 | AP12: Sunnyvale and Mountain View | AQ12: =IF($AM12>0,E12/$AM12, "") | AR12: =IF($AM12>0,F12/$AM12, "") | AS12: =IF($AM12>0,G12/$AM12, "") | AT12: =IF($AM12>0,H12/$AM12, "") | AU12: =IF($AM12>0,I12/$AM12, "") | AV12: =IF($AM12>0,J12/$AM12, "") | AW12: =IF($AM12>0,K12/$AM12, "") | AX12: =IF($AM12>0,L12/$AM12, "") | ... BY12: =IF($AM12>0,AM12/$AM12, "") | CB12: Sunnyvale and Mountain View | CC12: =IF(E$38>0, E12/E$38, "") | CD12: =IF(F$38>0, F12/F$38, "") | CE12: =IF(G$38>0, G12/G$38, "") | CF12: =IF(H$38>0, H12/H$38, "") | CG12: =IF(I$38>0, I12/I$38, "") | CH12: =IF(J$38>0, J12/J$38, "") | CI12: =IF(K$38>0, K12/K$38, "") | CJ12: =IF(L$38>0, L12/L$38, "") | ... DK12: =IF(AM$38>0, AM12/AM$38, "")
D13: Cupertino and Saratoga | E13: =IFERROR(VLOOKUP(CONCATENATE($A$15,"-",$A$12, "-", $D13, "-", E$3, "-", $A$9),OBS_District_Flows!$A:$K, 6,FALSE),0) -> 0 | F13: =IFERROR(VLOOKUP(CONCATENATE($A$15,"-",$A$12, "-", $D13, "-", F$3, "-", $A$9),OBS_District_Flows!$A:$K, 6,FALSE),0) -> 0 | G13: =IFERROR(VLOOKUP(CONCATENATE($A$15,"-",$A$12, "-", $D13, "-", G$3, "-", $A$9),OBS_District_Flows!$A:$K, 6,FALSE),0) -> 0 | H13: =IFERROR(VLOOKUP(CONCATENATE($A$15,"-",$A$12, "-", $D13, "-", H$3, "-", $A$9),OBS_District_Flows!$A:$K, 6,FALSE),0) -> 0 | I13: =IFERROR(VLOOKUP(CONCATENATE($A$15,"-",$A$12, "-", $D13, "-", I$3, "-", $A$9),OBS_District_Flows!$A:$K, 6,FALSE),0) -> 0 | J13: =IFERROR(VLOOKUP(CONCATENATE($A$15,"-",$A$12, "-", $D13, "-", J$3, "-", $A$9),OBS_District_Flows!$A:$K, 6,FALSE),0) -> 0 | K13: =IFERROR(VLOOKUP(CONCATENATE($A$15,"-",$A$12, "-", $D13, "-", K$3, "-", $A$9),OBS_District_Flows!$A:$K, 6,FALSE),0) -> 0 | L13: =IFERROR(VLOOKUP(CONCATENATE($A$15,"-",$A$12, "-", $D13, "-", L$3, "-", $A$9),OBS_District_Flows!$A:$K, 6,FALSE),0) -> 0 | ... AL13: =IFERROR(VLOOKUP(CONCATENATE($A$15,"-",$A$12, "-", $D13, "-", AL$3, "-", $A$9),OBS_District_Flows!$A:$K, 6,FALSE),0) -> 0 | AM13: =SUM(E13:AL13) -> 0 | AP13: Cupertino and Saratoga | AQ13: =IF($AM13>0,E13/$AM13, "") | AR13: =IF($AM13>0,F13/$AM13, "") | AS13: =IF($AM13>0,G13/$AM13, "") | AT13: =IF($AM13>0,H13/$AM13, "") | AU13: =IF($AM13>0,I13/$AM13, "") | AV13: =IF($AM13>0,J13/$AM13, "") | AW13: =IF($AM13>0,K13/$AM13, "") | AX13: =IF($AM13>0,L13/$AM13, "") | ... BY13: =IF($AM13>0,AM13/$AM13, "") | CB13: Cupertino and Saratoga | CC13: =IF(E$38>0, E13/E$38, "") | CD13: =IF(F$38>0, F13/F$38, "") | CE13: =IF(G$38>0, G13/G$38, "") | CF13: =IF(H$38>0, H13/H$38, "") | CG13: =IF(I$38>0, I13/I$38, "") | CH13: =IF(J$38>0, J13/J$38, "") | CI13: =IF(K$38>0, K13/K$38, "") | CJ13: =IF(L$38>0, L13/L$38, "") | ... DK13: =IF(AM$38>0, AM13/AM$38, "")
A14: Select Access Mode | D14: Central San Jose | E14: =IFERROR(VLOOKUP(CONCATENATE($A$15,"-",$A$12, "-", $D14, "-", E$3, "-", $A$9),OBS_District_Flows!$A:$K, 6,FALSE),0) -> 0 | F14: =IFERROR(VLOOKUP(CONCATENATE($A$15,"-",$A$12, "-", $D14, "-", F$3, "-", $A$9),OBS_District_Flows!$A:$K, 6,FALSE),0) -> 0 | G14: =IFERROR(VLOOKUP(CONCATENATE($A$15,"-",$A$12, "-", $D14, "-", G$3, "-", $A$9),OBS_District_Flows!$A:$K, 6,FALSE),0) -> 0 | H14: =IFERROR(VLOOKUP(CONCATENATE($A$15,"-",$A$12, "-", $D14, "-", H$3, "-", $A$9),OBS_District_Flows!$A:$K, 6,FALSE),0) -> 0 | I14: =IFERROR(VLOOKUP(CONCATENATE($A$15,"-",$A$12, "-", $D14, "-", I$3, "-", $A$9),OBS_District_Flows!$A:$K, 6,FALSE),0) -> 0 | J14: =IFERROR(VLOOKUP(CONCATENATE($A$15,"-",$A$12, "-", $D14, "-", J$3, "-", $A$9),OBS_District_Flows!$A:$K, 6,FALSE),0) -> 0 | K14: =IFERROR(VLOOKUP(CONCATENATE($A$15,"-",$A$12, "-", $D14, "-", K$3, "-", $A$9),OBS_District_Flows!$A:$K, 6,FALSE),0) -> 0 | L14: =IFERROR(VLOOKUP(CONCATENATE($A$15,"-",$A$12, "-", $D14, "-", L$3, "-", $A$9),OBS_District_Flows!$A:$K, 6,FALSE),0) -> 0 | ... AL14: =IFERROR(VLOOKUP(CONCATENATE($A$15,"-",$A$12, "-", $D14, "-", AL$3, "-", $A$9),OBS_District_Flows!$A:$K, 6,FALSE),0) -> 0 | AM14: =SUM(E14:AL14) -> 0 | AP14: Central San Jose | AQ14: =IF($AM14>0,E14/$AM14, "") | AR14: =IF($AM14>0,F14/$AM14, "") | AS14: =IF($AM14>0,G14/$AM14, "") | AT14: =IF($AM14>0,H14/$AM14, "") | AU14: =IF($AM14>0,I14/$AM14, "") | AV14: =IF($AM14>0,J14/$AM14, "") | AW14: =IF($AM14>0,K14/$AM14, "") | AX14: =IF($AM14>0,L14/$AM14, "") | ... BY14: =IF($AM14>0,AM14/$AM14, "") | CB14: Central San Jose | CC14: =IF(E$38>0, E14/E$38, "") | CD14: =IF(F$38>0, F14/F$38, "") | CE14: =IF(G$38>0, G14/G$38, "") | CF14: =IF(H$38>0, H14/H$38, "") | CG14: =IF(I$38>0, I14/I$38, "") | CH14: =IF(J$38>0, J14/J$38, "") | CI14: =IF(K$38>0, K14/K$38, "") | CJ14: =IF(L$38>0, L14/L$38, "") | ... DK14: =IF(AM$38>0, AM14/AM$38, "")
A15: Total | D15: Milpitas and East San Jose | E15: =IFERROR(VLOOKUP(CONCATENATE($A$15,"-",$A$12, "-", $D15, "-", E$3, "-", $A$9),OBS_District_Flows!$A:$K, 6,FALSE),0) -> 0 | F15: =IFERROR(VLOOKUP(CONCATENATE($A$15,"-",$A$12, "-", $D15, "-", F$3, "-", $A$9),OBS_District_Flows!$A:$K, 6,FALSE),0) -> 0 | G15: =IFERROR(VLOOKUP(CONCATENATE($A$15,"-",$A$12, "-", $D15, "-", G$3, "-", $A$9),OBS_District_Flows!$A:$K, 6,FALSE),0) -> 0 | H15: =IFERROR(VLOOKUP(CONCATENATE($A$15,"-",$A$12, "-", $D15, "-", H$3, "-", $A$9),OBS_District_Flows!$A:$K, 6,FALSE),0) -> 0 | I15: =IFERROR(VLOOKUP(CONCATENATE($A$15,"-",$A$12, "-", $D15, "-", I$3, "-", $A$9),OBS_District_Flows!$A:$K, 6,FALSE),0) -> 0 | J15: =IFERROR(VLOOKUP(CONCATENATE($A$15,"-",$A$12, "-", $D15, "-", J$3, "-", $A$9),OBS_District_Flows!$A:$K, 6,FALSE),0) -> 0 | K15: =IFERROR(VLOOKUP(CONCATENATE($A$15,"-",$A$12, "-", $D15, "-", K$3, "-", $A$9),OBS_District_Flows!$A:$K, 6,FALSE),0) -> 0 | L15: =IFERROR(VLOOKUP(CONCATENATE($A$15,"-",$A$12, "-", $D15, "-", L$3, "-", $A$9),OBS_District_Flows!$A:$K, 6,FALSE),0) -> 0 | ... AL15: =IFERROR(VLOOKUP(CONCATENATE($A$15,"-",$A$12, "-", $D15, "-", AL$3, "-", $A$9),OBS_District_Flows!$A:$K, 6,FALSE),0) -> 0 | AM15: =SUM(E15:AL15) -> 0 | AP15: Milpitas and East San Jose | AQ15: =IF($AM15>0,E15/$AM15, "") | AR15: =IF($AM15>0,F15/$AM15, "") | AS15: =IF($AM15>0,G15/$AM15, "") | AT15: =IF($AM15>0,H15/$AM15, "") | AU15: =IF($AM15>0,I15/$AM15, "") | AV15: =IF($AM15>0,J15/$AM15, "") | AW15: =IF($AM15>0,K15/$AM15, "") | AX15: =IF($AM15>0,L15/$AM15, "") | ... BY15: =IF($AM15>0,AM15/$AM15, "") | CB15: Milpitas and East San Jose | CC15: =IF(E$38>0, E15/E$38, "") | CD15: =IF(F$38>0, F15/F$38, "") | CE15: =IF(G$38>0, G15/G$38, "") | CF15: =IF(H$38>0, H15/H$38, "") | CG15: =IF(I$38>0, I15/I$38, "") | CH15: =IF(J$38>0, J15/J$38, "") | CI15: =IF(K$38>0, K15/K$38, "") | CJ15: =IF(L$38>0, L15/L$38, "") | ... DK15: =IF(AM$38>0, AM15/AM$38, "")
D16: South San Jose | E16: =IFERROR(VLOOKUP(CONCATENATE($A$15,"-",$A$12, "-", $D16, "-", E$3, "-", $A$9),OBS_District_Flows!$A:$K, 6,FALSE),0) -> 0 | F16: =IFERROR(VLOOKUP(CONCATENATE($A$15,"-",$A$12, "-", $D16, "-", F$3, "-", $A$9),OBS_District_Flows!$A:$K, 6,FALSE),0) -> 0 | G16: =IFERROR(VLOOKUP(CONCATENATE($A$15,"-",$A$12, "-", $D16, "-", G$3, "-", $A$9),OBS_District_Flows!$A:$K, 6,FALSE),0) -> 0 | H16: =IFERROR(VLOOKUP(CONCATENATE($A$15,"-",$A$12, "-", $D16, "-", H$3, "-", $A$9),OBS_District_Flows!$A:$K, 6,FALSE),0) -> 0 | I16: =IFERROR(VLOOKUP(CONCATENATE($A$15,"-",$A$12, "-", $D16, "-", I$3, "-", $A$9),OBS_District_Flows!$A:$K, 6,FALSE),0) -> 0 | J16: =IFERROR(VLOOKUP(CONCATENATE($A$15,"-",$A$12, "-", $D16, "-", J$3, "-", $A$9),OBS_District_Flows!$A:$K, 6,FALSE),0) -> 0 | K16: =IFERROR(VLOOKUP(CONCATENATE($A$15,"-",$A$12, "-", $D16, "-", K$3, "-", $A$9),OBS_District_Flows!$A:$K, 6,FALSE),0) -> 0 | L16: =IFERROR(VLOOKUP(CONCATENATE($A$15,"-",$A$12, "-", $D16, "-", L$3, "-", $A$9),OBS_District_Flows!$A:$K, 6,FALSE),0) -> 0 | ... AL16: =IFERROR(VLOOKUP(CONCATENATE($A$15,"-",$A$12, "-", $D16, "-", AL$3, "-", $A$9),OBS_District_Flows!$A:$K, 6,FALSE),0) -> 0 | AM16: =SUM(E16:AL16) -> 0 | AP16: South San Jose | AQ16: =IF($AM16>0,E16/$AM16, "") | AR16: =IF($AM16>0,F16/$AM16, "") | AS16: =IF($AM16>0,G16/$AM16, "") | AT16: =IF($AM16>0,H16/$AM16, "") | AU16: =IF($AM16>0,I16/$AM16, "") | AV16: =IF($AM16>0,J16/$AM16, "") | AW16: =IF($AM16>0,K16/$AM16, "") | AX16: =IF($AM16>0,L16/$AM16, "") | ... BY16: =IF($AM16>0,AM16/$AM16, "") | CB16: South San Jose | CC16: =IF(E$38>0, E16/E$38, "") | CD16: =IF(F$38>0, F16/F$38, "") | CE16: =IF(G$38>0, G16/G$38, "") | CF16: =IF(H$38>0, H16/H$38, "") | CG16: =IF(I$38>0, I16/I$38, "") | CH16: =IF(J$38>0, J16/J$38, "") | CI16: =IF(K$38>0, K16/K$38, "") | CJ16: =IF(L$38>0, L16/L$38, "") | ... DK16: =IF(AM$38>0, AM16/AM$38, "")
A17: Total Tours | D17: Gilroy and Morgan Hill | E17: =IFERROR(VLOOKUP(CONCATENATE($A$15,"-",$A$12, "-", $D17, "-", E$3, "-", $A$9),OBS_District_Flows!$A:$K, 6,FALSE),0) -> 0 | F17: =IFERROR(VLOOKUP(CONCATENATE($A$15,"-",$A$12, "-", $D17, "-", F$3, "-", $A$9),OBS_District_Flows!$A:$K, 6,FALSE),0) -> 0 | G17: =IFERROR(VLOOKUP(CONCATENATE($A$15,"-",$A$12, "-", $D17, "-", G$3, "-", $A$9),OBS_District_Flows!$A:$K, 6,FALSE),0) -> 0 | H17: =IFERROR(VLOOKUP(CONCATENATE($A$15,"-",$A$12, "-", $D17, "-", H$3, "-", $A$9),OBS_District_Flows!$A:$K, 6,FALSE),0) -> 0 | I17: =IFERROR(VLOOKUP(CONCATENATE($A$15,"-",$A$12, "-", $D17, "-", I$3, "-", $A$9),OBS_District_Flows!$A:$K, 6,FALSE),0) -> 0 | J17: =IFERROR(VLOOKUP(CONCATENATE($A$15,"-",$A$12, "-", $D17, "-", J$3, "-", $A$9),OBS_District_Flows!$A:$K, 6,FALSE),0) -> 0 | K17: =IFERROR(VLOOKUP(CONCATENATE($A$15,"-",$A$12, "-", $D17, "-", K$3, "-", $A$9),OBS_District_Flows!$A:$K, 6,FALSE),0) -> 0 | L17: =IFERROR(VLOOKUP(CONCATENATE($A$15,"-",$A$12, "-", $D17, "-", L$3, "-", $A$9),OBS_District_Flows!$A:$K, 6,FALSE),0) -> 0 | ... AL17: =IFERROR(VLOOKUP(CONCATENATE($A$15,"-",$A$12, "-", $D17, "-", AL$3, "-", $A$9),OBS_District_Flows!$A:$K, 6,FALSE),0) -> 0 | AM17: =SUM(E17:AL17) -> 0 | AP17: Gilroy and Morgan Hill | AQ17: =IF($AM17>0,E17/$AM17, "") | AR17: =IF($AM17>0,F17/$AM17, "") | AS17: =IF($AM17>0,G17/$AM17, "") | AT17: =IF($AM17>0,H17/$AM17, "") | AU17: =IF($AM17>0,I17/$AM17, "") | AV17: =IF($AM17>0,J17/$AM17, "") | AW17: =IF($AM17>0,K17/$AM17, "") | AX17: =IF($AM17>0,L17/$AM17, "") | ... BY17: =IF($AM17>0,AM17/$AM17, "") | CB17: Gilroy and Morgan Hill | CC17: =IF(E$38>0, E17/E$38, "") | CD17: =IF(F$38>0, F17/F$38, "") | CE17: =IF(G$38>0, G17/G$38, "") | CF17: =IF(H$38>0, H17/H$38, "") | CG17: =IF(I$38>0, I17/I$38, "") | CH17: =IF(J$38>0, J17/J$38, "") | CI17: =IF(K$38>0, K17/K$38, "") | CJ17: =IF(L$38>0, L17/L$38, "") | ... DK17: =IF(AM$38>0, AM17/AM$38, "")
A18: =AM38 -> 0 | D18: Livermore and Pleasanton | E18: =IFERROR(VLOOKUP(CONCATENATE($A$15,"-",$A$12, "-", $D18, "-", E$3, "-", $A$9),OBS_District_Flows!$A:$K, 6,FALSE),0) -> 0 | F18: =IFERROR(VLOOKUP(CONCATENATE($A$15,"-",$A$12, "-", $D18, "-", F$3, "-", $A$9),OBS_District_Flows!$A:$K, 6,FALSE),0) -> 0 | G18: =IFERROR(VLOOKUP(CONCATENATE($A$15,"-",$A$12, "-", $D18, "-", G$3, "-", $A$9),OBS_District_Flows!$A:$K, 6,FALSE),0) -> 0 | H18: =IFERROR(VLOOKUP(CONCATENATE($A$15,"-",$A$12, "-", $D18, "-", H$3, "-", $A$9),OBS_District_Flows!$A:$K, 6,FALSE),0) -> 0 | I18: =IFERROR(VLOOKUP(CONCATENATE($A$15,"-",$A$12, "-", $D18, "-", I$3, "-", $A$9),OBS_District_Flows!$A:$K, 6,FALSE),0) -> 0 | J18: =IFERROR(VLOOKUP(CONCATENATE($A$15,"-",$A$12, "-", $D18, "-", J$3, "-", $A$9),OBS_District_Flows!$A:$K, 6,FALSE),0) -> 0 | K18: =IFERROR(VLOOKUP(CONCATENATE($A$15,"-",$A$12, "-", $D18, "-", K$3, "-", $A$9),OBS_District_Flows!$A:$K, 6,FALSE),0) -> 0 | L18: =IFERROR(VLOOKUP(CONCATENATE($A$15,"-",$A$12, "-", $D18, "-", L$3, "-", $A$9),OBS_District_Flows!$A:$K, 6,FALSE),0) -> 0 | ... AL18: =IFERROR(VLOOKUP(CONCATENATE($A$15,"-",$A$12, "-", $D18, "-", AL$3, "-", $A$9),OBS_District_Flows!$A:$K, 6,FALSE),0) -> 0 | AM18: =SUM(E18:AL18) -> 0 | AP18: Livermore and Pleasanton | AQ18: =IF($AM18>0,E18/$AM18, "") | AR18: =IF($AM18>0,F18/$AM18, "") | AS18: =IF($AM18>0,G18/$AM18, "") | AT18: =IF($AM18>0,H18/$AM18, "") | AU18: =IF($AM18>0,I18/$AM18, "") | AV18: =IF($AM18>0,J18/$AM18, "") | AW18: =IF($AM18>0,K18/$AM18, "") | AX18: =IF($AM18>0,L18/$AM18, "") | ... BY18: =IF($AM18>0,AM18/$AM18, "") | CB18: Livermore and Pleasanton | CC18: =IF(E$38>0, E18/E$38, "") | CD18: =IF(F$38>0, F18/F$38, "") | CE18: =IF(G$38>0, G18/G$38, "") | CF18: =IF(H$38>0, H18/H$38, "") | CG18: =IF(I$38>0, I18/I$38, "") | CH18: =IF(J$38>0, J18/J$38, "") | CI18: =IF(K$38>0, K18/K$38, "") | CJ18: =IF(L$38>0, L18/L$38, "") | ... DK18: =IF(AM$38>0, AM18/AM$38, "")
D19: Fremont and Union City | E19: =IFERROR(VLOOKUP(CONCATENATE($A$15,"-",$A$12, "-", $D19, "-", E$3, "-", $A$9),OBS_District_Flows!$A:$K, 6,FALSE),0) -> 0 | F19: =IFERROR(VLOOKUP(CONCATENATE($A$15,"-",$A$12, "-", $D19, "-", F$3, "-", $A$9),OBS_District_Flows!$A:$K, 6,FALSE),0) -> 0 | G19: =IFERROR(VLOOKUP(CONCATENATE($A$15,"-",$A$12, "-", $D19, "-", G$3, "-", $A$9),OBS_District_Flows!$A:$K, 6,FALSE),0) -> 0 | H19: =IFERROR(VLOOKUP(CONCATENATE($A$15,"-",$A$12, "-", $D19, "-", H$3, "-", $A$9),OBS_District_Flows!$A:$K, 6,FALSE),0) -> 0 | I19: =IFERROR(VLOOKUP(CONCATENATE($A$15,"-",$A$12, "-", $D19, "-", I$3, "-", $A$9),OBS_District_Flows!$A:$K, 6,FALSE),0) -> 0 | J19: =IFERROR(VLOOKUP(CONCATENATE($A$15,"-",$A$12, "-", $D19, "-", J$3, "-", $A$9),OBS_District_Flows!$A:$K, 6,FALSE),0) -> 0 | K19: =IFERROR(VLOOKUP(CONCATENATE($A$15,"-",$A$12, "-", $D19, "-", K$3, "-", $A$9),OBS_District_Flows!$A:$K, 6,FALSE),0) -> 0 | L19: =IFERROR(VLOOKUP(CONCATENATE($A$15,"-",$A$12, "-", $D19, "-", L$3, "-", $A$9),OBS_District_Flows!$A:$K, 6,FALSE),0) -> 0 | ... AL19: =IFERROR(VLOOKUP(CONCATENATE($A$15,"-",$A$12, "-", $D19, "-", AL$3, "-", $A$9),OBS_District_Flows!$A:$K, 6,FALSE),0) -> 0 | AM19: =SUM(E19:AL19) -> 0 | AP19: Fremont and Union City | AQ19: =IF($AM19>0,E19/$AM19, "") | AR19: =IF($AM19>0,F19/$AM19, "") | AS19: =IF($AM19>0,G19/$AM19, "") | AT19: =IF($AM19>0,H19/$AM19, "") | AU19: =IF($AM19>0,I19/$AM19, "") | AV19: =IF($AM19>0,J19/$AM19, "") | AW19: =IF($AM19>0,K19/$AM19, "") | AX19: =IF($AM19>0,L19/$AM19, "") | ... BY19: =IF($AM19>0,AM19/$AM19, "") | CB19: Fremont and Union City | CC19: =IF(E$38>0, E19/E$38, "") | CD19: =IF(F$38>0, F19/F$38, "") | CE19: =IF(G$38>0, G19/G$38, "") | CF19: =IF(H$38>0, H19/H$38, "") | CG19: =IF(I$38>0, I19/I$38, "") | CH19: =IF(J$38>0, J19/J$38, "") | CI19: =IF(K$38>0, K19/K$38, "") | CJ19: =IF(L$38>0, L19/L$38, "") | ... DK19: =IF(AM$38>0, AM19/AM$38, "")
A20: Select View | D20: Hayward and San Leandro | E20: =IFERROR(VLOOKUP(CONCATENATE($A$15,"-",$A$12, "-", $D20, "-", E$3, "-", $A$9),OBS_District_Flows!$A:$K, 6,FALSE),0) -> 0 | F20: =IFERROR(VLOOKUP(CONCATENATE($A$15,"-",$A$12, "-", $D20, "-", F$3, "-", $A$9),OBS_District_Flows!$A:$K, 6,FALSE),0) -> 0 | G20: =IFERROR(VLOOKUP(CONCATENATE($A$15,"-",$A$12, "-", $D20, "-", G$3, "-", $A$9),OBS_District_Flows!$A:$K, 6,FALSE),0) -> 0 | H20: =IFERROR(VLOOKUP(CONCATENATE($A$15,"-",$A$12, "-", $D20, "-", H$3, "-", $A$9),OBS_District_Flows!$A:$K, 6,FALSE),0) -> 0 | I20: =IFERROR(VLOOKUP(CONCATENATE($A$15,"-",$A$12, "-", $D20, "-", I$3, "-", $A$9),OBS_District_Flows!$A:$K, 6,FALSE),0) -> 0 | J20: =IFERROR(VLOOKUP(CONCATENATE($A$15,"-",$A$12, "-", $D20, "-", J$3, "-", $A$9),OBS_District_Flows!$A:$K, 6,FALSE),0) -> 0 | K20: =IFERROR(VLOOKUP(CONCATENATE($A$15,"-",$A$12, "-", $D20, "-", K$3, "-", $A$9),OBS_District_Flows!$A:$K, 6,FALSE),0) -> 0 | L20: =IFERROR(VLOOKUP(CONCATENATE($A$15,"-",$A$12, "-", $D20, "-", L$3, "-", $A$9),OBS_District_Flows!$A:$K, 6,FALSE),0) -> 0 | ... AL20: =IFERROR(VLOOKUP(CONCATENATE($A$15,"-",$A$12, "-", $D20, "-", AL$3, "-", $A$9),OBS_District_Flows!$A:$K, 6,FALSE),0) -> 0 | AM20: =SUM(E20:AL20) -> 0 | AP20: Hayward and San Leandro | AQ20: =IF($AM20>0,E20/$AM20, "") | AR20: =IF($AM20>0,F20/$AM20, "") | AS20: =IF($AM20>0,G20/$AM20, "") | AT20: =IF($AM20>0,H20/$AM20, "") | AU20: =IF($AM20>0,I20/$AM20, "") | AV20: =IF($AM20>0,J20/$AM20, "") | AW20: =IF($AM20>0,K20/$AM20, "") | AX20: =IF($AM20>0,L20/$AM20, "") | ... BY20: =IF($AM20>0,AM20/$AM20, "") | CB20: Hayward and San Leandro | CC20: =IF(E$38>0, E20/E$38, "") | CD20: =IF(F$38>0, F20/F$38, "") | CE20: =IF(G$38>0, G20/G$38, "") | CF20: =IF(H$38>0, H20/H$38, "") | CG20: =IF(I$38>0, I20/I$38, "") | CH20: =IF(J$38>0, J20/J$38, "") | CI20: =IF(K$38>0, K20/K$38, "") | CJ20: =IF(L$38>0, L20/L$38, "") | ... DK20: =IF(AM$38>0, AM20/AM$38, "")
A21: Counts | D21: Oakland and Alameda | E21: =IFERROR(VLOOKUP(CONCATENATE($A$15,"-",$A$12, "-", $D21, "-", E$3, "-", $A$9),OBS_District_Flows!$A:$K, 6,FALSE),0) -> 0 | F21: =IFERROR(VLOOKUP(CONCATENATE($A$15,"-",$A$12, "-", $D21, "-", F$3, "-", $A$9),OBS_District_Flows!$A:$K, 6,FALSE),0) -> 0 | G21: =IFERROR(VLOOKUP(CONCATENATE($A$15,"-",$A$12, "-", $D21, "-", G$3, "-", $A$9),OBS_District_Flows!$A:$K, 6,FALSE),0) -> 0 | H21: =IFERROR(VLOOKUP(CONCATENATE($A$15,"-",$A$12, "-", $D21, "-", H$3, "-", $A$9),OBS_District_Flows!$A:$K, 6,FALSE),0) -> 0 | I21: =IFERROR(VLOOKUP(CONCATENATE($A$15,"-",$A$12, "-", $D21, "-", I$3, "-", $A$9),OBS_District_Flows!$A:$K, 6,FALSE),0) -> 0 | J21: =IFERROR(VLOOKUP(CONCATENATE($A$15,"-",$A$12, "-", $D21, "-", J$3, "-", $A$9),OBS_District_Flows!$A:$K, 6,FALSE),0) -> 0 | K21: =IFERROR(VLOOKUP(CONCATENATE($A$15,"-",$A$12, "-", $D21, "-", K$3, "-", $A$9),OBS_District_Flows!$A:$K, 6,FALSE),0) -> 0 | L21: =IFERROR(VLOOKUP(CONCATENATE($A$15,"-",$A$12, "-", $D21, "-", L$3, "-", $A$9),OBS_District_Flows!$A:$K, 6,FALSE),0) -> 0 | ... AL21: =IFERROR(VLOOKUP(CONCATENATE($A$15,"-",$A$12, "-", $D21, "-", AL$3, "-", $A$9),OBS_District_Flows!$A:$K, 6,FALSE),0) -> 0 | AM21: =SUM(E21:AL21) -> 0 | AP21: Oakland and Alameda | AQ21: =IF($AM21>0,E21/$AM21, "") | AR21: =IF($AM21>0,F21/$AM21, "") | AS21: =IF($AM21>0,G21/$AM21, "") | AT21: =IF($AM21>0,H21/$AM21, "") | AU21: =IF($AM21>0,I21/$AM21, "") | AV21: =IF($AM21>0,J21/$AM21, "") | AW21: =IF($AM21>0,K21/$AM21, "") | AX21: =IF($AM21>0,L21/$AM21, "") | ... BY21: =IF($AM21>0,AM21/$AM21, "") | CB21: Oakland and Alameda | CC21: =IF(E$38>0, E21/E$38, "") | CD21: =IF(F$38>0, F21/F$38, "") | CE21: =IF(G$38>0, G21/G$38, "") | CF21: =IF(H$38>0, H21/H$38, "") | CG21: =IF(I$38>0, I21/I$38, "") | CH21: =IF(J$38>0, J21/J$38, "") | CI21: =IF(K$38>0, K21/K$38, "") | CJ21: =IF(L$38>0, L21/L$38, "") | ... DK21: =IF(AM$38>0, AM21/AM$38, "")
A22: Row Percent | D22: Berkeley and Albany | E22: =IFERROR(VLOOKUP(CONCATENATE($A$15,"-",$A$12, "-", $D22, "-", E$3, "-", $A$9),OBS_District_Flows!$A:$K, 6,FALSE),0) -> 0 | F22: =IFERROR(VLOOKUP(CONCATENATE($A$15,"-",$A$12, "-", $D22, "-", F$3, "-", $A$9),OBS_District_Flows!$A:$K, 6,FALSE),0) -> 0 | G22: =IFERROR(VLOOKUP(CONCATENATE($A$15,"-",$A$12, "-", $D22, "-", G$3, "-", $A$9),OBS_District_Flows!$A:$K, 6,FALSE),0) -> 0 | H22: =IFERROR(VLOOKUP(CONCATENATE($A$15,"-",$A$12, "-", $D22, "-", H$3, "-", $A$9),OBS_District_Flows!$A:$K, 6,FALSE),0) -> 0 | I22: =IFERROR(VLOOKUP(CONCATENATE($A$15,"-",$A$12, "-", $D22, "-", I$3, "-", $A$9),OBS_District_Flows!$A:$K, 6,FALSE),0) -> 0 | J22: =IFERROR(VLOOKUP(CONCATENATE($A$15,"-",$A$12, "-", $D22, "-", J$3, "-", $A$9),OBS_District_Flows!$A:$K, 6,FALSE),0) -> 0 | K22: =IFERROR(VLOOKUP(CONCATENATE($A$15,"-",$A$12, "-", $D22, "-", K$3, "-", $A$9),OBS_District_Flows!$A:$K, 6,FALSE),0) -> 0 | L22: =IFERROR(VLOOKUP(CONCATENATE($A$15,"-",$A$12, "-", $D22, "-", L$3, "-", $A$9),OBS_District_Flows!$A:$K, 6,FALSE),0) -> 0 | ... AL22: =IFERROR(VLOOKUP(CONCATENATE($A$15,"-",$A$12, "-", $D22, "-", AL$3, "-", $A$9),OBS_District_Flows!$A:$K, 6,FALSE),0) -> 0 | AM22: =SUM(E22:AL22) -> 0 | AP22: Berkeley and Albany | AQ22: =IF($AM22>0,E22/$AM22, "") | AR22: =IF($AM22>0,F22/$AM22, "") | AS22: =IF($AM22>0,G22/$AM22, "") | AT22: =IF($AM22>0,H22/$AM22, "") | AU22: =IF($AM22>0,I22/$AM22, "") | AV22: =IF($AM22>0,J22/$AM22, "") | AW22: =IF($AM22>0,K22/$AM22, "") | AX22: =IF($AM22>0,L22/$AM22, "") | ... BY22: =IF($AM22>0,AM22/$AM22, "") | CB22: Berkeley and Albany | CC22: =IF(E$38>0, E22/E$38, "") | CD22: =IF(F$38>0, F22/F$38, "") | CE22: =IF(G$38>0, G22/G$38, "") | CF22: =IF(H$38>0, H22/H$38, "") | CG22: =IF(I$38>0, I22/I$38, "") | CH22: =IF(J$38>0, J22/J$38, "") | CI22: =IF(K$38>0, K22/K$38, "") | CJ22: =IF(L$38>0, L22/L$38, "") | ... DK22: =IF(AM$38>0, AM22/AM$38, "")
A23: Column Percent | D23: Richmond and El Cerrito | E23: =IFERROR(VLOOKUP(CONCATENATE($A$15,"-",$A$12, "-", $D23, "-", E$3, "-", $A$9),OBS_District_Flows!$A:$K, 6,FALSE),0) -> 0 | F23: =IFERROR(VLOOKUP(CONCATENATE($A$15,"-",$A$12, "-", $D23, "-", F$3, "-", $A$9),OBS_District_Flows!$A:$K, 6,FALSE),0) -> 0 | G23: =IFERROR(VLOOKUP(CONCATENATE($A$15,"-",$A$12, "-", $D23, "-", G$3, "-", $A$9),OBS_District_Flows!$A:$K, 6,FALSE),0) -> 0 | H23: =IFERROR(VLOOKUP(CONCATENATE($A$15,"-",$A$12, "-", $D23, "-", H$3, "-", $A$9),OBS_District_Flows!$A:$K, 6,FALSE),0) -> 0 | I23: =IFERROR(VLOOKUP(CONCATENATE($A$15,"-",$A$12, "-", $D23, "-", I$3, "-", $A$9),OBS_District_Flows!$A:$K, 6,FALSE),0) -> 0 | J23: =IFERROR(VLOOKUP(CONCATENATE($A$15,"-",$A$12, "-", $D23, "-", J$3, "-", $A$9),OBS_District_Flows!$A:$K, 6,FALSE),0) -> 0 | K23: =IFERROR(VLOOKUP(CONCATENATE($A$15,"-",$A$12, "-", $D23, "-", K$3, "-", $A$9),OBS_District_Flows!$A:$K, 6,FALSE),0) -> 0 | L23: =IFERROR(VLOOKUP(CONCATENATE($A$15,"-",$A$12, "-", $D23, "-", L$3, "-", $A$9),OBS_District_Flows!$A:$K, 6,FALSE),0) -> 0 | ... AL23: =IFERROR(VLOOKUP(CONCATENATE($A$15,"-",$A$12, "-", $D23, "-", AL$3, "-", $A$9),OBS_District_Flows!$A:$K, 6,FALSE),0) -> 0 | AM23: =SUM(E23:AL23) -> 0 | AP23: Richmond and El Cerrito | AQ23: =IF($AM23>0,E23/$AM23, "") | AR23: =IF($AM23>0,F23/$AM23, "") | AS23: =IF($AM23>0,G23/$AM23, "") | AT23: =IF($AM23>0,H23/$AM23, "") | AU23: =IF($AM23>0,I23/$AM23, "") | AV23: =IF($AM23>0,J23/$AM23, "") | AW23: =IF($AM23>0,K23/$AM23, "") | AX23: =IF($AM23>0,L23/$AM23, "") | ... BY23: =IF($AM23>0,AM23/$AM23, "") | CB23: Richmond and El Cerrito | CC23: =IF(E$38>0, E23/E$38, "") | CD23: =IF(F$38>0, F23/F$38, "") | CE23: =IF(G$38>0, G23/G$38, "") | CF23: =IF(H$38>0, H23/H$38, "") | CG23: =IF(I$38>0, I23/I$38, "") | CH23: =IF(J$38>0, J23/J$38, "") | CI23: =IF(K$38>0, K23/K$38, "") | CJ23: =IF(L$38>0, L23/L$38, "") | ... DK23: =IF(AM$38>0, AM23/AM$38, "")
D24: Concord and Martinez | E24: =IFERROR(VLOOKUP(CONCATENATE($A$15,"-",$A$12, "-", $D24, "-", E$3, "-", $A$9),OBS_District_Flows!$A:$K, 6,FALSE),0) -> 0 | F24: =IFERROR(VLOOKUP(CONCATENATE($A$15,"-",$A$12, "-", $D24, "-", F$3, "-", $A$9),OBS_District_Flows!$A:$K, 6,FALSE),0) -> 0 | G24: =IFERROR(VLOOKUP(CONCATENATE($A$15,"-",$A$12, "-", $D24, "-", G$3, "-", $A$9),OBS_District_Flows!$A:$K, 6,FALSE),0) -> 0 | H24: =IFERROR(VLOOKUP(CONCATENATE($A$15,"-",$A$12, "-", $D24, "-", H$3, "-", $A$9),OBS_District_Flows!$A:$K, 6,FALSE),0) -> 0 | I24: =IFERROR(VLOOKUP(CONCATENATE($A$15,"-",$A$12, "-", $D24, "-", I$3, "-", $A$9),OBS_District_Flows!$A:$K, 6,FALSE),0) -> 0 | J24: =IFERROR(VLOOKUP(CONCATENATE($A$15,"-",$A$12, "-", $D24, "-", J$3, "-", $A$9),OBS_District_Flows!$A:$K, 6,FALSE),0) -> 0 | K24: =IFERROR(VLOOKUP(CONCATENATE($A$15,"-",$A$12, "-", $D24, "-", K$3, "-", $A$9),OBS_District_Flows!$A:$K, 6,FALSE),0) -> 0 | L24: =IFERROR(VLOOKUP(CONCATENATE($A$15,"-",$A$12, "-", $D24, "-", L$3, "-", $A$9),OBS_District_Flows!$A:$K, 6,FALSE),0) -> 0 | ... AL24: =IFERROR(VLOOKUP(CONCATENATE($A$15,"-",$A$12, "-", $D24, "-", AL$3, "-", $A$9),OBS_District_Flows!$A:$K, 6,FALSE),0) -> 0 | AM24: =SUM(E24:AL24) -> 0 | AP24: Concord and Martinez | AQ24: =IF($AM24>0,E24/$AM24, "") | AR24: =IF($AM24>0,F24/$AM24, "") | AS24: =IF($AM24>0,G24/$AM24, "") | AT24: =IF($AM24>0,H24/$AM24, "") | AU24: =IF($AM24>0,I24/$AM24, "") | AV24: =IF($AM24>0,J24/$AM24, "") | AW24: =IF($AM24>0,K24/$AM24, "") | AX24: =IF($AM24>0,L24/$AM24, "") | ... BY24: =IF($AM24>0,AM24/$AM24, "") | CB24: Concord and Martinez | CC24: =IF(E$38>0, E24/E$38, "") | CD24: =IF(F$38>0, F24/F$38, "") | CE24: =IF(G$38>0, G24/G$38, "") | CF24: =IF(H$38>0, H24/H$38, "") | CG24: =IF(I$38>0, I24/I$38, "") | CH24: =IF(J$38>0, J24/J$38, "") | CI24: =IF(K$38>0, K24/K$38, "") | CJ24: =IF(L$38>0, L24/L$38, "") | ... DK24: =IF(AM$38>0, AM24/AM$38, "")
D25: Walnut Creek | E25: =IFERROR(VLOOKUP(CONCATENATE($A$15,"-",$A$12, "-", $D25, "-", E$3, "-", $A$9),OBS_District_Flows!$A:$K, 6,FALSE),0) -> 0 | F25: =IFERROR(VLOOKUP(CONCATENATE($A$15,"-",$A$12, "-", $D25, "-", F$3, "-", $A$9),OBS_District_Flows!$A:$K, 6,FALSE),0) -> 0 | G25: =IFERROR(VLOOKUP(CONCATENATE($A$15,"-",$A$12, "-", $D25, "-", G$3, "-", $A$9),OBS_District_Flows!$A:$K, 6,FALSE),0) -> 0 | H25: =IFERROR(VLOOKUP(CONCATENATE($A$15,"-",$A$12, "-", $D25, "-", H$3, "-", $A$9),OBS_District_Flows!$A:$K, 6,FALSE),0) -> 0 | I25: =IFERROR(VLOOKUP(CONCATENATE($A$15,"-",$A$12, "-", $D25, "-", I$3, "-", $A$9),OBS_District_Flows!$A:$K, 6,FALSE),0) -> 0 | J25: =IFERROR(VLOOKUP(CONCATENATE($A$15,"-",$A$12, "-", $D25, "-", J$3, "-", $A$9),OBS_District_Flows!$A:$K, 6,FALSE),0) -> 0 | K25: =IFERROR(VLOOKUP(CONCATENATE($A$15,"-",$A$12, "-", $D25, "-", K$3, "-", $A$9),OBS_District_Flows!$A:$K, 6,FALSE),0) -> 0 | L25: =IFERROR(VLOOKUP(CONCATENATE($A$15,"-",$A$12, "-", $D25, "-", L$3, "-", $A$9),OBS_District_Flows!$A:$K, 6,FALSE),0) -> 0 | ... AL25: =IFERROR(VLOOKUP(CONCATENATE($A$15,"-",$A$12, "-", $D25, "-", AL$3, "-", $A$9),OBS_District_Flows!$A:$K, 6,FALSE),0) -> 0 | AM25: =SUM(E25:AL25) -> 0 | AP25: Walnut Creek | AQ25: =IF($AM25>0,E25/$AM25, "") | AR25: =IF($AM25>0,F25/$AM25, "") | AS25: =IF($AM25>0,G25/$AM25, "") | AT25: =IF($AM25>0,H25/$AM25, "") | AU25: =IF($AM25>0,I25/$AM25, "") | AV25: =IF($AM25>0,J25/$AM25, "") | AW25: =IF($AM25>0,K25/$AM25, "") | AX25: =IF($AM25>0,L25/$AM25, "") | ... BY25: =IF($AM25>0,AM25/$AM25, "") | CB25: Walnut Creek | CC25: =IF(E$38>0, E25/E$38, "") | CD25: =IF(F$38>0, F25/F$38, "") | CE25: =IF(G$38>0, G25/G$38, "") | CF25: =IF(H$38>0, H25/H$38, "") | CG25: =IF(I$38>0, I25/I$38, "") | CH25: =IF(J$38>0, J25/J$38, "") | CI25: =IF(K$38>0, K25/K$38, "") | CJ25: =IF(L$38>0, L25/L$38, "") | ... DK25: =IF(AM$38>0, AM25/AM$38, "")
A26: few tours with missing | D26: Danville and San Ramon | E26: =IFERROR(VLOOKUP(CONCATENATE($A$15,"-",$A$12, "-", $D26, "-", E$3, "-", $A$9),OBS_District_Flows!$A:$K, 6,FALSE),0) -> 0 | F26: =IFERROR(VLOOKUP(CONCATENATE($A$15,"-",$A$12, "-", $D26, "-", F$3, "-", $A$9),OBS_District_Flows!$A:$K, 6,FALSE),0) -> 0 | G26: =IFERROR(VLOOKUP(CONCATENATE($A$15,"-",$A$12, "-", $D26, "-", G$3, "-", $A$9),OBS_District_Flows!$A:$K, 6,FALSE),0) -> 0 | H26: =IFERROR(VLOOKUP(CONCATENATE($A$15,"-",$A$12, "-", $D26, "-", H$3, "-", $A$9),OBS_District_Flows!$A:$K, 6,FALSE),0) -> 0 | I26: =IFERROR(VLOOKUP(CONCATENATE($A$15,"-",$A$12, "-", $D26, "-", I$3, "-", $A$9),OBS_District_Flows!$A:$K, 6,FALSE),0) -> 0 | J26: =IFERROR(VLOOKUP(CONCATENATE($A$15,"-",$A$12, "-", $D26, "-", J$3, "-", $A$9),OBS_District_Flows!$A:$K, 6,FALSE),0) -> 0 | K26: =IFERROR(VLOOKUP(CONCATENATE($A$15,"-",$A$12, "-", $D26, "-", K$3, "-", $A$9),OBS_District_Flows!$A:$K, 6,FALSE),0) -> 0 | L26: =IFERROR(VLOOKUP(CONCATENATE($A$15,"-",$A$12, "-", $D26, "-", L$3, "-", $A$9),OBS_District_Flows!$A:$K, 6,FALSE),0) -> 0 | ... AL26: =IFERROR(VLOOKUP(CONCATENATE($A$15,"-",$A$12, "-", $D26, "-", AL$3, "-", $A$9),OBS_District_Flows!$A:$K, 6,FALSE),0) -> 0 | AM26: =SUM(E26:AL26) -> 0 | AP26: Danville and San Ramon | AQ26: =IF($AM26>0,E26/$AM26, "") | AR26: =IF($AM26>0,F26/$AM26, "") | AS26: =IF($AM26>0,G26/$AM26, "") | AT26: =IF($AM26>0,H26/$AM26, "") | AU26: =IF($AM26>0,I26/$AM26, "") | AV26: =IF($AM26>0,J26/$AM26, "") | AW26: =IF($AM26>0,K26/$AM26, "") | AX26: =IF($AM26>0,L26/$AM26, "") | ... BY26: =IF($AM26>0,AM26/$AM26, "") | CB26: Danville and San Ramon | CC26: =IF(E$38>0, E26/E$38, "") | CD26: =IF(F$38>0, F26/F$38, "") | CE26: =IF(G$38>0, G26/G$38, "") | CF26: =IF(H$38>0, H26/H$38, "") | CG26: =IF(I$38>0, I26/I$38, "") | CH26: =IF(J$38>0, J26/J$38, "") | CI26: =IF(K$38>0, K26/K$38, "") | CJ26: =IF(L$38>0, L26/L$38, "") | ... DK26: =IF(AM$38>0, AM26/AM$38, "")
A27: location info not | D27: Antioch and Pittsburg | E27: =IFERROR(VLOOKUP(CONCATENATE($A$15,"-",$A$12, "-", $D27, "-", E$3, "-", $A$9),OBS_District_Flows!$A:$K, 6,FALSE),0) -> 0 | F27: =IFERROR(VLOOKUP(CONCATENATE($A$15,"-",$A$12, "-", $D27, "-", F$3, "-", $A$9),OBS_District_Flows!$A:$K, 6,FALSE),0) -> 0 | G27: =IFERROR(VLOOKUP(CONCATENATE($A$15,"-",$A$12, "-", $D27, "-", G$3, "-", $A$9),OBS_District_Flows!$A:$K, 6,FALSE),0) -> 0 | H27: =IFERROR(VLOOKUP(CONCATENATE($A$15,"-",$A$12, "-", $D27, "-", H$3, "-", $A$9),OBS_District_Flows!$A:$K, 6,FALSE),0) -> 0 | I27: =IFERROR(VLOOKUP(CONCATENATE($A$15,"-",$A$12, "-", $D27, "-", I$3, "-", $A$9),OBS_District_Flows!$A:$K, 6,FALSE),0) -> 0 | J27: =IFERROR(VLOOKUP(CONCATENATE($A$15,"-",$A$12, "-", $D27, "-", J$3, "-", $A$9),OBS_District_Flows!$A:$K, 6,FALSE),0) -> 0 | K27: =IFERROR(VLOOKUP(CONCATENATE($A$15,"-",$A$12, "-", $D27, "-", K$3, "-", $A$9),OBS_District_Flows!$A:$K, 6,FALSE),0) -> 0 | L27: =IFERROR(VLOOKUP(CONCATENATE($A$15,"-",$A$12, "-", $D27, "-", L$3, "-", $A$9),OBS_District_Flows!$A:$K, 6,FALSE),0) -> 0 | ... AL27: =IFERROR(VLOOKUP(CONCATENATE($A$15,"-",$A$12, "-", $D27, "-", AL$3, "-", $A$9),OBS_District_Flows!$A:$K, 6,FALSE),0) -> 0 | AM27: =SUM(E27:AL27) -> 0 | AP27: Antioch and Pittsburg | AQ27: =IF($AM27>0,E27/$AM27, "") | AR27: =IF($AM27>0,F27/$AM27, "") | AS27: =IF($AM27>0,G27/$AM27, "") | AT27: =IF($AM27>0,H27/$AM27, "") | AU27: =IF($AM27>0,I27/$AM27, "") | AV27: =IF($AM27>0,J27/$AM27, "") | AW27: =IF($AM27>0,K27/$AM27, "") | AX27: =IF($AM27>0,L27/$AM27, "") | ... BY27: =IF($AM27>0,AM27/$AM27, "") | CB27: Antioch and Pittsburg | CC27: =IF(E$38>0, E27/E$38, "") | CD27: =IF(F$38>0, F27/F$38, "") | CE27: =IF(G$38>0, G27/G$38, "") | CF27: =IF(H$38>0, H27/H$38, "") | CG27: =IF(I$38>0, I27/I$38, "") | CH27: =IF(J$38>0, J27/J$38, "") | CI27: =IF(K$38>0, K27/K$38, "") | CJ27: =IF(L$38>0, L27/L$38, "") | ... DK27: =IF(AM$38>0, AM27/AM$38, "")
A28: included | D28: Vallejo and Benicia | E28: =IFERROR(VLOOKUP(CONCATENATE($A$15,"-",$A$12, "-", $D28, "-", E$3, "-", $A$9),OBS_District_Flows!$A:$K, 6,FALSE),0) -> 0 | F28: =IFERROR(VLOOKUP(CONCATENATE($A$15,"-",$A$12, "-", $D28, "-", F$3, "-", $A$9),OBS_District_Flows!$A:$K, 6,FALSE),0) -> 0 | G28: =IFERROR(VLOOKUP(CONCATENATE($A$15,"-",$A$12, "-", $D28, "-", G$3, "-", $A$9),OBS_District_Flows!$A:$K, 6,FALSE),0) -> 0 | H28: =IFERROR(VLOOKUP(CONCATENATE($A$15,"-",$A$12, "-", $D28, "-", H$3, "-", $A$9),OBS_District_Flows!$A:$K, 6,FALSE),0) -> 0 | I28: =IFERROR(VLOOKUP(CONCATENATE($A$15,"-",$A$12, "-", $D28, "-", I$3, "-", $A$9),OBS_District_Flows!$A:$K, 6,FALSE),0) -> 0 | J28: =IFERROR(VLOOKUP(CONCATENATE($A$15,"-",$A$12, "-", $D28, "-", J$3, "-", $A$9),OBS_District_Flows!$A:$K, 6,FALSE),0) -> 0 | K28: =IFERROR(VLOOKUP(CONCATENATE($A$15,"-",$A$12, "-", $D28, "-", K$3, "-", $A$9),OBS_District_Flows!$A:$K, 6,FALSE),0) -> 0 | L28: =IFERROR(VLOOKUP(CONCATENATE($A$15,"-",$A$12, "-", $D28, "-", L$3, "-", $A$9),OBS_District_Flows!$A:$K, 6,FALSE),0) -> 0 | ... AL28: =IFERROR(VLOOKUP(CONCATENATE($A$15,"-",$A$12, "-", $D28, "-", AL$3, "-", $A$9),OBS_District_Flows!$A:$K, 6,FALSE),0) -> 0 | AM28: =SUM(E28:AL28) -> 0 | AP28: Vallejo and Benicia | AQ28: =IF($AM28>0,E28/$AM28, "") | AR28: =IF($AM28>0,F28/$AM28, "") | AS28: =IF($AM28>0,G28/$AM28, "") | AT28: =IF($AM28>0,H28/$AM28, "") | AU28: =IF($AM28>0,I28/$AM28, "") | AV28: =IF($AM28>0,J28/$AM28, "") | AW28: =IF($AM28>0,K28/$AM28, "") | AX28: =IF($AM28>0,L28/$AM28, "") | ... BY28: =IF($AM28>0,AM28/$AM28, "") | CB28: Vallejo and Benicia | CC28: =IF(E$38>0, E28/E$38, "") | CD28: =IF(F$38>0, F28/F$38, "") | CE28: =IF(G$38>0, G28/G$38, "") | CF28: =IF(H$38>0, H28/H$38, "") | CG28: =IF(I$38>0, I28/I$38, "") | CH28: =IF(J$38>0, J28/J$38, "") | CI28: =IF(K$38>0, K28/K$38, "") | CJ28: =IF(L$38>0, L28/L$38, "") | ... DK28: =IF(AM$38>0, AM28/AM$38, "")
D29: Fairfield and Vacaville | E29: =IFERROR(VLOOKUP(CONCATENATE($A$15,"-",$A$12, "-", $D29, "-", E$3, "-", $A$9),OBS_District_Flows!$A:$K, 6,FALSE),0) -> 0 | F29: =IFERROR(VLOOKUP(CONCATENATE($A$15,"-",$A$12, "-", $D29, "-", F$3, "-", $A$9),OBS_District_Flows!$A:$K, 6,FALSE),0) -> 0 | G29: =IFERROR(VLOOKUP(CONCATENATE($A$15,"-",$A$12, "-", $D29, "-", G$3, "-", $A$9),OBS_District_Flows!$A:$K, 6,FALSE),0) -> 0 | H29: =IFERROR(VLOOKUP(CONCATENATE($A$15,"-",$A$12, "-", $D29, "-", H$3, "-", $A$9),OBS_District_Flows!$A:$K, 6,FALSE),0) -> 0 | I29: =IFERROR(VLOOKUP(CONCATENATE($A$15,"-",$A$12, "-", $D29, "-", I$3, "-", $A$9),OBS_District_Flows!$A:$K, 6,FALSE),0) -> 0 | J29: =IFERROR(VLOOKUP(CONCATENATE($A$15,"-",$A$12, "-", $D29, "-", J$3, "-", $A$9),OBS_District_Flows!$A:$K, 6,FALSE),0) -> 0 | K29: =IFERROR(VLOOKUP(CONCATENATE($A$15,"-",$A$12, "-", $D29, "-", K$3, "-", $A$9),OBS_District_Flows!$A:$K, 6,FALSE),0) -> 0 | L29: =IFERROR(VLOOKUP(CONCATENATE($A$15,"-",$A$12, "-", $D29, "-", L$3, "-", $A$9),OBS_District_Flows!$A:$K, 6,FALSE),0) -> 0 | ... AL29: =IFERROR(VLOOKUP(CONCATENATE($A$15,"-",$A$12, "-", $D29, "-", AL$3, "-", $A$9),OBS_District_Flows!$A:$K, 6,FALSE),0) -> 0 | AM29: =SUM(E29:AL29) -> 0 | AP29: Fairfield and Vacaville | AQ29: =IF($AM29>0,E29/$AM29, "") | AR29: =IF($AM29>0,F29/$AM29, "") | AS29: =IF($AM29>0,G29/$AM29, "") | AT29: =IF($AM29>0,H29/$AM29, "") | AU29: =IF($AM29>0,I29/$AM29, "") | AV29: =IF($AM29>0,J29/$AM29, "") | AW29: =IF($AM29>0,K29/$AM29, "") | AX29: =IF($AM29>0,L29/$AM29, "") | ... BY29: =IF($AM29>0,AM29/$AM29, "") | CB29: Fairfield and Vacaville | CC29: =IF(E$38>0, E29/E$38, "") | CD29: =IF(F$38>0, F29/F$38, "") | CE29: =IF(G$38>0, G29/G$38, "") | CF29: =IF(H$38>0, H29/H$38, "") | CG29: =IF(I$38>0, I29/I$38, "") | CH29: =IF(J$38>0, J29/J$38, "") | CI29: =IF(K$38>0, K29/K$38, "") | CJ29: =IF(L$38>0, L29/L$38, "") | ... DK29: =IF(AM$38>0, AM29/AM$38, "")
D30: Napa | E30: =IFERROR(VLOOKUP(CONCATENATE($A$15,"-",$A$12, "-", $D30, "-", E$3, "-", $A$9),OBS_District_Flows!$A:$K, 6,FALSE),0) -> 0 | F30: =IFERROR(VLOOKUP(CONCATENATE($A$15,"-",$A$12, "-", $D30, "-", F$3, "-", $A$9),OBS_District_Flows!$A:$K, 6,FALSE),0) -> 0 | G30: =IFERROR(VLOOKUP(CONCATENATE($A$15,"-",$A$12, "-", $D30, "-", G$3, "-", $A$9),OBS_District_Flows!$A:$K, 6,FALSE),0) -> 0 | H30: =IFERROR(VLOOKUP(CONCATENATE($A$15,"-",$A$12, "-", $D30, "-", H$3, "-", $A$9),OBS_District_Flows!$A:$K, 6,FALSE),0) -> 0 | I30: =IFERROR(VLOOKUP(CONCATENATE($A$15,"-",$A$12, "-", $D30, "-", I$3, "-", $A$9),OBS_District_Flows!$A:$K, 6,FALSE),0) -> 0 | J30: =IFERROR(VLOOKUP(CONCATENATE($A$15,"-",$A$12, "-", $D30, "-", J$3, "-", $A$9),OBS_District_Flows!$A:$K, 6,FALSE),0) -> 0 | K30: =IFERROR(VLOOKUP(CONCATENATE($A$15,"-",$A$12, "-", $D30, "-", K$3, "-", $A$9),OBS_District_Flows!$A:$K, 6,FALSE),0) -> 0 | L30: =IFERROR(VLOOKUP(CONCATENATE($A$15,"-",$A$12, "-", $D30, "-", L$3, "-", $A$9),OBS_District_Flows!$A:$K, 6,FALSE),0) -> 0 | ... AL30: =IFERROR(VLOOKUP(CONCATENATE($A$15,"-",$A$12, "-", $D30, "-", AL$3, "-", $A$9),OBS_District_Flows!$A:$K, 6,FALSE),0) -> 0 | AM30: =SUM(E30:AL30) -> 0 | AP30: Napa | AQ30: =IF($AM30>0,E30/$AM30, "") | AR30: =IF($AM30>0,F30/$AM30, "") | AS30: =IF($AM30>0,G30/$AM30, "") | AT30: =IF($AM30>0,H30/$AM30, "") | AU30: =IF($AM30>0,I30/$AM30, "") | AV30: =IF($AM30>0,J30/$AM30, "") | AW30: =IF($AM30>0,K30/$AM30, "") | AX30: =IF($AM30>0,L30/$AM30, "") | ... BY30: =IF($AM30>0,AM30/$AM30, "") | CB30: Napa | CC30: =IF(E$38>0, E30/E$38, "") | CD30: =IF(F$38>0, F30/F$38, "") | CE30: =IF(G$38>0, G30/G$38, "") | CF30: =IF(H$38>0, H30/H$38, "") | CG30: =IF(I$38>0, I30/I$38, "") | CH30: =IF(J$38>0, J30/J$38, "") | CI30: =IF(K$38>0, K30/K$38, "") | CJ30: =IF(L$38>0, L30/L$38, "") | ... DK30: =IF(AM$38>0, AM30/AM$38, "")
D31: St Helena | E31: =IFERROR(VLOOKUP(CONCATENATE($A$15,"-",$A$12, "-", $D31, "-", E$3, "-", $A$9),OBS_District_Flows!$A:$K, 6,FALSE),0) -> 0 | F31: =IFERROR(VLOOKUP(CONCATENATE($A$15,"-",$A$12, "-", $D31, "-", F$3, "-", $A$9),OBS_District_Flows!$A:$K, 6,FALSE),0) -> 0 | G31: =IFERROR(VLOOKUP(CONCATENATE($A$15,"-",$A$12, "-", $D31, "-", G$3, "-", $A$9),OBS_District_Flows!$A:$K, 6,FALSE),0) -> 0 | H31: =IFERROR(VLOOKUP(CONCATENATE($A$15,"-",$A$12, "-", $D31, "-", H$3, "-", $A$9),OBS_District_Flows!$A:$K, 6,FALSE),0) -> 0 | I31: =IFERROR(VLOOKUP(CONCATENATE($A$15,"-",$A$12, "-", $D31, "-", I$3, "-", $A$9),OBS_District_Flows!$A:$K, 6,FALSE),0) -> 0 | J31: =IFERROR(VLOOKUP(CONCATENATE($A$15,"-",$A$12, "-", $D31, "-", J$3, "-", $A$9),OBS_District_Flows!$A:$K, 6,FALSE),0) -> 0 | K31: =IFERROR(VLOOKUP(CONCATENATE($A$15,"-",$A$12, "-", $D31, "-", K$3, "-", $A$9),OBS_District_Flows!$A:$K, 6,FALSE),0) -> 0 | L31: =IFERROR(VLOOKUP(CONCATENATE($A$15,"-",$A$12, "-", $D31, "-", L$3, "-", $A$9),OBS_District_Flows!$A:$K, 6,FALSE),0) -> 0 | ... AL31: =IFERROR(VLOOKUP(CONCATENATE($A$15,"-",$A$12, "-", $D31, "-", AL$3, "-", $A$9),OBS_District_Flows!$A:$K, 6,FALSE),0) -> 0 | AM31: =SUM(E31:AL31) -> 0 | AP31: St Helena | AQ31: =IF($AM31>0,E31/$AM31, "") | AR31: =IF($AM31>0,F31/$AM31, "") | AS31: =IF($AM31>0,G31/$AM31, "") | AT31: =IF($AM31>0,H31/$AM31, "") | AU31: =IF($AM31>0,I31/$AM31, "") | AV31: =IF($AM31>0,J31/$AM31, "") | AW31: =IF($AM31>0,K31/$AM31, "") | AX31: =IF($AM31>0,L31/$AM31, "") | ... BY31: =IF($AM31>0,AM31/$AM31, "") | CB31: St Helena | CC31: =IF(E$38>0, E31/E$38, "") | CD31: =IF(F$38>0, F31/F$38, "") | CE31: =IF(G$38>0, G31/G$38, "") | CF31: =IF(H$38>0, H31/H$38, "") | CG31: =IF(I$38>0, I31/I$38, "") | CH31: =IF(J$38>0, J31/J$38, "") | CI31: =IF(K$38>0, K31/K$38, "") | CJ31: =IF(L$38>0, L31/L$38, "") | ... DK31: =IF(AM$38>0, AM31/AM$38, "")
