Workbook

Sheet calibration
C2: Bay Area Travel Study 2023 | O2: Model Results | AB2: Model minus Observed
C3: work | D3: university | E3: school | F3: escort | G3: shop | H3: maintenance | I3: eatout | J3: visit | K3: discretionary | L3: atwork | M3: joint | P3: work | Q3: university | R3: school | S3: escort | T3: shop | U3: maintenance | V3: eatout | W3: visit | X3: discretionary | Y3: atwork | Z3: joint | AC3: work | AD3: university | AE3: school | AF3: escort | AG3: shop | AH3: maintenance | AI3: eatout | AJ3: visit | AK3: discretionary | AL3: atwork | AM3: joint
B4: 0 Out | C4: =SUM('BATS 2023'!Q4:Q7) -> 19346 | D4: =SUM('BATS 2023'!R4:R7) -> 440 | E4: =SUM('BATS 2023'!S4:S7) -> 2368 | F4: =SUM('BATS 2023'!T4:T7) -> 11754 | G4: =SUM('BATS 2023'!U4:U7) -> 12910 | H4: =SUM('BATS 2023'!V4:V7) -> 8324 | I4: =SUM('BATS 2023'!W4:W7) -> 9598 | J4: =SUM('BATS 2023'!X4:X7) -> 27932 | ... M4: =SUM('BATS 2023'!AA4:AA7) -> 36074 | O4: 0 Out | P4: =SUM(modeldata!C4:C7) -> 0 | Q4: =SUM(modeldata!D4:D7) -> 0 | R4: =SUM(modeldata!E4:E7) -> 0 | S4: =SUM(modeldata!F4:F7) -> 0 | T4: =SUM(modeldata!G4:G7) -> 0 | U4: =SUM(modeldata!H4:H7) -> 0 | V4: =SUM(modeldata!I4:I7) -> 0 | W4: =SUM(modeldata!J4:J7) -> 0 | ... Z4: =SUM(modeldata!M4:M7) -> 0 | AB4: 0 Out | AC4: =P4-C4 -> -19346 | AD4: =Q4-D4 -> -440 | AE4: =R4-E4 -> -2368 | AF4: =S4-F4 -> -11754 | AG4: =T4-G4 -> -12910 | AH4: =U4-H4 -> -8324 | AI4: =V4-I4 -> -9598 | AJ4: =W4-J4 -> -27932 | ... AM4: =Z4-M4 -> -36074
B5: 1 Out | C5: =SUM('BATS 2023'!Q8:Q11) -> 4680 | D5: =SUM('BATS 2023'!R8:R11) -> 94 | E5: =SUM('BATS 2023'!S8:S11) -> 222 | F5: =SUM('BATS 2023'!T8:T11) -> 896 | G5: =SUM('BATS 2023'!U8:U11) -> 4774 | H5: =SUM('BATS 2023'!V8:V11) -> 1704 | I5: =SUM('BATS 2023'!W8:W11) -> 3174 | J5: =SUM('BATS 2023'!X8:X11) -> 3548 | ... M5: =SUM('BATS 2023'!AA8:AA11) -> 6942 | O5: 1 Out | P5: =SUM(modeldata!C8:C11) -> 0 | Q5: =SUM(modeldata!D8:D11) -> 0 | R5: =SUM(modeldata!E8:E11) -> 0 | S5: =SUM(modeldata!F8:F11) -> 0 | T5: =SUM(modeldata!G8:G11) -> 0 | U5: =SUM(modeldata!H8:H11) -> 0 | V5: =SUM(modeldata!I8:I11) -> 0 | W5: =SUM(modeldata!J8:J11) -> 0 | ... Z5: =SUM(modeldata!M8:M11) -> 0 | AB5: 1 Out | AC5: =P5-C5 -> -4680 | AD5: =Q5-D5 -> -94 | AE5: =R5-E5 -> -222 | AF5: =S5-F5 -> -896 | AG5: =T5-G5 -> -4774 | AH5: =U5-H5 -> -1704 | AI5: =V5-I5 -> -3174 | AJ5: =W5-J5 -> -3548 | ... AM5: =Z5-M5 -> -6942
B6: 2 Out | C6: =SUM('BATS 2023'!Q12:Q15) -> 1862 | D6: =SUM('BATS 2023'!R12:R15) -> 24 | E6: =SUM('BATS 2023'!S12:S15) -> 44 | F6: =SUM('BATS 2023'!T12:T15) -> 228 | G6: =SUM('BATS 2023'!U12:U15) -> 2048 | H6: =SUM('BATS 2023'!V12:V15) -> 598 | I6: =SUM('BATS 2023'!W12:W15) -> 1306 | J6: =SUM('BATS 2023'!X12:X15) -> 1756 | ... M6: =SUM('BATS 2023'!AA12:AA15) -> 2620 | O6: 2 Out | P6: =SUM(modeldata!C12:C15) -> 0 | Q6: =SUM(modeldata!D12:D15) -> 0 | R6: =SUM(modeldata!E12:E15) -> 0 | S6: =SUM(modeldata!F12:F15) -> 0 | T6: =SUM(modeldata!G12:G15) -> 0 | U6: =SUM(modeldata!H12:H15) -> 0 | V6: =SUM(modeldata!I12:I15) -> 0 | W6: =SUM(modeldata!J12:J15) -> 0 | ... Z6: =SUM(modeldata!M12:M15) -> 0 | AB6: 2 Out | AC6: =P6-C6 -> -1862 | AD6: =Q6-D6 -> -24 | AE6: =R6-E6 -> -44 | AF6: =S6-F6 -> -228 | AG6: =T6-G6 -> -2048 | AH6: =U6-H6 -> -598 | AI6: =V6-I6 -> -1306 | AJ6: =W6-J6 -> -1756 | ... AM6: =Z6-M6 -> -2620
B7: 3 Out | C7: =SUM('BATS 2023'!Q16:Q19) -> 1316 | D7: =SUM('BATS 2023'!R16:R19) -> 24 | E7: =SUM('BATS 2023'!S16:S19) -> 16 | F7: =SUM('BATS 2023'!T16:T19) -> 92 | G7: =SUM('BATS 2023'!U16:U19) -> 1648 | H7: =SUM('BATS 2023'!V16:V19) -> 392 | I7: =SUM('BATS 2023'!W16:W19) -> 1266 | J7: =SUM('BATS 2023'!X16:X19) -> 1056 | ... M7: =SUM('BATS 2023'!AA16:AA19) -> 1270 | O7: 3 Out | P7: =SUM(modeldata!C16:C19) -> 0 | Q7: =SUM(modeldata!D16:D19) -> 0 | R7: =SUM(modeldata!E16:E19) -> 0 | S7: =SUM(modeldata!F16:F19) -> 0 | T7: =SUM(modeldata!G16:G19) -> 0 | U7: =SUM(modeldata!H16:H19) -> 0 | V7: =SUM(modeldata!I16:I19) -> 0 | W7: =SUM(modeldata!J16:J19) -> 0 | ... Z7: =SUM(modeldata!M16:M19) -> 0 | AB7: 3 Out | AC7: =P7-C7 -> -1316 | AD7: =Q7-D7 -> -24 | AE7: =R7-E7 -> -16 | AF7: =S7-F7 -> -92 | AG7: =T7-G7 -> -1648 | AH7: =U7-H7 -> -392 | AI7: =V7-I7 -> -1266 | AJ7: =W7-J7 -> -1056 | ... AM7: =Z7-M7 -> -1270
B8: Total | C8: =SUM(C4:C7) -> 27204 | D8: =SUM(D4:D7) -> 582 | E8: =SUM(E4:E7) -> 2650 | F8: =SUM(F4:F7) -> 12970 | G8: =SUM(G4:G7) -> 21380 | H8: =SUM(H4:H7) -> 11018 | I8: =SUM(I4:I7) -> 15344 | J8: =SUM(J4:J7) -> 34292 | ... M8: =SUM(M4:M7) -> 46906 | O8: Total | P8: =SUM(P4:P7) -> 0 | Q8: =SUM(Q4:Q7) -> 0 | R8: =SUM(R4:R7) -> 0 | S8: =SUM(S4:S7) -> 0 | T8: =SUM(T4:T7) -> 0 | U8: =SUM(U4:U7) -> 0 | V8: =SUM(V4:V7) -> 0 | W8: =SUM(W4:W7) -> 0 | ... Z8: =SUM(Z4:Z7) -> 0 | AB8: Total | AC8: =P8-C8 -> -27204 | AD8: =Q8-D8 -> -582 | AE8: =R8-E8 -> -2650 | AF8: =S8-F8 -> -12970 | AG8: =T8-G8 -> -21380 | AH8: =U8-H8 -> -11018 | AI8: =V8-I8 -> -15344 | AJ8: =W8-J8 -> -34292 | ... AM8: =Z8-M8 -> -46906
B10: 0 Ret | C10: =SUM('BATS 2023'!Q4,'BATS 2023'!Q8,'BATS 2023'!Q12,'BATS 2023'!Q16) -> 17838 | D10: =SUM('BATS 2023'!R4,'BATS 2023'!R8,'BATS 2023'!R12,'BATS 2023'!R16) -> 430 | E10: =SUM('BATS 2023'!S4,'BATS 2023'!S8,'BATS 2023'!S12,'BATS 2023'!S16) -> 2102 | F10: =SUM('BATS 2023'!T4,'BATS 2023'!T8,'BATS 2023'!T12,'BATS 2023'!T16) -> 11578 | G10: =SUM('BATS 2023'!U4,'BATS 2023'!U8,'BATS 2023'!U12,'BATS 2023'!U16) -> 15402 | H10: =SUM('BATS 2023'!V4,'BATS 2023'!V8,'BATS 2023'!V12,'BATS 2023'!V16) -> 7714 | I10: =SUM('BATS 2023'!W4,'BATS 2023'!W8,'BATS 2023'!W12,'BATS 2023'!W16) -> 11286 | J10: =SUM('BATS 2023'!X4,'BATS 2023'!X8,'BATS 2023'!X12,'BATS 2023'!X16) -> 29070 | ... M10: =SUM('BATS 2023'!AA4,'BATS 2023'!AA8,'BATS 2023'!AA12,'BATS 2023'!AA16) -> 37348 | O10: 0 Ret | P10: =modeldata!C4+modeldata!C8+modeldata!C12+modeldata!C16 -> 0 | Q10: =modeldata!D4+modeldata!D8+modeldata!D12+modeldata!D16 -> 0 | R10: =modeldata!E4+modeldata!E8+modeldata!E12+modeldata!E16 -> 0 | S10: =modeldata!F4+modeldata!F8+modeldata!F12+modeldata!F16 -> 0 | T10: =modeldata!G4+modeldata!G8+modeldata!G12+modeldata!G16 -> 0 | U10: =modeldata!H4+modeldata!H8+modeldata!H12+modeldata!H16 -> 0 | V10: =modeldata!I4+modeldata!I8+modeldata!I12+modeldata!I16 -> 0 | W10: =modeldata!J4+modeldata!J8+modeldata!J12+modeldata!J16 -> 0 | ... Z10: =modeldata!M4+modeldata!M8+modeldata!M12+modeldata!M16 -> 0 | AB10: 0 Ret | AC10: =P10-C10 -> -17838 | AD10: =Q10-D10 -> -430 | AE10: =R10-E10 -> -2102 | AF10: =S10-F10 -> -11578 | AG10: =T10-G10 -> -15402 | AH10: =U10-H10 -> -7714 | AI10: =V10-I10 -> -11286 | AJ10: =W10-J10 -> -29070 | ... AM10: =Z10-M10 -> -37348
B11: 1 Ret | C11: =SUM('BATS 2023'!Q5,'BATS 2023'!Q9,'BATS 2023'!Q13,'BATS 2023'!Q17) -> 5898 | D11: =SUM('BATS 2023'!R5,'BATS 2023'!R9,'BATS 2023'!R13,'BATS 2023'!R17) -> 110 | E11: =SUM('BATS 2023'!S5,'BATS 2023'!S9,'BATS 2023'!S13,'BATS 2023'!S17) -> 372 | F11: =SUM('BATS 2023'!T5,'BATS 2023'!T9,'BATS 2023'!T13,'BATS 2023'!T17) -> 1192 | G11: =SUM('BATS 2023'!U5,'BATS 2023'!U9,'BATS 2023'!U13,'BATS 2023'!U17) -> 4014 | H11: =SUM('BATS 2023'!V5,'BATS 2023'!V9,'BATS 2023'!V13,'BATS 2023'!V17) -> 2246 | I11: =SUM('BATS 2023'!W5,'BATS 2023'!W9,'BATS 2023'!W13,'BATS 2023'!W17) -> 2636 | J11: =SUM('BATS 2023'!X5,'BATS 2023'!X9,'BATS 2023'!X13,'BATS 2023'!X17) -> 3682 | ... M11: =SUM('BATS 2023'!AA5,'BATS 2023'!AA9,'BATS 2023'!AA13,'BATS 2023'!AA17) -> 7002 | O11: 1 Ret | P11: =modeldata!C5+modeldata!C9+modeldata!C13+modeldata!C17 -> 0 | Q11: =modeldata!D5+modeldata!D9+modeldata!D13+modeldata!D17 -> 0 | R11: =modeldata!E5+modeldata!E9+modeldata!E13+modeldata!E17 -> 0 | S11: =modeldata!F5+modeldata!F9+modeldata!F13+modeldata!F17 -> 0 | T11: =modeldata!G5+modeldata!G9+modeldata!G13+modeldata!G17 -> 0 | U11: =modeldata!H5+modeldata!H9+modeldata!H13+modeldata!H17 -> 0 | V11: =modeldata!I5+modeldata!I9+modeldata!I13+modeldata!I17 -> 0 | W11: =modeldata!J5+modeldata!J9+modeldata!J13+modeldata!J17 -> 0 | ... Z11: =modeldata!M5+modeldata!M9+modeldata!M13+modeldata!M17 -> 0 | AB11: 1 Ret | AC11: =P11-C11 -> -5898 | AD11: =Q11-D11 -> -110 | AE11: =R11-E11 -> -372 | AF11: =S11-F11 -> -1192 | AG11: =T11-G11 -> -4014 | AH11: =U11-H11 -> -2246 | AI11: =V11-I11 -> -2636 | AJ11: =W11-J11 -> -3682 | ... AM11: =Z11-M11 -> -7002
B12: 2 Ret | C12: =SUM('BATS 2023'!Q6,'BATS 2023'!Q10,'BATS 2023'!Q14,'BATS 2023'!Q18) -> 2110 | D12: =SUM('BATS 2023'!R6,'BATS 2023'!R10,'BATS 2023'!R14,'BATS 2023'!R18) -> 34 | E12: =SUM('BATS 2023'!S6,'BATS 2023'!S10,'BATS 2023'!S14,'BATS 2023'!S18) -> 120 | F12: =SUM('BATS 2023'!T6,'BATS 2023'!T10,'BATS 2023'!T14,'BATS 2023'!T18) -> 130 | G12: =SUM('BATS 2023'!U6,'BATS 2023'!U10,'BATS 2023'!U14,'BATS 2023'!U18) -> 1260 | H12: =SUM('BATS 2023'!V6,'BATS 2023'!V10,'BATS 2023'!V14,'BATS 2023'!V18) -> 594 | I12: =SUM('BATS 2023'!W6,'BATS 2023'!W10,'BATS 2023'!W14,'BATS 2023'!W18) -> 800 | J12: =SUM('BATS 2023'!X6,'BATS 2023'!X10,'BATS 2023'!X14,'BATS 2023'!X18) -> 1022 | ... M12: =SUM('BATS 2023'!AA6,'BATS 2023'!AA10,'BATS 2023'!AA14,'BATS 2023'!AA18) -> 1854 | O12: 2 Ret | P12: =modeldata!C6+modeldata!C10+modeldata!C14+modeldata!C18 -> 0 | Q12: =modeldata!D6+modeldata!D10+modeldata!D14+modeldata!D18 -> 0 | R12: =modeldata!E6+modeldata!E10+modeldata!E14+modeldata!E18 -> 0 | S12: =modeldata!F6+modeldata!F10+modeldata!F14+modeldata!F18 -> 0 | T12: =modeldata!G6+modeldata!G10+modeldata!G14+modeldata!G18 -> 0 | U12: =modeldata!H6+modeldata!H10+modeldata!H14+modeldata!H18 -> 0 | V12: =modeldata!I6+modeldata!I10+modeldata!I14+modeldata!I18 -> 0 | W12: =modeldata!J6+modeldata!J10+modeldata!J14+modeldata!J18 -> 0 | ... Z12: =modeldata!M6+modeldata!M10+modeldata!M14+modeldata!M18 -> 0 | AB12: 2 Ret | AC12: =P12-C12 -> -2110 | AD12: =Q12-D12 -> -34 | AE12: =R12-E12 -> -120 | AF12: =S12-F12 -> -130 | AG12: =T12-G12 -> -1260 | AH12: =U12-H12 -> -594 | AI12: =V12-I12 -> -800 | AJ12: =W12-J12 -> -1022 | ... AM12: =Z12-M12 -> -1854
B13: 3 Ret | C13: =SUM('BATS 2023'!Q7,'BATS 2023'!Q11,'BATS 2023'!Q15,'BATS 2023'!Q19) -> 1358 | D13: =SUM('BATS 2023'!R7,'BATS 2023'!R11,'BATS 2023'!R15,'BATS 2023'!R19) -> 8 | E13: =SUM('BATS 2023'!S7,'BATS 2023'!S11,'BATS 2023'!S15,'BATS 2023'!S19) -> 56 | F13: =SUM('BATS 2023'!T7,'BATS 2023'!T11,'BATS 2023'!T15,'BATS 2023'!T19) -> 70 | G13: =SUM('BATS 2023'!U7,'BATS 2023'!U11,'BATS 2023'!U15,'BATS 2023'!U19) -> 704 | H13: =SUM('BATS 2023'!V7,'BATS 2023'!V11,'BATS 2023'!V15,'BATS 2023'!V19) -> 464 | I13: =SUM('BATS 2023'!W7,'BATS 2023'!W11,'BATS 2023'!W15,'BATS 2023'!W19) -> 622 | J13: =SUM('BATS 2023'!X7,'BATS 2023'!X11,'BATS 2023'!X15,'BATS 2023'!X19) -> 518 | ... M13: =SUM('BATS 2023'!AA7,'BATS 2023'!AA11,'BATS 2023'!AA15,'BATS 2023'!AA19) -> 702 | O13: 3 Ret | P13: =modeldata!C7+modeldata!C11+modeldata!C15+modeldata!C19 -> 0 | Q13: =modeldata!D7+modeldata!D11+modeldata!D15+modeldata!D19 -> 0 | R13: =modeldata!E7+modeldata!E11+modeldata!E15+modeldata!E19 -> 0 | S13: =modeldata!F7+modeldata!F11+modeldata!F15+modeldata!F19 -> 0 | T13: =modeldata!G7+modeldata!G11+modeldata!G15+modeldata!G19 -> 0 | U13: =modeldata!H7+modeldata!H11+modeldata!H15+modeldata!H19 -> 0 | V13: =modeldata!I7+modeldata!I11+modeldata!I15+modeldata!I19 -> 0 | W13: =modeldata!J7+modeldata!J11+modeldata!J15+modeldata!J19 -> 0 | ... Z13: =modeldata!M7+modeldata!M11+modeldata!M15+modeldata!M19 -> 0 | AB13: 3 Ret | AC13: =P13-C13 -> -1358 | AD13: =Q13-D13 -> -8 | AE13: =R13-E13 -> -56 | AF13: =S13-F13 -> -70 | AG13: =T13-G13 -> -704 | AH13: =U13-H13 -> -464 | AI13: =V13-I13 -> -622 | AJ13: =W13-J13 -> -518 | ... AM13: =Z13-M13 -> -702
B14: Total | C14: =SUM(C10:C13) -> 27204 | D14: =SUM(D10:D13) -> 582 | E14: =SUM(E10:E13) -> 2650 | F14: =SUM(F10:F13) -> 12970 | G14: =SUM(G10:G13) -> 21380 | H14: =SUM(H10:H13) -> 11018 | I14: =SUM(I10:I13) -> 15344 | J14: =SUM(J10:J13) -> 34292 | ... M14: =SUM(M10:M13) -> 46906 | O14: Total | P14: =SUM(P10:P13) -> 0 | Q14: =SUM(Q10:Q13) -> 0 | R14: =SUM(R10:R13) -> 0 | S14: =SUM(S10:S13) -> 0 | T14: =SUM(T10:T13) -> 0 | U14: =SUM(U10:U13) -> 0 | V14: =SUM(V10:V13) -> 0 | W14: =SUM(W10:W13) -> 0 | ... Z14: =SUM(Z10:Z13) -> 0 | AB14: Total | AC14: =P14-C14 -> -27204 | AD14: =Q14-D14 -> -582 | AE14: =R14-E14 -> -2650 | AF14: =S14-F14 -> -12970 | AG14: =T14-G14 -> -21380 | AH14: =U14-H14 -> -11018 | AI14: =V14-I14 -> -15344 | AJ14: =W14-J14 -> -34292 | ... AM14: =Z14-M14 -> -46906
B16: 0 Stop | C16: ='BATS 2023'!Q4 -> 13536 | D16: ='BATS 2023'!R4 -> 328 | E16: ='BATS 2023'!S4 -> 1936 | F16: ='BATS 2023'!T4 -> 10630 | G16: ='BATS 2023'!U4 -> 9868 | H16: ='BATS 2023'!V4 -> 6004 | I16: ='BATS 2023'!W4 -> 7624 | J16: ='BATS 2023'!X4 -> 24698 | ... M16: ='BATS 2023'!AA4 -> 29986 | O16: 0 Stop | P16: =modeldata!C4 -> 0 | Q16: =modeldata!D4 -> 0 | R16: =modeldata!E4 -> 0 | S16: =modeldata!F4 -> 0 | T16: =modeldata!G4 -> 0 | U16: =modeldata!H4 -> 0 | V16: =modeldata!I4 -> 0 | W16: =modeldata!J4 -> 0 | ... Z16: =modeldata!M4 -> 0 | AB16: 0 Stop | AC16: =P16-C16 -> -13536 | AD16: =Q16-D16 -> -328 | AE16: =R16-E16 -> -1936 | AF16: =S16-F16 -> -10630 | AG16: =T16-G16 -> -9868 | AH16: =U16-H16 -> -6004 | AI16: =V16-I16 -> -7624 | AJ16: =W16-J16 -> -24698 | ... AM16: =Z16-M16 -> -29986
B17: 1 Stop | C17: ='BATS 2023'!Q5+'BATS 2023'!Q8 -> 6512 | D17: ='BATS 2023'!R5+'BATS 2023'!R8 -> 166 | E17: ='BATS 2023'!S5+'BATS 2023'!S8 -> 442 | F17: ='BATS 2023'!T5+'BATS 2023'!T8 -> 1704 | G17: ='BATS 2023'!U5+'BATS 2023'!U8 -> 5386 | H17: ='BATS 2023'!V5+'BATS 2023'!V8 -> 2674 | I17: ='BATS 2023'!W5+'BATS 2023'!W8 -> 3444 | J17: ='BATS 2023'!X5+'BATS 2023'!X8 -> 4744 | ... M17: ='BATS 2023'!AA5+'BATS 2023'!AA8 -> 9286 | O17: 1 Stop | P17: =modeldata!C5+modeldata!C8 -> 0 | Q17: =modeldata!D5+modeldata!D8 -> 0 | R17: =modeldata!E5+modeldata!E8 -> 0 | S17: =modeldata!F5+modeldata!F8 -> 0 | T17: =modeldata!G5+modeldata!G8 -> 0 | U17: =modeldata!H5+modeldata!H8 -> 0 | V17: =modeldata!I5+modeldata!I8 -> 0 | W17: =modeldata!J5+modeldata!J8 -> 0 | ... Z17: =modeldata!M5+modeldata!M8 -> 0 | AB17: 1 Stop | AC17: =P17-C17 -> -6512 | AD17: =Q17-D17 -> -166 | AE17: =R17-E17 -> -442 | AF17: =S17-F17 -> -1704 | AG17: =T17-G17 -> -5386 | AH17: =U17-H17 -> -2674 | AI17: =V17-I17 -> -3444 | AJ17: =W17-J17 -> -4744 | ... AM17: =Z17-M17 -> -9286
B18: 2 Stops | C18: =SUM('BATS 2023'!Q6,'BATS 2023'!Q12,'BATS 2023'!Q9) -> 3440 | D18: =SUM('BATS 2023'!R6,'BATS 2023'!R12,'BATS 2023'!R9) -> 40 | E18: =SUM('BATS 2023'!S6,'BATS 2023'!S12,'BATS 2023'!S9) -> 156 | F18: =SUM('BATS 2023'!T6,'BATS 2023'!T12,'BATS 2023'!T9) -> 406 | G18: =SUM('BATS 2023'!U6,'BATS 2023'!U12,'BATS 2023'!U9) -> 2858 | H18: =SUM('BATS 2023'!V6,'BATS 2023'!V12,'BATS 2023'!V9) -> 1272 | I18: =SUM('BATS 2023'!W6,'BATS 2023'!W12,'BATS 2023'!W9) -> 1844 | J18: =SUM('BATS 2023'!X6,'BATS 2023'!X12,'BATS 2023'!X9) -> 2696 | ... M18: =SUM('BATS 2023'!AA6,'BATS 2023'!AA12,'BATS 2023'!AA9) -> 4416 | O18: 2 Stops | P18: =modeldata!C6+modeldata!C9+modeldata!C12 -> 0 | Q18: =modeldata!D6+modeldata!D9+modeldata!D12 -> 0 | R18: =modeldata!E6+modeldata!E9+modeldata!E12 -> 0 | S18: =modeldata!F6+modeldata!F9+modeldata!F12 -> 0 | T18: =modeldata!G6+modeldata!G9+modeldata!G12 -> 0 | U18: =modeldata!H6+modeldata!H9+modeldata!H12 -> 0 | V18: =modeldata!I6+modeldata!I9+modeldata!I12 -> 0 | W18: =modeldata!J6+modeldata!J9+modeldata!J12 -> 0 | ... Z18: =modeldata!M6+modeldata!M9+modeldata!M12 -> 0 | AB18: 2 Stops | AC18: =P18-C18 -> -3440 | AD18: =Q18-D18 -> -40 | AE18: =R18-E18 -> -156 | AF18: =S18-F18 -> -406 | AG18: =T18-G18 -> -2858 | AH18: =U18-H18 -> -1272 | AI18: =V18-I18 -> -1844 | AJ18: =W18-J18 -> -2696 | ... AM18: =Z18-M18 -> -4416
B19: 3 Stops | C19: =SUM('BATS 2023'!Q7,'BATS 2023'!Q10,'BATS 2023'!Q13,'BATS 2023'!Q16) -> 2368 | D19: =SUM('BATS 2023'!R7,'BATS 2023'!R10,'BATS 2023'!R13,'BATS 2023'!R16) -> 36 | E19: =SUM('BATS 2023'!S7,'BATS 2023'!S10,'BATS 2023'!S13,'BATS 2023'!S16) -> 86 | F19: =SUM('BATS 2023'!T7,'BATS 2023'!T10,'BATS 2023'!T13,'BATS 2023'!T16) -> 172 | G19: =SUM('BATS 2023'!U7,'BATS 2023'!U10,'BATS 2023'!U13,'BATS 2023'!U16) -> 2184 | H19: =SUM('BATS 2023'!V7,'BATS 2023'!V10,'BATS 2023'!V13,'BATS 2023'!V16) -> 736 | I19: =SUM('BATS 2023'!W7,'BATS 2023'!W10,'BATS 2023'!W13,'BATS 2023'!W16) -> 1564 | J19: =SUM('BATS 2023'!X7,'BATS 2023'!X10,'BATS 2023'!X13,'BATS 2023'!X16) -> 1512 | ... M19: =SUM('BATS 2023'!AA7,'BATS 2023'!AA10,'BATS 2023'!AA13,'BATS 2023'!AA16) -> 2374 | O19: 3 Stops | P19: =modeldata!C7+modeldata!C10+modeldata!C13+modeldata!C16 -> 0 | Q19: =modeldata!D7+modeldata!D10+modeldata!D13+modeldata!D16 -> 0 | R19: =modeldata!E7+modeldata!E10+modeldata!E13+modeldata!E16 -> 0 | S19: =modeldata!F7+modeldata!F10+modeldata!F13+modeldata!F16 -> 0 | T19: =modeldata!G7+modeldata!G10+modeldata!G13+modeldata!G16 -> 0 | U19: =modeldata!H7+modeldata!H10+modeldata!H13+modeldata!H16 -> 0 | V19: =modeldata!I7+modeldata!I10+modeldata!I13+modeldata!I16 -> 0 | W19: =modeldata!J7+modeldata!J10+modeldata!J13+modeldata!J16 -> 0 | ... Z19: =modeldata!M7+modeldata!M10+modeldata!M13+modeldata!M16 -> 0 | AB19: 3 Stops | AC19: =P19-C19 -> -2368 | AD19: =Q19-D19 -> -36 | AE19: =R19-E19 -> -86 | AF19: =S19-F19 -> -172 | AG19: =T19-G19 -> -2184 | AH19: =U19-H19 -> -736 | AI19: =V19-I19 -> -1564 | AJ19: =W19-J19 -> -1512 | ... AM19: =Z19-M19 -> -2374
B20: 4 Stops | C20: =SUM('BATS 2023'!Q11,'BATS 2023'!Q14,'BATS 2023'!Q17) -> 846 | D20: =SUM('BATS 2023'!R11,'BATS 2023'!R14,'BATS 2023'!R17) -> 2 | E20: =SUM('BATS 2023'!S11,'BATS 2023'!S14,'BATS 2023'!S17) -> 26 | F20: =SUM('BATS 2023'!T11,'BATS 2023'!T14,'BATS 2023'!T17) -> 38 | G20: =SUM('BATS 2023'!U11,'BATS 2023'!U14,'BATS 2023'!U17) -> 714 | H20: =SUM('BATS 2023'!V11,'BATS 2023'!V14,'BATS 2023'!V17) -> 226 | I20: =SUM('BATS 2023'!W11,'BATS 2023'!W14,'BATS 2023'!W17) -> 576 | J20: =SUM('BATS 2023'!X11,'BATS 2023'!X14,'BATS 2023'!X17) -> 430 | ... M20: =SUM('BATS 2023'!AA11,'BATS 2023'!AA14,'BATS 2023'!AA17) -> 702 | O20: 4 Stops | P20: =modeldata!C11+modeldata!C14+modeldata!C17 -> 0 | Q20: =modeldata!D11+modeldata!D14+modeldata!D17 -> 0 | R20: =modeldata!E11+modeldata!E14+modeldata!E17 -> 0 | S20: =modeldata!F11+modeldata!F14+modeldata!F17 -> 0 | T20: =modeldata!G11+modeldata!G14+modeldata!G17 -> 0 | U20: =modeldata!H11+modeldata!H14+modeldata!H17 -> 0 | V20: =modeldata!I11+modeldata!I14+modeldata!I17 -> 0 | W20: =modeldata!J11+modeldata!J14+modeldata!J17 -> 0 | ... Z20: =modeldata!M11+modeldata!M14+modeldata!M17 -> 0 | AB20: 4 Stops | AC20: =P20-C20 -> -846 | AD20: =Q20-D20 -> -2 | AE20: =R20-E20 -> -26 | AF20: =S20-F20 -> -38 | AG20: =T20-G20 -> -714 | AH20: =U20-H20 -> -226 | AI20: =V20-I20 -> -576 | AJ20: =W20-J20 -> -430 | ... AM20: =Z20-M20 -> -702
B21: 5 Stops | C21: =SUM('BATS 2023'!Q15,'BATS 2023'!Q18) -> 348 | D21: =SUM('BATS 2023'!R15,'BATS 2023'!R18) -> 6 | E21: =SUM('BATS 2023'!S15,'BATS 2023'!S18) -> 2 | F21: =SUM('BATS 2023'!T15,'BATS 2023'!T18) -> 14 | G21: =SUM('BATS 2023'!U15,'BATS 2023'!U18) -> 270 | H21: =SUM('BATS 2023'!V15,'BATS 2023'!V18) -> 64 | I21: =SUM('BATS 2023'!W15,'BATS 2023'!W18) -> 194 | J21: =SUM('BATS 2023'!X15,'BATS 2023'!X18) -> 156 | ... M21: =SUM('BATS 2023'!AA15,'BATS 2023'!AA18) -> 92 | O21: 5 Stops | P21: =modeldata!C15+modeldata!C18 -> 0 | Q21: =modeldata!D15+modeldata!D18 -> 0 | R21: =modeldata!E15+modeldata!E18 -> 0 | S21: =modeldata!F15+modeldata!F18 -> 0 | T21: =modeldata!G15+modeldata!G18 -> 0 | U21: =modeldata!H15+modeldata!H18 -> 0 | V21: =modeldata!I15+modeldata!I18 -> 0 | W21: =modeldata!J15+modeldata!J18 -> 0 | ... Z21: =modeldata!M15+modeldata!M18 -> 0 | AB21: 5 Stops | AC21: =P21-C21 -> -348 | AD21: =Q21-D21 -> -6 | AE21: =R21-E21 -> -2 | AF21: =S21-F21 -> -14 | AG21: =T21-G21 -> -270 | AH21: =U21-H21 -> -64 | AI21: =V21-I21 -> -194 | AJ21: =W21-J21 -> -156 | ... AM21: =Z21-M21 -> -92
B22: 6+ Stops | C22: ='BATS 2023'!Q19 -> 154 | D22: ='BATS 2023'!R19 -> 4 | E22: ='BATS 2023'!S19 -> 2 | F22: ='BATS 2023'!T19 -> 6 | G22: ='BATS 2023'!U19 -> 100 | H22: ='BATS 2023'!V19 -> 42 | I22: ='BATS 2023'!W19 -> 98 | J22: ='BATS 2023'!X19 -> 56 | ... M22: ='BATS 2023'!AA19 -> 50 | O22: 6+ Stops | P22: =modeldata!C19 -> 0 | Q22: =modeldata!D19 -> 0 | R22: =modeldata!E19 -> 0 | S22: =modeldata!F19 -> 0 | T22: =modeldata!G19 -> 0 | U22: =modeldata!H19 -> 0 | V22: =modeldata!I19 -> 0 | W22: =modeldata!J19 -> 0 | ... Z22: =modeldata!M19 -> 0 | AB22: 6+ Stops | AC22: =P22-C22 -> -154 | AD22: =Q22-D22 -> -4 | AE22: =R22-E22 -> -2 | AF22: =S22-F22 -> -6 | AG22: =T22-G22 -> -100 | AH22: =U22-H22 -> -42 | AI22: =V22-I22 -> -98 | AJ22: =W22-J22 -> -56 | ... AM22: =Z22-M22 -> -50
B23: Total | C23: =SUM(C16:C22) -> 27204 | D23: =SUM(D16:D22) -> 582 | E23: =SUM(E16:E22) -> 2650 | F23: =SUM(F16:F22) -> 12970 | G23: =SUM(G16:G22) -> 21380 | H23: =SUM(H16:H22) -> 11018 | I23: =SUM(I16:I22) -> 15344 | J23: =SUM(J16:J22) -> 34292 | ... M23: =SUM(M16:M22) -> 46906 | O23: Total | P23: =SUM(P16:P22) -> 0 | Q23: =SUM(Q16:Q22) -> 0 | R23: =SUM(R16:R22) -> 0 | S23: =SUM(S16:S22) -> 0 | T23: =SUM(T16:T22) -> 0 | U23: =SUM(U16:U22) -> 0 | V23: =SUM(V16:V22) -> 0 | W23: =SUM(W16:W22) -> 0 | ... Z23: =SUM(Z16:Z22) -> 0 | AB23: Total | AC23: =P23-C23 -> -27204 | AD23: =Q23-D23 -> -582 | AE23: =R23-E23 -> -2650 | AF23: =S23-F23 -> -12970 | AG23: =T23-G23 -> -21380 | AH23: =U23-H23 -> -11018 | AI23: =V23-I23 -> -15344 | AJ23: =W23-J23 -> -34292 | ... AM23: =Z23-M23 -> -46906
B25: Calibration Targets Percent | O25: Model Results - Percentage | AB25: Model minus Observed
C26: work | D26: university | E26: school | F26: escort | G26: shop | H26: maintenance | I26: eatout | J26: visit | K26: discretionary | L26: atwork | M26: joint | P26: work | Q26: university | R26: school | S26: escort | T26: shop | U26: maintenance | V26: eatout | W26: visit | X26: discretionary | Y26: atwork | Z26: joint | AC26: work | AD26: university | AE26: school | AF26: escort | AG26: shop | AH26: maintenance | AI26: eatout | AJ26: visit | AK26: discretionary | AL26: atwork | AM26: joint
B27: 0 Out | C27: =C4/C$8 -> 0.71114542 | D27: =D4/D$8 -> 0.75601375 | E27: =E4/E$8 -> 0.89358491 | F27: =F4/F$8 -> 0.90624518 | G27: =G4/G$8 -> 0.60383536 | H27: =H4/H$8 -> 0.75549101 | I27: =I4/I$8 -> 0.62552138 | J27: =J4/J$8 -> 0.814534 | ... M27: =M4/M$8 -> 0.76907006 | O27: 0 Out | P27: =P4/P$8 -> #DIV/0! | Q27: =Q4/Q$8 -> #DIV/0! | R27: =R4/R$8 -> #DIV/0! | S27: =S4/S$8 -> #DIV/0! | T27: =T4/T$8 -> #DIV/0! | U27: =U4/U$8 -> #DIV/0! | V27: =V4/V$8 -> #DIV/0! | W27: =W4/W$8 -> #DIV/0! | ... Z27: =Z4/Z$8 -> #DIV/0! | AB27: 0 Out | AC27: =P27-C27 -> #DIV/0! | AD27: =Q27-D27 -> #DIV/0! | AE27: =R27-E27 -> #DIV/0! | AF27: =S27-F27 -> #DIV/0! | AG27: =T27-G27 -> #DIV/0! | AH27: =U27-H27 -> #DIV/0! | AI27: =V27-I27 -> #DIV/0! | AJ27: =W27-J27 -> #DIV/0! | ... AM27: =Z27-M27 -> #DIV/0!
B28: 1 Out | C28: =C5/C$8 -> 0.17203352 | D28: =D5/D$8 -> 0.16151203 | E28: =E5/E$8 -> 0.083773585 | F28: =F5/F$8 -> 0.069082498 | G28: =G5/G$8 -> 0.2232928 | H28: =H5/H$8 -> 0.15465602 | I28: =I5/I$8 -> 0.2068561 | J28: =J5/J$8 -> 0.10346436 | ... M28: =M5/M$8 -> 0.14799812 | O28: 1 Out | P28: =P5/P$8 -> #DIV/0! | Q28: =Q5/Q$8 -> #DIV/0! | R28: =R5/R$8 -> #DIV/0! | S28: =S5/S$8 -> #DIV/0! | T28: =T5/T$8 -> #DIV/0! | U28: =U5/U$8 -> #DIV/0! | V28: =V5/V$8 -> #DIV/0! | W28: =W5/W$8 -> #DIV/0! | ... Z28: =Z5/Z$8 -> #DIV/0! | AB28: 1 Out | AC28: =P28-C28 -> #DIV/0! | AD28: =Q28-D28 -> #DIV/0! | AE28: =R28-E28 -> #DIV/0! | AF28: =S28-F28 -> #DIV/0! | AG28: =T28-G28 -> #DIV/0! | AH28: =U28-H28 -> #DIV/0! | AI28: =V28-I28 -> #DIV/0! | AJ28: =W28-J28 -> #DIV/0! | ... AM28: =Z28-M28 -> #DIV/0!
B29: 2 Out | C29: =C6/C$8 -> 0.068445817 | D29: =D6/D$8 -> 0.041237113 | E29: =E6/E$8 -> 0.016603774 | F29: =F6/F$8 -> 0.017579029 | G29: =G6/G$8 -> 0.095790458 | H29: =H6/H$8 -> 0.054274823 | I29: =I6/I$8 -> 0.085114703 | J29: =J6/J$8 -> 0.051207279 | ... M29: =M6/M$8 -> 0.055856394 | O29: 2 Out | P29: =P6/P$8 -> #DIV/0! | Q29: =Q6/Q$8 -> #DIV/0! | R29: =R6/R$8 -> #DIV/0! | S29: =S6/S$8 -> #DIV/0! | T29: =T6/T$8 -> #DIV/0! | U29: =U6/U$8 -> #DIV/0! | V29: =V6/V$8 -> #DIV/0! | W29: =W6/W$8 -> #DIV/0! | ... Z29: =Z6/Z$8 -> #DIV/0! | AB29: 2 Out | AC29: =P29-C29 -> #DIV/0! | AD29: =Q29-D29 -> #DIV/0! | AE29: =R29-E29 -> #DIV/0! | AF29: =S29-F29 -> #DIV/0! | AG29: =T29-G29 -> #DIV/0! | AH29: =U29-H29 -> #DIV/0! | AI29: =V29-I29 -> #DIV/0! | AJ29: =W29-J29 -> #DIV/0! | ... AM29: =Z29-M29 -> #DIV/0!
B30: 3 Out | C30: =C7/C$8 -> 0.048375239 | D30: =D7/D$8 -> 0.041237113 | E30: =E7/E$8 -> 0.0060377358 | F30: =F7/F$8 -> 0.0070932922 | G30: =G7/G$8 -> 0.077081384 | H30: =H7/H$8 -> 0.035578145 | I30: =I7/I$8 -> 0.082507821 | J30: =J7/J$8 -> 0.030794354 | ... M30: =M7/M$8 -> 0.027075427 | O30: 3 Out | P30: =P7/P$8 -> #DIV/0! | Q30: =Q7/Q$8 -> #DIV/0! | R30: =R7/R$8 -> #DIV/0! | S30: =S7/S$8 -> #DIV/0! | T30: =T7/T$8 -> #DIV/0! | U30: =U7/U$8 -> #DIV/0! | V30: =V7/V$8 -> #DIV/0! | W30: =W7/W$8 -> #DIV/0! | ... Z30: =Z7/Z$8 -> #DIV/0! | AB30: 3 Out | AC30: =P30-C30 -> #DIV/0! | AD30: =Q30-D30 -> #DIV/0! | AE30: =R30-E30 -> #DIV/0! | AF30: =S30-F30 -> #DIV/0! | AG30: =T30-G30 -> #DIV/0! | AH30: =U30-H30 -> #DIV/0! | AI30: =V30-I30 -> #DIV/0! | AJ30: =W30-J30 -> #DIV/0! | ... AM30: =Z30-M30 -> #DIV/0!
B31: Total | C31: =C8/C$8 -> 1 | D31: =D8/D$8 -> 1 | E31: =E8/E$8 -> 1 | F31: =F8/F$8 -> 1 | G31: =G8/G$8 -> 1 | H31: =H8/H$8 -> 1 | I31: =I8/I$8 -> 1 | J31: =J8/J$8 -> 1 | ... M31: =M8/M$8 -> 1 | O31: Total | P31: =P8/P$8 -> #DIV/0! | Q31: =Q8/Q$8 -> #DIV/0! | R31: =R8/R$8 -> #DIV/0! | S31: =S8/S$8 -> #DIV/0! | T31: =T8/T$8 -> #DIV/0! | U31: =U8/U$8 -> #DIV/0! | V31: =V8/V$8 -> #DIV/0! | W31: =W8/W$8 -> #DIV/0! | ... Z31: =Z8/Z$8 -> #DIV/0! | AB31: Total | AC31: =P31-C31 -> #DIV/0! | AD31: =Q31-D31 -> #DIV/0! | AE31: =R31-E31 -> #DIV/0! | AF31: =S31-F31 -> #DIV/0! | AG31: =T31-G31 -> #DIV/0! | AH31: =U31-H31 -> #DIV/0! | AI31: =V31-I31 -> #DIV/0! | AJ31: =W31-J31 -> #DIV/0! | ... AM31: =Z31-M31 -> #DIV/0!
B33: 0 Ret | C33: =C10/C$14 -> 0.6557124 | D33: =D10/D$14 -> 0.73883162 | E33: =E10/E$14 -> 0.79320755 | F33: =F10/F$14 -> 0.8926754 | G33: =G10/G$14 -> 0.72039289 | H33: =H10/H$14 -> 0.70012706 | I33: =I10/I$14 -> 0.7355318 | J33: =J10/J$14 -> 0.84771958 | ... M33: =M10/M$14 -> 0.79623076 | O33: 0 Ret | P33: =P10/P$14 -> #DIV/0! | Q33: =Q10/Q$14 -> #DIV/0! | R33: =R10/R$14 -> #DIV/0! | S33: =S10/S$14 -> #DIV/0! | T33: =T10/T$14 -> #DIV/0! | U33: =U10/U$14 -> #DIV/0! | V33: =V10/V$14 -> #DIV/0! | W33: =W10/W$14 -> #DIV/0! | ... Z33: =Z10/Z$14 -> #DIV/0! | AB33: 0 Ret | AC33: =P33-C33 -> #DIV/0! | AD33: =Q33-D33 -> #DIV/0! | AE33: =R33-E33 -> #DIV/0! | AF33: =S33-F33 -> #DIV/0! | AG33: =T33-G33 -> #DIV/0! | AH33: =U33-H33 -> #DIV/0! | AI33: =V33-I33 -> #DIV/0! | AJ33: =W33-J33 -> #DIV/0! | ... AM33: =Z33-M33 -> #DIV/0!
B34: 1 Ret | C34: =C11/C$14 -> 0.21680635 | D34: =D11/D$14 -> 0.18900344 | E34: =E11/E$14 -> 0.14037736 | F34: =F11/F$14 -> 0.091904395 | G34: =G11/G$14 -> 0.18774556 | H34: =H11/H$14 -> 0.20384825 | I34: =I11/I$14 -> 0.17179353 | J34: =J11/J$14 -> 0.10737198 | ... M34: =M11/M$14 -> 0.14927728 | O34: 1 Ret | P34: =P11/P$14 -> #DIV/0! | Q34: =Q11/Q$14 -> #DIV/0! | R34: =R11/R$14 -> #DIV/0! | S34: =S11/S$14 -> #DIV/0! | T34: =T11/T$14 -> #DIV/0! | U34: =U11/U$14 -> #DIV/0! | V34: =V11/V$14 -> #DIV/0! | W34: =W11/W$14 -> #DIV/0! | ... Z34: =Z11/Z$14 -> #DIV/0! | AB34: 1 Ret | AC34: =P34-C34 -> #DIV/0! | AD34: =Q34-D34 -> #DIV/0! | AE34: =R34-E34 -> #DIV/0! | AF34: =S34-F34 -> #DIV/0! | AG34: =T34-G34 -> #DIV/0! | AH34: =U34-H34 -> #DIV/0! | AI34: =V34-I34 -> #DIV/0! | AJ34: =W34-J34 -> #DIV/0! | ... AM34: =Z34-M34 -> #DIV/0!
B35: 2 Ret | C35: =C12/C$14 -> 0.077562123 | D35: =D12/D$14 -> 0.058419244 | E35: =E12/E$14 -> 0.045283019 | F35: =F12/F$14 -> 0.01002313 | G35: =G12/G$14 -> 0.058933583 | H35: =H12/H$14 -> 0.053911781 | I35: =I12/I$14 -> 0.052137643 | J35: =J12/J$14 -> 0.029802869 | ... M35: =M12/M$14 -> 0.03952586 | O35: 2 Ret | P35: =P12/P$14 -> #DIV/0! | Q35: =Q12/Q$14 -> #DIV/0! | R35: =R12/R$14 -> #DIV/0! | S35: =S12/S$14 -> #DIV/0! | T35: =T12/T$14 -> #DIV/0! | U35: =U12/U$14 -> #DIV/0! | V35: =V12/V$14 -> #DIV/0! | W35: =W12/W$14 -> #DIV/0! | ... Z35: =Z12/Z$14 -> #DIV/0! | AB35: 2 Ret | AC35: =P35-C35 -> #DIV/0! | AD35: =Q35-D35 -> #DIV/0! | AE35: =R35-E35 -> #DIV/0! | AF35: =S35-F35 -> #DIV/0! | AG35: =T35-G35 -> #DIV/0! | AH35: =U35-H35 -> #DIV/0! | AI35: =V35-I35 -> #DIV/0! | AJ35: =W35-J35 -> #DIV/0! | ... AM35: =Z35-M35 -> #DIV/0!
B36: 3 Ret | C36: =C13/C$14 -> 0.04991913 | D36: =D13/D$14 -> 0.013745704 | E36: =E13/E$14 -> 0.021132075 | F36: =F13/F$14 -> 0.0053970702 | G36: =G13/G$14 -> 0.03292797 | H36: =H13/H$14 -> 0.042112906 | I36: =I13/I$14 -> 0.040537018 | J36: =J13/J$14 -> 0.015105564 | ... M36: =M13/M$14 -> 0.014966102 | O36: 3 Ret | P36: =P13/P$14 -> #DIV/0! | Q36: =Q13/Q$14 -> #DIV/0! | R36: =R13/R$14 -> #DIV/0! | S36: =S13/S$14 -> #DIV/0! | T36: =T13/T$14 -> #DIV/0! | U36: =U13/U$14 -> #DIV/0! | V36: =V13/V$14 -> #DIV/0! | W36: =W13/W$14 -> #DIV/0! | ... Z36: =Z13/Z$14 -> #DIV/0! | AB36: 3 Ret | AC36: =P36-C36 -> #DIV/0! | AD36: =Q36-D36 -> #DIV/0! | AE36: =R36-E36 -> #DIV/0! | AF36: =S36-F36 -> #DIV/0! | AG36: =T36-G36 -> #DIV/0! | AH36: =U36-H36 -> #DIV/0! | AI36: =V36-I36 -> #DIV/0! | AJ36: =W36-J36 -> #DIV/0! | ... AM36: =Z36-M36 -> #DIV/0!
B37: Total | C37: =C14/C$14 -> 1 | D37: =D14/D$14 -> 1 | E37: =E14/E$14 -> 1 | F37: =F14/F$14 -> 1 | G37: =G14/G$14 -> 1 | H37: =H14/H$14 -> 1 | I37: =I14/I$14 -> 1 | J37: =J14/J$14 -> 1 | ... M37: =M14/M$14 -> 1 | O37: Total | P37: =P14/P$14 -> #DIV/0! | Q37: =Q14/Q$14 -> #DIV/0! | R37: =R14/R$14 -> #DIV/0! | S37: =S14/S$14 -> #DIV/0! | T37: =T14/T$14 -> #DIV/0! | U37: =U14/U$14 -> #DIV/0! | V37: =V14/V$14 -> #DIV/0! | W37: =W14/W$14 -> #DIV/0! | ... Z37: =Z14/Z$14 -> #DIV/0! | AB37: Total | AC37: =P37-C37 -> #DIV/0! | AD37: =Q37-D37 -> #DIV/0! | AE37: =R37-E37 -> #DIV/0! | AF37: =S37-F37 -> #DIV/0! | AG37: =T37-G37 -> #DIV/0! | AH37: =U37-H37 -> #DIV/0! | AI37: =V37-I37 -> #DIV/0! | AJ37: =W37-J37 -> #DIV/0! | ... AM37: =Z37-M37 -> #DIV/0!
B39: 0 Stop | C39: =C16/C$23 -> 0.49757389 | D39: =D16/D$23 -> 0.56357388 | E39: =E16/E$23 -> 0.73056604 | F39: =F16/F$23 -> 0.81958365 | G39: =G16/G$23 -> 0.46155285 | H39: =H16/H$23 -> 0.54492648 | I39: =I16/I$23 -> 0.49687174 | J39: =J16/J$23 -> 0.72022629 | ... M39: =M16/M$23 -> 0.63927856 | O39: 0 Stop | P39: =P16/P$23 -> #DIV/0! | Q39: =Q16/Q$23 -> #DIV/0! | R39: =R16/R$23 -> #DIV/0! | S39: =S16/S$23 -> #DIV/0! | T39: =T16/T$23 -> #DIV/0! | U39: =U16/U$23 -> #DIV/0! | V39: =V16/V$23 -> #DIV/0! | W39: =W16/W$23 -> #DIV/0! | ... Z39: =Z16/Z$23 -> #DIV/0! | AB39: 0 Stop | AC39: =P39-C39 -> #DIV/0! | AD39: =Q39-D39 -> #DIV/0! | AE39: =R39-E39 -> #DIV/0! | AF39: =S39-F39 -> #DIV/0! | AG39: =T39-G39 -> #DIV/0! | AH39: =U39-H39 -> #DIV/0! | AI39: =V39-I39 -> #DIV/0! | AJ39: =W39-J39 -> #DIV/0! | ... AM39: =Z39-M39 -> #DIV/0!
B40: 1 Stop | C40: =C17/C$23 -> 0.23937656 | D40: =D17/D$23 -> 0.28522337 | E40: =E17/E$23 -> 0.16679245 | F40: =F17/F$23 -> 0.13138011 | G40: =G17/G$23 -> 0.25191768 | H40: =H17/H$23 -> 0.24269377 | I40: =I17/I$23 -> 0.22445255 | J40: =J17/J$23 -> 0.1383413 | ... M40: =M17/M$23 -> 0.19797041 | O40: 1 Stop | P40: =P17/P$23 -> #DIV/0! | Q40: =Q17/Q$23 -> #DIV/0! | R40: =R17/R$23 -> #DIV/0! | S40: =S17/S$23 -> #DIV/0! | T40: =T17/T$23 -> #DIV/0! | U40: =U17/U$23 -> #DIV/0! | V40: =V17/V$23 -> #DIV/0! | W40: =W17/W$23 -> #DIV/0! | ... Z40: =Z17/Z$23 -> #DIV/0! | AB40: 1 Stop | AC40: =P40-C40 -> #DIV/0! | AD40: =Q40-D40 -> #DIV/0! | AE40: =R40-E40 -> #DIV/0! | AF40: =S40-F40 -> #DIV/0! | AG40: =T40-G40 -> #DIV/0! | AH40: =U40-H40 -> #DIV/0! | AI40: =V40-I40 -> #DIV/0! | AJ40: =W40-J40 -> #DIV/0! | ... AM40: =Z40-M40 -> #DIV/0!
B41: 2 Stops | C41: =C18/C$23 -> 0.12645199 | D41: =D18/D$23 -> 0.068728522 | E41: =E18/E$23 -> 0.058867925 | F41: =F18/F$23 -> 0.031303007 | G41: =G18/G$23 -> 0.13367633 | H41: =H18/H$23 -> 0.11544745 | I41: =I18/I$23 -> 0.12017727 | J41: =J18/J$23 -> 0.07861892 | ... M41: =M18/M$23 -> 0.094145738 | O41: 2 Stops | P41: =P18/P$23 -> #DIV/0! | Q41: =Q18/Q$23 -> #DIV/0! | R41: =R18/R$23 -> #DIV/0! | S41: =S18/S$23 -> #DIV/0! | T41: =T18/T$23 -> #DIV/0! | U41: =U18/U$23 -> #DIV/0! | V41: =V18/V$23 -> #DIV/0! | W41: =W18/W$23 -> #DIV/0! | ... Z41: =Z18/Z$23 -> #DIV/0! | AB41: 2 Stops | AC41: =P41-C41 -> #DIV/0! | AD41: =Q41-D41 -> #DIV/0! | AE41: =R41-E41 -> #DIV/0! | AF41: =S41-F41 -> #DIV/0! | AG41: =T41-G41 -> #DIV/0! | AH41: =U41-H41 -> #DIV/0! | AI41: =V41-I41 -> #DIV/0! | AJ41: =W41-J41 -> #DIV/0! | ... AM41: =Z41-M41 -> #DIV/0!
B42: 3 Stops | C42: =C19/C$23 -> 0.087046023 | D42: =D19/D$23 -> 0.06185567 | E42: =E19/E$23 -> 0.03245283 | F42: =F19/F$23 -> 0.013261372 | G42: =G19/G$23 -> 0.10215154 | H42: =H19/H$23 -> 0.066799782 | I42: =I19/I$23 -> 0.10192909 | J42: =J19/J$23 -> 0.044091916 | ... M42: =M19/M$23 -> 0.050611862 | O42: 3 Stops | P42: =P19/P$23 -> #DIV/0! | Q42: =Q19/Q$23 -> #DIV/0! | R42: =R19/R$23 -> #DIV/0! | S42: =S19/S$23 -> #DIV/0! | T42: =T19/T$23 -> #DIV/0! | U42: =U19/U$23 -> #DIV/0! | V42: =V19/V$23 -> #DIV/0! | W42: =W19/W$23 -> #DIV/0! | ... Z42: =Z19/Z$23 -> #DIV/0! | AB42: 3 Stops | AC42: =P42-C42 -> #DIV/0! | AD42: =Q42-D42 -> #DIV/0! | AE42: =R42-E42 -> #DIV/0! | AF42: =S42-F42 -> #DIV/0! | AG42: =T42-G42 -> #DIV/0! | AH42: =U42-H42 -> #DIV/0! | AI42: =V42-I42 -> #DIV/0! | AJ42: =W42-J42 -> #DIV/0! | ... AM42: =Z42-M42 -> #DIV/0!
B43: 4 Stops | C43: =C20/C$23 -> 0.031098368 | D43: =D20/D$23 -> 0.0034364261 | E43: =E20/E$23 -> 0.0098113208 | F43: =F20/F$23 -> 0.0029298381 | G43: =G20/G$23 -> 0.033395697 | H43: =H20/H$23 -> 0.02051189 | I43: =I20/I$23 -> 0.037539103 | J43: =J20/J$23 -> 0.012539368 | ... M43: =M20/M$23 -> 0.014966102 | O43: 4 Stops | P43: =P20/P$23 -> #DIV/0! | Q43: =Q20/Q$23 -> #DIV/0! | R43: =R20/R$23 -> #DIV/0! | S43: =S20/S$23 -> #DIV/0! | T43: =T20/T$23 -> #DIV/0! | U43: =U20/U$23 -> #DIV/0! | V43: =V20/V$23 -> #DIV/0! | W43: =W20/W$23 -> #DIV/0! | ... Z43: =Z20/Z$23 -> #DIV/0! | AB43: 4 Stops | AC43: =P43-C43 -> #DIV/0! | AD43: =Q43-D43 -> #DIV/0! | AE43: =R43-E43 -> #DIV/0! | AF43: =S43-F43 -> #DIV/0! | AG43: =T43-G43 -> #DIV/0! | AH43: =U43-H43 -> #DIV/0! | AI43: =V43-I43 -> #DIV/0! | AJ43: =W43-J43 -> #DIV/0! | ... AM43: =Z43-M43 -> #DIV/0!
B44: 5 Stops | C44: =C21/C$23 -> 0.012792236 | D44: =D21/D$23 -> 0.010309278 | E44: =E21/E$23 -> 0.00075471698 | F44: =F21/F$23 -> 0.001079414 | G44: =G21/G$23 -> 0.012628625 | H44: =H21/H$23 -> 0.0058086767 | I44: =I21/I$23 -> 0.012643379 | J44: =J21/J$23 -> 0.004549166 | ... M44: =M21/M$23 -> 0.0019613695 | O44: 5 Stops | P44: =P21/P$23 -> #DIV/0! | Q44: =Q21/Q$23 -> #DIV/0! | R44: =R21/R$23 -> #DIV/0! | S44: =S21/S$23 -> #DIV/0! | T44: =T21/T$23 -> #DIV/0! | U44: =U21/U$23 -> #DIV/0! | V44: =V21/V$23 -> #DIV/0! | W44: =W21/W$23 -> #DIV/0! | ... Z44: =Z21/Z$23 -> #DIV/0! | AB44: 5 Stops | AC44: =P44-C44 -> #DIV/0! | AD44: =Q44-D44 -> #DIV/0! | AE44: =R44-E44 -> #DIV/0! | AF44: =S44-F44 -> #DIV/0! | AG44: =T44-G44 -> #DIV/0! | AH44: =U44-H44 -> #DIV/0! | AI44: =V44-I44 -> #DIV/0! | AJ44: =W44-J44 -> #DIV/0! | ... AM44: =Z44-M44 -> #DIV/0!
B45: 6+ Stops | C45: =C22/C$23 -> 0.0056609322 | D45: =D22/D$23 -> 0.0068728522 | E45: =E22/E$23 -> 0.00075471698 | F45: =F22/F$23 -> 0.00046260601 | G45: =G22/G$23 -> 0.0046772685 | H45: =H22/H$23 -> 0.0038119441 | I45: =I22/I$23 -> 0.0063868613 | J45: =J22/J$23 -> 0.0016330339 | ... M45: =M22/M$23 -> 0.0010659617 | O45: 6+ Stops | P45: =P22/P$23 -> #DIV/0! | Q45: =Q22/Q$23 -> #DIV/0! | R45: =R22/R$23 -> #DIV/0! | S45: =S22/S$23 -> #DIV/0! | T45: =T22/T$23 -> #DIV/0! | U45: =U22/U$23 -> #DIV/0! | V45: =V22/V$23 -> #DIV/0! | W45: =W22/W$23 -> #DIV/0! | ... Z45: =Z22/Z$23 -> #DIV/0! | AB45: 6+ Stops | AC45: =P45-C45 -> #DIV/0! | AD45: =Q45-D45 -> #DIV/0! | AE45: =R45-E45 -> #DIV/0! | AF45: =S45-F45 -> #DIV/0! | AG45: =T45-G45 -> #DIV/0! | AH45: =U45-H45 -> #DIV/0! | AI45: =V45-I45 -> #DIV/0! | AJ45: =W45-J45 -> #DIV/0! | ... AM45: =Z45-M45 -> #DIV/0!
B46: Total | C46: =C23/C$23 -> 1 | D46: =D23/D$23 -> 1 | E46: =E23/E$23 -> 1 | F46: =F23/F$23 -> 1 | G46: =G23/G$23 -> 1 | H46: =H23/H$23 -> 1 | I46: =I23/I$23 -> 1 | J46: =J23/J$23 -> 1 | ... M46: =M23/M$23 -> 1 | O46: Total | P46: =P23/P$23 -> #DIV/0! | Q46: =Q23/Q$23 -> #DIV/0! | R46: =R23/R$23 -> #DIV/0! | S46: =S23/S$23 -> #DIV/0! | T46: =T23/T$23 -> #DIV/0! | U46: =U23/U$23 -> #DIV/0! | V46: =V23/V$23 -> #DIV/0! | W46: =W23/W$23 -> #DIV/0! | ... Z46: =Z23/Z$23 -> #DIV/0! | AB46: Total | AC46: =P46-C46 -> #DIV/0! | AD46: =Q46-D46 -> #DIV/0! | AE46: =R46-E46 -> #DIV/0! | AF46: =S46-F46 -> #DIV/0! | AG46: =T46-G46 -> #DIV/0! | AH46: =U46-H46 -> #DIV/0! | AI46: =V46-I46 -> #DIV/0! | AJ46: =W46-J46 -> #DIV/0! | ... AM46: =Z46-M46 -> #DIV/0!
...

Sheet constants
C1: Exisiting | S1: New Constants
C2: Alt1 | D2: Alt2 | E2: Alt3 | F2: Alt4 | G2: Alt5 | H2: Alt6 | I2: Alt7 | J2: Alt8 | K2: Alt9 | L2: Alt10 | M2: Alt11 | N2: Alt12 | O2: Alt13 | P2: Alt14 | Q2: Alt15 | R2: Alt16 | S2: Alt1 | T2: Alt2 | U2: Alt3 | V2: Alt4 | W2: Alt5 | X2: Alt6 | Y2: Alt7 | Z2: Alt8 | AA2: Alt9 | AB2: Alt10 | AC2: Alt11 | AD2: Alt12 | AE2: Alt13 | AF2: Alt14 | AG2: Alt15 | AH2: Alt16
C3: 0 Stop | D3: 1 Stop | E3: 2 Stops | F3: 3 Stops | G3: 1 Stop | H3: 2 Stops | I3: 3 Stops | J3: 4 Stops | K3: 2 Stops | L3: 3 Stops | M3: 4 Stops | N3: 5 Stops | O3: 3 Stops | P3: 4 Stops | Q3: 5 Stops | R3: 6+ Stops | S3: 0 Stop | T3: 1 Stop | U3: 2 Stops | V3: 3 Stops | W3: 1 Stop | X3: 2 Stops | Y3: 3 Stops | Z3: 4 Stops | AA3: 2 Stops | AB3: 3 Stops | AC3: 4 Stops | AD3: 5 Stops | AE3: 3 Stops | AF3: 4 Stops | AG3: 5 Stops | AH3: 6+ Stops
C4: 0 Out | D4: 0 Out | E4: 0 Out | F4: 0 Out | G4: 1 Out | H4: 1 Out | I4: 1 Out | J4: 1 Out | K4: 2 out | L4: 2 out | M4: 2 out | N4: 2 out | O4: 3 Out | P4: 3 Out | Q4: 3 Out | R4: 3 Out | S4: 0 Out | T4: 0 Out | U4: 0 Out | V4: 0 Out | W4: 1 Out | X4: 1 Out | Y4: 1 Out | Z4: 1 Out | AA4: 2 out | AB4: 2 out | AC4: 2 out | AD4: 2 out | AE4: 3 Out | AF4: 3 Out | AG4: 3 Out | AH4: 3 Out
A5: Purpose | C5: 0 Ret | D5: 1 Ret | E5: 2 Ret | F5: 3 Ret | G5: 0 Ret | H5: 1 Ret | I5: 2 Ret | J5: 3 Ret | K5: 0 Ret | L5: 1 Ret | M5: 2 Ret | N5: 3 Ret | O5: 0 Ret | P5: 1 Ret | Q5: 2 Ret | R5: 3 Ret | S5: 0 Ret | T5: 1 Ret | U5: 2 Ret | V5: 3 Ret | W5: 0 Ret | X5: 1 Ret | Y5: 2 Ret | Z5: 3 Ret | AA5: 0 Ret | AB5: 1 Ret | AC5: 2 Ret | AD5: 3 Ret | AE5: 0 Ret | AF5: 1 Ret | AG5: 2 Ret | AH5: 3 Ret
A6: work | B6: Outbound Stops | S6: =INDEX(calibration!$AC$52:$AM$66,MATCH(constants!S$4,calibration!$AB$52:$AB$66,0),MATCH(constants!$A6,calibration!$P$51:$Z$51,0)) -> 0 | T6: =INDEX(calibration!$AC$52:$AM$66,MATCH(constants!T$4,calibration!$AB$52:$AB$66,0),MATCH(constants!$A6,calibration!$P$51:$Z$51,0)) -> 0 | U6: =INDEX(calibration!$AC$52:$AM$66,MATCH(constants!U$4,calibration!$AB$52:$AB$66,0),MATCH(constants!$A6,calibration!$P$51:$Z$51,0)) -> 0 | V6: =INDEX(calibration!$AC$52:$AM$66,MATCH(constants!V$4,calibration!$AB$52:$AB$66,0),MATCH(constants!$A6,calibration!$P$51:$Z$51,0)) -> 0 | W6: =INDEX(calibration!$AC$52:$AM$66,MATCH(constants!W$4,calibration!$AB$52:$AB$66,0),MATCH(constants!$A6,calibration!$P$51:$Z$51,0)) -> #DIV/0! | X6: =INDEX(calibration!$AC$52:$AM$66,MATCH(constants!X$4,calibration!$AB$52:$AB$66,0),MATCH(constants!$A6,calibration!$P$51:$Z$51,0)) -> #DIV/0! | Y6: =INDEX(calibration!$AC$52:$AM$66,MATCH(constants!Y$4,calibration!$AB$52:$AB$66,0),MATCH(constants!$A6,calibration!$P$51:$Z$51,0)) -> #DIV/0! | Z6: =INDEX(calibration!$AC$52:$AM$66,MATCH(constants!Z$4,calibration!$AB$52:$AB$66,0),MATCH(constants!$A6,calibration!$P$51:$Z$51,0)) -> #DIV/0! | ... AH6: =INDEX(calibration!$AC$52:$AM$66,MATCH(constants!AH$4,calibration!$AB$52:$AB$66,0),MATCH(constants!$A6,calibration!$P$51:$Z$51,0)) -> #DIV/0!
A7: work | B7: Return Stops | S7: =INDEX(calibration!$AC$52:$AM$66,MATCH(S$5,calibration!$AB$52:$AB$66,0),MATCH(constants!$A7,calibration!$P$51:$Z$51,0)) -> 0 | T7: =INDEX(calibration!$AC$52:$AM$66,MATCH(T$5,calibration!$AB$52:$AB$66,0),MATCH(constants!$A7,calibration!$P$51:$Z$51,0)) -> #DIV/0! | U7: =INDEX(calibration!$AC$52:$AM$66,MATCH(U$5,calibration!$AB$52:$AB$66,0),MATCH(constants!$A7,calibration!$P$51:$Z$51,0)) -> #DIV/0! | V7: =INDEX(calibration!$AC$52:$AM$66,MATCH(V$5,calibration!$AB$52:$AB$66,0),MATCH(constants!$A7,calibration!$P$51:$Z$51,0)) -> #DIV/0! | W7: =INDEX(calibration!$AC$52:$AM$66,MATCH(W$5,calibration!$AB$52:$AB$66,0),MATCH(constants!$A7,calibration!$P$51:$Z$51,0)) -> 0 | X7: =INDEX(calibration!$AC$52:$AM$66,MATCH(X$5,calibration!$AB$52:$AB$66,0),MATCH(constants!$A7,calibration!$P$51:$Z$51,0)) -> #DIV/0! | Y7: =INDEX(calibration!$AC$52:$AM$66,MATCH(Y$5,calibration!$AB$52:$AB$66,0),MATCH(constants!$A7,calibration!$P$51:$Z$51,0)) -> #DIV/0! | Z7: =INDEX(calibration!$AC$52:$AM$66,MATCH(Z$5,calibration!$AB$52:$AB$66,0),MATCH(constants!$A7,calibration!$P$51:$Z$51,0)) -> #DIV/0! | ... AH7: =INDEX(calibration!$AC$52:$AM$66,MATCH(AH$5,calibration!$AB$52:$AB$66,0),MATCH(constants!$A7,calibration!$P$51:$Z$51,0)) -> #DIV/0!
A8: work | B8: Total Number of Stops | S8: =INDEX(calibration!$AC$52:$AM$66,MATCH(S$3,calibration!$AB$52:$AB$66,0),MATCH(constants!$A8,calibration!$P$51:$Z$51,0)) -> 0 | T8: =INDEX(calibration!$AC$52:$AM$66,MATCH(T$3,calibration!$AB$52:$AB$66,0),MATCH(constants!$A8,calibration!$P$51:$Z$51,0)) -> 0 | U8: =INDEX(calibration!$AC$52:$AM$66,MATCH(U$3,calibration!$AB$52:$AB$66,0),MATCH(constants!$A8,calibration!$P$51:$Z$51,0)) -> #DIV/0! | V8: =INDEX(calibration!$AC$52:$AM$66,MATCH(V$3,calibration!$AB$52:$AB$66,0),MATCH(constants!$A8,calibration!$P$51:$Z$51,0)) -> #DIV/0! | W8: =INDEX(calibration!$AC$52:$AM$66,MATCH(W$3,calibration!$AB$52:$AB$66,0),MATCH(constants!$A8,calibration!$P$51:$Z$51,0)) -> 0 | X8: =INDEX(calibration!$AC$52:$AM$66,MATCH(X$3,calibration!$AB$52:$AB$66,0),MATCH(constants!$A8,calibration!$P$51:$Z$51,0)) -> #DIV/0! | Y8: =INDEX(calibration!$AC$52:$AM$66,MATCH(Y$3,calibration!$AB$52:$AB$66,0),MATCH(constants!$A8,calibration!$P$51:$Z$51,0)) -> #DIV/0! | Z8: =INDEX(calibration!$AC$52:$AM$66,MATCH(Z$3,calibration!$AB$52:$AB$66,0),MATCH(constants!$A8,calibration!$P$51:$Z$51,0)) -> #DIV/0! | ... AH8: =INDEX(calibration!$AC$52:$AM$66,MATCH(AH$3,calibration!$AB$52:$AB$66,0),MATCH(constants!$A8,calibration!$P$51:$Z$51,0)) -> #DIV/0!
A9: university | B9: Outbound Stops | S9: =INDEX(calibration!$AC$52:$AM$66,MATCH(constants!S$4,calibration!$AB$52:$AB$66,0),MATCH(constants!$A9,calibration!$P$51:$Z$51,0)) -> 0 | T9: =INDEX(calibration!$AC$52:$AM$66,MATCH(constants!T$4,calibration!$AB$52:$AB$66,0),MATCH(constants!$A9,calibration!$P$51:$Z$51,0)) -> 0 | U9: =INDEX(calibration!$AC$52:$AM$66,MATCH(constants!U$4,calibration!$AB$52:$AB$66,0),MATCH(constants!$A9,calibration!$P$51:$Z$51,0)) -> 0 | V9: =INDEX(calibration!$AC$52:$AM$66,MATCH(constants!V$4,calibration!$AB$52:$AB$66,0),MATCH(constants!$A9,calibration!$P$51:$Z$51,0)) -> 0 | W9: =INDEX(calibration!$AC$52:$AM$66,MATCH(constants!W$4,calibration!$AB$52:$AB$66,0),MATCH(constants!$A9,calibration!$P$51:$Z$51,0)) -> #DIV/0! | X9: =INDEX(calibration!$AC$52:$AM$66,MATCH(constants!X$4,calibration!$AB$52:$AB$66,0),MATCH(constants!$A9,calibration!$P$51:$Z$51,0)) -> #DIV/0! | Y9: =INDEX(calibration!$AC$52:$AM$66,MATCH(constants!Y$4,calibration!$AB$52:$AB$66,0),MATCH(constants!$A9,calibration!$P$51:$Z$51,0)) -> #DIV/0! | Z9: =INDEX(calibration!$AC$52:$AM$66,MATCH(constants!Z$4,calibration!$AB$52:$AB$66,0),MATCH(constants!$A9,calibration!$P$51:$Z$51,0)) -> #DIV/0! | ... AH9: =INDEX(calibration!$AC$52:$AM$66,MATCH(constants!AH$4,calibration!$AB$52:$AB$66,0),MATCH(constants!$A9,calibration!$P$51:$Z$51,0)) -> #DIV/0!
A10: university | B10: Return Stops | S10: =INDEX(calibration!$AC$52:$AM$66,MATCH(S$5,calibration!$AB$52:$AB$66,0),MATCH(constants!$A10,calibration!$P$51:$Z$51,0)) -> 0 | T10: =INDEX(calibration!$AC$52:$AM$66,MATCH(T$5,calibration!$AB$52:$AB$66,0),MATCH(constants!$A10,calibration!$P$51:$Z$51,0)) -> #DIV/0! | U10: =INDEX(calibration!$AC$52:$AM$66,MATCH(U$5,calibration!$AB$52:$AB$66,0),MATCH(constants!$A10,calibration!$P$51:$Z$51,0)) -> #DIV/0! | V10: =INDEX(calibration!$AC$52:$AM$66,MATCH(V$5,calibration!$AB$52:$AB$66,0),MATCH(constants!$A10,calibration!$P$51:$Z$51,0)) -> #DIV/0! | W10: =INDEX(calibration!$AC$52:$AM$66,MATCH(W$5,calibration!$AB$52:$AB$66,0),MATCH(constants!$A10,calibration!$P$51:$Z$51,0)) -> 0 | X10: =INDEX(calibration!$AC$52:$AM$66,MATCH(X$5,calibration!$AB$52:$AB$66,0),MATCH(constants!$A10,calibration!$P$51:$Z$51,0)) -> #DIV/0! | Y10: =INDEX(calibration!$AC$52:$AM$66,MATCH(Y$5,calibration!$AB$52:$AB$66,0),MATCH(constants!$A10,calibration!$P$51:$Z$51,0)) -> #DIV/0! | Z10: =INDEX(calibration!$AC$52:$AM$66,MATCH(Z$5,calibration!$AB$52:$AB$66,0),MATCH(constants!$A10,calibration!$P$51:$Z$51,0)) -> #DIV/0! | ... AH10: =INDEX(calibration!$AC$52:$AM$66,MATCH(AH$5,calibration!$AB$52:$AB$66,0),MATCH(constants!$A10,calibration!$P$51:$Z$51,0)) -> #DIV/0!
A11: university | B11: Total Number of Stops | S11: =INDEX(calibration!$AC$52:$AM$66,MATCH(S$3,calibration!$AB$52:$AB$66,0),MATCH(constants!$A11,calibration!$P$51:$Z$51,0)) -> 0 | T11: =INDEX(calibration!$AC$52:$AM$66,MATCH(T$3,calibration!$AB$52:$AB$66,0),MATCH(constants!$A11,calibration!$P$51:$Z$51,0)) -> 0 | U11: =INDEX(calibration!$AC$52:$AM$66,MATCH(U$3,calibration!$AB$52:$AB$66,0),MATCH(constants!$A11,calibration!$P$51:$Z$51,0)) -> #DIV/0! | V11: =INDEX(calibration!$AC$52:$AM$66,MATCH(V$3,calibration!$AB$52:$AB$66,0),MATCH(constants!$A11,calibration!$P$51:$Z$51,0)) -> #DIV/0! | W11: =INDEX(calibration!$AC$52:$AM$66,MATCH(W$3,calibration!$AB$52:$AB$66,0),MATCH(constants!$A11,calibration!$P$51:$Z$51,0)) -> 0 | X11: =INDEX(calibration!$AC$52:$AM$66,MATCH(X$3,calibration!$AB$52:$AB$66,0),MATCH(constants!$A11,calibration!$P$51:$Z$51,0)) -> #DIV/0! | Y11: =INDEX(calibration!$AC$52:$AM$66,MATCH(Y$3,calibration!$AB$52:$AB$66,0),MATCH(constants!$A11,calibration!$P$51:$Z$51,0)) -> #DIV/0! | Z11: =INDEX(calibration!$AC$52:$AM$66,MATCH(Z$3,calibration!$AB$52:$AB$66,0),MATCH(constants!$A11,calibration!$P$51:$Z$51,0)) -> #DIV/0! | ... AH11: =INDEX(calibration!$AC$52:$AM$66,MATCH(AH$3,calibration!$AB$52:$AB$66,0),MATCH(constants!$A11,calibration!$P$51:$Z$51,0)) -> #DIV/0!
A12: school | B12: Outbound Stops | S12: =INDEX(calibration!$AC$52:$AM$66,MATCH(constants!S$4,calibration!$AB$52:$AB$66,0),MATCH(constants!$A12,calibration!$P$51:$Z$51,0)) -> 0 | T12: =INDEX(calibration!$AC$52:$AM$66,MATCH(constants!T$4,calibration!$AB$52:$AB$66,0),MATCH(constants!$A12,calibration!$P$51:$Z$51,0)) -> 0 | U12: =INDEX(calibration!$AC$52:$AM$66,MATCH(constants!U$4,calibration!$AB$52:$AB$66,0),MATCH(constants!$A12,calibration!$P$51:$Z$51,0)) -> 0 | V12: =INDEX(calibration!$AC$52:$AM$66,MATCH(constants!V$4,calibration!$AB$52:$AB$66,0),MATCH(constants!$A12,calibration!$P$51:$Z$51,0)) -> 0 | W12: =INDEX(calibration!$AC$52:$AM$66,MATCH(constants!W$4,calibration!$AB$52:$AB$66,0),MATCH(constants!$A12,calibration!$P$51:$Z$51,0)) -> #DIV/0! | X12: =INDEX(calibration!$AC$52:$AM$66,MATCH(constants!X$4,calibration!$AB$52:$AB$66,0),MATCH(constants!$A12,calibration!$P$51:$Z$51,0)) -> #DIV/0! | Y12: =INDEX(calibration!$AC$52:$AM$66,MATCH(constants!Y$4,calibration!$AB$52:$AB$66,0),MATCH(constants!$A12,calibration!$P$51:$Z$51,0)) -> #DIV/0! | Z12: =INDEX(calibration!$AC$52:$AM$66,MATCH(constants!Z$4,calibration!$AB$52:$AB$66,0),MATCH(constants!$A12,calibration!$P$51:$Z$51,0)) -> #DIV/0! | ... AH12: =INDEX(calibration!$AC$52:$AM$66,MATCH(constants!AH$4,calibration!$AB$52:$AB$66,0),MATCH(constants!$A12,calibration!$P$51:$Z$51,0)) -> #DIV/0!
A13: school | B13: Return Stops | S13: =INDEX(calibration!$AC$52:$AM$66,MATCH(S$5,calibration!$AB$52:$AB$66,0),MATCH(constants!$A13,calibration!$P$51:$Z$51,0)) -> 0 | T13: =INDEX(calibration!$AC$52:$AM$66,MATCH(T$5,calibration!$AB$52:$AB$66,0),MATCH(constants!$A13,calibration!$P$51:$Z$51,0)) -> #DIV/0! | U13: =INDEX(calibration!$AC$52:$AM$66,MATCH(U$5,calibration!$AB$52:$AB$66,0),MATCH(constants!$A13,calibration!$P$51:$Z$51,0)) -> #DIV/0! | V13: =INDEX(calibration!$AC$52:$AM$66,MATCH(V$5,calibration!$AB$52:$AB$66,0),MATCH(constants!$A13,calibration!$P$51:$Z$51,0)) -> #DIV/0! | W13: =INDEX(calibration!$AC$52:$AM$66,MATCH(W$5,calibration!$AB$52:$AB$66,0),MATCH(constants!$A13,calibration!$P$51:$Z$51,0)) -> 0 | X13: =INDEX(calibration!$AC$52:$AM$66,MATCH(X$5,calibration!$AB$52:$AB$66,0),MATCH(constants!$A13,calibration!$P$51:$Z$51,0)) -> #DIV/0! | Y13: =INDEX(calibration!$AC$52:$AM$66,MATCH(Y$5,calibration!$AB$52:$AB$66,0),MATCH(constants!$A13,calibration!$P$51:$Z$51,0)) -> #DIV/0! | Z13: =INDEX(calibration!$AC$52:$AM$66,MATCH(Z$5,calibration!$AB$52:$AB$66,0),MATCH(constants!$A13,calibration!$P$51:$Z$51,0)) -> #DIV/0! | ... AH13: =INDEX(calibration!$AC$52:$AM$66,MATCH(AH$5,calibration!$AB$52:$AB$66,0),MATCH(constants!$A13,calibration!$P$51:$Z$51,0)) -> #DIV/0!
A14: school | B14: Total Number of Stops | S14: =INDEX(calibration!$AC$52:$AM$66,MATCH(S$3,calibration!$AB$52:$AB$66,0),MATCH(constants!$A14,calibration!$P$51:$Z$51,0)) -> 0 | T14: =INDEX(calibration!$AC$52:$AM$66,MATCH(T$3,calibration!$AB$52:$AB$66,0),MATCH(constants!$A14,calibration!$P$51:$Z$51,0)) -> 0 | U14: =INDEX(calibration!$AC$52:$AM$66,MATCH(U$3,calibration!$AB$52:$AB$66,0),MATCH(constants!$A14,calibration!$P$51:$Z$51,0)) -> #DIV/0! | V14: =INDEX(calibration!$AC$52:$AM$66,MATCH(V$3,calibration!$AB$52:$AB$66,0),MATCH(constants!$A14,calibration!$P$51:$Z$51,0)) -> #DIV/0! | W14: =INDEX(calibration!$AC$52:$AM$66,MATCH(W$3,calibration!$AB$52:$AB$66,0),MATCH(constants!$A14,calibration!$P$51:$Z$51,0)) -> 0 | X14: =INDEX(calibration!$AC$52:$AM$66,MATCH(X$3,calibration!$AB$52:$AB$66,0),MATCH(constants!$A14,calibration!$P$51:$Z$51,0)) -> #DIV/0! | Y14: =INDEX(calibration!$AC$52:$AM$66,MATCH(Y$3,calibration!$AB$52:$AB$66,0),MATCH(constants!$A14,calibration!$P$51:$Z$51,0)) -> #DIV/0! | Z14: =INDEX(calibration!$AC$52:$AM$66,MATCH(Z$3,calibration!$AB$52:$AB$66,0),MATCH(constants!$A14,calibration!$P$51:$Z$51,0)) -> #DIV/0! | ... AH14: =INDEX(calibration!$AC$52:$AM$66,MATCH(AH$3,calibration!$AB$52:$AB$66,0),MATCH(constants!$A14,calibration!$P$51:$Z$51,0)) -> #DIV/0!
A15: escort | B15: Outbound Stops | S15: =INDEX(calibration!$AC$52:$AM$66,MATCH(constants!S$4,calibration!$AB$52:$AB$66,0),MATCH(constants!$A15,calibration!$P$51:$Z$51,0)) -> 0 | T15: =INDEX(calibration!$AC$52:$AM$66,MATCH(constants!T$4,calibration!$AB$52:$AB$66,0),MATCH(constants!$A15,calibration!$P$51:$Z$51,0)) -> 0 | U15: =INDEX(calibration!$AC$52:$AM$66,MATCH(constants!U$4,calibration!$AB$52:$AB$66,0),MATCH(constants!$A15,calibration!$P$51:$Z$51,0)) -> 0 | V15: =INDEX(calibration!$AC$52:$AM$66,MATCH(constants!V$4,calibration!$AB$52:$AB$66,0),MATCH(constants!$A15,calibration!$P$51:$Z$51,0)) -> 0 | W15: =INDEX(calibration!$AC$52:$AM$66,MATCH(constants!W$4,calibration!$AB$52:$AB$66,0),MATCH(constants!$A15,calibration!$P$51:$Z$51,0)) -> #DIV/0! | X15: =INDEX(calibration!$AC$52:$AM$66,MATCH(constants!X$4,calibration!$AB$52:$AB$66,0),MATCH(constants!$A15,calibration!$P$51:$Z$51,0)) -> #DIV/0! | Y15: =INDEX(calibration!$AC$52:$AM$66,MATCH(constants!Y$4,calibration!$AB$52:$AB$66,0),MATCH(constants!$A15,calibration!$P$51:$Z$51,0)) -> #DIV/0! | Z15: =INDEX(calibration!$AC$52:$AM$66,MATCH(constants!Z$4,calibration!$AB$52:$AB$66,0),MATCH(constants!$A15,calibration!$P$51:$Z$51,0)) -> #DIV/0! | ... AH15: =INDEX(calibration!$AC$52:$AM$66,MATCH(constants!AH$4,calibration!$AB$52:$AB$66,0),MATCH(constants!$A15,calibration!$P$51:$Z$51,0)) -> #DIV/0!
A16: escort | B16: Return Stops | S16: =INDEX(calibration!$AC$52:$AM$66,MATCH(S$5,calibration!$AB$52:$AB$66,0),MATCH(constants!$A16,calibration!$P$51:$Z$51,0)) -> 0 | T16: =INDEX(calibration!$AC$52:$AM$66,MATCH(T$5,calibration!$AB$52:$AB$66,0),MATCH(constants!$A16,calibration!$P$51:$Z$51,0)) -> #DIV/0! | U16: =INDEX(calibration!$AC$52:$AM$66,MATCH(U$5,calibration!$AB$52:$AB$66,0),MATCH(constants!$A16,calibration!$P$51:$Z$51,0)) -> #DIV/0! | V16: =INDEX(calibration!$AC$52:$AM$66,MATCH(V$5,calibration!$AB$52:$AB$66,0),MATCH(constants!$A16,calibration!$P$51:$Z$51,0)) -> #DIV/0! | W16: =INDEX(calibration!$AC$52:$AM$66,MATCH(W$5,calibration!$AB$52:$AB$66,0),MATCH(constants!$A16,calibration!$P$51:$Z$51,0)) -> 0 | X16: =INDEX(calibration!$AC$52:$AM$66,MATCH(X$5,calibration!$AB$52:$AB$66,0),MATCH(constants!$A16,calibration!$P$51:$Z$51,0)) -> #DIV/0! | Y16: =INDEX(calibration!$AC$52:$AM$66,MATCH(Y$5,calibration!$AB$52:$AB$66,0),MATCH(constants!$A16,calibration!$P$51:$Z$51,0)) -> #DIV/0! | Z16: =INDEX(calibration!$AC$52:$AM$66,MATCH(Z$5,calibration!$AB$52:$AB$66,0),MATCH(constants!$A16,calibration!$P$51:$Z$51,0)) -> #DIV/0! | ... AH16: =INDEX(calibration!$AC$52:$AM$66,MATCH(AH$5,calibration!$AB$52:$AB$66,0),MATCH(constants!$A16,calibration!$P$51:$Z$51,0)) -> #DIV/0!
A17: escort | B17: Total Number of Stops | S17: =INDEX(calibration!$AC$52:$AM$66,MATCH(S$3,calibration!$AB$52:$AB$66,0),MATCH(constants!$A17,calibration!$P$51:$Z$51,0)) -> 0 | T17: =INDEX(calibration!$AC$52:$AM$66,MATCH(T$3,calibration!$AB$52:$AB$66,0),MATCH(constants!$A17,calibration!$P$51:$Z$51,0)) -> 0 | U17: =INDEX(calibration!$AC$52:$AM$66,MATCH(U$3,calibration!$AB$52:$AB$66,0),MATCH(constants!$A17,calibration!$P$51:$Z$51,0)) -> #DIV/0! | V17: =INDEX(calibration!$AC$52:$AM$66,MATCH(V$3,calibration!$AB$52:$AB$66,0),MATCH(constants!$A17,calibration!$P$51:$Z$51,0)) -> #DIV/0! | W17: =INDEX(calibration!$AC$52:$AM$66,MATCH(W$3,calibration!$AB$52:$AB$66,0),MATCH(constants!$A17,calibration!$P$51:$Z$51,0)) -> 0 | X17: =INDEX(calibration!$AC$52:$AM$66,MATCH(X$3,calibration!$AB$52:$AB$66,0),MATCH(constants!$A17,calibration!$P$51:$Z$51,0)) -> #DIV/0! | Y17: =INDEX(calibration!$AC$52:$AM$66,MATCH(Y$3,calibration!$AB$52:$AB$66,0),MATCH(constants!$A17,calibration!$P$51:$Z$51,0)) -> #DIV/0! | Z17: =INDEX(calibration!$AC$52:$AM$66,MATCH(Z$3,calibration!$AB$52:$AB$66,0),MATCH(constants!$A17,calibration!$P$51:$Z$51,0)) -> #DIV/0! | ... AH17: =INDEX(calibration!$AC$52:$AM$66,MATCH(AH$3,calibration!$AB$52:$AB$66,0),MATCH(constants!$A17,calibration!$P$51:$Z$51,0)) -> #DIV/0!
A18: shop | B18: Outbound Stops | S18: =INDEX(calibration!$AC$52:$AM$66,MATCH(constants!S$4,calibration!$AB$52:$AB$66,0),MATCH(constants!$A18,calibration!$P$51:$Z$51,0)) -> 0 | T18: =INDEX(calibration!$AC$52:$AM$66,MATCH(constants!T$4,calibration!$AB$52:$AB$66,0),MATCH(constants!$A18,calibration!$P$51:$Z$51,0)) -> 0 | U18: =INDEX(calibration!$AC$52:$AM$66,MATCH(constants!U$4,calibration!$AB$52:$AB$66,0),MATCH(constants!$A18,calibration!$P$51:$Z$51,0)) -> 0 | V18: =INDEX(calibration!$AC$52:$AM$66,MATCH(constants!V$4,calibration!$AB$52:$AB$66,0),MATCH(constants!$A18,calibration!$P$51:$Z$51,0)) -> 0 | W18: =INDEX(calibration!$AC$52:$AM$66,MATCH(constants!W$4,calibration!$AB$52:$AB$66,0),MATCH(constants!$A18,calibration!$P$51:$Z$51,0)) -> #DIV/0! | X18: =INDEX(calibration!$AC$52:$AM$66,MATCH(constants!X$4,calibration!$AB$52:$AB$66,0),MATCH(constants!$A18,calibration!$P$51:$Z$51,0)) -> #DIV/0! | Y18: =INDEX(calibration!$AC$52:$AM$66,MATCH(constants!Y$4,calibration!$AB$52:$AB$66,0),MATCH(constants!$A18,calibration!$P$51:$Z$51,0)) -> #DIV/0! | Z18: =INDEX(calibration!$AC$52:$AM$66,MATCH(constants!Z$4,calibration!$AB$52:$AB$66,0),MATCH(constants!$A18,calibration!$P$51:$Z$51,0)) -> #DIV/0! | ... AH18: =INDEX(calibration!$AC$52:$AM$66,MATCH(constants!AH$4,calibration!$AB$52:$AB$66,0),MATCH(constants!$A18,calibration!$P$51:$Z$51,0)) -> #DIV/0!
A19: shop | B19: Return Stops | S19: =INDEX(calibration!$AC$52:$AM$66,MATCH(S$5,calibration!$AB$52:$AB$66,0),MATCH(constants!$A19,calibration!$P$51:$Z$51,0)) -> 0 | T19: =INDEX(calibration!$AC$52:$AM$66,MATCH(T$5,calibration!$AB$52:$AB$66,0),MATCH(constants!$A19,calibration!$P$51:$Z$51,0)) -> #DIV/0! | U19: =INDEX(calibration!$AC$52:$AM$66,MATCH(U$5,calibration!$AB$52:$AB$66,0),MATCH(constants!$A19,calibration!$P$51:$Z$51,0)) -> #DIV/0! | V19: =INDEX(calibration!$AC$52:$AM$66,MATCH(V$5,calibration!$AB$52:$AB$66,0),MATCH(constants!$A19,calibration!$P$51:$Z$51,0)) -> #DIV/0! | W19: =INDEX(calibration!$AC$52:$AM$66,MATCH(W$5,calibration!$AB$52:$AB$66,0),MATCH(constants!$A19,calibration!$P$51:$Z$51,0)) -> 0 | X19: =INDEX(calibration!$AC$52:$AM$66,MATCH(X$5,calibration!$AB$52:$AB$66,0),MATCH(constants!$A19,calibration!$P$51:$Z$51,0)) -> #DIV/0! | Y19: =INDEX(calibration!$AC$52:$AM$66,MATCH(Y$5,calibration!$AB$52:$AB$66,0),MATCH(constants!$A19,calibration!$P$51:$Z$51,0)) -> #DIV/0! | Z19: =INDEX(calibration!$AC$52:$AM$66,MATCH(Z$5,calibration!$AB$52:$AB$66,0),MATCH(constants!$A19,calibration!$P$51:$Z$51,0)) -> #DIV/0! | ... AH19: =INDEX(calibration!$AC$52:$AM$66,MATCH(AH$5,calibration!$AB$52:$AB$66,0),MATCH(constants!$A19,calibration!$P$51:$Z$51,0)) -> #DIV/0!
A20: shop | B20: Total Number of Stops | S20: =INDEX(calibration!$AC$52:$AM$66,MATCH(S$3,calibration!$AB$52:$AB$66,0),MATCH(constants!$A20,calibration!$P$51:$Z$51,0)) -> 0 | T20: =INDEX(calibration!$AC$52:$AM$66,MATCH(T$3,calibration!$AB$52:$AB$66,0),MATCH(constants!$A20,calibration!$P$51:$Z$51,0)) -> 0 | U20: =INDEX(calibration!$AC$52:$AM$66,MATCH(U$3,calibration!$AB$52:$AB$66,0),MATCH(constants!$A20,calibration!$P$51:$Z$51,0)) -> #DIV/0! | V20: =INDEX(calibration!$AC$52:$AM$66,MATCH(V$3,calibration!$AB$52:$AB$66,0),MATCH(constants!$A20,calibration!$P$51:$Z$51,0)) -> #DIV/0! | W20: =INDEX(calibration!$AC$52:$AM$66,MATCH(W$3,calibration!$AB$52:$AB$66,0),MATCH(constants!$A20,calibration!$P$51:$Z$51,0)) -> 0 | X20: =INDEX(calibration!$AC$52:$AM$66,MATCH(X$3,calibration!$AB$52:$AB$66,0),MATCH(constants!$A20,calibration!$P$51:$Z$51,0)) -> #DIV/0! | Y20: =INDEX(calibration!$AC$52:$AM$66,MATCH(Y$3,calibration!$AB$52:$AB$66,0),MATCH(constants!$A20,calibration!$P$51:$Z$51,0)) -> #DIV/0! | Z20: =INDEX(calibration!$AC$52:$AM$66,MATCH(Z$3,calibration!$AB$52:$AB$66,0),MATCH(constants!$A20,calibration!$P$51:$Z$51,0)) -> #DIV/0! | ... AH20: =INDEX(calibration!$AC$52:$AM$66,MATCH(AH$3,calibration!$AB$52:$AB$66,0),MATCH(constants!$A20,calibration!$P$51:$Z$51,0)) -> #DIV/0!
A21: maintenance | B21: Outbound Stops | S21: =INDEX(calibration!$AC$52:$AM$66,MATCH(constants!S$4,calibration!$AB$52:$AB$66,0),MATCH(constants!$A21,calibration!$P$51:$Z$51,0)) -> 0 | T21: =INDEX(calibration!$AC$52:$AM$66,MATCH(constants!T$4,calibration!$AB$52:$AB$66,0),MATCH(constants!$A21,calibration!$P$51:$Z$51,0)) -> 0 | U21: =INDEX(calibration!$AC$52:$AM$66,MATCH(constants!U$4,calibration!$AB$52:$AB$66,0),MATCH(constants!$A21,calibration!$P$51:$Z$51,0)) -> 0 | V21: =INDEX(calibration!$AC$52:$AM$66,MATCH(constants!V$4,calibration!$AB$52:$AB$66,0),MATCH(constants!$A21,calibration!$P$51:$Z$51,0)) -> 0 | W21: =INDEX(calibration!$AC$52:$AM$66,MATCH(constants!W$4,calibration!$AB$52:$AB$66,0),MATCH(constants!$A21,calibration!$P$51:$Z$51,0)) -> #DIV/0! | X21: =INDEX(calibration!$AC$52:$AM$66,MATCH(constants!X$4,calibration!$AB$52:$AB$66,0),MATCH(constants!$A21,calibration!$P$51:$Z$51,0)) -> #DIV/0! | Y21: =INDEX(calibration!$AC$52:$AM$66,MATCH(constants!Y$4,calibration!$AB$52:$AB$66,0),MATCH(constants!$A21,calibration!$P$51:$Z$51,0)) -> #DIV/0! | Z21: =INDEX(calibration!$AC$52:$AM$66,MATCH(constants!Z$4,calibration!$AB$52:$AB$66,0),MATCH(constants!$A21,calibration!$P$51:$Z$51,0)) -> #DIV/0! | ... AH21: =INDEX(calibration!$AC$52:$AM$66,MATCH(constants!AH$4,calibration!$AB$52:$AB$66,0),MATCH(constants!$A21,calibration!$P$51:$Z$51,0)) -> #DIV/0!
