Workbook
Name runA: 'Emission Factors'!$B$6
Name runB: 'Emission Factors'!$C$6
Name runC: 'Emission Factors'!$D$6
Name tripA: 'Emission Factors'!$B$10
Name tripB: 'Emission Factors'!$C$10
Name tripC: 'Emission Factors'!$D$10

Sheet Main Sheet
A1: Bike Share
A2: Inputs
A3: Variable | B3: Value | F3: Source/Notes
A4: VMT reductions due to bike share
A5: VMT displaced / trip (bike + transit) - Conventional Bike | B5: 0.75 | F5: Volker, Handy, Kendall, & Barbour, 2020
A6: VMT displaced / trip (bike + transit) - e-Bike | B6: 1.3 | F6: Calculated based on Rzepecki, 2019, applying the adjustment factor from Volker, Handy, Kendall, & Barbour, 2020
A7: Baseline service conditions (2022) | B7: Baseline | C7: 2035 | D7: 2050
A8: Total population | B8: 7516241 | F8: ACS 1-Year 2022
A9: Bikes available | B9: 6040 | C9: 9000 | D9: 9000 | F9: MTC Data (7,575 bikes by 2024, extrapolation to 2035)
A10: Daily trips on bike share | B10: =Research!E35 -> 7164 | C10: =B10*(1+(C9-B9)/B9) -> 10674.834 | D10: =C10*(1+(D9-C9)/C9) -> 10674.834 | F10: Lyft Bay Wheels System Data from January-December 2022
A11: Percent e-bikes | B11: 0.3 | C11: 1 | D11: 1 | F11: Lyft system data and MTC assumption about industry trends
C14: 2035_TM160_IPA_17
A15: Variable | C15: 2035 | D15: 2050 | F15: Source/Notes
A16: Model Outputs | E16: Lookup Value
A17: Total population | C17: {=IFERROR(INDEX('Model Data'!$F:$F,MATCH(1,($C$14='Model Data'!$D:$D)*($E17='Model Data'!$E:$E),0)),"")} -> 8476332 | D17: {=IFERROR(INDEX('Model Data'!$F:$F,MATCH(1,($D$14='Model Data'!$D:$D)*($E17='Model Data'!$E:$E),0)),"")} | E17: total_population | F17: TazData, TOTPOP field
A18: Total jobs | C18: {=IFERROR(INDEX('Model Data'!$F:$F,MATCH(1,($C$14='Model Data'!$D:$D)*($E18='Model Data'!$E:$E),0)),"")} -> 4854742 | D18: {=IFERROR(INDEX('Model Data'!$F:$F,MATCH(1,($D$14='Model Data'!$D:$D)*($E18='Model Data'!$E:$E),0)),"")} | E18: total_employment | F18: TazData, TOTEMP field
A19: % population growth since baseline year | C19: =IFERROR(C17/$B$8-1,"") -> 0.12773553 | D19: =IFERROR(D17/$B$8-1,"")
A20: Results
A21: Estimated daily bike share trips | C21: =IFERROR((1+C19)*$C$10,"") -> 12038.39 | D21: =IFERROR((1+D19)*$C$10,"")
A22: Total daily VMT reductions | C22: =IFERROR((C$21*(1-C$11)*$B$5)+((C$21*C$11)*$B$6),"") -> 15649.907 | D22: =IFERROR((D$21*(1-D$11)*$B$5)+((D$21*D$11)*$B$6),"")
A23: Total daily GHG reductions (tons) | C23: =IFERROR(C21*INDEX('Emission Factors'!$10:$10,,MATCH(C15,'Emission Factors'!$2:$2,0))+C22*INDEX('Emission Factors'!$6:$6,,MATCH(C15,'Emission Factors'!$2:$2,0)),"") -> 7.1002424 | D23: =IFERROR(D21*INDEX('Emission Factors'!$10:$10,,MATCH(D15,'Emission Factors'!$2:$2,0))+D22*INDEX('Emission Factors'!$6:$6,,MATCH(D15,'Emission Factors'!$2:$2,0)),"")
A24: Per capita GHG reductions | C24: {=IFERROR(-C23/INDEX('Model Data'!$F:$F,MATCH(1,(C$14='Model Data'!$D:$D)*($E24='Model Data'!$E:$E),0))/('SB 375 calcs'!B3/'SB 375 calcs'!B2),"")} -> -9.5763531e-05 | D24: {=IFERROR(-D23/INDEX('Model Data'!$F:$F,MATCH(1,(D$14='Model Data'!$D:$D)*($E24='Model Data'!$E:$E),0))/('SB 375 calcs'!B3/'SB 375 calcs'!B2),"")} | E24: total_pop_popsyn

Sheet Research
A1: Bikeshare Ridership
K2: City | L2: Planned Bikes | M2: Bikes Deployed | N2: % Complete
K3: Berkeley | L3: 400 | M3: 1500 | N3: 1
K4: Emeryville | L4: 100 | N4: 1
K5: Oakland | L5: 850 | N5: 1
K6: San Francisco | L6: 4500 | M6: 2000 | N6: 0.44
K7: San Jose | L7: 1000 | M7: 500 | N7: 0.5
K8: Total | L8: 7000 | M8: 4000 | N8: 0.57
K9: Source: MTC
A10: Bikeshare Availability (May-October 2019); Source: Lyft Bay Wheels System Data (https://www.lyft.com/bikes/bay-wheels/system-data)
A11: City | B11: 43586 | C11: 43587 | D11: 43588 | E11: 43589 | F11: 43590 | G11: 43591 | H11: 43592 | I11: 43593 | J11: 43594 | K11: 43595 | L11: 43596 | M11: 43597 | N11: 43598 | O11: 43599 | P11: 43600 | Q11: 43601 | R11: 43602 | S11: 43603 | T11: 43604 | U11: 43605 | V11: 43606 | W11: 43607 | X11: 43608 | Y11: 43609 | Z11: 43610 | AA11: 43611 | AB11: 43612 | AC11: 43613 | AD11: 43614 | AE11: 43615 | AF11: 43616 | AG11: 43617 | AH11: 43618 | AI11: 43619 | AJ11: 43620 | AK11: 43621 | AL11: 43622 | AM11: 43623 | AN11: 43624 | AO11: 43625 | AP11: 43626 | AQ11: 43627 | AR11: 43628 | AS11: 43629 | AT11: 43630 | AU11: 43631 | AV11: 43632 | AW11: 43633 | AX11: 43634 | AY11: 43635 | AZ11: 43636 | BA11: 43637 | BB11: 43638 | BC11: 43639 | BD11: 43640 | BE11: 43641 | BF11: 43642 | BG11: 43643 | BH11: 43644 | BI11: 43645 | BJ11: 43646 | BK11: 43647 | BL11: 43648 | BM11: 43649 | BN11: 43650 | BO11: 43651 | BP11: 43652 | BQ11: 43653 | BR11: 43654 | BS11: 43655 | BT11: 43656 | BU11: 43657 | BV11: 43658 | BW11: 43659 | BX11: 43660 | BY11: 43661 | BZ11: 43662 | CA11: 43663 | CB11: 43664 | CC11: 43665 | CD11: 43666 | CE11: 43667 | CF11: 43668 | CG11: 43669 | CH11: 43670 | CI11: 43671 | CJ11: 43672 | CK11: 43673 | CL11: 43674 | CM11: 43675 | CN11: 43676 | CO11: 43677 | CP11: 43678 | CQ11: 43679 | CR11: 43680 | CS11: 43681 | CT11: 43682 | CU11: 43683 | CV11: 43684 | CW11: 43685 | CX11: 43686 | CY11: 43687 | CZ11: 43688 | DA11: 43689 | DB11: 43690 | DC11: 43691 | DD11: 43692 | DE11: 43693 | DF11: 43694 | DG11: 43695 | DH11: 43696 | DI11: 43697 | DJ11: 43698 | DK11: 43699 | DL11: 43700 | DM11: 43701 | DN11: 43702 | DO11: 43703 | DP11: 43704 | DQ11: 43705 | DR11: 43706 | DS11: 43707 | DT11: 43708 | DU11: 43709 | DV11: 43710 | DW11: 43711 | DX11: 43712 | DY11: 43713 | DZ11: 43714 | EA11: 43715 | EB11: 43716 | EC11: 43717 | ED11: 43718 | EE11: 43719 | EF11: 43720 | EG11: 43721 | EH11: 43722 | EI11: 43723 | EJ11: 43724 | EK11: 43725 | EL11: 43726 | EM11: 43727 | EN11: 43728 | EO11: 43729 | EP11: 43730 | EQ11: 43731 | ER11: 43732 | ES11: 43733 | ET11: 43734 | EU11: 43735 | EV11: 43736 | EW11: 43737 | EX11: 43738 | EY11: 43739 | EZ11: 43740 | FA11: 43741 | FB11: 43742 | FC11: 43743 | FD11: 43744 | FE11: 43745 | FF11: 43746 | FG11: 43747 | FH11: 43748 | FI11: 43749 | FJ11: 43750 | FK11: 43751 | FL11: 43752 | FM11: 43753 | FN11: 43754 | FO11: 43755 | FP11: 43756 | FQ11: 43757 | FR11: 43758 | FS11: 43759 | FT11: 43760 | FU11: 43761 | FV11: 43762 | FW11: 43763 | FX11: 43764 | FY11: 43765 | FZ11: 43766 | GA11: 43767 | GB11: 43768 | GC11: 43769
A12: Berkeley | B12: 245 | C12: 245 | D12: 257 | E12: 293 | F12: 285 | G12: 257 | H12: 261 | I12: 257 | J12: 244 | K12: 254 | L12: 276 | M12: 272 | N12: 286 | O12: 297 | P12: 297 | Q12: 307 | R12: 311 | S12: 317 | T12: 331 | U12: 332 | V12: 327 | W12: 324 | X12: 304 | Y12: 297 | Z12: 291 | AA12: 291 | AB12: 279 | AC12: 271 | AD12: 289 | AE12: 290 | AF12: 291 | AG12: 304 | AH12: 287 | AI12: 296 | AJ12: 327 | AK12: 305 | AL12: 255 | AM12: 250 | AN12: 243 | AO12: 233 | AP12: 221 | AQ12: 232 | AR12: 263 | AS12: 235 | AT12: 219 | AU12: 209 | AV12: 192 | AW12: 200 | AX12: 198 | AY12: 189 | AZ12: 196 | BA12: 191 | BB12: 193 | BC12: 187 | BD12: 176 | BE12: 156 | BF12: 166 | BG12: 163 | BH12: 176 | BI12: 174 | BJ12: 173 | BK12: 196 | BL12: 210 | BM12: 221 | BN12: 215 | BO12: 232 | BP12: 219 | BQ12: 237 | BR12: 266 | BS12: 231 | BT12: 223 | BU12: 218 | BV12: 216 | BW12: 226 | BX12: 212 | BY12: 201 | BZ12: 200 | CA12: 189 | CB12: 200 | CC12: 218 | CD12: 193 | CE12: 194 | CF12: 182 | CG12: 184 | CH12: 183 | CI12: 191 | CJ12: 184 | CK12: 204 | CL12: 204 | CM12: 217 | CN12: 217 | CO12: 208 | CP12: 211 | CQ12: 183 | CR12: 197 | CS12: 278 | CT12: 283 | CU12: 289 | CV12: 290 | CW12: 285 | CX12: 264 | CY12: 284 | CZ12: 302 | DA12: 322 | DB12: 336 | DC12: 333 | DD12: 318 | DE12: 303 | DF12: 284 | DG12: 315 | DH12: 338 | DI12: 315 | DJ12: 319 | DK12: 323 | DL12: 322 | DM12: 319 | DN12: 334 | DO12: 290 | DP12: 297 | DQ12: 265 | DR12: 288 | DS12: 288 | DT12: 298 | DU12: 311 | DV12: 315 | DW12: 337 | DX12: 316 | DY12: 293 | DZ12: 294 | EA12: 294 | EB12: 275 | EC12: 303 | ED12: 305 | EE12: 313 | EF12: 324 | EG12: 321 | EH12: 307 | EI12: 315 | EJ12: 367 | EK12: 379 | EL12: 366 | EM12: 358 | EN12: 359 | EO12: 299 | EP12: 308 | EQ12: 351 | ER12: 448 | ES12: 418 | ET12: 444 | EU12: 446 | EV12: 465 | EW12: 438 | EX12: 459 | EY12: 439 | EZ12: 407 | FA12: 380 | FB12: 361 | FC12: 374 | FD12: 368 | FE12: 406 | FF12: 352 | FG12: 315 | FH12: 309 | FI12: 331 | FJ12: 368 | FK12: 370 | FL12: 379 | FM12: 400 | FN12: 395 | FO12: 377 | FP12: 382 | FQ12: 377 | FR12: 356 | FS12: 390 | FT12: 398 | FU12: 374 | FV12: 371 | FW12: 402 | FX12: 386 | FY12: 395 | FZ12: 380 | GA12: 385 | GB12: 359 | GC12: 404
A13: Emeryville | B13: 94 | C13: 88 | D13: 82 | E13: 81 | F13: 82 | G13: 83 | H13: 80 | I13: 81 | J13: 76 | K13: 77 | L13: 77 | M13: 62 | N13: 74 | O13: 77 | P13: 87 | Q13: 81 | R13: 78 | S13: 77 | T13: 79 | U13: 86 | V13: 78 | W13: 84 | X13: 89 | Y13: 96 | Z13: 90 | AA13: 86 | AB13: 98 | AC13: 102 | AD13: 88 | AE13: 74 | AF13: 72 | AG13: 74 | AH13: 87 | AI13: 94 | AJ13: 80 | AK13: 104 | AL13: 96 | AM13: 114 | AN13: 116 | AO13: 126 | AP13: 157 | AQ13: 135 | AR13: 130 | AS13: 143 | AT13: 166 | AU13: 159 | AV13: 169 | AW13: 145 | AX13: 129 | AY13: 137 | AZ13: 120 | BA13: 106 | BB13: 99 | BC13: 98 | BD13: 125 | BE13: 131 | BF13: 120 | BG13: 105 | BH13: 105 | BI13: 103 | BJ13: 107 | BK13: 114 | BL13: 96 | BM13: 107 | BN13: 115 | BO13: 103 | BP13: 114 | BQ13: 113 | BR13: 116 | BS13: 116 | BT13: 127 | BU13: 114 | BV13: 127 | BW13: 115 | BX13: 109 | BY13: 115 | BZ13: 115 | CA13: 124 | CB13: 132 | CC13: 116 | CD13: 128 | CE13: 128 | CF13: 142 | CG13: 130 | CH13: 127 | CI13: 127 | CJ13: 159 | CK13: 131 | CL13: 123 | CM13: 133 | CN13: 143 | CO13: 141 | CP13: 135 | CQ13: 125 | CR13: 120 | CS13: 95 | CT13: 80 | CU13: 79 | CV13: 66 | CW13: 75 | CX13: 87 | CY13: 73 | CZ13: 85 | DA13: 81 | DB13: 97 | DC13: 85 | DD13: 88 | DE13: 102 | DF13: 78 | DG13: 79 | DH13: 72 | DI13: 88 | DJ13: 90 | DK13: 112 | DL13: 95 | DM13: 88 | DN13: 77 | DO13: 86 | DP13: 95 | DQ13: 108 | DR13: 111 | DS13: 104 | DT13: 93 | DU13: 83 | DV13: 78 | DW13: 78 | DX13: 91 | DY13: 98 | DZ13: 108 | EA13: 97 | EB13: 115 | EC13: 102 | ED13: 109 | EE13: 113 | EF13: 113 | EG13: 116 | EH13: 128 | EI13: 123 | EJ13: 123 | EK13: 122 | EL13: 108 | EM13: 118 | EN13: 120 | EO13: 122 | EP13: 116 | EQ13: 119 | ER13: 140 | ES13: 156 | ET13: 169 | EU13: 181 | EV13: 147 | EW13: 124 | EX13: 110 | EY13: 118 | EZ13: 118 | FA13: 119 | FB13: 135 | FC13: 114 | FD13: 106 | FE13: 91 | FF13: 127 | FG13: 143 | FH13: 123 | FI13: 117 | FJ13: 130 | FK13: 133 | FL13: 145 | FM13: 139 | FN13: 127 | FO13: 121 | FP13: 140 | FQ13: 131 | FR13: 128 | FS13: 111 | FT13: 122 | FU13: 123 | FV13: 108 | FW13: 114 | FX13: 120 | FY13: 109 | FZ13: 115 | GA13: 111 | GB13: 121 | GC13: 137
A14: Oakland | B14: 474 | C14: 474 | D14: 486 | E14: 443 | F14: 459 | G14: 491 | H14: 497 | I14: 514 | J14: 543 | K14: 542 | L14: 523 | M14: 548 | N14: 539 | O14: 530 | P14: 527 | Q14: 535 | R14: 532 | S14: 538 | T14: 536 | U14: 532 | V14: 546 | W14: 542 | X14: 572 | Y14: 578 | Z14: 579 | AA14: 581 | AB14: 577 | AC14: 591 | AD14: 586 | AE14: 608 | AF14: 606 | AG14: 585 | AH14: 592 | AI14: 580 | AJ14: 546 | AK14: 557 | AL14: 598 | AM14: 607 | AN14: 597 | AO14: 592 | AP14: 563 | AQ14: 591 | AR14: 569 | AS14: 588 | AT14: 568 | AU14: 583 | AV14: 596 | AW14: 607 | AX14: 624 | AY14: 638 | AZ14: 654 | BA14: 662 | BB14: 654 | BC14: 665 | BD14: 659 | BE14: 663 | BF14: 663 | BG14: 664 | BH14: 650 | BI14: 654 | BJ14: 647 | BK14: 646 | BL14: 647 | BM14: 638 | BN14: 617 | BO14: 648 | BP14: 651 | BQ14: 638 | BR14: 596 | BS14: 626 | BT14: 682 | BU14: 746 | BV14: 782 | BW14: 809 | BX14: 863 | BY14: 910 | BZ14: 930 | CA14: 947 | CB14: 948 | CC14: 928 | CD14: 877 | CE14: 890 | CF14: 839 | CG14: 872 | CH14: 811 | CI14: 795 | CJ14: 801 | CK14: 759 | CL14: 756 | CM14: 711 | CN14: 769 | CO14: 737 | CP14: 636 | CQ14: 625 | CR14: 601 | CS14: 555 | CT14: 509 | CU14: 488 | CV14: 449 | CW14: 459 | CX14: 520 | CY14: 518 | CZ14: 507 | DA14: 473 | DB14: 452 | DC14: 447 | DD14: 500 | DE14: 504 | DF14: 545 | DG14: 517 | DH14: 496 | DI14: 533 | DJ14: 531 | DK14: 518 | DL14: 553 | DM14: 574 | DN14: 554 | DO14: 572 | DP14: 563 | DQ14: 591 | DR14: 562 | DS14: 568 | DT14: 561 | DU14: 574 | DV14: 583 | DW14: 563 | DX14: 578 | DY14: 597 | DZ14: 598 | EA14: 593 | EB14: 597 | EC14: 587 | ED14: 610 | EE14: 669 | EF14: 731 | EG14: 798 | EH14: 810 | EI14: 774 | EJ14: 727 | EK14: 717 | EL14: 690 | EM14: 659 | EN14: 711 | EO14: 775 | EP14: 749 | EQ14: 711 | ER14: 714 | ES14: 824 | ET14: 885 | EU14: 906 | EV14: 904 | EW14: 907 | EX14: 818 | EY14: 822 | EZ14: 811 | FA14: 825 | FB14: 844 | FC14: 853 | FD14: 827 | FE14: 853 | FF14: 857 | FG14: 894 | FH14: 918 | FI14: 886 | FJ14: 850 | FK14: 852 | FL14: 832 | FM14: 832 | FN14: 801 | FO14: 795 | FP14: 836 | FQ14: 877 | FR14: 910 | FS14: 853 | FT14: 840 | FU14: 876 | FV14: 888 | FW14: 850 | FX14: 864 | FY14: 847 | FZ14: 863 | GA14: 845 | GB14: 851 | GC14: 807
A15: San Francisco | B15: 1113 | C15: 1135 | D15: 1124 | E15: 1131 | F15: 1095 | G15: 1131 | H15: 1124 | I15: 1169 | J15: 1173 | K15: 1195 | L15: 1164 | M15: 1170 | N15: 1180 | O15: 1205 | P15: 1263 | Q15: 1283 | R15: 1270 | S15: 1319 | T15: 1291 | U15: 1264 | V15: 1255 | W15: 1263 | X15: 1242 | Y15: 1278 | Z15: 1235 | AA15: 1236 | AB15: 1232 | AC15: 1262 | AD15: 1273 | AE15: 1282 | AF15: 1285 | AG15: 1250 | AH15: 1253 | AI15: 1260 | AJ15: 1264 | AK15: 1230 | AL15: 1127 | AM15: 1164 | AN15: 1172 | AO15: 1155 | AP15: 1129 | AQ15: 1131 | AR15: 1115 | AS15: 1136 | AT15: 1081 | AU15: 1047 | AV15: 1005 | AW15: 1055 | AX15: 1064 | AY15: 1092 | AZ15: 1099 | BA15: 1068 | BB15: 1059 | BC15: 1032 | BD15: 1091 | BE15: 1100 | BF15: 1067 | BG15: 1068 | BH15: 1060 | BI15: 1023 | BJ15: 1059 | BK15: 1139 | BL15: 1136 | BM15: 1175 | BN15: 1252 | BO15: 1290 | BP15: 1302 | BQ15: 1281 | BR15: 1267 | BS15: 1243 | BT15: 1259 | BU15: 1263 | BV15: 1259 | BW15: 1225 | BX15: 1235 | BY15: 1242 | BZ15: 1227 | CA15: 1230 | CB15: 1236 | CC15: 1372 | CD15: 1421 | CE15: 1463 | CF15: 1733 | CG15: 1687 | CH15: 1719 | CI15: 1677 | CJ15: 1744 | CK15: 1621 | CL15: 1519 | CM15: 1500 | CN15: 1417 | CO15: 1353 | CP15: 1051 | CQ15: 1002 | CR15: 968 | CS15: 987 | CT15: 1099 | CU15: 1034 | CV15: 905 | CW15: 912 | CX15: 993 | CY15: 1038 | CZ15: 1019 | DA15: 1021 | DB15: 991 | DC15: 1037 | DD15: 1137 | DE15: 1154 | DF15: 1175 | DG15: 1311 | DH15: 1415 | DI15: 1425 | DJ15: 1486 | DK15: 1746 | DL15: 1812 | DM15: 1777 | DN15: 1763 | DO15: 1769 | DP15: 1757 | DQ15: 1843 | DR15: 1904 | DS15: 2074 | DT15: 2036 | DU15: 2028 | DV15: 2076 | DW15: 2083 | DX15: 2070 | DY15: 2126 | DZ15: 2147 | EA15: 2094 | EB15: 2074 | EC15: 2111 | ED15: 2097 | EE15: 2111 | EF15: 2117 | EG15: 2172 | EH15: 2176 | EI15: 2227 | EJ15: 2367 | EK15: 2387 | EL15: 2461 | EM15: 2462 | EN15: 2466 | EO15: 2460 | EP15: 2474 | EQ15: 2501 | ER15: 2457 | ES15: 2545 | ET15: 2550 | EU15: 2614 | EV15: 2564 | EW15: 2542 | EX15: 2541 | EY15: 2541 | EZ15: 2716 | FA15: 2692 | FB15: 2688 | FC15: 2630 | FD15: 2605 | FE15: 2527 | FF15: 2351 | FG15: 2321 | FH15: 2401 | FI15: 2367 | FJ15: 2410 | FK15: 2376 | FL15: 2353 | FM15: 2299 | FN15: 2246 | FO15: 2351 | FP15: 2436 | FQ15: 2406 | FR15: 2359 | FS15: 2380 | FT15: 2350 | FU15: 2506 | FV15: 2497 | FW15: 2457 | FX15: 2451 | FY15: 2508 | FZ15: 2557 | GA15: 2604 | GB15: 2598 | GC15: 2634
A16: San Jose | B16: 331 | C16: 332 | D16: 332 | E16: 330 | F16: 325 | G16: 324 | H16: 321 | I16: 326 | J16: 335 | K16: 336 | L16: 333 | M16: 332 | N16: 332 | O16: 329 | P16: 336 | Q16: 338 | R16: 352 | S16: 321 | T16: 315 | U16: 348 | V16: 346 | W16: 351 | X16: 349 | Y16: 345 | Z16: 347 | AA16: 347 | AB16: 345 | AC16: 344 | AD16: 350 | AE16: 349 | AF16: 350 | AG16: 350 | AH16: 346 | AI16: 347 | AJ16: 351 | AK16: 357 | AL16: 357 | AM16: 358 | AN16: 354 | AO16: 340 | AP16: 341 | AQ16: 404 | AR16: 412 | AS16: 398 | AT16: 430 | AU16: 442 | AV16: 420 | AW16: 446 | AX16: 514 | AY16: 548 | AZ16: 534 | BA16: 530 | BB16: 487 | BC16: 428 | BD16: 476 | BE16: 486 | BF16: 501 | BG16: 488 | BH16: 464 | BI16: 444 | BJ16: 388 | BK16: 400 | BL16: 420 | BM16: 415 | BN16: 487 | BO16: 486 | BP16: 538 | BQ16: 525 | BR16: 502 | BS16: 507 | BT16: 513 | BU16: 491 | BV16: 468 | BW16: 441 | BX16: 457 | BY16: 451 | BZ16: 433 | CA16: 450 | CB16: 452 | CC16: 457 | CD16: 422 | CE16: 363 | CF16: 362 | CG16: 339 | CH16: 361 | CI16: 322 | CJ16: 332 | CK16: 302 | CL16: 258 | CM16: 273 | CN16: 243 | CO16: 254 | CP16: 190 | CQ16: 241 | CR16: 302 | CS16: 307 | CT16: 321 | CU16: 323 | CV16: 246 | CW16: 247 | CX16: 251 | CY16: 246 | CZ16: 254 | DA16: 263 | DB16: 259 | DC16: 250 | DD16: 284 | DE16: 278 | DF16: 260 | DG16: 267 | DH16: 269 | DI16: 264 | DJ16: 274 | DK16: 280 | DL16: 273 | DM16: 268 | DN16: 260 | DO16: 314 | DP16: 453 | DQ16: 511 | DR16: 534 | DS16: 540 | DT16: 537 | DU16: 542 | DV16: 539 | DW16: 539 | DX16: 547 | DY16: 547 | DZ16: 539 | EA16: 536 | EB16: 532 | EC16: 539 | ED16: 595 | EE16: 594 | EF16: 600 | EG16: 620 | EH16: 632 | EI16: 628 | EJ16: 641 | EK16: 638 | EL16: 647 | EM16: 652 | EN16: 648 | EO16: 618 | EP16: 582 | EQ16: 657 | ER16: 647 | ES16: 717 | ET16: 717 | EU16: 728 | EV16: 805 | EW16: 903 | EX16: 985 | EY16: 988 | EZ16: 978 | FA16: 965 | FB16: 973 | FC16: 970 | FD16: 955 | FE16: 847 | FF16: 792 | FG16: 835 | FH16: 826 | FI16: 869 | FJ16: 840 | FK16: 864 | FL16: 889 | FM16: 861 | FN16: 825 | FO16: 847 | FP16: 856 | FQ16: 858 | FR16: 850 | FS16: 894 | FT16: 872 | FU16: 885 | FV16: 879 | FW16: 869 | FX16: 869 | FY16: 866 | FZ16: 870 | GA16: 867 | GB16: 870 | GC16: 878
A17: Total | B17: =SUM(B12:B16) -> 2257 | C17: =SUM(C12:C16) -> 2274 | D17: =SUM(D12:D16) -> 2281 | E17: =SUM(E12:E16) -> 2278 | F17: =SUM(F12:F16) -> 2246 | G17: =SUM(G12:G16) -> 2286 | H17: =SUM(H12:H16) -> 2283 | I17: =SUM(I12:I16) -> 2347 | ... GC17: =SUM(GC12:GC16) -> 4860
A18: Average (May-Oct) | B18: =AVERAGE(B17:GC17) -> 3202.9293
A20: Bikeshare Trips (January-December 2022); Source: Lyft Bay Wheels System Data (https://www.lyft.com/bikes/bay-wheels/system-data)
A21: Month | B21: Classic Rides | C21: Docked Rides | D21: Electric Rides | E21: Total Rides
A22: January | B22: 50260 | C22: 1218 | D22: 99748 | E22: 151226
A23: February | B23: 61164 | C23: 1387 | D23: 110300 | E23: 172851
A24: March | B24: 75775 | C24: 1663 | D24: 127571 | E24: 205009
A25: April | B25: 77621 | C25: 2346 | D25: 138263 | E25: 218230
A26: May | B26: 82872 | C26: 2582 | D26: 147499 | E26: 232953
A27: June | B27: 88461 | C27: 54 | D27: 167441 | E27: 255956
A28: July | B28: 81907 | D28: 160195 | E28: 242102
A29: August | B29: 91332 | D29: 175223 | E29: 266555
A30: September | B30: 94184 | D30: 179295 | E30: 273479
A31: October | B31: 93208 | D31: 172555 | E31: 265763
A32: November | B32: 70735 | D32: 123177 | E32: 193912
A33: December | B33: 48005 | D33: 88759 | E33: 136764
A34: Total Rides | B34: 915524 | C34: 9250 | D34: 1690026 | E34: 2614800
A35: Rides/Day | B35: 2508 | C35: 25 | D35: 4630 | E35: 7164

Sheet Model Data
D1: directory | E1: variable | F1: value
D2: 2035_TM160_IPA_17 | E2: total_employment | F2: 4854742
D3: 2035_TM160_IPA_17 | E3: total_population | F3: 8476332
D4: 2035_TM160_IPA_17 | E4: total_pop_popsyn | F4: 8526053

Sheet Emission Factors
A1: Emission Factors | B1: EMFAC2021 v1.0.2 (in PBA50, used EMFAC2014, v1.0.7) | E1: All rates in grams per mile | F1: Provided to James and Joel by Harold on 10-26-23
C2: 2035 | E2: 2050
A3: Regional CO2 running EF (grams/mi) | C3: 349.21 | E3: 351.31
A4: g/lb conversion | C4: 453.592 | E4: 453.592
A5: lb/ton conversion | C5: 2000 | E5: 2000
A6: Regional CO2 running EF (tons/mi) | C6: 0.000385 | E6: 0.000387
A7: Regional CO2 tripend EF (grams/trip) | C7: 81.04 | E7: 81.4
A8: g/lb conversion | C8: 453.592 | E8: 453.592
A9: lb/ton conversion | C9: 2000 | E9: 2000
A10: Regional CO2 tripend EF (tons/trip) | C10: 8.93e-05 | E10: 8.97e-05
A11: Regional Urban Bus CO2 exhaust EF (grams/mi) | C11: 1902.72 | E11: 1828.62
A12: g/lb conversion | C12: 453.592 | E12: 453.592
A13: lb/ton conversion | C13: 2000 | E13: 2000
A14: Regional Urban Bus CO2 exhaust EF (tons/mi) | C14: 0.002097 | E14: 0.002016
A16: YEAR 2035
A17: NO CONTROLS CO2 Exhaust & Tripend Emission Rates | C17: Exhaust | D17: Tripend | G17: Urban Buses
G18: CO2 Exhaust Emisison Rates
A19: Alameda | C19: 348.174 | D19: 80.077
A20: Contra Costa | C20: 346.579 | D20: 80.481 | G20: 1929.08 | I20: Alameda
A21: Marin | C21: 344.236 | D21: 81.234 | G21: 1866.55 | I21: Contra Costa
A22: Napa | C22: 337.179 | D22: 80.351 | G22: 1975.16 | I22: Marin
A23: San Francisco | C23: 366.889 | D23: 81.133 | G23: 1852.1 | I23: Napa
A24: San Mateo | C24: 373.488 | D24: 85.458 | G24: 1994.31 | I24: San Francisco
A25: Santa Clara | C25: 345.508 | D25: 80.152 | G25: 1889.5 | I25: San Mateo
A26: Solano (SF) | C26: 337.959 | D26: 80.065 | G26: 1892.93 | I26: Santa Clara
A27: Solano (SV) | C27: 343.201 | D27: 80.863 | G27: 1841.17 | I27: Solano
A28: Sonoma (NC) | C28: 343.155 | D28: 79.667 | G28: 1894.88 | I28: Sonoma
A29: Sonoma (SF) | C29: 338.961 | D29: 79.859 | G29: 1902.72 | I29: Region
G30: in grams per mile
A31: Regionwide | C31: 349.208 | D31: 81.041
A33: YEAR 2050
A34: NO CONTROLS CO2 Exhaust & Tripend Emission Rates | C34: Exhaust | D34: Tripend | G34: Urban Buses
G35: CO2 Exhaust Emisison Rates
A37: Alameda | C37: 351.081 | D37: 80.52 | G37: 1832.05 | I37: Alameda
A38: Contra Costa | C38: 345.954 | D38: 80.269 | G38: 1828.78 | I38: Contra Costa
A39: Marin | C39: 345.958 | D39: 81.55 | G39: 1836.34 | I39: Marin
A40: Napa | C40: 334.67 | D40: 79.578 | G40: 1824.28 | I40: Napa
A41: San Francisco | C41: 368.428 | D41: 81.702 | G41: 1839.26 | I41: San Francisco
A42: San Mateo | C42: 377.42 | D42: 86.298 | G42: 1833.29 | I42: San Mateo
A43: Santa Clara | C43: 349.978 | D43: 80.678 | G43: 1830.05 | I43: Santa Clara
...

Sheet SB 375 calcs
B1: 2005
A2: Population | B2: 6978983
A3: DailyCO2 | B3: 60690
A4: RunID | B4: 2005_TM160_IPA_04

Sheet Output_test
A1: Sheet | B1: Variable Name | C1: Value | D1: Location
A2: Main Sheet | B2: Out_bikeshare_trips_2035 | C2: ='Main Sheet'!C21 -> 12038.39
A3: Main Sheet | B3: Out_bikeshare_trips_2050 | C3: ='Main Sheet'!D21
A4: Main Sheet | B4: Out_daily_VMT_reduced_2035 | C4: ='Main Sheet'!C22 -> 15649.907
A5: Main Sheet | B5: Out_daily_VMT_reduced_2050 | C5: ='Main Sheet'!D22
A6: Main Sheet | B6: Out_daily_GHG_reduced_2035 | C6: ='Main Sheet'!C23 -> 7.1002424
A7: Main Sheet | B7: Out_daily_GHG_reduced_2050 | C7: ='Main Sheet'!D23
A8: Main Sheet | B8: Out_per_capita_GHG_reduced_2035 | C8: ='Main Sheet'!C24 -> -9.5763531e-05
A9: Main Sheet | B9: Out_per_capita_GHG_reduced_2050 | C9: ='Main Sheet'!D24
A10: Main Sheet | B10: VMT_displaced_conventional | C10: ='Main Sheet'!B5 -> 0.75
A11: Main Sheet | B11: VMT_displaced_ebike | C11: ='Main Sheet'!B6 -> 1.3
A12: Main Sheet | B12: Total_pop_baseline | C12: ='Main Sheet'!B8 -> 7516241
A13: Main Sheet | B13: Bikes_available_baseline | C13: ='Main Sheet'!B9 -> 6040
A14: Main Sheet | B14: Bikes_available_2035 | C14: ='Main Sheet'!C9 -> 9000
A15: Main Sheet | B15: Bikes_available_2050 | C15: ='Main Sheet'!D9 -> 9000
A16: Main Sheet | B16: Daily_trips_baseline | C16: ='Main Sheet'!B10 -> 7164
A17: Main Sheet | B17: Daily_trips_2035 | C17: ='Main Sheet'!C10 -> 10674.834
A18: Main Sheet | B18: Daily_trips_2050 | C18: ='Main Sheet'!D10 -> 10674.834
A19: Main Sheet | B19: Percent_ebikes_baseline | C19: ='Main Sheet'!B11 -> 0.3
A20: Main Sheet | B20: Percent_ebikes_2035 | C20: ='Main Sheet'!C11 -> 1
A21: Main Sheet | B21: Percent_ebikes_2050 | C21: ='Main Sheet'!D11 -> 1
A22: Main Sheet | B22: Run_directory_2035 | C22: ='Main Sheet'!C14 -> 2035_TM160_IPA_17
A23: Main Sheet | B23: Run_directory_2050 | C23: ='Main Sheet'!D14 -> 0 | I23: ='Main Sheet'!D19
A24: Main Sheet | B24: Model_totpop_2035 | C24: ='Main Sheet'!C17 -> 8476332
A25: Main Sheet | B25: Model_totpop_2050 | C25: ='Main Sheet'!D17
A26: Main Sheet | B26: Model_totjobs_2035 | C26: ='Main Sheet'!C18 -> 4854742
A27: Main Sheet | B27: Model_totjobs_2050 | C27: ='Main Sheet'!D18
A28: Main Sheet | B28: Percent_popgrowth_2035 | C28: ='Main Sheet'!C19 -> 0.12773553
A29: Main Sheet | B29: Percent_popgrowth_2050 | C29: ='Main Sheet'!D19
A30: Main Sheet | B30: Run_directory_2035 | C30: ='Main Sheet'!C14 -> 2035_TM160_IPA_17 | D30: =ADDRESS(ROW('Main Sheet'!C14),COLUMN('Main Sheet'!C14),4) -> C14
A31: Main Sheet | B31: Run_directory_2050 | C31: ='Main Sheet'!D14 -> 0 | D31: =ADDRESS(ROW('Main Sheet'!D14),COLUMN('Main Sheet'!D14),4) -> D14
A32: Main Sheet | B32: year_2035 | C32: ='Main Sheet'!C15 -> 2035 | D32: =ADDRESS(ROW('Main Sheet'!C15),COLUMN('Main Sheet'!C15),4) -> C15
A33: Main Sheet | B33: year_2035 | C33: ='Main Sheet'!D15 -> 2050 | D33: =ADDRESS(ROW('Main Sheet'!D15),COLUMN('Main Sheet'!D15),4) -> D15

Sheet Output
A1: Sheet | B1: Main sheet | C1: Main sheet | D1: Main sheet | E1: Main sheet | F1: Main sheet | G1: Main sheet | H1: Main sheet | I1: Main sheet | J1: Main sheet | K1: Main sheet | L1: Main sheet | M1: Main sheet | N1: Main sheet | O1: Main sheet | P1: Main sheet | Q1: Main sheet | R1: Main sheet | S1: Main sheet | T1: Main sheet | U1: Main sheet | V1: Main sheet | W1: Main sheet | X1: Main sheet | Y1: Main sheet | Z1: Main sheet | AA1: Main sheet | AB1: Main sheet | AC1: Main sheet | AD1: Main sheet | AE1: Main sheet | AF1: Main sheet
A2: Baseline Run ID | B2: Horizon Run ID | C2: Out_bikeshare_trips_2035 | D2: Out_bikeshare_trips_2050 | E2: Out_daily_VMT_reduced_2035 | F2: Out_daily_VMT_reduced_2050 | G2: Out_daily_GHG_reduced_2035 | H2: Out_daily_GHG_reduced_2050 | I2: Out_per_capita_GHG_reduced_2035 | J2: Out_per_capita_GHG_reduced_2050 | K2: VMT_displaced_conventional | L2: VMT_displaced_ebike | M2: Total_pop_baseline | N2: Bikes_available_baseline | O2: Bikes_available_2035 | P2: Bikes_available_2050 | Q2: Daily_trips_baseline | R2: Daily_trips_2035 | S2: Daily_trips_2050 | T2: Percent_ebikes_baseline | U2: Percent_ebikes_2035 | V2: Percent_ebikes_2050 | W2: Run_directory_2035 | X2: Run_directory_2050 | Y2: Model_totpop_2035 | Z2: Model_totpop_2050 | AA2: Model_totjobs_2035 | AB2: Model_totjobs_2050 | AC2: Percent_popgrowth_2035 | AD2: Percent_popgrowth_2050 | AE2: Run_cell_address_2035 | AF2: Run_cell_address_2035
A3: ='SB 375 calcs'!B4 -> 2005_TM160_IPA_04 | B3: =INDEX('Model Data'!D:D,MATCH('Main Sheet'!E24,'Model Data'!E:E,0),1) -> 2035_TM160_IPA_17 | C3: ='Main Sheet'!C21 -> 12038.39 | D3: ='Main Sheet'!D21 | E3: ='Main Sheet'!C22 -> 15649.907 | F3: ='Main Sheet'!D22 | G3: ='Main Sheet'!C23 -> 7.1002424 | H3: ='Main Sheet'!D23 | I3: ='Main Sheet'!C24 -> -9.5763531e-05 | J3: ='Main Sheet'!D24 | K3: ='Main Sheet'!B5 -> 0.75 | L3: ='Main Sheet'!B6 -> 1.3 | M3: ='Main Sheet'!B8 -> 7516241 | N3: ='Main Sheet'!B9 -> 6040 | O3: ='Main Sheet'!C9 -> 9000 | P3: ='Main Sheet'!D9 -> 9000 | Q3: ='Main Sheet'!B10 -> 7164 | R3: ='Main Sheet'!C10 -> 10674.834 | S3: ='Main Sheet'!D10 -> 10674.834 | T3: ='Main Sheet'!B11 -> 0.3 | U3: ='Main Sheet'!C11 -> 1 | V3: ='Main Sheet'!D11 -> 1 | W3: ='Main Sheet'!C14 -> 2035_TM160_IPA_17 | X3: ='Main Sheet'!D14 -> 0 | Y3: ='Main Sheet'!C17 -> 8476332 | Z3: ='Main Sheet'!D17 | AA3: ='Main Sheet'!C18 -> 4854742 | AB3: ='Main Sheet'!D18 | AC3: ='Main Sheet'!C19 -> 0.12773553 | AD3: ='Main Sheet'!D19 | AE3: =ADDRESS(ROW('Main Sheet'!C14),COLUMN('Main Sheet'!C14),4) -> C14 | AF3: =ADDRESS(ROW('Main Sheet'!D14),COLUMN('Main Sheet'!D14),4) -> D14
