Workbook

Sheet NOTES
C2: SheetName | D2: Description
C3: Summary | D3: 2023 and forecasted 2050 ground access passengers data, along with various forecasts from the master plans of the three airports
C4: Enplanements(Selected) | D4: Chart of 2000, 2019, forecasted 2050 enplanements at all three airports with CAGR
C5: Enplanements_2 | D5: Chart of 2019, 2023, 2025, forecasted 2050 enplanements at all three airports
C6: Enplanements_by_Year | D6: Tabular data used to develop the above two charts
C7: FAA_TAF | D7: FAA Terminal Area Forecasts for the three airports
C8: SFO | D8: Historical enplanement data for SFO
C9: OAK | D9: Historical enplanement data for OAK
C10: SJC | D10: Historical enplanement data for SJC
C11: BayAreaPopulation | D11: 9-County Bay area population projections from CA Dept of Finance
C12: TSA | D12: TSA Checkpoint Passenger Volumes

Sheet Summary
C2: 2023 Data Summary
C3: Airport | D3: Annual Enplanements | E3: % Connecting Passengers | F3: Annual Ground Access Passengers | G3: Average Daily Ground Access Passengers | H3: Average Daily Ground Access Passengers (two-way)
C4: SFO | D4: =SFO!K38 -> 24979810 | E4: =ROUND(SFO!H42,3) -> 0.225 | F4: =ROUND(D4*(1-E4),0) -> 19359353 | G4: =ROUND(F4/365,0) -> 53039 | H4: =G4*2 -> 106078
C5: OAK | D5: =OAK!C20 -> 5611677 | E5: =ROUND(OAK!I20,3) -> 0.158 | F5: =ROUND(D5*(1-E5),0) -> 4725032 | G5: =ROUND(F5/365,0) -> 12945 | H5: =G5*2 -> 25890
C6: SJC | D6: =SJC!G14 -> 6052435 | E6: =SJC!G18 -> 0.098284079 | F6: =ROUND(D6*(1-E6),0) -> 5457577 | G6: =ROUND(F6/365,0) -> 14952 | H6: =G6*2 -> 29904
J7: 2023 Data Summary - Source
J8: Airport | K8: Annual Enplanements | L8: % Connecting Passengers | M8: Annual Ground Access Passengers | N8: Average Daily Ground Access Passengers | O8: Average Daily Ground Access Passengers (two-way)
J9: SFO | K9: Dec 2023 reports from respective airport websites: https://www.flysfo.com/about/media/facts-statistics/air-traffic-statistics https://www.iflyoak.com/business/facts-figures/ https://www.flysanjose.com/airport-activity | L9: Using average of most recent (2011-2015) connecting passengers data from: Chapter_2_Aviation_Activity_Forecasts_Draft_Final.PDF Table 2.4-2 | SFO Historical Enplaned Passengers by Segment https://www.flysfo.com/about-sfo/sfo-tomorrow/draft-final-airport-development-plan | M9: Exclude connecting passengers from annual enplanements | N9: Annual Ground Access Passengers divided by 365 | O9: Average Daily Ground Access Passengers multiplied by 2 (Assume equal enplanements and deplanements)
J10: OAK | L10: Data from press release on airport website: https://www.iflyoak.com/press_release/oakland-international-airport-saw-over-42-percent-jump-in-international-passengers-in-january/
J11: SJC | L11: Airport website splits enplanements by originating and connecting passengers
C12: 2050 Forecast Data Summary
C13: Airport | D13: Annual Enplanements | E13: % Connecting Passengers | F13: Annual Ground Access Passengers | G13: Average Daily Ground Access Passengers | H13: Average Daily Ground Access Passengers (two-way)
C14: SFO | D14: =D50*1000000/2 -> 35535000 | E14: =E4 -> 0.225 | F14: =ROUND(D14*(1-E14),0) -> 27539625 | G14: =ROUND(F14/365,0) -> 75451 | H14: =G14*2 -> 150902
C15: OAK | D15: =D39 -> 9685616 | E15: =E5 -> 0.158 | F15: =ROUND(D15*(1-E15),0) -> 8155289 | G15: =ROUND(F15/365,0) -> 22343 | H15: =G15*2 -> 44686
C16: SJC | D16: =D40 -> 10426606 | E16: =SJC!E18 -> 0.05115094 | F16: =ROUND(D16*(1-E16),0) -> 9893275 | G16: =ROUND(F16/365,0) -> 27105 | H16: =G16*2 -> 54210
J17: 2050 Forecast Data Summary - Source
J18: Airport | K18: Annual Enplanements | L18: % Connecting Passengers
C19: Airport | D19: Growth (2000-2019) | E19: Growth (2019-2050) | F19: Growth (2023-2050) | G19: Growth (2025-2050) | J19: SFO | K19: 2016 Master Plan - High Constrained Forecast. Aligns with max anticipated airline operations | L19: Same as 2023
C20: SFO | D20: =Enplanements_by_Year!D6/Enplanements_by_Year!D4-1 -> 0.41849938 | E20: =D14/SFO!K34-1 -> 0.23966203 | F20: =D14/D4-1 -> 0.42254885 | G20: =D14/(D52/2)-1 -> 0.30399813 | J20: OAK | K20: FAA TAF Forecast (2025 Model): https://taf.faa.gov/ | L20: Same as 2023
C21: OAK | D21: =Enplanements_by_Year!E6/Enplanements_by_Year!E4-1 -> 0.28731263 | E21: =D15/OAK!C16-1 -> 0.44789271 | F21: =D15/D5-1 -> 0.72597532 | G21: =D15/D65-1 -> 1.1076626 | J21: SJC | L21: Same as 2025 (aligns with around 4.1% used in Master Plan)
C22: SJC | D22: =Enplanements_by_Year!F6/Enplanements_by_Year!F4-1 -> 0.24597626 | E22: =D16/SJC!I14-1 -> 0.35619145 | F22: =D16/D6-1 -> 0.72271259 | G22: =D16/H79-1 -> 0.95672448
C24: Airport | D24: CAGR (2000-2019) | E24: CAGR (2019-2050) | F24: CAGR (2023-2050) | G24: CAGR (2025-2050)
C25: SFO | D25: =(Enplanements_by_Year!D6/Enplanements_by_Year!D4)^(1/19)-1 -> 0.018570298 | E25: =(D14/SFO!K34)^(1/31)-1 -> 0.0069543533 | F25: =(D14/D4)^(1/27)-1 -> 0.013139284 | G25: =(D14/(D52/2))^(1/25)-1 -> 0.010673966 | J25: Key Considerations in developing 2050 Forecasts
C26: OAK | D26: =(Enplanements_by_Year!E6/Enplanements_by_Year!E4)^(1/19)-1 -> 0.013381201 | E26: =(D15/OAK!C16)^(1/31)-1 -> 0.012010561 | F26: =(D15/D5)^(1/27)-1 -> 0.020420227 | G26: =(D15/D65)^(1/25)-1 -> 0.030272348 | J26: 1. Capacity constraints at SFO, OAK
C27: SJC | D27: =(Enplanements_by_Year!F6/Enplanements_by_Year!F4)^(1/19)-1 -> 0.01164195 | E27: =(D16/SJC!I14)^(1/31)-1 -> 0.0098768562 | F27: =(D16/D6)^(1/27)-1 -> 0.020348718 | G27: =(D16/H79)^(1/25)-1 -> 0.027214609 | J27: 2. Available forecasts don't align with latest actual enplanements
J28: 3. Consecutive years of declining enplanements at OAK and SJC (i.e., enplanements in 2025<2024<2023)
J29: 4. Enplanements in 2025 less than 2019 at all three airports
C36: 2050 TAF Forecast | G36: Source: | H36: See FAA_TAF sheet. The sheet was pulled from https://taf.faa.gov/ in Feb 2026
C37: Airport | D37: Annual Enplanements | E37: Aircraft Operations
C38: SFO | D38: =FAA_TAF!D210 -> 48985793 | E38: =FAA_TAF!M210 -> 706246
C39: OAK | D39: =FAA_TAF!D110 -> 9685616 | E39: =FAA_TAF!M110 -> 311354
C40: SJC | D40: =FAA_TAF!D310 -> 10426606 | E40: =FAA_TAF!M310 -> 249111
C43: SFO Forecasts
C44: Forecast Summary table from Master Plan (2016) | G44: Source: | H44: https://www.flysfo.com/sites/default/files/default/about/Chapter_0_Executive_Summary_Draft_Final_Stand_Alone.pdf
C45: Demand Level | D45: Annual Passengers (Millions) | E45: Annual Passenger Aircraft Operations | F45: Annual Total Aircraft Operations
C46: Historical 2013 | D46: 44.84 | E46: 386400 | F46: 421400
C47: 2018 | D47: 50.48 | E47: 407800 | F47: 446100
C48: 2023 | D48: 57.66 | E48: 451900 | F48: 494500
C49: Base Constrained | D49: 62.22 | E49: 455400 | F49: 498900
C50: High Constrained | D50: 71.07 | E50: 463100 | F50: 506600
...

Sheet Enplanements_by_Year
C2: Enplanement Data
C3: Year | D3: SFO | E3: OAK | F3: SJC
B4: Actual | C4: 2000 | D4: =SFO!K15 -> 20208025 | E4: =OAK!C4 -> 5196451 | F4: =SJC!K14 -> 6170384
B5: Actual | C5: 2010 | D5: =SFO!K25 -> 19539692 | E5: =OAK!C7 -> 4769915 | F5: =SJC!J14 -> 4056167
B6: Actual | C6: 2019 | D6: =SFO!K34 -> 28665071 | E6: =OAK!C16 -> 6689457 | F6: =SJC!I14 -> 7688152 | G6: =D6/D4-1 -> 0.41849938 | H6: =E6/E4-1 -> 0.28731263 | I6: =F6/F4-1 -> 0.24597626
B7: Actual | C7: 2023 | D7: =SFO!K38 -> 24979810 | E7: =OAK!C20 -> 5611677 | F7: =SJC!G14 -> 6052435
B8: Actual | C8: 2025 | D8: =SFO!K40 -> 27250806 | E8: =OAK!C22 -> 4595430 | F8: =SJC!E14 -> 5328602
B9: Forecast | C9: 2050 | D9: =Summary!D14 -> 35535000 | E9: =Summary!D15 -> 9685616 | F9: =Summary!D16 -> 10426606 | G9: =D9/D6-1 -> 0.23966203 | H9: =E9/E6-1 -> 0.44789271 | I9: =F9/F6-1 -> 0.35619145
C11: Enplanement Data (Selected Years)
C12: Year | D12: SFO | E12: OAK | F12: SJC
B13: Actual | C13: 2000 | D13: =D4 -> 20208025 | E13: =E4 -> 5196451 | F13: =F4 -> 6170384
B14: Actual | C14: 2019 | D14: =D6 -> 28665071 | E14: =E6 -> 6689457 | F14: =F6 -> 7688152
B15: Forecast | C15: 2050 Forecast | D15: =D9 -> 35535000 | E15: =E9 -> 9685616 | F15: =F9 -> 10426606
C18: 2025 Monthly Enplanements (Average Daily)
C19: Month | D19: SFO | E19: OAK | F19: SJC | G19: Total | H19: Average
C20: Jan | D20: =SFO!E47 -> 62779.645 | E20: =OAK!E27 -> 10640.129 | F20: =SJC!E23 -> 11940.097 | G20: =SUM(D20:F20) -> 85359.871 | H20: =AVERAGE($G$20:$G$31) -> 101771.98
C21: Feb | D21: =SFO!E48 -> 63430.393 | E21: =OAK!E28 -> 12021.143 | F21: =SJC!E24 -> 13430.179 | G21: =SUM(D21:F21) -> 88881.714 | H21: =AVERAGE($G$20:$G$31) -> 101771.98
C22: Mar | D22: =SFO!E49 -> 69058.387 | E22: =OAK!E29 -> 12707.645 | F22: =SJC!E25 -> 14154.581 | G22: =SUM(D22:F22) -> 95920.613 | H22: =AVERAGE($G$20:$G$31) -> 101771.98
C23: Apr | D23: =SFO!E50 -> 72882.833 | E23: =OAK!E30 -> 13234.467 | F23: =SJC!E26 -> 14688.667 | G23: =SUM(D23:F23) -> 100805.97 | H23: =AVERAGE($G$20:$G$31) -> 101771.98
C24: May | D24: =SFO!E51 -> 78648 | E24: =OAK!E31 -> 13509.774 | F24: =SJC!E27 -> 14942.419 | G24: =SUM(D24:F24) -> 107100.19 | H24: =AVERAGE($G$20:$G$31) -> 101771.98
C25: Jun | D25: =SFO!E52 -> 87795.767 | E25: =OAK!E32 -> 13915.967 | F25: =SJC!E28 -> 16975.233 | G25: =SUM(D25:F25) -> 118686.97 | H25: =AVERAGE($G$20:$G$31) -> 101771.98
C26: Jul | D26: =SFO!E53 -> 82857.323 | E26: =OAK!E33 -> 13280.419 | F26: =SJC!E29 -> 16050.677 | G26: =SUM(D26:F26) -> 112188.42 | H26: =AVERAGE($G$20:$G$31) -> 101771.98
C27: Aug | D27: =SFO!E54 -> 79695.129 | E27: =OAK!E34 -> 12933.903 | F27: =SJC!E30 -> 15652.323 | G27: =SUM(D27:F27) -> 108281.35 | H27: =AVERAGE($G$20:$G$31) -> 101771.98
C28: Sep | D28: =SFO!E55 -> 73365.767 | E28: =OAK!E35 -> 12383.867 | F28: =SJC!E31 -> 14488.9 | G28: =SUM(D28:F28) -> 100238.53 | H28: =AVERAGE($G$20:$G$31) -> 101771.98
C29: Oct | D29: =SFO!E56 -> 77891.677 | E29: =OAK!E36 -> 12427 | F29: =SJC!E32 -> 14860.355 | G29: =SUM(D29:F29) -> 105179.03 | H29: =AVERAGE($G$20:$G$31) -> 101771.98
C30: Nov | D30: =SFO!E57 -> 72347.533 | E30: =OAK!E37 -> 11766 | F30: =SJC!E33 -> 13848.467 | G30: =SUM(D30:F30) -> 97962 | H30: =AVERAGE($G$20:$G$31) -> 101771.98
C31: Dec | D31: =SFO!E58 -> 74327.839 | E31: =OAK!E38 -> 12237.548 | F31: =SJC!E34 -> 14093.71 | G31: =SUM(D31:F31) -> 100659.1 | H31: =AVERAGE($G$20:$G$31) -> 101771.98

Sheet FAA_TAF
A1: APO TERMINAL AREA FORECAST DETAIL REPORT | S1: Source: | T1: https://taf.faa.gov/
A2: Forecast Issued February 2026
A6: OAK SFO SJC
E9: AIRCRAFT OPERATIONS
B10: Enplanements | E10: Itinerant Operations | J10: Local Operations
A11: Fiscal | B11: Air | C11: Commuter | D11: Total | E11: Air | F11: Air Taxi & | G11: GA | H11: Military | I11: Total | J11: Civil | K11: Military | L11: Total | M11: Total | N11: Total | O11: Based
A12: Year | B12: Carrier | E12: Carrier | F12: Commuter | M12: Ops | N12: Tracon | O12: Aircraft
N13: Ops
A16: REGION:AWP STATE:CA LOCID:OAK
A17: CITY:OAKLAND AIRPORT:San Francisco Bay Oakland International
A18: 1990 | B18: 2707091 | C18: 13411 | D18: 2720502 | E18: 64768 | F18: 39797 | G18: 105672 | H18: 709 | I18: 210946 | J18: 85290 | K18: 90 | L18: 85380 | M18: 296326 | N18: 0 | O18: 409
A19: 1991 | B19: 2951727 | C19: 48252 | D19: 2999979 | E19: 108401 | F19: 50772 | G19: 140407 | H19: 601 | I19: 300181 | J19: 113667 | K19: 68 | L19: 113735 | M19: 413916 | N19: 0 | O19: 303
A20: 1992 | B20: 3081399 | C20: 54333 | D20: 3135732 | E20: 107669 | F20: 51982 | G20: 140227 | H20: 838 | I20: 300716 | J20: 118415 | K20: 102 | L20: 118517 | M20: 419233 | N20: 0 | O20: 366
A21: 1993 | B21: 3537031 | C21: 48255 | D21: 3585286 | E21: 121953 | F21: 55164 | G21: 136876 | H21: 847 | I21: 314840 | J21: 124356 | K21: 18 | L21: 124374 | M21: 439214 | N21: 0 | O21: 366
A22: 1994 | B22: 3848105 | C22: 36317 | D22: 3884422 | E22: 130335 | F22: 57770 | G22: 142389 | H22: 702 | I22: 331196 | J22: 139563 | K22: 142 | L22: 139705 | M22: 470901 | N22: 0 | O22: 366
A23: 1995 | B23: 4698250 | C23: 22690 | D23: 4720940 | E23: 164371 | F23: 52357 | G23: 142621 | H23: 727 | I23: 360076 | J23: 142530 | K23: 346 | L23: 142876 | M23: 502952 | N23: 0 | O23: 366
A24: 1996 | B24: 4784598 | C24: 17713 | D24: 4802311 | E24: 169641 | F24: 64734 | G24: 166099 | H24: 831 | I24: 401305 | J24: 114701 | K24: 492 | L24: 115193 | M24: 516498 | N24: 0 | O24: 366
A25: 1997 | B25: 4508218 | C25: 7506 | D25: 4515724 | E25: 163007 | F25: 59145 | G25: 160395 | H25: 520 | I25: 383067 | J25: 104689 | K25: 720 | L25: 105409 | M25: 488476 | N25: 0 | O25: 366
A26: 1998 | B26: 4455223 | C26: 2332 | D26: 4457555 | E26: 160456 | F26: 60628 | G26: 169499 | H26: 692 | I26: 391275 | J26: 124491 | K26: 160 | L26: 124651 | M26: 515926 | N26: 0 | O26: 366
A27: 1999 | B27: 4733764 | C27: 0 | D27: 4733764 | E27: 162766 | F27: 54646 | G27: 167339 | H27: 580 | I27: 385331 | J27: 122836 | K27: 287 | L27: 123123 | M27: 508454 | N27: 0 | O27: 370
A28: 2000 | B28: 5087602 | C28: 0 | D28: 5087602 | E28: 149007 | F28: 45633 | G28: 161531 | H28: 416 | I28: 356587 | J28: 121793 | K28: 178 | L28: 121971 | M28: 478558 | N28: 0 | O28: 370
A29: 2001 | B29: 5623479 | C29: 0 | D29: 5623479 | E29: 158700 | F29: 43001 | G29: 143600 | H29: 533 | I29: 345834 | J29: 64280 | K29: 41 | L29: 64321 | M29: 410155 | N29: 0 | O29: 370
... A47: 2019 | B47: 6413830 | C47: 171061 | D47: 6584891 | E47: 131544 | F47: 31622 | G47: 39390 | H47: 534 | I47: 203090 | J47: 40883 | K47: 468 | L47: 41351 | M47: 244441 | N47: 0 | O47: 264
A49: APO TERMINAL AREA FORECAST DETAIL REPORT
A50: Forecast Issued February 2026
A54: OAK SFO SJC
E57: AIRCRAFT OPERATIONS
B58: Enplanements | E58: Itinerant Operations | J58: Local Operations
A59: Fiscal | B59: Air | C59: Commuter | D59: Total | E59: Air | F59: Air Taxi & | G59: GA | H59: Military | I59: Total | J59: Civil | K59: Military | L59: Total | M59: Total | N59: Total | O59: Based
A60: Year | B60: Carrier | E60: Carrier | F60: Commuter | M60: Ops | N60: Tracon | O60: Aircraft
N61: Ops
A64: 2020 | B64: 3287247 | C64: 151170 | D64: 3438417 | E64: 94914 | F64: 26123 | G64: 27043 | H64: 449 | I64: 148529 | J64: 26964 | K64: 362 | L64: 27326 | M64: 175855 | N64: 0 | O64: 264
A65: 2021 | B65: 3105628 | C65: 196763 | D65: 3302391 | E65: 86716 | F65: 25876 | G65: 30690 | H65: 402 | I65: 143684 | J65: 32930 | K65: 288 | L65: 33218 | M65: 176902 | N65: 0 | O65: 264
A66: 2022 | B66: 5036598 | C66: 263844 | D66: 5300442 | E66: 113237 | F66: 28447 | G66: 32624 | H66: 509 | I66: 174817 | J66: 35774 | K66: 529 | L66: 36303 | M66: 211120 | N66: 0 | O66: 264
A67: 2023 | B67: 5311542 | C67: 235015 | D67: 5546557 | E67: 115119 | F67: 25412 | G67: 28375 | H67: 399 | I67: 169305 | J67: 38616 | K67: 306 | L67: 38922 | M67: 208227 | N67: 0 | O67: 268
A68: 2024 | B68: 5233237 | C68: 215784 | D68: 5449021 | E68: 109458 | F68: 24947 | G68: 28603 | H68: 487 | I68: 163495 | J68: 41723 | K68: 129 | L68: 41852 | M68: 205347 | N68: 0 | O68: 264
A69: 2025* | B69: 4478822 | C69: 206603 | D69: 4685425 | E69: 98591 | F69: 25187 | G69: 28954 | H69: 372 | I69: 153104 | J69: 52237 | K69: 183 | L69: 52420 | M69: 205524 | N69: 0 | O69: 264
A70: 2026* | B70: 3823642 | C70: 217190 | D70: 4040832 | E70: 87945 | F70: 25275 | G70: 29556 | H70: 372 | I70: 143148 | J70: 54722 | K70: 183 | L70: 54905 | M70: 198053 | N70: 0 | O70: 269
A71: 2027* | B71: 4245690 | C71: 241825 | D71: 4487515 | E71: 97319 | F71: 25194 | G71: 30157 | H71: 372 | I71: 153042 | J71: 54804 | K71: 183 | L71: 54987 | M71: 208029 | N71: 0 | O71: 274
A72: 2028* | B72: 4549556 | C72: 259092 | D72: 4808648 | E72: 103725 | F72: 25331 | G72: 30852 | H72: 372 | I72: 160280 | J72: 54885 | K72: 183 | L72: 55068 | M72: 215348 | N72: 0 | O72: 279
...

Sheet SFO
B2: Passengers | N2: Source
B3: Year | C3: Originating Passengers | F3: Connecting Passengers | I3: Total Enplaned Passengers | N3: Year | O3: Originating Passengers | R3: Connecting Passengers | U3: Total Enplaned Passengers
C4: Domestic | D4: International | E4: Total | F4: Domestic | G4: International | H4: Total | I4: Domestic | J4: International | K4: Total | O4: Domestic | P4: International | Q4: Total | R4: Domestic | S4: International | T4: Total | U4: Domestic | V4: International | W4: Total
B5: 1990 | C5: 9726530 | D5: 1487229 | E5: 11213759 | F5: 3449157 | G5: 512030 | H5: 3961187 | I5: 13175687 | J5: 1999259 | K5: 15174946 | N5: 1990 | O5: Chapter_2_Aviation_Activity_Forecasts_Draft_Final.PDF Table 2.4-2 | SFO Historical Enplaned Passengers by Segment https://www.flysfo.com/about-sfo/sfo-tomorrow/draft-final-airport-development-plan
B6: 1991 | C6: 10093080 | D6: 1360258 | E6: 11453338 | F6: 3599557 | G6: 545000 | H6: 4144557 | I6: 13692637 | J6: 1905258 | K6: 15597895 | N6: 1991
B7: 1992 | C7: 9957850 | D7: 1494359 | E7: 11452209 | F7: 3801224 | G7: 616910 | H7: 4418134 | I7: 13759074 | J7: 2111269 | K7: 15870343 | N7: 1992
B8: 1993 | C8: 10042010 | D8: 1646580 | E8: 11688590 | F8: 3658011 | G8: 675220 | H8: 4333231 | I8: 13700021 | J8: 2321800 | K8: 16021821 | N8: 1993
B9: 1994 | C9: 9950060 | D9: 1919648 | E9: 11869708 | F9: 4427022 | G9: 706090 | H9: 5133112 | I9: 14377082 | J9: 2625738 | K9: 17002820 | N9: 1994
B10: 1995 | C10: 10538170 | D10: 2171642 | E10: 12709812 | F10: 4327055 | G10: 761890 | H10: 5088945 | I10: 14865225 | J10: 2933532 | K10: 17798757 | N10: 1995
B11: 1996 | C11: 11295130 | D11: 2408858 | E11: 13703988 | F11: 4711014 | G11: 871560 | H11: 5582574 | I11: 16006144 | J11: 3280418 | K11: 19286562 | N11: 1996
B12: 1997 | C12: 11879460 | D12: 2618419 | E12: 14497879 | F12: 4588409 | G12: 876520 | H12: 5464929 | I12: 16467869 | J12: 3494939 | K12: 19962808 | N12: 1997
B13: 1998 | C13: 11806860 | D13: 2601321 | E13: 14408181 | F13: 4525445 | G13: 725360 | H13: 5250805 | I13: 16332305 | J13: 3326681 | K13: 19658986 | N13: 1998
B14: 1999 | C14: 11998930 | D14: 2862701 | E14: 14861631 | F14: 4194881 | G14: 726810 | H14: 4921691 | I14: 16193811 | J14: 3589511 | K14: 19783322 | N14: 1999
B15: 2000 | C15: 12258500 | D15: 3201319 | E15: 15459819 | F15: 3874966 | G15: 873240 | H15: 4748206 | I15: 16133466 | J15: 4074559 | K15: 20208025 | N15: 2000
B16: 2001 | C16: 9512850 | D16: 2941926 | E16: 12454776 | F16: 3750783 | G16: 846140 | H16: 4596923 | I16: 13263633 | J16: 3788066 | K16: 17051699 | N16: 2001
B17: 2002 | C17: 8346560 | D17: 2786500 | E17: 11133060 | F17: 3425029 | G17: 863290 | H17: 4288319 | I17: 11771589 | J17: 3649790 | K17: 15421379 | N17: 2002
... B30: 2015 | C30: 14907093 | D30: 4527305 | E30: 19434398 | F30: 4493286 | G30: 1027335 | H30: 5520621 | I30: 19400379 | J30: 5554640 | K30: 24955019 | N30: 2015
B31: 2016 | I31: 20331323 | J31: 6078819 | K31: 26410142 | N31: 2016 | U31: December reports from: https://www.flysfo.com/about/media/facts-statistics/air-traffic-statistics
B32: 2017 | I32: 21220349 | J32: 6642080 | K32: 27862429 | N32: 2017
B33: 2018 | I33: 21695935 | J33: 7040356 | K33: 28736291 | N33: 2018
B34: 2019 | I34: 21116518 | J34: 7548553 | K34: 28665071 | N34: 2019
B35: 2020 | I35: 6571602 | J35: 1609116 | K35: 8180718 | N35: 2020
B36: 2021 | I36: 10547727 | J36: 1614453 | K36: 12162180 | N36: 2021
B37: 2022 | I37: 16070630 | J37: 4976942 | K37: 21047572 | N37: 2022
B38: 2023 | I38: 17994192 | J38: 6985618 | K38: 24979810 | N38: 2023
B39: 2024 | I39: 18204966 | J39: 7849620 | K39: 26054586 | N39: 2024
B40: 2025 | I40: 19303101 | J40: 7947705 | K40: 27250806 | N40: 2025
B42: % Connecting Passengers (2011-2015) | H42: =SUM(H26:H30)/SUM(K26:K30) -> 0.22510153
B45: 2025 Monthly Enplanements | F45: Source: Monthly reports from: | H45: https://www.flysfo.com/about/media/facts-statistics/air-traffic-statistics
B46: Month | C46: Enplanement | D46: #Days | E46: Average Daily
B47: Jan | C47: 1946169 | D47: 31 | E47: =C47/D47 -> 62779.645
B48: Feb | C48: 1776051 | D48: 28 | E48: =C48/D48 -> 63430.393
B49: Mar | C49: 2140810 | D49: 31 | E49: =C49/D49 -> 69058.387
B50: Apr | C50: 2186485 | D50: 30 | E50: =C50/D50 -> 72882.833
B51: May | C51: 2438088 | D51: 31 | E51: =C51/D51 -> 78648
B52: Jun | C52: 2633873 | D52: 30 | E52: =C52/D52 -> 87795.767
B53: Jul | C53: 2568577 | D53: 31 | E53: =C53/D53 -> 82857.323
B54: Aug | C54: 2470549 | D54: 31 | E54: =C54/D54 -> 79695.129
B55: Sep | C55: 2200973 | D55: 30 | E55: =C55/D55 -> 73365.767
B56: Oct | C56: 2414642 | D56: 31 | E56: =C56/D56 -> 77891.677
...

Sheet OAK
B2: Passengers
B3: Year | C3: Total Enplaned Passengers | D3: Source
B4: 2000 | C4: 5196451 | D4: FAA enplanement data: https://www.faa.gov/airports/planning_capacity/passenger_allcargo_stats/passenger/previous_years
B5: 2008 | C5: 5724888 | D5: December reports from: https://www.iflyoak.com/business/facts-figures/
B6: 2009 | C6: 4750185
B7: 2010 | C7: 4769915
B8: 2011 | C8: 4642107
B9: 2012 | C9: 5022684
B10: 2013 | C10: 4870006
B11: 2014 | C11: 5167242
B12: 2015 | C12: 5603543
B13: 2016 | C13: 6041455
B14: 2017 | C14: 6530308
B15: 2018 | C15: 6798321
B16: 2019 | C16: 6689457
B17: 2020 | C17: 2306739
B18: 2021 | C18: 4083962
B19: 2022 | C19: 5579900 | I19: %Connecting Sources
B20: 2023 | C20: 5611677 | I20: =63481/402504 -> 0.1577152 | J20: Oakland International Airport saw over 42 percent jump in international passengers in January - Oakland San Francisco Bay Airport (OAK)
B21: 2024 | C21: =5080487+310503 -> 5390990 | I21: =62233/441372 -> 0.14099898 | J21: Oakland International Airport’s passenger totals for 2022 soar to over 11 million - Oakland San Francisco Bay Airport (OAK)
B22: 2025 | C22: =4204915+390515 -> 4595430
B25: 2025 Monthly Enplanements
B26: Month | C26: Enplanement | D26: #Days | E26: Average Daily | G26: Source: Monthly reports from: | J26: https://www.iflyoak.com/business/facts-figures/
B27: Jan | C27: =298970+30874 -> 329844 | D27: 31 | E27: =C27/D27 -> 10640.129
B28: Feb | C28: =303119+33473 -> 336592 | D28: 28 | E28: =C28/D28 -> 12021.143
B29: Mar | C29: =366033+27904 -> 393937 | D29: 31 | E29: =C29/D29 -> 12707.645
B30: Apr | C30: =366999+30035 -> 397034 | D30: 30 | E30: =C30/D30 -> 13234.467
B31: May | C31: =391839+26964 -> 418803 | D31: 31 | E31: =C31/D31 -> 13509.774
B32: Jun | C32: =383422+34057 -> 417479 | D32: 30 | E32: =C32/D32 -> 13915.967
B33: Jul | C33: =379852+31841 -> 411693 | D33: 31 | E33: =C33/D33 -> 13280.419
B34: Aug | C34: =372252+28699 -> 400951 | D34: 31 | E34: =C34/D34 -> 12933.903
B35: Sep | C35: =343053+28463 -> 371516 | D35: 30 | E35: =C35/D35 -> 12383.867
B36: Oct | C36: =352354+32883 -> 385237 | D36: 31 | E36: =C36/D36 -> 12427
B37: Nov | C37: =315854+37126 -> 352980 | D37: 30 | E37: =C37/D37 -> 11766
B38: Dec | C38: =331168+48196 -> 379364 | D38: 31 | E38: =C38/D38 -> 12237.548
B39: Total | C39: =SUM(C27:C38) -> 4595430 | D39: =SUM(D27:D38) -> 365 | E39: =C39/D39 -> 12590.219
B43: Air Traffic Operations
C44: Total (All Categories) | D44: Source | E44: Total (TAF Data) | F44: Source
B45: 2015 | C45: 215750 | D45: December reports from: https://www.iflyoak.com/business/facts-figures/ | E45: =FAA_TAF!M43 -> 209678 | F45: See FAA_TAF sheet. The sheet was pulled from https://taf.faa.gov/ in Feb 2026
B46: 2016 | C46: 222771 | E46: =FAA_TAF!M44 -> 224591
...

Sheet SJC
B3: Passengers | M3: Source
E4: 2025 | F4: 2024 | G4: 2023 | H4: 2022 | I4: 2019 | J4: 2010 | K4: 2000 | M4: 2022-2025 data - December reports from: | N4: https://www.flysanjose.com/airport-activity
B5: O&D | C5: Dom. | D5: Enplane | E5: 4785692 | F5: 5251924 | G5: 5098677 | H5: 4823867 | M5: Pre-2022 data is from FAA enplanement data: | N5: https://www.faa.gov/airports/planning_capacity/passenger_allcargo_stats/passenger/previous_years
B6: O&D | C6: Dom. | D6: Deplane | E6: 4801231 | F6: 5274752 | G6: 5094848 | H6: 4812012
B7: O&D | C7: Intl. | D7: Enplane | E7: 270347 | F7: 318743 | G7: 358900 | H7: 247437
B8: O&D | C8: Intl. | D8: Deplane | E8: 272771 | F8: 319881 | G8: 355019 | H8: 245513
B9: Connect | C9: Dom. | D9: Enplane | E9: 272563 | F9: 342985 | G9: 594858 | H9: 602447
B10: Connect | C10: Dom. | D10: Deplane | E10: 272563 | F10: 342985 | G10: 594858 | H10: 602447
B11: Connect | C11: Intl. | D11: Enplane | E11: 0 | F11: 0 | G11: 0 | H11: 0
B12: Connect | C12: Intl. | D12: Deplane | E12: 0 | F12: 0 | G12: 0 | H12: 0
B13: Total | E13: 10675167 | F13: 11851270 | G13: 12097160 | H13: 11333723
D14: Enplaned | E14: 5328602 | F14: 5913652 | G14: 6052435 | H14: 5673751 | I14: 7688152 | J14: 4056167 | K14: 6170384
D15: Deplaned | E15: 5346565 | F15: 5937618 | G15: 6044725 | H15: 5659972
B16: Total | E16: 10675167 | F16: 11851270 | G16: 12097160 | H16: 11333723
D18: % Connecting | E18: =SUM(E9,E11)/E14 -> 0.05115094 | F18: =SUM(F9,F11)/F14 -> 0.057998847 | G18: =SUM(G9,G11)/G14 -> 0.098284079 | H18: =SUM(H9,H11)/H14 -> 0.10618143
B21: 2025 Monthly Enplanements
B22: Month | C22: Enplanements | D22: #Days | E22: Average Daily | G22: Source: Monthly reports from: | J22: https://www.flysanjose.com/airport-activity
B23: Jan | C23: 370143 | D23: 31 | E23: =C23/D23 -> 11940.097
B24: Feb | C24: 376045 | D24: 28 | E24: =C24/D24 -> 13430.179
B25: Mar | C25: 438792 | D25: 31 | E25: =C25/D25 -> 14154.581
B26: Apr | C26: 440660 | D26: 30 | E26: =C26/D26 -> 14688.667
B27: May | C27: 463215 | D27: 31 | E27: =C27/D27 -> 14942.419
B28: Jun | C28: 509257 | D28: 30 | E28: =C28/D28 -> 16975.233
B29: Jul | C29: 497571 | D29: 31 | E29: =C29/D29 -> 16050.677
B30: Aug | C30: 485222 | D30: 31 | E30: =C30/D30 -> 15652.323
B31: Sep | C31: 434667 | D31: 30 | E31: =C31/D31 -> 14488.9
B32: Oct | C32: 460671 | D32: 31 | E32: =C32/D32 -> 14860.355
B33: Nov | C33: 415454 | D33: 30 | E33: =C33/D33 -> 13848.467
B34: Dec | C34: 436905 | D34: 31 | E34: =C34/D34 -> 14093.71
B35: Total | C35: =SUM(C23:C34) -> 5328602 | D35: =SUM(D23:D34) -> 365 | E35: =C35/D35 -> 14598.91
B39: Air Traffic Operations
C40: Total (All Categories) | D40: Source | E40: Total (TAF Data) | F40: Source
B41: 2015 | D41: December reports from: https://www.iflyoak.com/business/facts-figures/ | E41: =FAA_TAF!M259 -> 147370 | F41: See FAA_TAF sheet. The sheet was pulled from https://taf.faa.gov/ in Feb 2026
B42: 2016 | E42: =FAA_TAF!M260 -> 156461
B43: 2017 | E43: =FAA_TAF!M261 -> 173078
B44: 2018 | E44: =FAA_TAF!M262 -> 192961
B45: 2019 | E45: =FAA_TAF!M263 -> 204503
B46: 2020 | C46: 115952 | E46: =FAA_TAF!M264 -> 140923
B47: 2021 | C47: 133289 | E47: =FAA_TAF!M265 -> 122814
B48: 2022 | C48: 164291 | E48: =FAA_TAF!M266 -> 161758
...

Sheet BayAreaPopulation
C2: Plan Bay Area 2050+ Regional Growth Forecast
D4: 2020 | E4: 2025 | F4: 2030 | G4: 2035 | H4: 2040 | I4: 2045 | J4: 2050
C5: Population | D5: 7749000 | E5: 7723000 | F5: 8048000 | G5: 8476000 | H5: 8903000 | I5: 9266000 | J5: 9586000 | L5: Source: | M5: Provided by MTC
C6: Households | D6: 2798000 | E6: 2902000 | F6: 3027000 | G6: 3312000 | H6: 3511000 | I6: 3662000 | J6: 3796000
C7: Housing Units | D7: 2875000 | E7: 3018000 | F7: 3187000 | G7: 3486000 | H7: 3696000 | I7: 3855000 | J7: 3996000
C8: Employment | D8: 4025000 | E8: 4154000 | F8: 4661000 | G8: 4855000 | H8: 5079000 | I8: 5255000 | J8: 5436000
C10: Note: numbers rounded to the thousands.
C11: Note: the forecast was presented to the Commission and the ABAG Executive Board in January 2025 as part of the Plan Bay Area 2050+ Final Blueprint approval item.
C13: Growth (2025-2050) | D13: =J5/E5-1 -> 0.2412275
C14: CAGR (2025-2050) | D14: =(J5/E5)^(1/25)-1 -> 0.0086815

Sheet TSA
A1: Year | B1: Month | C1: total_weekday_counts | D1: total_weekend_counts | E1: number_of_weekdays | F1: number_of_weekends | G1: average_weekday_counts | H1: average_weekend_counts | L1: Date | M1: Numbers | O1: Source: | P1: https://www.tsa.gov/travel/passenger-volumes
A2: 2023 | B2: January | C2: 43271471 | D2: 17635411 | E2: 22 | F2: 9 | G2: 1966885.1 | H2: 1959490.1 | L2: 45658 | M2: 2317817
A3: 2023 | B3: February | C3: 41720599 | D3: 16640531 | E3: 20 | F3: 8 | G3: 2086029.9 | H3: 2080066.4 | J3: <--Processed Data | L3: 45659 | M3: 2612162
A4: 2023 | B4: March | C4: 53019728 | D4: 18899734 | E4: 23 | F4: 8 | G4: 2305205.6 | H4: 2362466.8 | J4: RawData--> | L4: 45660 | M4: 2563751
A5: 2023 | B5: April | C5: 47031073 | D5: 23185853 | E5: 20 | F5: 10 | G5: 2351553.6 | H5: 2318585.3 | L5: 45661 | M5: 2543303
A6: 2023 | B6: May | C6: 55952617 | D6: 18609139 | E6: 23 | F6: 8 | G6: 2432722.5 | H6: 2326142.4 | J6: Data shows average weekday travel is similar to average weekend travel. | L6: 45662 | M6: 2579257
A7: 2023 | B7: June | C7: 56920820 | D7: 20235378 | E7: 22 | F7: 8 | G7: 2587310 | H7: 2529422.2 | L7: 45663 | M7: 2222167
A8: 2023 | B8: July | C8: 53865903 | D8: 25981148 | E8: 21 | F8: 10 | G8: 2565043 | H8: 2598114.8 | L8: 45664 | M8: 1915448
A9: 2023 | B9: August | C9: 55821296 | D9: 19544726 | E9: 23 | F9: 8 | G9: 2427012.9 | H9: 2443090.8 | L9: 45665 | M9: 1885768
A10: 2023 | B10: September | C10: 49965046 | D10: 20248622 | E10: 21 | F10: 9 | G10: 2379287.9 | H10: 2249846.9 | L10: 45666 | M10: 2033464
A11: 2023 | B11: October | C11: 53632271 | D11: 22096812 | E11: 22 | F11: 9 | G11: 2437830.5 | H11: 2455201.3 | L11: 45667 | M11: 2000526
A12: 2023 | B12: November | C12: 51781167 | D12: 19926711 | E12: 22 | F12: 8 | G12: 2353689.4 | H12: 2490838.9 | L12: 45668 | M12: 1858186
A13: 2023 | B13: December | C13: 49971443 | D13: 22590697 | E13: 21 | F13: 10 | G13: 2379592.5 | H13: 2259069.7 | L13: 45669 | M13: 2322779
A14: 2023 | B14: Total | C14: 612953434 | D14: 245594762 | E14: 260 | F14: 105 | G14: 2357513.2 | H14: 2338997.7 | L14: 45670 | M14: 2063978
A15: 2024 | B15: January | C15: 48006907 | D15: 16640344 | E15: 23 | F15: 8 | G15: 2087256.8 | H15: 2080043 | L15: 45671 | M15: 1651244
A16: 2024 | B16: February | C16: 47091100 | D16: 17416138 | E16: 21 | F16: 8 | G16: 2242433.3 | H16: 2177017.2 | L16: 45672 | M16: 1844782
A17: 2024 | B17: March | C17: 52362511 | D17: 24999508 | E17: 21 | F17: 10 | G17: 2493452.9 | H17: 2499950.8 | L17: 45673 | M17: 2369562
A18: 2024 | B18: April | C18: 54405207 | D18: 19634317 | E18: 22 | F18: 8 | G18: 2472964 | H18: 2454289.6 | L18: 45674 | M18: 2526699
... A40: 2025 | B40: Total | C40: 646143947 | D40: 260592029 | E40: 261 | F40: 104 | G40: 2475647.3 | H40: 2505692.6 | L40: 45696 | M40: 1828477
L41: 45697 | M41: 2186024
L42: 45698 | M42: 2323951
L43: 45699 | M43: 1753906
L44: 45700 | M44: 1990225
L45: 45701 | M45: 2563360
L46: 45702 | M46: 2626024
L47: 45703 | M47: 2160974
L48: 45704 | M48: 2394991
L49: 45705 | M49: 2721332
L50: 45706 | M50: 2243788
L51: 45707 | M51: 2122519
L52: 45708 | M52: 2466484
... L1097: 45291 | M1097: 2116715
