Workbook

Sheet Airport_File_Map
A1: FILE_NAME | B1: AIRPORT | C1: DIRECTION | D1: YEAR | E1: AIRPORT_TAZ | F1: TAZ_MIN | G1: TAZ_MAX
A2: 2023_fromOAK | B2: OAK | C2: from | D2: 2023 | E2: 874 | F2: 1 | G2: 1454
A3: 2023_toOAK | B3: OAK | C3: to | D3: 2023 | E3: 874 | F3: 1 | G3: 1454
A4: 2050_fromOAK | B4: OAK | C4: from | D4: 2050 | E4: 874 | F4: 1 | G4: 1454
A5: 2050_toOAK | B5: OAK | C5: to | D5: 2050 | E5: 874 | F5: 1 | G5: 1454
A6: 2023_fromSFO | B6: SFO | C6: from | D6: 2023 | E6: 239 | F6: 1 | G6: 1454
A7: 2023_toSFO | B7: SFO | C7: to | D7: 2023 | E7: 239 | F7: 1 | G7: 1454
A8: 2050_fromSFO | B8: SFO | C8: from | D8: 2050 | E8: 239 | F8: 1 | G8: 1454
A9: 2050_toSFO | B9: SFO | C9: to | D9: 2050 | E9: 239 | F9: 1 | G9: 1454
A10: 2023_fromSJC | B10: SJC | C10: from | D10: 2023 | E10: 434 | F10: 1 | G10: 1454
A11: 2023_toSJC | B11: SJC | C11: to | D11: 2023 | E11: 434 | F11: 1 | G11: 1454
A12: 2050_fromSJC | B12: SJC | C12: from | D12: 2050 | E12: 434 | F12: 1 | G12: 1454
A13: 2050_toSJC | B13: SJC | C13: to | D13: 2050 | E13: 434 | F13: 1 | G13: 1454

Sheet Air_Pax_Targets
A1: FILE_NAME | B1: AIRPORT | C1: DIRECTION | D1: YEAR | E1: TARGET
A2: 2023_fromOAK | B2: OAK | C2: from | D2: 2023 | E2: 12945
A3: 2023_toOAK | B3: OAK | C3: to | D3: 2023 | E3: 12945
A4: 2050_fromOAK | B4: OAK | C4: from | D4: 2050 | E4: 22343
A5: 2050_toOAK | B5: OAK | C5: to | D5: 2050 | E5: 22343
A6: 2023_fromSFO | B6: SFO | C6: from | D6: 2023 | E6: 53039
A7: 2023_toSFO | B7: SFO | C7: to | D7: 2023 | E7: 53039
A8: 2050_fromSFO | B8: SFO | C8: from | D8: 2050 | E8: 75451
A9: 2050_toSFO | B9: SFO | C9: to | D9: 2050 | E9: 75451
A10: 2023_fromSJC | B10: SJC | C10: from | D10: 2023 | E10: 14952
A11: 2023_toSJC | B11: SJC | C11: to | D11: 2023 | E11: 14952
A12: 2050_fromSJC | B12: SJC | C12: from | D12: 2050 | E12: 27105
A13: 2050_toSJC | B13: SJC | C13: to | D13: 2050 | E13: 27105

Sheet Super_Dist_Shares
A1: FILE_NAME | B1: AIRPORT | C1: DIRECTION | D1: YEAR | E1: DISTRICT | F1: SHARE
A2: 2023_fromOAK | B2: OAK | C2: from | D2: 2023 | E2: 1 | F2: 0.0806
A3: 2023_fromOAK | B3: OAK | C3: from | D3: 2023 | E3: 2 | F3: 0.0378
A4: 2023_fromOAK | B4: OAK | C4: from | D4: 2023 | E4: 3 | F4: 0.0242
A5: 2023_fromOAK | B5: OAK | C5: from | D5: 2023 | E5: 4 | F5: 0.0128
A6: 2023_fromOAK | B6: OAK | C6: from | D6: 2023 | E6: 5 | F6: 0.0106
A7: 2023_fromOAK | B7: OAK | C7: from | D7: 2023 | E7: 6 | F7: 0.0106
A8: 2023_fromOAK | B8: OAK | C8: from | D8: 2023 | E8: 7 | F8: 0.0036
A9: 2023_fromOAK | B9: OAK | C9: from | D9: 2023 | E9: 8 | F9: 0.009
A10: 2023_fromOAK | B10: OAK | C10: from | D10: 2023 | E10: 9 | F10: 0.0071
A11: 2023_fromOAK | B11: OAK | C11: from | D11: 2023 | E11: 10 | F11: 0.0032
A12: 2023_fromOAK | B12: OAK | C12: from | D12: 2023 | E12: 11 | F12: 0.0054
A13: 2023_fromOAK | B13: OAK | C13: from | D13: 2023 | E13: 12 | F13: 0.0015
... A409: 2050_toSJC | B409: SJC | C409: to | D409: 2050 | E409: 34 | F409: 0.001

Sheet Zone_Shares
A1: AIRPORT | B1: DIRECTION | C1: ZONE | D1: DISTRICT | E1: ZDIST_SHARE_ES | F1: ZDIST_SHARE_PK | G1: ZDIST_SHARE_RN | H1: ZDIST_SHARE_TX | I1: ZDIST_SHARE_LI | J1: ZDIST_SHARE_VN | K1: ZDIST_SHARE_HT | L1: ZDIST_SHARE_CH
A2: OAK | B2: from | C2: 1 | D2: 1 | E2: 0.01289936 | F2: 0.032155748 | G2: 0.0078666156 | H2: 0.0087065497 | I2: 0.010741511 | J2: 0.011750306 | K2: 0.010869565 | L2: 0.010204082
A3: OAK | B3: from | C3: 2 | D3: 1 | E3: 0.022309549 | F3: 0.04353057 | G3: 0.019910195 | H3: 0.020315283 | I3: 0.022591823 | J3: 0.023867809 | K3: 0.032608696 | L3: 0.020408163
A4: OAK | B4: from | C4: 3 | D4: 1 | E4: 0.0027314219 | F4: 0.00010937329 | G4: 0.0047687006 | H4: 0.0043532748 | I4: 0.0042966043 | J4: 0.0041615667 | K4: 0 | L4: 0
A5: OAK | B5: from | C5: 4 | D5: 1 | E5: 0.020987894 | F5: 0.03390572 | G5: 0.022242334 | H5: 0.02196425 | I5: 0.023562024 | J5: 0.024479804 | K5: 0.032608696 | L5: 0.020408163
A6: OAK | B6: from | C6: 5 | D6: 1 | E6: 0.041693834 | F6: 0.037624412 | G6: 0.058964809 | H6: 0.056328738 | I6: 0.056271656 | J6: 0.057037944 | K6: 0.065217391 | L6: 0.054421769
A7: OAK | B7: from | C7: 6 | D7: 1 | E7: 0.02206284 | F7: 0.0049217981 | G7: 0.037035748 | H7: 0.034694281 | I7: 0.033194733 | J7: 0.033047736 | K7: 0.043478261 | L7: 0.027210884
A8: OAK | B8: from | C8: 7 | D8: 1 | E8: 0.10434032 | F8: 0.022202778 | G8: 0.1815239 | H8: 0.16892026 | I8: 0.16188496 | J8: 0.16181151 | K8: 0.18478261 | L8: 0.13945578
A9: OAK | B9: from | C9: 8 | D9: 1 | E9: 0.019560505 | F9: 0.0038280652 | G9: 0.031884159 | H9: 0.029813337 | I9: 0.028551629 | J9: 0.028396573 | K9: 0.032608696 | L9: 0.023809524
A10: OAK | B10: from | C10: 9 | D10: 1 | E10: 0.015348829 | F10: 0.027452696 | G10: 0.011765115 | H10: 0.01226832 | I10: 0.013582814 | J10: 0.014075887 | K10: 0.010869565 | L10: 0.013605442
A11: OAK | B11: from | C11: 10 | D11: 1 | E11: 0.026997022 | F11: 0.018046593 | G11: 0.039715966 | H11: 0.037662423 | I11: 0.036936937 | J11: 0.037331701 | K11: 0.043478261 | L11: 0.030612245
A12: OAK | B12: from | C12: 11 | D12: 1 | E12: 0.044724831 | F12: 0.005249918 | G12: 0.08019771 | H12: 0.074533342 | I12: 0.071101871 | J12: 0.070869033 | K12: 0.076086957 | L12: 0.06462585
A13: OAK | B13: from | C13: 12 | D13: 1 | E13: 0.029111671 | F13: 0.021218418 | G13: 0.042709457 | H13: 0.040630565 | I13: 0.04005544 | J13: 0.040391677 | K13: 0.043478261 | L13: 0.034013605
... A876: OAK | B876: from | C876: 875 | D876: 18 | E876: 0.12333247 | F876: 0.086403307 | G876: 0.46226664 | H876: 0.34812789 | I876: 0.3363697 | J876: 0.35029821 | K876: 0.4749467 | L876: 0.14903565
A877: OAK | B877: from | C877: 876 | D877: 18 | E877: 0.00062169723 | F877: 0.00062011943 | G877: 9.89511181476351e-05 | H877: 0.00021034918 | I877: 0 | J877: 0 | K877: 0 | L877: 0.0008766803
A878: OAK | B878: from | C878: 877 | D878: 18 | E878: 0.0009018988 | F878: 0.00087276068 | G878: 0.00026386965 | H878: 0.00021034918 | I878: 0 | J878: 0 | K878: 0 | L878: 0.0008766803
A879: OAK | B879: from | C879: 878 | D879: 18 | E879: 0.0015980246 | F879: 0.0015847497 | G879: 0.00032983706 | H879: 0.00073622213 | I879: 0.0004443457 | J879: 0.00079522863 | K879: 0 | L879: 0.0014611338
A880: OAK | B880: from | C880: 879 | D880: 18 | E880: 0.0010069744 | F880: 0.00094166284 | G880: 0.00029685335 | H880: 0.00042069836 | I880: 0 | J880: 0 | K880: 0 | L880: 0.0008766803
A881: OAK | B881: from | C881: 880 | D881: 18 | E881: 0.0010901592 | F881: 0.0010564998 | G881: 0.00029685335 | H881: 0.00042069836 | I881: 0 | J881: 0.00039761431 | K881: 0 | L881: 0.0008766803
A882: OAK | B882: from | C882: 881 | D882: 18 | E882: 0.0010376214 | F882: 0.001010565 | G882: 0.00029685335 | H882: 0.00042069836 | I882: 0 | J882: 0 | K882: 0 | L882: 0.0008766803
A883: OAK | B883: from | C883: 882 | D883: 18 | E883: 0.00080995766 | F883: 0.00080385852 | G883: 0.00019790224 | H883: 0.00021034918 | I883: 0 | J883: 0 | K883: 0 | L883: 0.0008766803
A884: OAK | B884: from | C884: 883 | D884: 18 | E884: 0.011567071 | F884: 0.011460726 | G884: 0.0028695824 | H884: 0.005889777 | I884: 0.0057764941 | J884: 0.0051689861 | K884: 0.0015991471 | L884: 0.011104617
A885: OAK | B885: from | C885: 884 | D885: 18 | E885: 0.018046732 | F885: 0.016812127 | G885: 0.0097301933 | H885: 0.012726125 | I885: 0.012219507 | J885: 0.011530815 | K885: 0.0063965885 | L885: 0.018410286
A886: OAK | B886: from | C886: 885 | D886: 18 | E886: 0.029421165 | F886: 0.029168581 | G886: 0.0072564153 | H886: 0.014724443 | I886: 0.015107754 | J886: 0.013518887 | K886: 0.0031982942 | L886: 0.029222677
A887: OAK | B887: from | C887: 886 | D887: 18 | E887: 0.010901592 | F887: 0.010771704 | G887: 0.0027046639 | H887: 0.0055742533 | I887: 0.0055543213 | J887: 0.0051689861 | K887: 0.0015991471 | L887: 0.01081239
A888: OAK | B888: from | C888: 887 | D888: 18 | E888: 0.0081302237 | F888: 0.0080615526 | G888: 0.0020120061 | H888: 0.0043121582 | I888: 0.0039991113 | J888: 0.0035785288 | K888: 0.00053304904 | L888: 0.0081823495
A889: OAK | B889: from | C889: 888 | D889: 18 | E889: 0.0015104616 | F889: 0.0014928801 | G889: 0.00032983706 | H889: 0.00063104754 | I889: 0.0004443457 | J889: 0.00079522863 | K889: 0 | L889: 0.0014611338
... A966: OAK | B966: from | C966: 965 | D966: 18 | E966: 0.0029990324 | F966: 0.0063389986 | G966: 0.00032983706 | H966: 0.0011569205 | I966: 0.0024439014 | J966: 0.0027833002 | K966: 0.0042643923 | L966: 0.0014611338
A967: OAK | B967: from | C967: 966 | D967: 18 | E967: 2.18907476565955e-05 | F967: 0 | G967: 0 | H967: 0 | I967: 0 | J967: 0 | K967: 0 | L967: 0
A968: OAK | B968: from | C968: 967 | D968: 18 | E968: 0.014316549 | F968: 0.0058796509 | G968: 0.060755987 | H968: 0.045119899 | I968: 0.042435014 | J968: 0.043737575 | K968: 0.057569296 | L968: 0.019286967
A969: OAK | B969: from | C969: 968 | D969: 18 | E969: 0.037888506 | F969: 0.056890216 | G969: 0.08196451 | H969: 0.067311737 | I969: 0.073761386 | J969: 0.079920477 | K969: 0.11833689 | L969: 0.030683811
A970: OAK | B970: from | C970: 969 | D970: 18 | E970: 0.010796517 | F970: 0.021979789 | G970: 0.011577281 | H970: 0.011358856 | I970: 0.015107754 | J970: 0.01749503 | K970: 0.027185501 | L970: 0.0061367621
A971: OAK | B971: from | C971: 970 | D971: 18 | E971: 0.0033011247 | F971: 0.0059944878 | G971: 0.0030015173 | H971: 0.0031552377 | I971: 0.0037769385 | J971: 0.0047713718 | K971: 0.0069296375 | L971: 0.0020455874
A972: OAK | B972: from | C972: 971 | D972: 18 | E972: 0.012048668 | F972: 0.011276987 | G972: 0.038953757 | H972: 0.029974758 | I972: 0.029771162 | J972: 0.031013917 | K972: 0.043176972 | L972: 0.013442431
A973: OAK | B973: from | C973: 972 | D973: 18 | E973: 0.0029640072 | F973: 0.0018833257 | G973: 0.0059040834 | H973: 0.0048380311 | I973: 0.004443457 | J973: 0.0047713718 | K973: 0.0042643923 | L973: 0.0035067212
A974: OAK | B974: from | C974: 973 | D974: 18 | E974: 0.0050567627 | F974: 0.0045016077 | G974: 0.0038920773 | H974: 0.0044173328 | I974: 0.0039991113 | J974: 0.0035785288 | K974: 0.0026652452 | L974: 0.0055523086
A975: OAK | B975: from | C975: 974 | D975: 18 | E975: 0.0027976376 | F975: 0.0027560864 | G975: 0.00065967412 | H975: 0.0011569205 | I975: 0.0013330371 | J975: 0.0011928429 | K975: 0 | L975: 0.0026300409
A976: OAK | B976: from | C976: 975 | D976: 18 | E976: 0.0029990324 | F976: 0.0029627928 | G976: 0.00079160895 | H976: 0.0014724443 | I976: 0.00155521 | J976: 0.0011928429 | K976: 0 | L976: 0.0029222677
A977: OAK | B977: from | C977: 976 | D977: 18 | E977: 0.001199613 | F977: 0.0011943041 | G977: 0.00029685335 | H977: 0.00052587295 | I977: 0 | J977: 0.00039761431 | K977: 0 | L977: 0.0011689071
A978: OAK | B978: from | C978: 977 | D978: 18 | E978: 0.0022328563 | F978: 0.0016995866 | G978: 0.0031664358 | H978: 0.0029448885 | I978: 0.0028882471 | J978: 0.0027833002 | K978: 0.0021321962 | L978: 0.0023378141
...

Sheet TOD_Access_Submode_Shares
A1: FILE_NAME | B1: AIRPORT | C1: DIRECTION | D1: YEAR | E1: TOD | F1: ACCESS MODE | G1: SUBMODE | H1: SHARE_TOD | I1: SHARE_ACCESSMODE | J1: SHARE_SUBMODE
A2: 2023_fromOAK | B2: OAK | C2: from | D2: 2023 | E2: EA | F2: ES | G2: DA | H2: {=INDEX(Lookups!$D$2:$D$31,MATCH(1,(Lookups!$A$2:$A$31=TOD_Access_Submode_Shares!B2)*(Lookups!$B$2:$B$31=TOD_Access_Submode_Shares!C2)*(Lookups!$C$2:$C$31=TOD_Access_Submode_Shares!E2),0))} -> 0.064585576 | I2: {=INDEX(Lookups!$M$2:$M$49,MATCH(1,(Lookups!$J$2:$J$49=B2)*(Lookups!$K$2:$K$49=C2)*(Lookups!$L$2:$L$49=F2),0))} -> 0.33 | J2: 0.28
A3: 2023_fromOAK | B3: OAK | C3: from | D3: 2023 | E3: EA | F3: ES | G3: S2 | H3: {=INDEX(Lookups!$D$2:$D$31,MATCH(1,(Lookups!$A$2:$A$31=TOD_Access_Submode_Shares!B3)*(Lookups!$B$2:$B$31=TOD_Access_Submode_Shares!C3)*(Lookups!$C$2:$C$31=TOD_Access_Submode_Shares!E3),0))} -> 0.064585576 | I3: {=INDEX(Lookups!$M$2:$M$49,MATCH(1,(Lookups!$J$2:$J$49=B3)*(Lookups!$K$2:$K$49=C3)*(Lookups!$L$2:$L$49=F3),0))} -> 0.33 | J3: 0.49
A4: 2023_fromOAK | B4: OAK | C4: from | D4: 2023 | E4: EA | F4: ES | G4: S3 | H4: {=INDEX(Lookups!$D$2:$D$31,MATCH(1,(Lookups!$A$2:$A$31=TOD_Access_Submode_Shares!B4)*(Lookups!$B$2:$B$31=TOD_Access_Submode_Shares!C4)*(Lookups!$C$2:$C$31=TOD_Access_Submode_Shares!E4),0))} -> 0.064585576 | I4: {=INDEX(Lookups!$M$2:$M$49,MATCH(1,(Lookups!$J$2:$J$49=B4)*(Lookups!$K$2:$K$49=C4)*(Lookups!$L$2:$L$49=F4),0))} -> 0.33 | J4: 0.23
A5: 2023_fromOAK | B5: OAK | C5: from | D5: 2023 | E5: EA | F5: PK | G5: DA | H5: {=INDEX(Lookups!$D$2:$D$31,MATCH(1,(Lookups!$A$2:$A$31=TOD_Access_Submode_Shares!B5)*(Lookups!$B$2:$B$31=TOD_Access_Submode_Shares!C5)*(Lookups!$C$2:$C$31=TOD_Access_Submode_Shares!E5),0))} -> 0.064585576 | I5: {=INDEX(Lookups!$M$2:$M$49,MATCH(1,(Lookups!$J$2:$J$49=B5)*(Lookups!$K$2:$K$49=C5)*(Lookups!$L$2:$L$49=F5),0))} -> 0.09 | J5: 0.62
A6: 2023_fromOAK | B6: OAK | C6: from | D6: 2023 | E6: EA | F6: PK | G6: S2 | H6: {=INDEX(Lookups!$D$2:$D$31,MATCH(1,(Lookups!$A$2:$A$31=TOD_Access_Submode_Shares!B6)*(Lookups!$B$2:$B$31=TOD_Access_Submode_Shares!C6)*(Lookups!$C$2:$C$31=TOD_Access_Submode_Shares!E6),0))} -> 0.064585576 | I6: {=INDEX(Lookups!$M$2:$M$49,MATCH(1,(Lookups!$J$2:$J$49=B6)*(Lookups!$K$2:$K$49=C6)*(Lookups!$L$2:$L$49=F6),0))} -> 0.09 | J6: 0.28
A7: 2023_fromOAK | B7: OAK | C7: from | D7: 2023 | E7: EA | F7: PK | G7: S3 | H7: {=INDEX(Lookups!$D$2:$D$31,MATCH(1,(Lookups!$A$2:$A$31=TOD_Access_Submode_Shares!B7)*(Lookups!$B$2:$B$31=TOD_Access_Submode_Shares!C7)*(Lookups!$C$2:$C$31=TOD_Access_Submode_Shares!E7),0))} -> 0.064585576 | I7: {=INDEX(Lookups!$M$2:$M$49,MATCH(1,(Lookups!$J$2:$J$49=B7)*(Lookups!$K$2:$K$49=C7)*(Lookups!$L$2:$L$49=F7),0))} -> 0.09 | J7: 0.1
A8: 2023_fromOAK | B8: OAK | C8: from | D8: 2023 | E8: EA | F8: RN | G8: DA | H8: {=INDEX(Lookups!$D$2:$D$31,MATCH(1,(Lookups!$A$2:$A$31=TOD_Access_Submode_Shares!B8)*(Lookups!$B$2:$B$31=TOD_Access_Submode_Shares!C8)*(Lookups!$C$2:$C$31=TOD_Access_Submode_Shares!E8),0))} -> 0.064585576 | I8: {=INDEX(Lookups!$M$2:$M$49,MATCH(1,(Lookups!$J$2:$J$49=B8)*(Lookups!$K$2:$K$49=C8)*(Lookups!$L$2:$L$49=F8),0))} -> 0.13 | J8: 0.46
A9: 2023_fromOAK | B9: OAK | C9: from | D9: 2023 | E9: EA | F9: RN | G9: S2 | H9: {=INDEX(Lookups!$D$2:$D$31,MATCH(1,(Lookups!$A$2:$A$31=TOD_Access_Submode_Shares!B9)*(Lookups!$B$2:$B$31=TOD_Access_Submode_Shares!C9)*(Lookups!$C$2:$C$31=TOD_Access_Submode_Shares!E9),0))} -> 0.064585576 | I9: {=INDEX(Lookups!$M$2:$M$49,MATCH(1,(Lookups!$J$2:$J$49=B9)*(Lookups!$K$2:$K$49=C9)*(Lookups!$L$2:$L$49=F9),0))} -> 0.13 | J9: 0.4
A10: 2023_fromOAK | B10: OAK | C10: from | D10: 2023 | E10: EA | F10: RN | G10: S3 | H10: {=INDEX(Lookups!$D$2:$D$31,MATCH(1,(Lookups!$A$2:$A$31=TOD_Access_Submode_Shares!B10)*(Lookups!$B$2:$B$31=TOD_Access_Submode_Shares!C10)*(Lookups!$C$2:$C$31=TOD_Access_Submode_Shares!E10),0))} -> 0.064585576 | I10: {=INDEX(Lookups!$M$2:$M$49,MATCH(1,(Lookups!$J$2:$J$49=B10)*(Lookups!$K$2:$K$49=C10)*(Lookups!$L$2:$L$49=F10),0))} -> 0.13 | J10: 0.14
A11: 2023_fromOAK | B11: OAK | C11: from | D11: 2023 | E11: EA | F11: TX | G11: DA | H11: {=INDEX(Lookups!$D$2:$D$31,MATCH(1,(Lookups!$A$2:$A$31=TOD_Access_Submode_Shares!B11)*(Lookups!$B$2:$B$31=TOD_Access_Submode_Shares!C11)*(Lookups!$C$2:$C$31=TOD_Access_Submode_Shares!E11),0))} -> 0.064585576 | I11: {=INDEX(Lookups!$M$2:$M$49,MATCH(1,(Lookups!$J$2:$J$49=B11)*(Lookups!$K$2:$K$49=C11)*(Lookups!$L$2:$L$49=F11),0))} -> 0.33 | J11: 0.04
A12: 2023_fromOAK | B12: OAK | C12: from | D12: 2023 | E12: EA | F12: TX | G12: S2 | H12: {=INDEX(Lookups!$D$2:$D$31,MATCH(1,(Lookups!$A$2:$A$31=TOD_Access_Submode_Shares!B12)*(Lookups!$B$2:$B$31=TOD_Access_Submode_Shares!C12)*(Lookups!$C$2:$C$31=TOD_Access_Submode_Shares!E12),0))} -> 0.064585576 | I12: {=INDEX(Lookups!$M$2:$M$49,MATCH(1,(Lookups!$J$2:$J$49=B12)*(Lookups!$K$2:$K$49=C12)*(Lookups!$L$2:$L$49=F12),0))} -> 0.33 | J12: 0.65
A13: 2023_fromOAK | B13: OAK | C13: from | D13: 2023 | E13: EA | F13: TX | G13: S3 | H13: {=INDEX(Lookups!$D$2:$D$31,MATCH(1,(Lookups!$A$2:$A$31=TOD_Access_Submode_Shares!B13)*(Lookups!$B$2:$B$31=TOD_Access_Submode_Shares!C13)*(Lookups!$C$2:$C$31=TOD_Access_Submode_Shares!E13),0))} -> 0.064585576 | I13: {=INDEX(Lookups!$M$2:$M$49,MATCH(1,(Lookups!$J$2:$J$49=B13)*(Lookups!$K$2:$K$49=C13)*(Lookups!$L$2:$L$49=F13),0))} -> 0.33 | J13: 0.31
... A1081: 2050_toSJC | B1081: SJC | C1081: to | D1081: 2050 | E1081: EV | F1081: CH | G1081: S3 | H1081: {=INDEX(Lookups!$D$2:$D$31,MATCH(1,(Lookups!$A$2:$A$31=TOD_Access_Submode_Shares!B1081)*(Lookups!$B$2:$B$31=TOD_Access_Submode_Shares!C1081)*(Lookups!$C$2:$C$31=TOD_Access_Submode_Shares!E1081),0))} -> 0.055613851 | I1081: {=INDEX(Lookups!$M$2:$M$49,MATCH(1,(Lookups!$J$2:$J$49=B1081)*(Lookups!$K$2:$K$49=C1081)*(Lookups!$L$2:$L$49=F1081),0))} -> 0.0433 | J1081: 1

Sheet Transit_TOD_Access_Shares
A1: FILE_NAME | B1: ACCESS_MODE | C1: TOD | D1: SHARE_TOD | E1: SHARE_ACCESSMODE
A2: TR_2023_fromOAK | B2: TR | C2: EA | D2: {=INDEX(Lookups!$H$2:$H$31,MATCH(1,(Lookups!$F$2:$F$31=A2)*(Lookups!$G$2:$G$31=C2),0))} -> 0.020659482 | E2: =_xlfn.XLOOKUP(A2,Lookups!O:O,Lookups!P:P) -> 0.05
A3: TR_2023_fromOAK | B3: TR | C3: AM | D3: {=INDEX(Lookups!$H$2:$H$31,MATCH(1,(Lookups!$F$2:$F$31=A3)*(Lookups!$G$2:$G$31=C3),0))} -> 0.1566227 | E3: =_xlfn.XLOOKUP(A3,Lookups!O:O,Lookups!P:P) -> 0.05
A4: TR_2023_fromOAK | B4: TR | C4: MD | D4: {=INDEX(Lookups!$H$2:$H$31,MATCH(1,(Lookups!$F$2:$F$31=A4)*(Lookups!$G$2:$G$31=C4),0))} -> 0.32980225 | E4: =_xlfn.XLOOKUP(A4,Lookups!O:O,Lookups!P:P) -> 0.05
A5: TR_2023_fromOAK | B5: TR | C5: PM | D5: {=INDEX(Lookups!$H$2:$H$31,MATCH(1,(Lookups!$F$2:$F$31=A5)*(Lookups!$G$2:$G$31=C5),0))} -> 0.28394725 | E5: =_xlfn.XLOOKUP(A5,Lookups!O:O,Lookups!P:P) -> 0.05
A6: TR_2023_fromOAK | B6: TR | C6: EV | D6: {=INDEX(Lookups!$H$2:$H$31,MATCH(1,(Lookups!$F$2:$F$31=A6)*(Lookups!$G$2:$G$31=C6),0))} -> 0.20896832 | E6: =_xlfn.XLOOKUP(A6,Lookups!O:O,Lookups!P:P) -> 0.05
A7: TR_2023_fromSFO | B7: TR | C7: EA | D7: {=INDEX(Lookups!$H$2:$H$31,MATCH(1,(Lookups!$F$2:$F$31=A7)*(Lookups!$G$2:$G$31=C7),0))} -> 0.0029969608 | E7: =_xlfn.XLOOKUP(A7,Lookups!O:O,Lookups!P:P) -> 0.05
A8: TR_2023_fromSFO | B8: TR | C8: AM | D8: {=INDEX(Lookups!$H$2:$H$31,MATCH(1,(Lookups!$F$2:$F$31=A8)*(Lookups!$G$2:$G$31=C8),0))} -> 0.076174403 | E8: =_xlfn.XLOOKUP(A8,Lookups!O:O,Lookups!P:P) -> 0.05
A9: TR_2023_fromSFO | B9: TR | C9: MD | D9: {=INDEX(Lookups!$H$2:$H$31,MATCH(1,(Lookups!$F$2:$F$31=A9)*(Lookups!$G$2:$G$31=C9),0))} -> 0.36652286 | E9: =_xlfn.XLOOKUP(A9,Lookups!O:O,Lookups!P:P) -> 0.05
A10: TR_2023_fromSFO | B10: TR | C10: PM | D10: {=INDEX(Lookups!$H$2:$H$31,MATCH(1,(Lookups!$F$2:$F$31=A10)*(Lookups!$G$2:$G$31=C10),0))} -> 0.35934282 | E10: =_xlfn.XLOOKUP(A10,Lookups!O:O,Lookups!P:P) -> 0.05
A11: TR_2023_fromSFO | B11: TR | C11: EV | D11: {=INDEX(Lookups!$H$2:$H$31,MATCH(1,(Lookups!$F$2:$F$31=A11)*(Lookups!$G$2:$G$31=C11),0))} -> 0.19496296 | E11: =_xlfn.XLOOKUP(A11,Lookups!O:O,Lookups!P:P) -> 0.05
A12: TR_2023_fromSJC | B12: TR | C12: EA | D12: {=INDEX(Lookups!$H$2:$H$31,MATCH(1,(Lookups!$F$2:$F$31=A12)*(Lookups!$G$2:$G$31=C12),0))} -> 0 | E12: =_xlfn.XLOOKUP(A12,Lookups!O:O,Lookups!P:P) -> 0.0034
A13: TR_2023_fromSJC | B13: TR | C13: AM | D13: {=INDEX(Lookups!$H$2:$H$31,MATCH(1,(Lookups!$F$2:$F$31=A13)*(Lookups!$G$2:$G$31=C13),0))} -> 0.11241911 | E13: =_xlfn.XLOOKUP(A13,Lookups!O:O,Lookups!P:P) -> 0.0034
... A31: TR_2023_toSJC | B31: TR | C31: EV | D31: {=INDEX(Lookups!$H$2:$H$31,MATCH(1,(Lookups!$F$2:$F$31=A31)*(Lookups!$G$2:$G$31=C31),0))} -> 0.17873303 | E31: =_xlfn.XLOOKUP(A31,Lookups!O:O,Lookups!P:P) -> 0.0034
A32: TR_2050_fromOAK | B32: TR | C32: EA | D32: =D2 -> 0.020659482 | E32: =E2 -> 0.05
A33: TR_2050_fromOAK | B33: TR | C33: AM | D33: =D3 -> 0.1566227 | E33: =E3 -> 0.05
A34: TR_2050_fromOAK | B34: TR | C34: MD | D34: =D4 -> 0.32980225 | E34: =E4 -> 0.05
A35: TR_2050_fromOAK | B35: TR | C35: PM | D35: =D5 -> 0.28394725 | E35: =E5 -> 0.05
A36: TR_2050_fromOAK | B36: TR | C36: EV | D36: =D6 -> 0.20896832 | E36: =E6 -> 0.05
A37: TR_2050_fromSFO | B37: TR | C37: EA | D37: =D7 -> 0.0029969608 | E37: =E7 -> 0.05
A38: TR_2050_fromSFO | B38: TR | C38: AM | D38: =D8 -> 0.076174403 | E38: =E8 -> 0.05
A39: TR_2050_fromSFO | B39: TR | C39: MD | D39: =D9 -> 0.36652286 | E39: =E9 -> 0.05
A40: TR_2050_fromSFO | B40: TR | C40: PM | D40: =D10 -> 0.35934282 | E40: =E10 -> 0.05
A41: TR_2050_fromSFO | B41: TR | C41: EV | D41: =D11 -> 0.19496296 | E41: =E11 -> 0.05
A42: TR_2050_fromSJC | B42: TR | C42: EA | D42: =D12 -> 0 | E42: =E12 -> 0.0034
A43: TR_2050_fromSJC | B43: TR | C43: AM | D43: =D13 -> 0.11241911 | E43: =E13 -> 0.0034
... A61: TR_2050_toSJC | B61: TR | C61: EV | D61: =D31 -> 0.17873303 | E61: =E31 -> 0.0034

Sheet Transit_Zone_Shares
A1: AIRPORT | B1: DIRECTION | C1: ZONE | D1: ZSHARE_TR
A2: OAK | B2: from | C2: 1 | D2: 0.0102
A3: OAK | B3: from | C3: 2 | D3: 0.0104
A4: OAK | B4: from | C4: 3 | D4: 0.0019
A5: OAK | B5: from | C5: 4 | D5: 0.0079
A6: OAK | B6: from | C6: 5 | D6: 0.0252
A7: OAK | B7: from | C7: 6 | D7: 0.0114
A8: OAK | B8: from | C8: 7 | D8: 0.0242
A9: OAK | B9: from | C9: 8 | D9: 0.0043
A10: OAK | B10: from | C10: 9 | D10: 0.0138
A11: OAK | B11: from | C11: 10 | D11: 0.0039
A12: OAK | B12: from | C12: 11 | D12: 0.0048
A13: OAK | B13: from | C13: 12 | D13: 0.0217
... A8725: SJC | B8725: to | C8725: 1454 | D8725: 0

Sheet Veh_Occupancy
A1: SUBMODE | B1: CONVERSION_FACTOR
A2: DA | B2: 1
A3: S2 | B3: 2
A4: S3 | B4: 3.2
A5: VN_HT_CH_S3 | B5: 5

Sheet Lookups
A1: AIRPORT | B1: DIRECTION | C1: TOD | D1: SHARE_TOD | F1: FILE_NAME_TRANSIT | G1: TOD | H1: SHARE_TOD_TRANSIT | J1: AIRPORT | K1: DIRECTION | L1: ACCESS_MODE | M1: SHARE_ACCESSMODE | O1: FILE_NAME_TRANSIT | P1: TRANSIT_MODE_SHARE
A2: OAK | B2: from | C2: EA | D2: 0.064585576 | F2: TR_2023_fromOAK | G2: EA | H2: 0.020659482 | J2: OAK | K2: from | L2: ES | M2: =M26 -> 0.33 | O2: TR_2023_fromOAK | P2: =P5 -> 0.05
A3: OAK | B3: from | C3: AM | D3: 0.15285253 | F3: TR_2023_fromOAK | G3: AM | H3: 0.1566227 | J3: OAK | K3: from | L3: PK | M3: =M27 -> 0.09 | O3: TR_2023_fromSFO | P3: =P6 -> 0.05
A4: OAK | B4: from | C4: MD | D4: 0.27018299 | F4: TR_2023_fromOAK | G4: MD | H4: 0.32980225 | J4: OAK | K4: from | L4: RN | M4: =M28 -> 0.13 | O4: TR_2023_fromSJC | P4: =P7 -> 0.0034
A5: OAK | B5: from | C5: PM | D5: 0.22389666 | F5: TR_2023_fromOAK | G5: PM | H5: 0.28394725 | J5: OAK | K5: from | L5: TX | M5: =M29 -> 0.33 | O5: TR_2023_toOAK | P5: 0.05
A6: OAK | B6: from | C6: EV | D6: 0.28848224 | F6: TR_2023_fromOAK | G6: EV | H6: 0.20896832 | J6: OAK | K6: from | L6: LI | M6: =M30 -> 0.01 | O6: TR_2023_toSFO | P6: 0.05
A7: SFO | B7: from | C7: EA | D7: 0.064171123 | F7: TR_2023_fromSFO | G7: EA | H7: 0.0029969608 | J7: OAK | K7: from | L7: VN | M7: =M31 -> 0.01 | O7: TR_2023_toSJC | P7: 0.0034
A8: SFO | B8: from | C8: AM | D8: 0.16470588 | F8: TR_2023_fromSFO | G8: AM | H8: 0.076174403 | J8: OAK | K8: from | L8: HT | M8: =M32 -> 0.02
A9: SFO | B9: from | C9: MD | D9: 0.2459893 | F9: TR_2023_fromSFO | G9: MD | H9: 0.36652286 | J9: OAK | K9: from | L9: CH | M9: =M33 -> 0.03
A10: SFO | B10: from | C10: PM | D10: 0.22032086 | F10: TR_2023_fromSFO | G10: PM | H10: 0.35934282 | J10: SFO | K10: from | L10: ES | M10: =M34 -> 0.33
A11: SFO | B11: from | C11: EV | D11: 0.30481283 | F11: TR_2023_fromSFO | G11: EV | H11: 0.19496296 | J11: SFO | K11: from | L11: PK | M11: =M35 -> 0.09
A12: SJC | B12: from | C12: EA | D12: 0.074032292 | F12: TR_2023_fromSJC | G12: EA | H12: 0 | J12: SFO | K12: from | L12: RN | M12: =M36 -> 0.13
A13: SJC | B13: from | C13: AM | D13: 0.11052708 | F13: TR_2023_fromSJC | G13: AM | H13: 0.11241911 | J13: SFO | K13: from | L13: TX | M13: =M37 -> 0.33
A14: SJC | B14: from | C14: MD | D14: 0.21479792 | F14: TR_2023_fromSJC | G14: MD | H14: 0.45669584 | J14: SFO | K14: from | L14: LI | M14: =M38 -> 0.01
A15: SJC | B15: from | C15: PM | D15: 0.325325 | F15: TR_2023_fromSJC | G15: PM | H15: 0.23253088 | J15: SFO | K15: from | L15: VN | M15: =M39 -> 0.01
A16: SJC | B16: from | C16: EV | D16: 0.27631771 | F16: TR_2023_fromSJC | G16: EV | H16: 0.19835417 | J16: SFO | K16: from | L16: HT | M16: =M40 -> 0.02
A17: OAK | B17: to | C17: EA | D17: 0.27069677 | F17: TR_2023_toOAK | G17: EA | H17: 0.022633745 | J17: SFO | K17: from | L17: CH | M17: =M41 -> 0.03
A18: OAK | B18: to | C18: AM | D18: 0.3824129 | F18: TR_2023_toOAK | G18: AM | H18: 0.19958848 | J18: SJC | K18: from | L18: ES | M18: =M42 -> 0.2433
A19: OAK | B19: to | C19: MD | D19: 0.13857097 | F19: TR_2023_toOAK | G19: MD | H19: 0.30452675 | J19: SJC | K19: from | L19: PK | M19: =M43 -> 0.12
... A25: SFO | B25: to | C25: PM | D25: 0.10779082 | F25: TR_2023_toSFO | G25: PM | H25: 0.26925485 | J25: SJC | K25: from | L25: CH | M25: =M49 -> 0.0433
A26: SFO | B26: to | C26: EV | D26: 0.12273212 | F26: TR_2023_toSFO | G26: EV | H26: 0.11365059 | J26: OAK | K26: to | L26: ES | M26: 0.33
A27: SJC | B27: to | C27: EA | D27: 0.28436516 | F27: TR_2023_toSJC | G27: EA | H27: 0 | J27: OAK | K27: to | L27: PK | M27: 0.09
A28: SJC | B28: to | C28: AM | D28: 0.47534103 | F28: TR_2023_toSJC | G28: AM | H28: 0.24886878 | J28: OAK | K28: to | L28: RN | M28: 0.13
A29: SJC | B29: to | C29: MD | D29: 0.14165792 | F29: TR_2023_toSJC | G29: MD | H29: 0.24886878 | J29: OAK | K29: to | L29: TX | M29: 0.33
A30: SJC | B30: to | C30: PM | D30: 0.043022036 | F30: TR_2023_toSJC | G30: PM | H30: 0.32352941 | J30: OAK | K30: to | L30: LI | M30: 0.01
A31: SJC | B31: to | C31: EV | D31: 0.055613851 | F31: TR_2023_toSJC | G31: EV | H31: 0.17873303 | J31: OAK | K31: to | L31: VN | M31: 0.01
J32: OAK | K32: to | L32: HT | M32: 0.02
J33: OAK | K33: to | L33: CH | M33: 0.03
J34: SFO | K34: to | L34: ES | M34: 0.33
J35: SFO | K35: to | L35: PK | M35: 0.09
J36: SFO | K36: to | L36: RN | M36: 0.13
J37: SFO | K37: to | L37: TX | M37: 0.33
J38: SFO | K38: to | L38: LI | M38: 0.01
J39: SFO | K39: to | L39: VN | M39: 0.01
J40: SFO | K40: to | L40: HT | M40: 0.02
J41: SFO | K41: to | L41: CH | M41: 0.03
J42: SJC | K42: to | L42: ES | M42: 0.2433
J43: SJC | K43: to | L43: PK | M43: 0.12
... J49: SJC | K49: to | L49: CH | M49: 0.0433

Sheet Source
A1: Year | B1: AIRPORT | C1: DIRECTION | D1: TOD Splits | E1: Access Mode Splits | F1: Submode (DA, S2, S3) Splits | G1: Super District Splits | H1: Zone Splits | I1: Vehicle Occupancy Factors
A2: 2023 | B2: OAK | C2: from | D2: FourAirportStudy (2023) is used for non-transit modes. Transit Passenger Surveys are used for transit mode. Specifically non-work trip summaries provided by MTC from 2022 SAMTRANS and 2024 BART surveys are used for OAK and SFO and 2017 VTA is used for SJC. | E2: Same as 'to' shares | F2: GoslingData(2007) | G2: GoslingData(2007) | H2: GoslingData(2007) by access mode at the super district level. Zone splits for transit are based on Transit Passenger Surveys using the same surveys as those used for the transit TOD splits. | I2: Assumption
B3: SFO
B4: SJC
B5: OAK | C5: to | E5: Using SFO Ground Access Survey 2024 because OAK data from FourAirport shows 0% Rental car and very high (43%) parked share which seems unlikely.
B6: SFO | E6: Ground Access Survey 2024
B7: SJC | E7: ASQ Departures Survey (2025), with reallocations of about 2% from Taxi/TNC mode to Limousine and Hotel shuttle modes
A8: 2050 | B8: OAK | C8: from | D8: Same as 2023 Year
B9: SFO
B10: SJC
B11: OAK | C11: to
B12: SFO
B13: SJC

Sheet Notes
B2: Sheet Name | C2: Description | D2: Comments | E2: How do I edit the values in this sheet?
B3: Airport_File_Map | C3: Contains the 12 output file names corresponding to the 3 airports*2 directions*2 scenario years, along with zone numbers for the airports | D3: These 12 files are in the same format as the Gosling DBFs used by the initial air passenger Cube script. The transit trips are written out in separate file. | E3: Directly edit the values in this sheet. If you're changing the scenario year or number of airports, edit the corresponding values appropriately in all the other sheets as well.
B4: Air_Pax_Targets | C4: Contains the one-way air passenger ground access person trip targets (column TARGET) for each of the 12 files as defined in 'Airport_File_Map' sheet. | D4: The targets are developed using annual enplanements and subtracting connecting passengers and converting to average day. The calculations and source of the targets are documented in the 'Enplanement_Summary' Excel workbook. | E4: Directly edit the TARGET values in this sheet.
B5: Super_Dist_Shares | C5: Contains the super district share of air passenger trips for each of the 12 files as defined in 'Airport_File_Map' sheet. | D5: This sheet has 408 rows corresponding to 34 superdistricts*12 files. The SHARE values sum up to 100% within each FILE_NAME. | E5: Directly edit the SHARE values in this sheet.
B6: Zone_Shares | C6: Contains the zonal shares for each of the 3 airports*2 directions combos by the eight non-transit access modes. | D6: This sheet has 8724 rows corresponding to 1454 zones*3 airports*2 directions. The ZDIST_SHARE_** values sum up to 100% or 0% within each AIRPORT, DIRECTION, and DISTRICT combo. Golsing data was used to develop this sheet. 0% implies that particular combo had no trips in the Gosling data. | E6: Either manually or processed from another dataset.
B7: TOD_Access_Submode_Shares | C7: Contains the TOD, access mode, and submode shares of air passenger trips for each of the 12 files as defined in 'Airport_File_Map' sheet. | D7: This sheet has 1080 rows corresponding to 5 TOD*18 access modes-sub modes combination*12 files. Transit is not one of the modes defined here. The combinations here are identical to the Gosling files. TOD - EA, AM, MD, PM, EV. Within each FILE_NAME, the SHARE_TOD sums up to 100% for unique TOD values. Access Modes - ES (Escort), PK (Parked), RN (Rental Car), TX (Taxi/TNC), LI (Limousine), VN (Share ride van), HT (Hotel Shuttle), CH (Charter Bus). Within each FILE_NAME and TOD combo, the SHARE_ACCESSMODE sums up to [100% minus the transit mode share] for unique ACCESS_MODE values. Submodes - DA (Drive Alone), S2 (Share ride 2), S3 (Share ride 3+). Note that ES, PK, RN, TX, LI are split by all three submodes, whereas VN, HT, CH are assumed to be S3 submode only. Within each FILE_NAME, TOD, and ACCESS_MODE combo, the SHARE_SUBMODE sums up to 100% for unique SUBMODE values. | E7: Directly edit the SHARE_SUBMODE values in this sheet. To edit the SHARE_TOD and SHARE_ACCESSMODE values in this sheet, edit the corresponding values in the 'Lookups' sheet. There's an Excel formula that pulls the values from the 'Lookups' sheet.
B8: Transit_TOD_Access_Shares | C8: Contains the 12 output file names (3 airports*2 directions*2 scenario years) for transit air passenger person trips, along with the transit mode share and the transit share of air passenger trips by TOD | D8: The transit trip tables are written out separately. The corresponding transit TOD shares and overall transit mode shares are defined in this sheet. The TOD splits for transit are assumed to be same as the TOD splits for non-transit mode. | E8: To edit the SHARE_TOD and SHARE_ACCESSMODE values in this sheet, edit the SHARE_TOD_TRANSIT and TRANSIT_MODE_SHARE values in the 'Lookups' sheet. There's an Excel formula that pulls the values from the 'Lookups' sheet.
B9: Transit_Zone_Shares | C9: Contains the zonal shares for each of the 3 airports*2 directions combos for the transit access mode | D9: This sheet has 8724 rows corresponding to 1454 zones*3 airports*2 directions. The ZSHARE_TR values sum up to 100% AIRPORT, DIRECTION combo. Transit Passengers Survey data was used to develop this sheet. | E9: Either manually or processed from another dataset.
B10: Veh_Occupancy | C10: Contains the factor to convert person trips to vehicle trips for all non-transit mode. | D10: The non-transit modes are sub-divided into DA, S2, S3 submodes. This sheet has factors for each of the three. Further, Share ride van (VN), Hotel Shuttle (HT), and Charter Bus (CH) are assumed to be S3 submode only (similar to Gosling), and have a different factor than the S3 submode for the other non-transit modes. | E10: Directly edit the CONVERSION_FACTOR values in this sheet. Script updates will be required if you want to use for example different factors for each of VN, HT, and CH modes.
B11: Lookups | C11: Contains TOD and access mode shares which are linked via Excel Formula to the 'TOD_Access_Submode_Shares' and 'Transit_Shares' sheets. | D11: The script does not read this sheet. | E11: Manually. Editing values here impacts the values in 'Transit_TOD_Access_Shares' and 'TOD_Access_Submode_Shares' sheets
B12: Source | C12: Contains the data source for all the various shares used in this workbook | D12: The script does not read this sheet. | E12: Edit it manually every time you change the source for any data
B16: Inputs to the Script
B17: This Parameters.xlsx file
B18: The TAZ shape file of the region with super districts (.\Input)
B21: Outputs from the Script
B22: Main Non Transit DBFs in "Gosling Summaries Format" (.\Output) - 12 files (3 airports × 2 directions × 2 scenario years)
C23: Based on:
C24: Super_Dist_Shares × TOD_Access_Submode_Shares × Air_Pax_Targets / Veh_Occupancy
B26: Transit DBFs (.\Output_Transit) - 12 files (3 airports × 2 directions × 2 scenario years)
C27: Based on:
C28: Transit_TOD_Access_Shares × Transit_Zone_Shares x Air_Pax_Targets
