Workbook

Sheet ATUS-2023
B2: Source: Bureau of Labor Statistics News Release for American Time Use Survey - 2023 Results
B3: https://www.bls.gov/news.release/pdf/atus.pdf
B45: Table 6. Employed persons working at home, workplace, and time spent working at each location by full- and part-time status and sex, jobholding status, and educational attainment, 2023 annual averages
B46: [Numbers in thousands]
C47: Total Employed | D47: Employed persons who worked on an average day | G47: Employed persons who worked at their workplace on an average day | J47: Employed persons who worked at home on an average day
B48: Characteristic | D48: Number | E48: Percent of employed | F48: Average hours of work | G48: Number | H48: Percent of those who worked | I48: Average hours of work at workplace | J48: Number | K48: Percent of those who worked | L48: Average hours of work at workplace
B49: Full- and part-time status
B50: Total, 15 years and over | C50: 175956 | D50: 113901 | E50: =D50/C50 -> 0.6473266 | F50: 7.75 | G50: 82644 | H50: =G50/D50 -> 0.72557748 | I50: 7.86 | J50: 39403 | K50: =J50/D50 -> 0.34594077 | L50: 5.12
B51: Full-time workers | C51: 141092 | D51: 98308 | E51: =D51/C51 -> 0.69676523 | F51: 8.15 | G51: 71800 | H51: =G51/D51 -> 0.73035765 | I51: 8.19 | J51: 34366 | K51: =J51/D51 -> 0.34957481 | L51: 5.37
B52: Part-time workers | C52: 34864 | D52: 15592 | E52: =D52/C52 -> 0.4472235 | F52: 5.28 | G52: 10844 | H52: =G52/D52 -> 0.69548486 | I52: 5.66 | J52: 5037 | K52: =J52/D52 -> 0.32305028 | L52: 3.45

Sheet ATUS-2022
B2: Source: Bureau of Labor Statistics News Release for American Time Use Survey - 2022 Results
B3: https://www.bls.gov/news.release/pdf/atus.pdf
B45: Table 6. Employed persons working at home, workplace, and time spent working at each location by full- and part-time status and sex, jobholding status, and educational attainment, 2022 annual averages
B46: [Numbers in thousands]
C47: Total Employed | D47: Employed persons who worked on an average day | G47: Employed persons who worked at their workplace on an average day | J47: Employed persons who worked at home on an average day
B48: Characteristic | D48: Number | E48: Percent of employed | F48: Average hours of work | G48: Number | H48: Percent of those who worked | I48: Average hours of work at workplace | J48: Number | K48: Percent of those who worked | L48: Average hours of work at workplace
B49: Full- and part-time status
B50: Total, 15 years and over | C50: 170196 | D50: 112477 | E50: =D50/C50 -> 0.66086747 | F50: 7.69 | G50: 77303 | H50: =G50/D50 -> 0.68727829 | I50: 7.88 | J50: 38028 | K50: =J50/D50 -> 0.33809579 | L50: 5.41
B51: Full-time workers | C51: 135315 | D51: 95152 | E51: =D51/C51 -> 0.70318886 | F51: 8.08 | G51: 65495 | H51: =G51/D51 -> 0.68831974 | I51: 8.22 | J51: 33156 | K51: =J51/D51 -> 0.348453 | L51: 5.71
B52: Part-time workers | C52: 34881 | D52: 17326 | E52: =D52/C52 -> 0.49671741 | F52: 5.52 | G52: 11808 | H52: =G52/D52 -> 0.6815191 | I52: 6.02 | J52: 4873 | K52: =J52/D52 -> 0.28125361 | L52: 3.33

Sheet ACS Summary
A2: Region | B2: Year | C2: Data_Type | D2: Mode | E2: Observed Share | F2: Source | G2: Linear Projection | H2: Exponential Extrapolation
A3: Bay Area | B3: 1970 | C3: Residence | D3: Work From Home | E3: 0.023734634 | F3: BayAreaCensus
A4: Bay Area | B4: 1980 | C4: Residence | D4: Work From Home | E4: 0.019189289 | F4: BayAreaCensus
A5: Bay Area | B5: 1990 | C5: Residence | D5: Work From Home | E5: 0.034339612 | F5: BayAreaCensus
A6: Bay Area | B6: 2000 | C6: Residence | D6: Work From Home | E6: 0.039973018 | F6: BayAreaCensus
A7: Bay Area | B7: 2006 | C7: Residence | D7: Work From Home | E7: 0.054620526 | F7: B08301_ACS06_1YR
A8: Bay Area | B8: 2007 | C8: Residence | D8: Work From Home | E8: 0.052047679 | F8: B08301_ACS07_1YR
A9: Bay Area | B9: 2008 | C9: Residence | D9: Work From Home | E9: 0.051475164 | F9: B08301_ACS08_1YR
A10: Bay Area | B10: 2009 | C10: Residence | D10: Work From Home | E10: 0.055304059 | F10: B08301_ACS09_1YR
A11: Bay Area | B11: 2010 | C11: Residence | D11: Work From Home | E11: 0.058507434 | F11: B08301_ACS10_1YR
A12: Bay Area | B12: 2011 | C12: Residence | D12: Work From Home | E12: 0.058832856 | F12: B08301_ACS11_1YR
A13: Bay Area | B13: 2012 | C13: Residence | D13: Work From Home | E13: 0.056016278 | F13: B08301_ACS12_1YR
A14: Bay Area | B14: 2013 | C14: Residence | D14: Work From Home | E14: 0.053802472 | F14: B08301_ACS13_1YR
... A19: Bay Area | B19: 2018 | C19: Residence | D19: Work From Home | E19: 0.06385909 | F19: B08301 _ACS18_1YR
A20: Bay Area | B20: 2019 | C20: Residence | D20: Work From Home | E20: ='Data-ACSDT1Y2019'!B27 -> 0.065062754 | F20: B08301 _ACS19_1YR
A21: Bay Area | B21: 2020 | C21: Residence | D21: Work From Home | E21: ='Data-ACSDT5Y2020'!B27 -> 0.10230163 | F21: B08301 _ACS20_5YR
A22: Bay Area | B22: 2021 | C22: Residence | D22: Work From Home | E22: ='Data-ACSDT1Y2021'!B27 -> 0.33036269 | F22: B08301 _ACS21_1YR
A23: Bay Area | B23: 2022 | C23: Residence | D23: Work From Home | E23: ='Data-ACSDT1Y2022'!B27 -> 0.24913762 | F23: B08301 _ACS22_1YR
A24: Bay Area | B24: 2023 | C24: Residence | D24: Work From Home | E24: ='Data-ACSDT1Y2023'!B27 -> 0.1848035 | F24: B08301 _ACS23_1YR
A25: Bay Area | B25: 2024 | C25: Residence | D25: Work From Home | E25: ='Data-ACSDT1Y2024'!B27 -> 0.17031241 | F25: B08301 _ACS24_1YR | G25: (note: 2024 data added in February 2026, for plan document, not used in modeling)
A26: Bay Area | B26: 2025 | F26: Projection | G26: {=SUM(LINEST($E$3:$E$24,$B$3:$B$24,TRUE,FALSE)*{2025,1})} -> 0.12792468 | H26: {=GROWTH($E$3:$E$24,$B$3:$B$24,B26,TRUE)} -> 0.11569172
A27: Bay Area | B27: 2030 | F27: Projection | G27: {=SUM(LINEST($E$3:$E$24,$B$3:$B$24,TRUE,FALSE)*{2030,1})} -> 0.14255231 | H27: {=GROWTH($E$3:$E$24,$B$3:$B$24,B27,TRUE)} -> 0.13986405
A28: Bay Area | B28: 2035 | F28: Projection | G28: {=SUM(LINEST($E$3:$E$24,$B$3:$B$24,TRUE,FALSE)*{2035,1})} -> 0.15717994 | H28: {=GROWTH($E$3:$E$24,$B$3:$B$24,B28,TRUE)} -> 0.16908688
A29: Bay Area | B29: 2040 | F29: Projection | G29: {=SUM(LINEST($E$3:$E$24,$B$3:$B$24,TRUE,FALSE)*{2040,1})} -> 0.17180756 | H29: {=GROWTH($E$3:$E$24,$B$3:$B$24,B29,TRUE)} -> 0.20441545
A30: Bay Area | B30: 2045 | F30: Projection | G30: {=SUM(LINEST($E$3:$E$24,$B$3:$B$24,TRUE,FALSE)*{2045,1})} -> 0.18643519 | H30: {=GROWTH($E$3:$E$24,$B$3:$B$24,B30,TRUE)} -> 0.24712549
A31: Bay Area | B31: 2050 | F31: Projection | G31: {=SUM(LINEST($E$3:$E$24,$B$3:$B$24,TRUE,FALSE)*{2050,1})} -> 0.20106282 | H31: {=GROWTH($E$3:$E$24,$B$3:$B$24,B31,TRUE)} -> 0.29875924

Sheet Info-ACSDT1Y2024
A1: Means of Transportation to Work
A3: Note: The table shown may have been modified by user selections. Some information may be missing.
A5: DATA NOTES
A6: TABLE ID: | B6: B08301
A7: SURVEY/PROGRAM: | B7: American Community Survey
A8: VINTAGE: | B8: 2024
A9: DATASET: | B9: ACSDT1Y2024
A10: PRODUCT: | B10: ACS 1-Year Estimates Detailed Tables
A11: UNIVERSE: | B11: Workers 16 years and over
A12: MLA: | B12: U.S. Census Bureau. "Means of Transportation to Work." American Community Survey, ACS 1-Year Estimates Detailed Tables, Table B08301, https://data.census.gov/table/ACSDT1Y2024.B08301?q=B08301:+MEANS+OF+TRANSPORTATION+TO+WORK&g=050XX00US06001,06013,06041,06055,06075,06081,06085,06095,06097&y=2024. Accessed on 19 Feb 2026.
A13: FTP URL: | B13: None
A14: API URL: | B14: https://api.census.gov/data/2024/acs/acs1
A16: USER SELECTIONS
A17: TABLES | B17: B08301
A18: GEOS | B18: Alameda County, California; Contra Costa County, California; Marin County, California; Napa County, California; San Francisco County, California; San Mateo County, California; Santa Clara County, California; Solano County, California; Sonoma County, California
A19: VINTAGES | B19: 2024
A21: EXCLUDED COLUMNS | B21: None
A23: APPLIED FILTERS | B23: None
A25: APPLIED SORTS | B25: None
A27: PIVOT & GROUPING
A28: PIVOT COLUMNS | B28: None
A29: PIVOT MODE | B29: Off
A30: ROW GROUPS | B30: None
A31: VALUE COLUMNS | B31: None
A33: WEB ADDRESS | B33: https://data.census.gov/table/ACSDT1Y2024.B08301?q=B08301:+MEANS+OF+TRANSPORTATION+TO+WORK&g=050XX00US06001,06013,06041,06055,06075,06081,06085,06095,06097&y=2024
A35: TABLE NOTES
A36: Key Table Information
A37: Table Title | B37: Means of Transportation to Work
A38: Table ID | B38: ACSDT1Y2024.B08301
A39: Survey/Program | B39: American Community Survey
A40: Year | B40: 2024
A41: Dataset | B41: ACS 1-Year Estimates Detailed Tables
A42: Source | B42: U.S. Census Bureau, 2024 American Community Survey, 1-Year Estimates
A43: Dataset Universe | B43: The dataset universe of the American Community Survey (ACS) is the U.S. resident population and housing. For more information about ACS residence rules, see the ACS Design and Methodology Report. Note that each table describes the specific universe of interest for that set of estimates.
A44: Methodology
A45: Unit(s) of Observation | B45: American Community Survey (ACS) data are collected from individuals living in housing units and group quarters, and about housing units whether occupied or vacant. For more information about ACS sampling and data collection, see the ACS Design and Methodology Report.
A46: Geography Coverage | B46: ACS data generally reflect the geographic boundaries of legal and statistical areas as of January 1 of the estimate year. For more information, see Geography Boundaries by Year. Estimates of urban and rural populations, housing units, and characteristics reflect boundaries of urban areas defined based on 2020 Census data. As a result, data for urban and rural areas from the ACS do not necessarily reflect the results of ongoing urbanization.
A47: Sampling | B47: The ACS consists of two separate samples: housing unit addresses and group quarters facilities. Independent housing unit address samples are selected for each county or county-equivalent in the U.S. and Puerto Rico, with sampling rates depending on a measure of size for the area. For more information on sampling in the ACS, see the Accuracy of the Data document.
A48: Confidentiality | B48: The Census Bureau has modified or suppressed some estimates in ACS data products to protect respondents' confidentiality. Title 13 United States Code, Section 9, prohibits the Census Bureau from publishing results in which an individual's data can be identified. For more information on confidentiality protection in the ACS, see the Accuracy of the Data document.
A49: Technical Documentation/Methodology | B49: Information about the American Community Survey (ACS) can be found on the ACS website. Supporting documentation including code lists, subject definitions, data accuracy, and statistical testing, and a full list of ACS tables and table shells (without estimates) can be found on the Technical Documentation section of the ACS website. Sample size and data quality measures (including coverage rates, allocation rates, and response rates) can be found on the American Community Survey website in the Methodology section. Data are based on a sample and are subject to sampling variability. The degree of uncertainty for an estimate arising from sampling variability is represented through the use of a margin of error. The value shown here is the 90 percent margin of error. The margin of error can be interpreted roughly as providing a 90 percent probability that the interval defined by the estimate minus the margin of error and the estimate plus the margin of error (the lower and upper confidence bounds) contains the true value. In addition to sampling variability, the ACS estimates are subject to nonsampling error (for a discussion of nonsampling variability, see ACS Technical Documentation). The effect of nonsampling error is not represented in these tables. Users must consider potential differences in geographic boundaries, questionnaire content or coding, or other methodological issues when comparing ACS data from different years. Statistically significant differences shown in ACS Comparison Profiles, or in data users' own analysis, may be the result of these differences and thus might not necessarily reflect changes to the social, economic, housing, or demographic characteristics being compared. For more information, see Comparing ACS Data.
...

Sheet Data-ACSDT1Y2024
B1: Alameda County, California | D1: Contra Costa County, California | F1: Marin County, California | H1: Napa County, California | J1: San Francisco County, California | L1: San Mateo County, California | N1: Santa Clara County, California | P1: Solano County, California | R1: Sonoma County, California
A2: Label | B2: Estimate | C2: Margin of Error | D2: Estimate | E2: Margin of Error | F2: Estimate | G2: Margin of Error | H2: Estimate | I2: Margin of Error | J2: Estimate | K2: Margin of Error | L2: Estimate | M2: Margin of Error | N2: Estimate | O2: Margin of Error | P2: Estimate | Q2: Margin of Error | R2: Estimate | S2: Margin of Error
A3: Total: | B3: 858737 | C3: ±9,430 | D3: 546458 | E3: ±8,444 | F3: 123945 | G3: ±3,755 | H3: 65567 | I3: ±2,091 | J3: 468430 | K3: ±7,060 | L3: 394856 | M3: ±6,057 | N3: 996180 | O3: ±11,058 | P3: 204889 | Q3: ±4,678 | R3: 239045 | S3: ±4,929
A4: Car, truck, or van: | B4: 567504 | C4: ±12,400 | D4: 405929 | E4: ±9,519 | F4: 76197 | G4: ±4,551 | H4: 51409 | I4: ±2,401 | J4: 170125 | K4: ±6,572 | L4: 281882 | M4: ±7,178 | N4: 758009 | O4: ±10,961 | P4: 171397 | Q4: ±5,429 | R4: 190783 | S4: ±5,371
A5: Drove alone | B5: 477739 | C5: ±13,188 | D5: 346838 | E5: ±8,407 | F5: 66533 | G5: ±4,466 | H5: 45238 | I5: ±2,926 | J5: 142260 | K5: ±5,890 | L5: 243914 | M5: ±7,822 | N5: 649283 | O5: ±11,268 | P5: 154229 | Q5: ±5,463 | R5: 163478 | S5: ±6,126
A6: Carpooled: | B6: 89765 | C6: ±7,092 | D6: 59091 | E6: ±5,779 | F6: 9664 | G6: ±2,292 | H6: 6171 | I6: ±1,606 | J6: 27865 | K6: ±3,644 | L6: 37968 | M6: ±3,898 | N6: 108726 | O6: ±6,673 | P6: 17168 | Q6: ±2,672 | R6: 27305 | S6: ±3,822
A7: In 2-person carpool | B7: 63540 | C7: ±6,054 | D7: 38348 | E7: ±4,419 | F7: 6952 | G7: ±2,115 | H7: 3921 | I7: ±1,318 | J7: 20959 | K7: ±2,878 | L7: 24967 | M7: ±3,287 | N7: 76775 | O7: ±5,780 | P7: 12472 | Q7: ±2,622 | R7: 18898 | S7: ±3,484
A8: In 3-person carpool | B8: 13816 | C8: ±3,203 | D8: 12719 | E8: ±2,626 | F8: 1071 | G8: ±954 | H8: 1521 | I8: ±979 | J8: 3965 | K8: ±1,487 | L8: 8756 | M8: ±2,535 | N8: 16695 | O8: ±2,347 | P8: 2852 | Q8: ±988 | R8: 4852 | S8: ±1,623
A9: In 4-person carpool | B9: 6536 | C9: ±2,383 | D9: 3535 | E9: ±1,315 | F9: 1381 | G9: ±1,473 | H9: 324 | I9: ±308 | J9: 1950 | K9: ±1,027 | L9: 2213 | M9: ±1,080 | N9: 9723 | O9: ±3,006 | P9: 944 | Q9: ±525 | R9: 1881 | S9: ±1,506
A10: In 5- or 6-person carpool | B10: 4572 | C10: ±2,377 | D10: 3163 | E10: ±1,464 | F10: 207 | G10: ±364 | H10: 182 | I10: ±196 | J10: 615 | K10: ±436 | L10: 1587 | M10: ±795 | N10: 4578 | O10: ±1,663 | P10: 841 | Q10: ±854 | R10: 1135 | S10: ±756
A11: In 7-or-more-person carpool | B11: 1301 | C11: ±666 | D11: 1326 | E11: ±1,365 | F11: 53 | G11: ±91 | H11: 223 | I11: ±290 | J11: 376 | K11: ±281 | L11: 445 | M11: ±232 | N11: 955 | O11: ±480 | P11: 59 | Q11: ±95 | R11: 539 | S11: ±468
A12: Public transportation: | B12: 83077 | C12: ±5,470 | D12: 30304 | E12: ±3,669 | F12: 7357 | G12: ±2,035 | H12: 1118 | I12: ±619 | J12: 117279 | K12: ±6,864 | L12: 23263 | M12: ±2,465 | N12: 28793 | O12: ±3,872 | P12: 4128 | Q12: ±1,222 | R12: 4615 | S12: ±1,428
A13: Bus | B13: 30318 | C13: ±3,723 | D13: 4091 | E13: ±1,420 | F13: 4868 | G13: ±1,777 | H13: 708 | I13: ±500 | J13: 77526 | K13: ±5,744 | L13: 10102 | M13: ±1,825 | N13: 15838 | O13: ±2,814 | P13: 2533 | Q13: ±976 | R13: 3145 | S13: ±1,087
A14: Subway or elevated rail | B14: 38113 | C14: ±3,660 | D14: 17389 | E14: ±2,957 | F14: 0 | G14: ±225 | H14: 186 | I14: ±231 | J14: 26029 | K14: ±3,093 | L14: 6337 | M14: ±1,286 | N14: 1256 | O14: ±548 | P14: 448 | Q14: ±396 | R14: 544 | S14: ±510
... A23: Worked from home | B23: 154971 | C23: ±7,295 | D23: 94847 | E23: ±5,318 | F23: 32166 | G23: ±2,997 | H23: 9833 | I23: ±1,732 | J23: 100347 | K23: ±5,261 | L23: 68690 | M23: ±4,833 | N23: 146556 | O23: ±7,773 | P23: 22434 | Q23: ±2,557 | R23: 34052 | S23: ±2,881
A25: Worked at home Bay Area | B25: =SUMIF($B$2:$S$2,"=Estimate",$B$23:$S$23) -> 663896
A26: Total | B26: =SUMIF($B$2:$S$2,"=Estimate",$B$3:$S$3) -> 3898107
A27: Share | B27: =B25/B26 -> 0.17031241

Sheet Info-ACSDT1Y2023
A1: Means of Transportation to Work
A3: Note: The table shown may have been modified by user selections. Some information may be missing.
A5: DATA NOTES
A6: TABLE ID: | B6: B08301
A7: SURVEY/PROGRAM: | B7: American Community Survey
A8: VINTAGE: | B8: 2023
A9: DATASET: | B9: ACSDT1Y2023
A10: PRODUCT: | B10: ACS 1-Year Estimates Detailed Tables
A11: UNIVERSE: | B11: Workers 16 years and over
A12: MLA: | B12: U.S. Census Bureau, U.S. Department of Commerce and U.S. Census Bureau. "Means of Transportation to Work." American Community Survey, ACS 1-Year Estimates Detailed Tables, Table B08301, 2023, https://data.census.gov/table/ACSDT1Y2023.B08301?q=B08301: Means of Transportation to Work&g=050XX00US06001,06013,06041,06055,06075,06081,06085,06095,06097&y=2023. Accessed on September 17, 2024.
A13: FTP URL: | B13: None
A14: API URL: | B14: https://api.census.gov/data/2023/acs/acs1
A16: USER SELECTIONS
A17: TABLES | B17: B08301
A18: GEOS | B18: Alameda County, California; Contra Costa County, California; Marin County, California; Napa County, California; San Francisco County, California; Santa Clara County, California; Sonoma County, California; Solano County, California; San Mateo County, California
A19: VINTAGES | B19: 2023
A21: EXCLUDED COLUMNS | B21: None
A23: APPLIED FILTERS | B23: None
A25: APPLIED SORTS | B25: None
A27: PIVOT & GROUPING
A28: PIVOT COLUMNS | B28: None
A29: PIVOT MODE | B29: Off
A30: ROW GROUPS | B30: None
A31: VALUE COLUMNS | B31: None
A33: WEB ADDRESS | B33: https://data.census.gov/table/ACSDT1Y2023.B08301?q=B08301:%20Means%20of%20Transportation%20to%20Work&g=050XX00US06001,06013,06041,06055,06075,06081,06085,06095,06097&y=2023
A35: TABLE NOTES
B36: Although the American Community Survey (ACS) produces population, demographic and housing unit estimates, the decennial census is the official source of population totals for April 1st of each decennial year. In between censuses, the Census Bureau's Population Estimates Program produces and disseminates the official estimates of the population for the nation, states, counties, cities, and towns and estimates of housing units and the group quarters population for states and counties.
B37: Information about the American Community Survey (ACS) can be found on the ACS website. Supporting documentation including code lists, subject definitions, data accuracy, and statistical testing, and a full list of ACS tables and table shells (without estimates) can be found on the Technical Documentation section of the ACS website. Sample size and data quality measures (including coverage rates, allocation rates, and response rates) can be found on the American Community Survey website in the Methodology section.
B38: Source: U.S. Census Bureau, 2023 American Community Survey 1-Year Estimates
B39: ACS data generally reflect the geographic boundaries of legal and statistical areas as of January 1 of the estimate year. For more information, see Geography Boundaries by Year.
B40: Data are based on a sample and are subject to sampling variability. The degree of uncertainty for an estimate arising from sampling variability is represented through the use of a margin of error. The value shown here is the 90 percent margin of error. The margin of error can be interpreted roughly as providing a 90 percent probability that the interval defined by the estimate minus the margin of error and the estimate plus the margin of error (the lower and upper confidence bounds) contains the true value. In addition to sampling variability, the ACS estimates are subject to nonsampling error (for a discussion of nonsampling variability, see ACS Technical Documentation). The effect of nonsampling error is not represented in these tables.
B41: Users must consider potential differences in geographic boundaries, questionnaire content or coding, or other methodological issues when comparing ACS data from different years. Statistically significant differences shown in ACS Comparison Profiles, or in data users' own analysis, may be the result of these differences and thus might not necessarily reflect changes to the social, economic, housing, or demographic characteristics being compared. For more information, see Comparing ACS Data.
B42: Workers include members of the Armed Forces and civilians who were at work last week.
B43: Estimates of urban and rural populations, housing units, and characteristics reflect boundaries of urban areas defined based on 2020 Census data. As a result, data for urban and rural areas from the ACS do not necessarily reflect the results of ongoing urbanization.
B44: Explanation of Symbols:- The estimate could not be computed because there were an insufficient number of sample observations. For a ratio of medians estimate, one or both of the median estimates falls in the lowest interval or highest interval of an open-ended distribution. For a 5-year median estimate, the margin of error associated with a median was larger than the median itself.N The estimate or margin of error cannot be displayed because there were an insufficient number of sample cases in the selected geographic area. (X) The estimate or margin of error is not applicable or not available.median- The median falls in the lowest interval of an open-ended distribution (for example "2,500-")median+ The median falls in the highest interval of an open-ended distribution (for example "250,000+").** The margin of error could not be computed because there were an insufficient number of sample observations.*** The margin of error could not be computed because the median falls in the lowest interval or highest interval of an open-ended distribution.***** A margin of error is not appropriate because the corresponding estimate is controlled to an independent population or housing estimate. Effectively, the corresponding estimate has no sampling error and the margin of error may be treated as zero.
A46: COLUMN NOTES | B46: None

Sheet Data-ACSDT1Y2023
B1: Alameda County, California | D1: Contra Costa County, California | F1: Marin County, California | H1: Napa County, California | J1: San Francisco County, California | L1: San Mateo County, California | N1: Santa Clara County, California | P1: Solano County, California | R1: Sonoma County, California
A2: Label | B2: Estimate | C2: Margin of Error | D2: Estimate | E2: Margin of Error | F2: Estimate | G2: Margin of Error | H2: Estimate | I2: Margin of Error | J2: Estimate | K2: Margin of Error | L2: Estimate | M2: Margin of Error | N2: Estimate | O2: Margin of Error | P2: Estimate | Q2: Margin of Error | R2: Estimate | S2: Margin of Error
A3: Total: | B3: 826474 | C3: ±10,757 | D3: 560086 | E3: ±7,855 | F3: 121331 | G3: ±3,704 | H3: 67918 | I3: ±2,420 | J3: 460397 | K3: ±6,195 | L3: 377939 | M3: ±5,759 | N3: 981958 | O3: ±10,355 | P3: 207335 | Q3: ±5,118 | R3: 244909 | S3: ±5,361
A4: Car, truck, or van: | B4: 527734 | C4: ±10,851 | D4: 401743 | E4: ±8,436 | F4: 75757 | G4: ±4,238 | H4: 53504 | I4: ±3,060 | J4: 169270 | K4: ±6,455 | L4: 266924 | M4: ±6,392 | N4: 746589 | O4: ±10,992 | P4: 174760 | Q4: ±5,015 | R4: 195481 | S4: ±5,868
A5: Drove alone | B5: 452339 | C5: ±10,742 | D5: 341396 | E5: ±8,182 | F5: 67085 | G5: ±4,109 | H5: 47032 | I5: ±3,552 | J5: 136951 | K5: ±5,269 | L5: 228231 | M5: ±6,837 | N5: 644885 | O5: ±12,951 | P5: 154819 | Q5: ±5,212 | R5: 170305 | S5: ±5,513
A6: Carpooled: | B6: 75395 | C6: ±5,542 | D6: 60347 | E6: ±5,743 | F6: 8672 | G6: ±2,006 | H6: 6472 | I6: ±2,095 | J6: 32319 | K6: ±3,740 | L6: 38693 | M6: ±3,967 | N6: 101704 | O6: ±6,422 | P6: 19941 | Q6: ±2,979 | R6: 25176 | S6: ±3,801
A7: In 2-person carpool | B7: 56385 | C7: ±3,918 | D7: 43121 | E7: ±4,418 | F7: 7098 | G7: ±1,976 | H7: 2615 | I7: ±1,008 | J7: 25356 | K7: ±3,114 | L7: 27279 | M7: ±3,402 | N7: 73452 | O7: ±5,414 | P7: 15972 | Q7: ±2,758 | R7: 15555 | S7: ±2,855
A8: In 3-person carpool | B8: 13838 | C8: ±3,425 | D8: 11522 | E8: ±2,646 | F8: 1431 | G8: ±657 | H8: 982 | I8: ±522 | J8: 4018 | K8: ±1,939 | L8: 5910 | M8: ±1,730 | N8: 15815 | O8: ±2,794 | P8: 2394 | Q8: ±906 | R8: 7315 | S8: ±2,478
A9: In 4-person carpool | B9: 3065 | C9: ±1,344 | D9: 3690 | E9: ±1,455 | F9: 79 | G9: ±79 | H9: 471 | I9: ±476 | J9: 1430 | K9: ±829 | L9: 3587 | M9: ±1,620 | N9: 8457 | O9: ±2,360 | P9: 455 | Q9: ±310 | R9: 1349 | S9: ±978
A10: In 5- or 6-person carpool | B10: 1821 | C10: ±705 | D10: 1247 | E10: ±550 | F10: 64 | G10: ±108 | H10: 1995 | I10: ±1,850 | J10: 1045 | K10: ±710 | L10: 1649 | M10: ±857 | N10: 2697 | O10: ±1,357 | P10: 843 | Q10: ±594 | R10: 512 | S10: ±420
A11: In 7-or-more-person carpool | B11: 286 | C11: ±283 | D11: 767 | E11: ±472 | F11: 0 | G11: ±221 | H11: 409 | I11: ±342 | J11: 470 | K11: ±357 | L11: 268 | M11: ±229 | N11: 1283 | O11: ±615 | P11: 277 | Q11: ±234 | R11: 445 | S11: ±473
A12: Public transportation (excluding taxicab): | B12: 74554 | C12: ±4,758 | D12: 35857 | E12: ±3,662 | F12: 4750 | G12: ±1,168 | H12: 576 | I12: ±318 | J12: 101330 | K12: ±5,874 | L12: 20563 | M12: ±2,998 | N12: 28329 | O12: ±3,358 | P12: 3991 | Q12: ±1,465 | R12: 1842 | S12: ±651
A13: Bus | B13: 25253 | C13: ±3,326 | D13: 7968 | E13: ±1,422 | F13: 2332 | G13: ±1,045 | H13: 236 | I13: ±190 | J13: 64337 | K13: ±4,087 | L13: 10333 | M13: ±2,263 | N13: 16852 | O13: ±2,659 | P13: 1144 | Q13: ±679 | R13: 1041 | S13: ±483
A14: Subway or elevated rail | B14: 35648 | C14: ±3,776 | D14: 19058 | E14: ±2,889 | F14: 49 | G14: ±80 | H14: 0 | I14: ±221 | J14: 24141 | K14: ±2,990 | L14: 5553 | M14: ±1,424 | N14: 2364 | O14: ±850 | P14: 244 | Q14: ±198 | R14: 0 | S14: ±221
... A23: Worked from home | B23: 168282 | C23: ±8,059 | D23: 99371 | E23: ±5,645 | F23: 31875 | G23: ±2,945 | H23: 8760 | I23: ±1,640 | J23: 112342 | K23: ±5,579 | L23: 69928 | M23: ±4,207 | N23: 160686 | O23: ±7,281 | P23: 23047 | Q23: ±2,741 | R23: 36897 | S23: ±3,605
A25: Worked at home Bay Area | B25: =SUMIF($B$2:$S$2,"=Estimate",$B$23:$S$23) -> 711188
A26: Total | B26: =SUMIF($B$2:$S$2,"=Estimate",$B$3:$S$3) -> 3848347
A27: Share | B27: =B25/B26 -> 0.1848035

Sheet Info-ACSDT1Y2022
A1: Means of Transportation to Work
A3: Note: The table shown may have been modified by user selections. Some information may be missing.
A5: DATA NOTES
A6: TABLE ID: | B6: B08301
A7: SURVEY/PROGRAM: | B7: American Community Survey
A8: VINTAGE: | B8: 2022
A9: DATASET: | B9: ACSDT1Y2022
A10: PRODUCT: | B10: ACS 1-Year Estimates Detailed Tables
A11: UNIVERSE: | B11: Workers 16 years and over
A12: FTP URL: | B12: None
A13: API URL: | B13: https://api.census.gov/data/2022/acs/acs1
A15: USER SELECTIONS
A16: TABLES | B16: B08301
A17: DATASETS | B17: ACS 1-Year Estimates Detailed Tables
A18: GEOS | B18: San Francisco County, California; Alameda County, California; Contra Costa County, California; Marin County, California; Napa County, California; San Mateo County, California; Santa Clara County, California; Solano County, California; Sonoma County, California
A19: VINTAGES | B19: 2022
A21: EXCLUDED COLUMNS | B21: None
A23: APPLIED FILTERS | B23: None
A25: APPLIED SORTS | B25: None
A27: PIVOT & GROUPING
A28: PIVOT COLUMNS | B28: None
A29: PIVOT MODE | B29: Off
A30: ROW GROUPS | B30: None
A31: VALUE COLUMNS | B31: None
A33: WEB ADDRESS | B33: https://data.census.gov/table?q=B08301&g=050XX00US06001,06013,06041,06055,06075,06081,06085,06095,06097&y=2022&d=ACS+1-Year+Estimates+Detailed+Tables&tid=ACSDT1Y2022.B08301
A35: TABLE NOTES | B35: Although the American Community Survey (ACS) produces population, demographic and housing unit estimates, the decennial census is the official source of population totals for April 1st of each decennial year. In between censuses, the Census Bureau's Population Estimates Program produces and disseminates the official estimates of the population for the nation, states, counties, cities, and towns and estimates of housing units for states and counties.
B36: Information about the American Community Survey (ACS) can be found on the ACS website. Supporting documentation including code lists, subject definitions, data accuracy, and statistical testing, and a full list of ACS tables and table shells (without estimates) can be found on the Technical Documentation section of the ACS website. Sample size and data quality measures (including coverage rates, allocation rates, and response rates) can be found on the American Community Survey website in the Methodology section.
B37: Source: U.S. Census Bureau, 2022 American Community Survey 1-Year Estimates
B38: Data are based on a sample and are subject to sampling variability. The degree of uncertainty for an estimate arising from sampling variability is represented through the use of a margin of error. The value shown here is the 90 percent margin of error. The margin of error can be interpreted roughly as providing a 90 percent probability that the interval defined by the estimate minus the margin of error and the estimate plus the margin of error (the lower and upper confidence bounds) contains the true value. In addition to sampling variability, the ACS estimates are subject to nonsampling error (for a discussion of nonsampling variability, see ACS Technical Documentation). The effect of nonsampling error is not represented in these tables.
B39: Workers include members of the Armed Forces and civilians who were at work last week.
B40: The 2022 American Community Survey (ACS) data generally reflect the March 2020 Office of Management and Budget (OMB) delineations of metropolitan and micropolitan statistical areas. In certain instances the names, codes, and boundaries of the principal cities shown in ACS tables may differ from the OMB delineations due to differences in the effective dates of the geographic entities.
B41: Estimates of urban and rural populations, housing units, and characteristics reflect boundaries of urban areas defined based on 2020 Census data. As a result, data for urban and rural areas from the ACS do not necessarily reflect the results of ongoing urbanization.
B42: Explanation of Symbols:- The estimate could not be computed because there were an insufficient number of sample observations. For a ratio of medians estimate, one or both of the median estimates falls in the lowest interval or highest interval of an open-ended distribution. For a 5-year median estimate, the margin of error associated with a median was larger than the median itself.N The estimate or margin of error cannot be displayed because there were an insufficient number of sample cases in the selected geographic area. (X) The estimate or margin of error is not applicable or not available.median- The median falls in the lowest interval of an open-ended distribution (for example "2,500-")median+ The median falls in the highest interval of an open-ended distribution (for example "250,000+").** The margin of error could not be computed because there were an insufficient number of sample observations.*** The margin of error could not be computed because the median falls in the lowest interval or highest interval of an open-ended distribution.***** A margin of error is not appropriate because the corresponding estimate is controlled to an independent population or housing estimate. Effectively, the corresponding estimate has no sampling error and the margin of error may be treated as zero.
A44: COLUMN NOTES | B44: None

Sheet Data-ACSDT1Y2022
B1: Alameda County, California | D1: Contra Costa County, California | F1: Marin County, California | H1: San Francisco County, California | J1: San Mateo County, California | L1: Santa Clara County, California | N1: Solano County, California | P1: Sonoma County, California
A2: Label | B2: Estimate | C2: Margin of Error | D2: Estimate | E2: Margin of Error | F2: Estimate | G2: Margin of Error | H2: Estimate | I2: Margin of Error | J2: Estimate | K2: Margin of Error | L2: Estimate | M2: Margin of Error | N2: Estimate | O2: Margin of Error | P2: Estimate | Q2: Margin of Error
A3: Total: | B3: 835685 | C3: ±9,162 | D3: 555483 | E3: ±7,182 | F3: 122594 | G3: ±4,141 | H3: 465181 | I3: ±6,310 | J3: 375625 | K3: ±5,938 | L3: 967786 | M3: ±8,362 | N3: 202290 | O3: ±5,510 | P3: 240821 | Q3: ±5,612
A4: Car, truck, or van: | B4: 495616 | C4: ±8,776 | D4: 390453 | E4: ±9,121 | F4: 68395 | G4: ±4,837 | H4: 163366 | I4: ±6,047 | J4: 245456 | K4: ±6,362 | L4: 659260 | M4: ±11,219 | N4: 167990 | O4: ±4,969 | P4: 193211 | Q4: ±4,989
A5: Drove alone | B5: 430950 | C5: ±8,297 | D5: 333309 | E5: ±8,407 | F5: 61421 | G5: ±4,538 | H5: 135266 | I5: ±6,054 | J5: 210245 | K5: ±6,270 | L5: 573510 | M5: ±10,349 | N5: 143896 | O5: ±4,845 | P5: 173114 | Q5: ±4,969
A6: Carpooled: | B6: 64666 | C6: ±5,877 | D6: 57144 | E6: ±5,298 | F6: 6974 | G6: ±1,879 | H6: 28100 | I6: ±3,660 | J6: 35211 | K6: ±4,154 | L6: 85750 | M6: ±6,170 | N6: 24094 | O6: ±3,618 | P6: 20097 | Q6: ±3,251
A7: In 2-person carpool | B7: 50841 | C7: ±5,436 | D7: 42207 | E7: ±3,872 | F7: 5753 | G7: ±1,754 | H7: 19888 | I7: ±3,042 | J7: 25185 | K7: ±3,370 | L7: 63413 | M7: ±5,354 | N7: 17661 | O7: ±2,969 | P7: 15431 | Q7: ±2,509
A8: In 3-person carpool | B8: 10113 | C8: ±2,452 | D8: 11394 | E8: ±2,610 | F8: 855 | G8: ±538 | H8: 4511 | I8: ±1,383 | J8: 5221 | K8: ±1,833 | L8: 13374 | M8: ±2,084 | N8: 4640 | O8: ±2,021 | P8: 1506 | Q8: ±564
A9: In 4-person carpool | B9: 2229 | C9: ±1,049 | D9: 2103 | E9: ±720 | F9: 366 | G9: ±473 | H9: 2521 | I9: ±1,231 | J9: 3593 | K9: ±1,783 | L9: 5573 | M9: ±1,605 | N9: 893 | O9: ±657 | P9: 2272 | Q9: ±2,161
A10: In 5- or 6-person carpool | B10: 1280 | C10: ±706 | D10: 968 | E10: ±590 | F10: 0 | G10: ±218 | H10: 794 | I10: ±436 | J10: 1082 | K10: ±680 | L10: 1527 | M10: ±853 | N10: 656 | O10: ±490 | P10: 380 | Q10: ±401
A11: In 7-or-more-person carpool | B11: 203 | C11: ±239 | D11: 472 | E11: ±356 | F11: 0 | G11: ±218 | H11: 386 | I11: ±492 | J11: 130 | K11: ±213 | L11: 1863 | M11: ±1,041 | N11: 244 | O11: ±211 | P11: 508 | Q11: ±258
A12: Public transportation (excluding taxicab): | B12: 57111 | C12: ±4,263 | D12: 25259 | E12: ±3,279 | F12: 6147 | G12: ±2,338 | H12: 78649 | I12: ±4,666 | J12: 15459 | K12: ±2,141 | L12: 19997 | M12: ±2,657 | N12: 1977 | O12: ±819 | P12: 2180 | Q12: ±830
A13: Bus | B13: 17073 | C13: ±1,948 | D13: 5811 | E13: ±1,595 | F13: 4813 | G13: ±2,166 | H13: 52619 | I13: ±3,971 | J13: 5990 | K13: ±1,468 | L13: 12914 | M13: ±2,378 | N13: 353 | O13: ±327 | P13: 1129 | Q13: ±492
A14: Subway or elevated rail | B14: 31117 | C14: ±3,543 | D14: 14230 | E14: ±2,358 | F14: 0 | G14: ±218 | H14: 14815 | I14: ±2,284 | J14: 4839 | K14: ±954 | L14: 1567 | M14: ±693 | N14: 180 | O14: ±279 | P14: 176 | Q14: ±250
... A23: Worked from home | B23: 234028 | C23: ±8,204 | D23: 115159 | E23: ±5,481 | F23: 40124 | G23: ±3,062 | H23: 151314 | I23: ±6,574 | J23: 95427 | K23: ±4,807 | L23: 240372 | M23: ±7,528 | N23: 26569 | O23: ±2,840 | P23: 35126 | Q23: ±2,995
A25: Worked at home Bay Area | B25: =SUMIF($B$2:$S$2,"=Estimate",$B$23:$S$23) -> 938119
A26: Total | B26: =SUMIF($B$2:$S$2,"=Estimate",$B$3:$S$3) -> 3765465
A27: Share | B27: =B25/B26 -> 0.24913762

Sheet Info-ACSDT1Y2021
A1: MEANS OF TRANSPORTATION TO WORK
A3: Note: The table shown may have been modified by user selections. Some information may be missing.
A5: DATA NOTES
A6: TABLE ID: | B6: B08301
A7: SURVEY/PROGRAM: | B7: American Community Survey
A8: VINTAGE: | B8: 2021
A9: DATASET: | B9: ACSDT1Y2021
A10: PRODUCT: | B10: ACS 1-Year Estimates Detailed Tables
A11: UNIVERSE: | B11: Workers 16 years and over
A12: FTP URL: | B12: None
A13: API URL: | B13: https://api.census.gov/data/2021/acs/acs1
A15: USER SELECTIONS
A16: TABLES | B16: B08301
A17: GEOS | B17: Alameda County, California; Contra Costa County, California; Marin County, California; San Francisco County, California; San Mateo County, California; Solano County, California; Sonoma County, California; Santa Clara County, California; Napa County, California
A19: EXCLUDED COLUMNS | B19: None
A21: APPLIED FILTERS | B21: None
A23: APPLIED SORTS | B23: None
A25: PIVOT & GROUPING
A26: PIVOT COLUMNS | B26: None
A27: PIVOT MODE | B27: Off
A28: ROW GROUPS | B28: None
A29: VALUE COLUMNS | B29: None
A31: WEB ADDRESS | B31: https://data.census.gov/table?q=B08301:+MEANS+OF+TRANSPORTATION+TO+WORK&g=0500000US06001,06013,06041,06055,06075,06081,06085,06095,06097&tid=ACSDT1Y2021.B08301
A33: TABLE NOTES | B33: Although the American Community Survey (ACS) produces population, demographic and housing unit estimates, it is the Census Bureau's Population Estimates Program that produces and disseminates the official estimates of the population for the nation, states, counties, cities, and towns and estimates of housing units for states and counties.
B34: Supporting documentation on code lists, subject definitions, data accuracy, and statistical testing can be found on the American Community Survey website in the Technical Documentation section. Sample size and data quality measures (including coverage rates, allocation rates, and response rates) can be found on the American Community Survey website in the Methodology section.
B35: Source: U.S. Census Bureau, 2021 American Community Survey 1-Year Estimates
B36: Data are based on a sample and are subject to sampling variability. The degree of uncertainty for an estimate arising from sampling variability is represented through the use of a margin of error. The value shown here is the 90 percent margin of error. The margin of error can be interpreted roughly as providing a 90 percent probability that the interval defined by the estimate minus the margin of error and the estimate plus the margin of error (the lower and upper confidence bounds) contains the true value. In addition to sampling variability, the ACS estimates are subject to nonsampling error (for a discussion of nonsampling variability, see ACS Technical Documentation). The effect of nonsampling error is not represented in these tables.
B37: Workers include members of the Armed Forces and civilians who were at work last week.
B38: The 2021 American Community Survey (ACS) data generally reflect the March 2020 Office of Management and Budget (OMB) delineations of metropolitan and micropolitan statistical areas. In certain instances the names, codes, and boundaries of the principal cities shown in ACS tables may differ from the OMB delineations due to differences in the effective dates of the geographic entities.
B39: Estimates of urban and rural populations, housing units, and characteristics reflect boundaries of urban areas defined based on Census 2010 data. As a result, data for urban and rural areas from the ACS do not necessarily reflect the results of ongoing urbanization.
B40: Explanation of Symbols:- The estimate could not be computed because there were an insufficient number of sample observations. For a ratio of medians estimate, one or both of the median estimates falls in the lowest interval or highest interval of an open-ended distribution. For a 5-year median estimate, the margin of error associated with a median was larger than the median itself.N The estimate or margin of error cannot be displayed because there were an insufficient number of sample cases in the selected geographic area. (X) The estimate or margin of error is not applicable or not available.median- The median falls in the lowest interval of an open-ended distribution (for example "2,500-")median+ The median falls in the highest interval of an open-ended distribution (for example "250,000+").** The margin of error could not be computed because there were an insufficient number of sample observations.*** The margin of error could not be computed because the median falls in the lowest interval or highest interval of an open-ended distribution.***** A margin of error is not appropriate because the corresponding estimate is controlled to an independent population or housing estimate. Effectively, the corresponding estimate has no sampling error and the margin of error may be treated as zero.
A42: COLUMN NOTES | B42: None

Sheet Data-ACSDT1Y2021
B1: Alameda County, California | D1: Contra Costa County, California | F1: Marin County, California | H1: San Francisco County, California | J1: San Mateo County, California | L1: Santa Clara County, California | N1: Solano County, California | P1: Sonoma County, California
A2: Label | B2: Estimate | C2: Margin of Error | D2: Estimate | E2: Margin of Error | F2: Estimate | G2: Margin of Error | H2: Estimate | I2: Margin of Error | J2: Estimate | K2: Margin of Error | L2: Estimate | M2: Margin of Error | N2: Estimate | O2: Margin of Error | P2: Estimate | Q2: Margin of Error
A3: Total: | B3: 820292 | C3: ±8,105 | D3: 546082 | E3: ±7,771 | F3: 123636 | G3: ±3,740 | H3: 438943 | I3: ±7,596 | J3: 372133 | K3: ±5,318 | L3: 931537 | M3: ±8,505 | N3: 203334 | O3: ±4,847 | P3: 232502 | Q3: ±4,669
A4: Car, truck, or van: | B4: 458567 | C4: ±9,650 | D4: 359409 | E4: ±7,554 | F4: 69949 | G4: ±3,825 | H4: 138291 | I4: ±6,677 | J4: 216862 | K4: ±6,427 | L4: 549075 | M4: ±11,789 | N4: 166810 | O4: ±5,102 | P4: 173668 | Q4: ±5,132
A5: Drove alone | B5: 403663 | C5: ±9,311 | D5: 312869 | E5: ±8,270 | F5: 61570 | G5: ±3,814 | H5: 118249 | I5: ±6,140 | J5: 187160 | K5: ±6,860 | L5: 484962 | M5: ±11,315 | N5: 149972 | O5: ±4,740 | P5: 152302 | Q5: ±5,622
A6: Carpooled: | B6: 54904 | C6: ±3,449 | D6: 46540 | E6: ±5,195 | F6: 8379 | G6: ±2,048 | H6: 20042 | I6: ±3,138 | J6: 29702 | K6: ±3,965 | L6: 64113 | M6: ±4,485 | N6: 16838 | O6: ±2,851 | P6: 21366 | Q6: ±2,959
A7: In 2-person carpool | B7: 43358 | C7: ±3,446 | D7: 34761 | E7: ±4,577 | F7: 4789 | G7: ±1,303 | H7: 13988 | I7: ±2,182 | J7: 22289 | K7: ±3,685 | L7: 46592 | M7: ±3,767 | N7: 13429 | O7: ±2,531 | P7: 14585 | Q7: ±2,132
A8: In 3-person carpool | B8: 7822 | C8: ±1,573 | D8: 5543 | E8: ±1,464 | F8: 3112 | G8: ±1,235 | H8: 4412 | I8: ±1,906 | J8: 4541 | K8: ±1,290 | L8: 9192 | M8: ±2,126 | N8: 2224 | O8: ±817 | P8: 4935 | Q8: ±1,832
A9: In 4-person carpool | B9: 2825 | C9: ±855 | D9: 4305 | E9: ±1,685 | F9: 284 | G9: ±304 | H9: 1253 | I9: ±741 | J9: 1319 | K9: ±649 | L9: 4433 | M9: ±1,447 | N9: 228 | O9: ±163 | P9: 849 | Q9: ±710
A10: In 5- or 6-person carpool | B10: 796 | C10: ±355 | D10: 1739 | E10: ±1,192 | F10: 194 | G10: ±300 | H10: 235 | I10: ±186 | J10: 905 | K10: ±1,227 | L10: 3222 | M10: ±1,252 | N10: 598 | O10: ±429 | P10: 591 | Q10: ±606
A11: In 7-or-more-person carpool | B11: 103 | C11: ±119 | D11: 192 | E11: ±319 | F11: 0 | G11: ±218 | H11: 154 | I11: ±253 | J11: 648 | K11: ±565 | L11: 674 | M11: ±544 | N11: 359 | O11: ±334 | P11: 406 | Q11: ±373
A12: Public transportation (excluding taxicab): | B12: 33280 | C12: ±3,098 | D12: 15407 | E12: ±2,327 | F12: 2123 | G12: ±906 | H12: 49819 | I12: ±4,467 | J12: 12419 | K12: ±2,157 | L12: 10796 | M12: ±1,954 | N12: 3455 | O12: ±1,220 | P12: 1148 | Q12: ±497
A13: Bus | B13: 15269 | C13: ±2,082 | D13: 4564 | E13: ±1,335 | F13: 1689 | G13: ±897 | H13: 35270 | I13: ±3,643 | J13: 6934 | K13: ±1,742 | L13: 7171 | M13: ±1,615 | N13: 1655 | O13: ±981 | P13: 892 | Q13: ±446
A14: Subway or elevated rail | B14: 14758 | C14: ±2,245 | D14: 7529 | E14: ±1,787 | F14: 46 | G14: ±76 | H14: 10552 | I14: ±1,904 | J14: 3055 | K14: ±992 | L14: 540 | M14: ±359 | N14: 802 | O14: ±665 | P14: 64 | Q14: ±108
... A23: Worked from home | B23: 287142 | C23: ±7,194 | D23: 152844 | E23: ±5,647 | F23: 44360 | G23: ±2,958 | H23: 200083 | I23: ±7,499 | J23: 122795 | K23: ±5,756 | L23: 330900 | M23: ±8,434 | N23: 25953 | O23: ±2,901 | P23: 47845 | Q23: ±3,954
A25: Worked at home Bay Area | B25: =SUMIF($B$2:$S$2,"=Estimate",$B$23:$S$23) -> 1211922
A26: Total | B26: =SUMIF($B$2:$S$2,"=Estimate",$B$3:$S$3) -> 3668459
A27: Share | B27: =B25/B26 -> 0.33036269

Sheet Info-ACSDT5Y2020
A1: MEANS OF TRANSPORTATION TO WORK
A3: Note: The table shown may have been modified by user selections. Some information may be missing.
A5: DATA NOTES
A6: TABLE ID: | B6: B08301
A7: SURVEY/PROGRAM: | B7: American Community Survey
A8: VINTAGE: | B8: 2020
A9: DATASET: | B9: ACSDT5Y2020
A10: PRODUCT: | B10: ACS 5-Year Estimates Detailed Tables
A11: UNIVERSE: | B11: Workers 16 years and over
A12: FTP URL: | B12: None
A13: API URL: | B13: https://api.census.gov/data/2020/acs/acs5
A15: USER SELECTIONS
A16: TABLES | B16: B08301
A17: GEOS | B17: Alameda County, California; Contra Costa County, California; Marin County, California; San Francisco County, California; San Mateo County, California; Solano County, California; Sonoma County, California; Santa Clara County, California; Napa County, California
A19: EXCLUDED COLUMNS | B19: None
A21: APPLIED FILTERS | B21: None
A23: APPLIED SORTS | B23: None
A25: PIVOT & GROUPING
A26: PIVOT COLUMNS | B26: None
A27: PIVOT MODE | B27: Off
A28: ROW GROUPS | B28: None
A29: VALUE COLUMNS | B29: None
A31: WEB ADDRESS | B31: https://data.census.gov/table?q=B08301:+MEANS+OF+TRANSPORTATION+TO+WORK&g=0500000US06001,06013,06041,06055,06075,06081,06085,06095,06097&tid=ACSDT5Y2020.B08301
A33: TABLE NOTES | B33: Although the American Community Survey (ACS) produces population, demographic and housing unit estimates, for 2020, the 2020 Census provides the official counts of the population and housing units for the nation, states, counties, cities, and towns. For 2016 to 2019, the Population Estimates Program provides estimates of the population for the nation, states, counties, cities, and towns and intercensal housing unit estimates for the nation, states, and counties.
B34: Supporting documentation on code lists, subject definitions, data accuracy, and statistical testing can be found on the American Community Survey website in the Technical Documentation section. Sample size and data quality measures (including coverage rates, allocation rates, and response rates) can be found on the American Community Survey website in the Methodology section.
B35: Source: U.S. Census Bureau, 2016-2020 American Community Survey 5-Year Estimates
B36: Data are based on a sample and are subject to sampling variability. The degree of uncertainty for an estimate arising from sampling variability is represented through the use of a margin of error. The value shown here is the 90 percent margin of error. The margin of error can be interpreted roughly as providing a 90 percent probability that the interval defined by the estimate minus the margin of error and the estimate plus the margin of error (the lower and upper confidence bounds) contains the true value. In addition to sampling variability, the ACS estimates are subject to nonsampling error (for a discussion of nonsampling variability, see ACS Technical Documentation). The effect of nonsampling error is not represented in these tables.
B37: Workers include members of the Armed Forces and civilians who were at work last week.
B38: 2019 ACS data products include updates to several categories of the existing means of transportation question. For more information, see: Change to Means of Transportation.
B39: The 2016-2020 American Community Survey (ACS) data generally reflect the September 2018 Office of Management and Budget (OMB) delineations of metropolitan and micropolitan statistical areas. In certain instances, the names, codes, and boundaries of the principal cities shown in ACS tables may differ from the OMB delineation lists due to differences in the effective dates of the geographic entities.
B40: Estimates of urban and rural populations, housing units, and characteristics reflect boundaries of urban areas defined based on Census 2010 data. As a result, data for urban and rural areas from the ACS do not necessarily reflect the results of ongoing urbanization.
B41: Explanation of Symbols:- The estimate could not be computed because there were an insufficient number of sample observations. For a ratio of medians estimate, one or both of the median estimates falls in the lowest interval or highest interval of an open-ended distribution.N The estimate or margin of error cannot be displayed because there were an insufficient number of sample cases in the selected geographic area. (X) The estimate or margin of error is not applicable or not available.median- The median falls in the lowest interval of an open-ended distribution (for example "2,500-")median+ The median falls in the highest interval of an open-ended distribution (for example "250,000+").** The margin of error could not be computed because there were an insufficient number of sample observations.*** The margin of error could not be computed because the median falls in the lowest interval or highest interval of an open-ended distribution.***** A margin of error is not appropriate because the corresponding estimate is controlled to an independent population or housing estimate. Effectively, the corresponding estimate has no sampling error and the margin of error may be treated as zero.
A43: COLUMN NOTES | B43: None

Sheet Data-ACSDT5Y2020
B1: Alameda County, California | D1: Contra Costa County, California | F1: Marin County, California | H1: Napa County, California | J1: San Francisco County, California | L1: San Mateo County, California | N1: Santa Clara County, California | P1: Solano County, California | R1: Sonoma County, California
A2: Label | B2: Estimate | C2: Margin of Error | D2: Estimate | E2: Margin of Error | F2: Estimate | G2: Margin of Error | H2: Estimate | I2: Margin of Error | J2: Estimate | K2: Margin of Error | L2: Estimate | M2: Margin of Error | N2: Estimate | O2: Margin of Error | P2: Estimate | Q2: Margin of Error | R2: Estimate | S2: Margin of Error
A3: Total: | B3: 799481 | C3: ±4,695 | D3: 547220 | E3: ±3,489 | F3: 127210 | G3: ±1,790 | H3: 69147 | I3: ±1,053 | J3: 509743 | K3: ±3,382 | L3: 405104 | M3: ±2,731 | N3: 972577 | O3: ±4,104 | P3: 207283 | Q3: ±2,031 | R3: 248048 | S3: ±2,585
A4: Car, truck, or van: | B4: 544105 | C4: ±5,530 | D4: 418231 | E4: ±3,997 | F4: 89146 | G4: ±1,819 | H4: 59051 | I4: ±1,099 | J4: 189734 | K4: ±3,372 | L4: 303097 | M4: ±3,011 | N4: 789624 | O4: ±4,678 | P4: 183472 | Q4: ±2,228 | R4: 209988 | S4: ±2,876
A5: Drove alone | B5: 467989 | C5: ±4,861 | D5: 359707 | E5: ±3,697 | F5: 79546 | G5: ±1,960 | H5: 51787 | I5: ±1,046 | J5: 155297 | K5: ±3,059 | L5: 263177 | M5: ±3,176 | N5: 690759 | O5: ±4,490 | P5: 157234 | Q5: ±2,278 | R5: 184166 | S5: ±2,837
A6: Carpooled: | B6: 76116 | C6: ±2,590 | D6: 58524 | E6: ±2,249 | F6: 9600 | G6: ±984 | H6: 7264 | I6: ±641 | J6: 34437 | K6: ±1,721 | L6: 39920 | M6: ±1,668 | N6: 98865 | O6: ±2,731 | P6: 26238 | Q6: ±1,324 | R6: 25822 | S6: ±1,515
A7: In 2-person carpool | B7: 55335 | C7: ±2,220 | D7: 40789 | E7: ±1,750 | F7: 7448 | G7: ±827 | H7: 4647 | I7: ±463 | J7: 24054 | K7: ±1,264 | L7: 29164 | M7: ±1,282 | N7: 74901 | O7: ±2,457 | P7: 17518 | Q7: ±1,127 | R7: 19267 | S7: ±1,189
A8: In 3-person carpool | B8: 14113 | C8: ±1,069 | D8: 10743 | E8: ±999 | F8: 1387 | G8: ±395 | H8: 1573 | I8: ±340 | J8: 6479 | K8: ±873 | L8: 6960 | M8: ±715 | N8: 14559 | O8: ±1,318 | P8: 4753 | Q8: ±632 | R8: 3771 | S8: ±494
A9: In 4-person carpool | B9: 3740 | C9: ±505 | D9: 4209 | E9: ±686 | F9: 331 | G9: ±158 | H9: 430 | I9: ±190 | J9: 1989 | K9: ±411 | L9: 2487 | M9: ±526 | N9: 5282 | O9: ±699 | P9: 1701 | Q9: ±394 | R9: 1727 | S9: ±499
A10: In 5- or 6-person carpool | B10: 2147 | C10: ±496 | D10: 1734 | E10: ±445 | F10: 388 | G10: ±124 | H10: 510 | I10: ±271 | J10: 1012 | K10: ±212 | L10: 863 | M10: ±265 | N10: 2970 | O10: ±576 | P10: 1404 | Q10: ±449 | R10: 589 | S10: ±262
A11: In 7-or-more-person carpool | B11: 781 | C11: ±218 | D11: 1049 | E11: ±355 | F11: 46 | G11: ±41 | H11: 104 | I11: ±58 | J11: 903 | K11: ±213 | L11: 446 | M11: ±161 | N11: 1153 | O11: ±303 | P11: 862 | Q11: ±214 | R11: 468 | S11: ±200
A12: Public transportation (excluding taxicab): | B12: 114029 | C12: ±2,530 | D12: 56093 | E12: ±1,841 | F12: 10060 | G12: ±765 | H12: 940 | I12: ±183 | J12: 161085 | K12: ±3,133 | L12: 41094 | M12: ±1,579 | N12: 39110 | O12: ±1,638 | P12: 5671 | Q12: ±587 | R12: 3926 | S12: ±482
A13: Bus | B13: 35173 | C13: ±1,450 | D13: 9363 | E13: ±862 | F13: 6257 | G13: ±580 | H13: 501 | I13: ±146 | J13: 101416 | K13: ±2,536 | L13: 12762 | M13: ±1,069 | N13: 21071 | O13: ±1,239 | P13: 2348 | Q13: ±359 | R13: 3229 | S13: ±469
A14: Subway or elevated rail | B14: 64960 | C14: ±1,833 | D14: 38041 | E14: ±1,444 | F14: 76 | G14: ±71 | H14: 25 | I14: ±24 | J14: 41610 | K14: ±1,858 | L14: 17253 | M14: ±1,114 | N14: 2704 | O14: ±437 | P14: 956 | Q14: ±247 | R14: 146 | S14: ±99
... A23: Worked from home | B23: 87775 | C23: ±2,733 | D23: 54352 | E23: ±2,264 | F23: 21423 | G23: ±1,025 | H23: 5021 | I23: ±464 | J23: 60016 | K23: ±2,551 | L23: 38506 | M23: ±1,889 | N23: 94694 | O23: ±3,024 | P23: 13226 | Q23: ±1,053 | R23: 22512 | S23: ±1,225
A25: Worked at home Bay Area | B25: =SUMIF($B$2:$S$2,"=Estimate",$B$23:$S$23) -> 397525
A26: Total | B26: =SUMIF($B$2:$S$2,"=Estimate",$B$3:$S$3) -> 3885813
A27: Share | B27: =B25/B26 -> 0.10230163

Sheet Info-ACSDT1Y2019
A1: MEANS OF TRANSPORTATION TO WORK
A3: Note: The table shown may have been modified by user selections. Some information may be missing.
A5: DATA NOTES
A6: TABLE ID: | B6: B08301
A7: SURVEY/PROGRAM: | B7: American Community Survey
A8: VINTAGE: | B8: 2019
A9: DATASET: | B9: ACSDT1Y2019
A10: PRODUCT: | B10: ACS 1-Year Estimates Detailed Tables
A11: UNIVERSE: | B11: Workers 16 years and over
A12: FTP URL: | B12: None
A13: API URL: | B13: https://api.census.gov/data/2019/acs/acs1
A15: USER SELECTIONS
A16: TABLES | B16: B08301
A17: GEOS | B17: Alameda County, California; Contra Costa County, California; Marin County, California; San Francisco County, California; San Mateo County, California; Solano County, California; Sonoma County, California; Santa Clara County, California; Napa County, California
A19: EXCLUDED COLUMNS | B19: None
A21: APPLIED FILTERS | B21: None
A23: APPLIED SORTS | B23: None
A25: PIVOT & GROUPING
A26: PIVOT COLUMNS | B26: None
A27: PIVOT MODE | B27: Off
A28: ROW GROUPS | B28: None
A29: VALUE COLUMNS | B29: None
A31: WEB ADDRESS | B31: https://data.census.gov/table?q=B08301:+MEANS+OF+TRANSPORTATION+TO+WORK&g=0500000US06001,06013,06041,06055,06075,06081,06085,06095,06097&tid=ACSDT1Y2019.B08301
A33: TABLE NOTES | B33: Although the American Community Survey (ACS) produces population, demographic and housing unit estimates, it is the Census Bureau's Population Estimates Program that produces and disseminates the official estimates of the population for the nation, states, counties, cities, and towns and estimates of housing units for states and counties.
B34: Supporting documentation on code lists, subject definitions, data accuracy, and statistical testing can be found on the American Community Survey website in the Technical Documentation section. Sample size and data quality measures (including coverage rates, allocation rates, and response rates) can be found on the American Community Survey website in the Methodology section.
B35: Source: U.S. Census Bureau, 2019 American Community Survey 1-Year Estimates
B36: Data are based on a sample and are subject to sampling variability. The degree of uncertainty for an estimate arising from sampling variability is represented through the use of a margin of error. The value shown here is the 90 percent margin of error. The margin of error can be interpreted roughly as providing a 90 percent probability that the interval defined by the estimate minus the margin of error and the estimate plus the margin of error (the lower and upper confidence bounds) contains the true value. In addition to sampling variability, the ACS estimates are subject to nonsampling error (for a discussion of nonsampling variability, see ACS Technical Documentation). The effect of nonsampling error is not represented in these tables.
B37: Workers include members of the Armed Forces and civilians who were at work last week.
B38: 2019 ACS data products include updates to several categories of the existing means of transportation question. For more information, see: Change to Means of Transportation.
B39: The 2019 American Community Survey (ACS) data generally reflect the September 2018 Office of Management and Budget (OMB) delineations of metropolitan and micropolitan statistical areas. In certain instances the names, codes, and boundaries of the principal cities shown in ACS tables may differ from the OMB delineations due to differences in the effective dates of the geographic entities.
B40: Estimates of urban and rural populations, housing units, and characteristics reflect boundaries of urban areas defined based on Census 2010 data. As a result, data for urban and rural areas from the ACS do not necessarily reflect the results of ongoing urbanization.
B41: Explanation of Symbols: * An "**" entry in the margin of error column indicates that either no sample observations or too few sample observations were available to compute a standard error and thus the margin of error. A statistical test is not appropriate. * An "-" entry in the estimate column indicates that either no sample observations or too few sample observations were available to compute an estimate, or a ratio of medians cannot be calculated because one or both of the median estimates falls in the lowest interval or upper interval of an open-ended distribution, or the margin of error associated with a median was larger than the median itself. * An "-" following a median estimate means the median falls in the lowest interval of an open-ended distribution. * An "+" following a median estimate means the median falls in the upper interval of an open-ended distribution. * An "***" entry in the margin of error column indicates that the median falls in the lowest interval or upper interval of an open-ended distribution. A statistical test is not appropriate. * An "*****" entry in the margin of error column indicates that the estimate is controlled. A statistical test for sampling variability is not appropriate. * An "N" entry in the estimate and margin of error columns indicates that data for this geographic area cannot be displayed because the number of sample cases is too small. * An "(X)" means that the estimate is not applicable or not available.
A43: COLUMN NOTES | B43: None

Sheet Data-ACSDT1Y2019
B1: Alameda County, California | D1: Contra Costa County, California | F1: Marin County, California | H1: Napa County, California | J1: San Francisco County, California | L1: San Mateo County, California | N1: Santa Clara County, California | P1: Solano County, California | R1: Sonoma County, California
A2: Label | B2: Estimate | C2: Margin of Error | D2: Estimate | E2: Margin of Error | F2: Estimate | G2: Margin of Error | H2: Estimate | I2: Margin of Error | J2: Estimate | K2: Margin of Error | L2: Estimate | M2: Margin of Error | N2: Estimate | O2: Margin of Error | P2: Estimate | Q2: Margin of Error | R2: Estimate | S2: Margin of Error
A3: Total: | B3: 812004 | C3: ±10,648 | D3: 559646 | E3: ±7,121 | F3: 128119 | G3: ±3,688 | H3: 67719 | I3: ±2,630 | J3: 526022 | K3: ±5,686 | L3: 412818 | M3: ±5,957 | N3: 995301 | O3: ±10,071 | P3: 215285 | Q3: ±4,464 | R3: 251132 | S3: ±4,676
A4: Car, truck, or van: | B4: 564704 | C4: ±10,743 | D4: 436382 | E4: ±7,998 | F4: 89313 | G4: ±4,183 | H4: 58092 | I4: ±2,396 | J4: 183968 | K4: ±7,628 | L4: 313448 | M4: ±6,410 | N4: 844908 | O4: ±11,353 | P4: 191637 | Q4: ±4,875 | R4: 214680 | S4: ±5,428
A5: Drove alone | B5: 492931 | C5: ±10,376 | D5: 380290 | E5: ±7,760 | F5: 76934 | G5: ±3,996 | H5: 51318 | I5: ±2,349 | J5: 153014 | K5: ±6,727 | L5: 274447 | M5: ±6,667 | N5: 740364 | O5: ±12,719 | P5: 163732 | Q5: ±5,399 | R5: 189234 | S5: ±5,717
